File: data/primary_data/Zx1.csv
Time;Crosshead separation;Load;Extensometer elongation
(sec);(mm);(kN);(%)
0;0;0,25459;0,05855
0,1;0,00104;0,2551;0,05854
0,2;0,00284;0,25807;0,0586
0,3;0,00544;0,26516;0,05864
0,4;0,00888;0,28904;0,05871
0,5;0,0136;0,36803;0,0591
0,596;0,01936;0,46857;0,05952
0,678;0,02512;0,56985;0,06006
0,754;0,03116;0,66987;0,06058
0,828;0,03768;0,77193;0,06105
0,926;0,04748;0,87257;0,0614
1,026;0,05908;0,94973;0,06157
1,126;0,07236;1,01332;0,06174
1,226;0,08716;1,0828;0,06216
1,326;0,10336;1,17029;0,06253
1,412;0,11848;1,27039;0,06294
1,49;0,13296;1,37123;0,06332
1,562;0,14704;1,47252;0,0638
1,634;0,1618;1,57409;0,0642
1,7;0,176;1,6772;0,06463
1,76;0,18932;1,78015;0,06507
1,818;0,20268;1,88217;0,06543
1,872;0,21544;1,98614;0,06591
1,922;0,22752;2,08676;0,06633
1,972;0,23992;2,18888;0,06675
2,018;0,25156;2,28929;0,06719
2,062;0,26284;2,39256;0,0676
2,104;0,2738;2,49527;0,06803
2,144;0,2844;2,59737;0,06847
2,184;0,29516;2,7016;0,06892
2,222;0,30552;2,80477;0,0694
2,258;0,31544;2,90673;0,06988
2,294;0,32544;3,00981;0,07035
2,328;0,33504;3,11111;0,07078
2,362;0,34472;3,21446;0,07132
2,394;0,35392;3,31487;0,07179
2,426;0,36316;3,41894;0,07224
2,458;0,37248;3,5246;0,07273
2,49;0,38188;3,63078;0,0732
2,522;0,39132;3,7374;0,07367
2,552;0,4002;3,83985;0,07412
2,582;0,40912;3,94424;0,0746
2,612;0,41808;4,05074;0,07505
2,64;0,42656;4,15272;0,07551
2,668;0,43508;4,25798;0,07596
2,696;0,44364;4,36523;0,07648
2,722;0,45164;4,46526;0,07692
2,748;0,45964;4,56635;0,07736
2,774;0,46768;4,66847;0,07782
2,8;0,4758;4,77034;0,07828
2,826;0,48392;4,87436;0,07876
2,852;0,49204;4,98009;0,07928
2,878;0,50024;5,08633;0,07977
2,904;0,50848;5,19297;0,08027
2,928;0,51612;5,29302;0,0807
2,952;0,52376;5,39374;0,08112
2,976;0,5314;5,4964;0,08162
3;0,53904;5,5993;0,08206
3,024;0,54672;5,70415;0,08249
3,048;0,55444;5,81018;0,08299
3,072;0,56212;5,91683;0,08349
3,096;0,56988;6,02344;0,08396
3,118;0,577;6,12365;0,08438
3,142;0,5848;6,23224;0,08484
3,164;0,59192;6,3341;0,08528
3,186;0,59908;6,43529;0,08574
3,208;0,60624;6,53732;0,0862
3,23;0,61344;6,63958;0,08662
3,252;0,6206;6,74305;0,08706
3,274;0,62784;6,84671;0,08747
3,296;0,63508;6,95095;0,08789
3,318;0,64232;7,05558;0,08839
3,34;0,64956;7,16064;0,08886
3,362;0,6568;7,26571;0,08932
3,384;0,66404;7,37119;0,08981
3,406;0,67128;7,47713;0,0903
3,428;0,67852;7,58395;0,09074
3,45;0,68584;7,69142;0,09117
3,472;0,69316;7,79965;0,09161
3,494;0,70048;7,9091;0,09206
3,514;0,70716;8,01;0,09249
3,534;0,71384;8,11138;0,09289
3,554;0,72052;8,21304;0,09334
3,574;0,7272;8,31558;0,09378
3,594;0,73392;8,41738;0,09421
3,614;0,7406;8,52002;0,09467
3,634;0,74728;8,62211;0,0951
3,654;0,75396;8,72477;0,09554
3,674;0,76068;8,82922;0,09598
3,694;0,7674;8,93428;0,09641
3,714;0,77412;9,03965;0,09687
3,734;0,78084;9,14609;0,09733
3,754;0,78756;9,25144;0,09778
3,774;0,79428;9,35633;0,09828
3,794;0,801;9,46209;0,09875
3,814;0,80772;9,56775;0,09921
3,834;0,81448;9,67379;0,09968
3,854;0,82124;9,77958;0,10012
3,874;0,828;9,88475;0,10055
3,894;0,8348;9,99091;0,10101
3,914;0,84156;10,09624;0,10146
3,934;0,84832;10,20233;0,10192
3,954;0,85512;10,30955;0,10233
3,974;0,86188;10,41622;0,10278
3,994;0,86864;10,5223;0,10324
4,014;0,87544;10,62788;0,10367
4,034;0,88216;10,73364;0,10411
4,054;0,88896;10,83938;0,10454
4,074;0,89572;10,94545;0,10498
4,094;0,90252;11,0515;0,10542
4,114;0,90928;11,15729;0,10586
4,134;0,91604;11,2621;0,10628
4,154;0,92276;11,36583;0,10669
4,174;0,92952;11,46897;0,10715
4,194;0,93632;11,57127;0,10758
4,214;0,94308;11,67531;0,10801
4,234;0,94984;11,7793;0,10846
4,254;0,95664;11,88232;0,10887
4,274;0,96348;11,98436;0,10928
4,294;0,97032;12,08581;0,10974
4,314;0,97716;12,18735;0,11023
4,334;0,984;12,28855;0,11068
4,354;0,9908;12,39112;0,11111
4,374;0,99768;12,49339;0,11155
4,394;1,00452;12,59504;0,11202
4,416;1,01208;12,70471;0,11252
4,436;1,01896;12,80646;0,11296
4,456;1,02584;12,90922;0,11339
4,476;1,03272;13,01419;0,11383
4,496;1,03964;13,1197;0,11427
4,516;1,04652;13,22652;0,11466
4,536;1,05344;13,33296;0,1151
4,556;1,06036;13,43749;0,11557
4,576;1,06732;13,54269;0,11602
4,596;1,07432;13,64886;0,11646
4,616;1,08128;13,75663;0,11694
4,636;1,08828;13,86472;0,11739
4,656;1,09528;13,97155;0,11779
4,676;1,1022;14,07812;0,11823
4,696;1,10908;14,18386;0,11871
4,716;1,11596;14,28864;0,11917
4,736;1,12284;14,39468;0,11964
4,756;1,12968;14,5015;0,12009
4,776;1,13656;14,60905;0,12056
4,796;1,14348;14,71569;0,12097
4,816;1,1504;14,82323;0,12143
4,836;1,1574;14,93046;0,12189
4,856;1,16436;15,03904;0,12236
4,876;1,17132;15,1499;0,12281
4,896;1,17824;15,2598;0,12329
4,916;1,1852;15,36892;0,12378
4,936;1,19216;15,47749;0,12424
4,956;1,19908;15,58603;0,12469
4,976;1,20604;15,69645;0,12518
4,996;1,21304;15,80737;0,12565
5,014;1,21932;15,90832;0,12608
5,032;1,2256;16,00949;0,12651
5,052;1,23256;16,12017;0,12701
5,072;1,23952;16,22932;0,12749
5,092;1,24652;16,33778;0,12795
5,112;1,25348;16,44664;0,12839
5,132;1,26048;16,55702;0,12885
5,15;1,26676;16,65721;0,12927
5,17;1,27376;16,76748;0,12975
5,19;1,28072;16,8768;0,13024
5,21;1,28776;16,98607;0,1307
5,23;1,2948;17,09542;0,13117
5,25;1,3018;17,20545;0,13163
5,27;1,3088;17,31593;0,1321
5,29;1,31576;17,42566;0,13255
5,31;1,32268;17,53298;0,13301
5,33;1,32964;17,63874;0,13349
5,35;1,3366;17,74422;0,13395
5,37;1,3436;17,8506;0,13438
5,39;1,35056;17,95977;0,13485
5,41;1,3576;18,06971;0,13528
5,43;1,3646;18,18023;0,13575
5,45;1,37164;18,28994;0,13623
5,47;1,37868;18,39861;0,13669
5,49;1,38572;18,50789;0,13717
5,51;1,39272;18,61783;0,13763
5,528;1,39904;18,71821;0,13806
5,546;1,40536;18,81841;0,1385
5,566;1,41236;18,92762;0,13902
5,586;1,41936;19,03705;0,13952
5,606;1,4264;19,14626;0,13995
5,626;1,4334;19,25679;0,14045
5,644;1,43964;19,3568;0,1409
5,664;1,44664;19,46704;0,1414
5,684;1,4536;19,57669;0,14189
5,704;1,46056;19,68675;0,14238
5,724;1,46756;19,79611;0,14283
5,744;1,47456;19,90573;0,14329
5,764;1,48156;20,01667;0,14379
5,782;1,48788;20,11689;0,14421
5,8;1,4942;20,21751;0,14466
5,82;1,5012;20,32851;0,14515
5,84;1,5082;20,43923;0,14564
5,86;1,5152;20,55011;0,14612
5,878;1,52152;20,65058;0,14654
5,896;1,52784;20,75221;0,14696
5,914;1,53416;20,85508;0,14739
5,932;1,5404;20,95728;0,14785
5,95;1,54668;21,05825;0,14829
5,97;1,55372;21,16911;0,14877
5,988;1,55996;21,26983;0,14922
6,006;1,56624;21,371;0,14969
6,024;1,57252;21,47357;0,15013
6,042;1,57876;21,57574;0,15056
6,06;1,58504;21,67785;0,15105
6,078;1,59124;21,77994;0,15153
6,096;1,59748;21,88095;0,15198
6,116;1,60444;21,99205;0,15251
6,134;1,61068;22,09234;0,15299
6,152;1,61696;22,19353;0,15343
6,17;1,6232;22,29571;0,15388
6,188;1,62944;22,39767;0,15432
6,206;1,63568;22,49959;0,15474
6,224;1,64192;22,60044;0,15518
6,242;1,64816;22,70133;0,15563
6,262;1,65512;22,81182;0,15614
6,28;1,66136;22,91291;0,15658
6,298;1,66764;23,01519;0,15704
6,316;1,67388;23,11782;0,15748
6,334;1,68012;23,21984;0,15793
6,352;1,6864;23,32246;0,15839
6,37;1,69264;23,42517;0,15887
6,388;1,69888;23,52752;0,15933
6,406;1,70512;23,62917;0,15979
6,424;1,71132;23,7305;0,16027
6,442;1,71748;23,83303;0,16076
6,46;1,72368;23,93497;0,16122
6,478;1,72984;24,03602;0,16169
6,496;1,73604;24,1366;0,16215
6,514;1,74224;24,23797;0,16259
6,532;1,7484;24,34026;0,16309
6,55;1,7546;24,44247;0,16356
6,568;1,7608;24,54537;0,16402
6,586;1,76696;24,6491;0,16449
6,604;1,77316;24,7515;0,16494
6,622;1,77932;24,8522;0,1654
6,64;1,78548;24,95334;0,16589
6,658;1,79164;25,05407;0,16636
6,676;1,79776;25,1548;0,16683
6,694;1,80392;25,25612;0,16729
6,712;1,81008;25,35709;0,16776
6,73;1,81628;25,45824;0,16821
6,748;1,82244;25,55906;0,16869
6,766;1,82856;25,65963;0,16918
6,786;1,8354;25,77074;0,1697
6,804;1,84152;25,87176;0,17016
6,822;1,84764;25,97331;0,17061
6,84;1,85372;26,07511;0,17111
6,858;1,8598;26,17767;0,17165
6,876;1,86588;26,27886;0,17215
6,894;1,872;26,37992;0,17261
6,912;1,87808;26,48114;0,17306
6,93;1,88416;26,5823;0,17354
6,948;1,89024;26,6844;0,17406
6,966;1,89628;26,78741;0,17454
6,984;1,90236;26,89016;0,17502
7,002;1,90836;26,99131;0,17552
7,022;1,91508;27,10203;0,17607
7,04;1,92108;27,20221;0,17655
7,06;1,92776;27,31327;0,17706
7,078;1,93376;27,41345;0,17756
7,096;1,93976;27,51402;0,17804
7,114;1,94576;27,61498;0,1785
7,132;1,95176;27,71574;0,17902
7,152;1,9584;27,82511;0,17959
7,172;1,965;27,93386;0,18012
7,192;1,9716;28,04331;0,18067
7,212;1,97816;28,15133;0,18123
7,232;1,98476;28,25979;0,18178
7,252;1,99132;28,36956;0,18233
7,272;1,99788;28,47816;0,18289
7,292;2,00444;28,58675;0,18343
7,312;2,011;28,69583;0,18398
7,332;2,0176;28,80497;0,18453
7,352;2,02416;28,91516;0,18507
7,37;2,03;29,01559;0,1856
7,388;2,03588;29,11599;0,1861
7,406;2,04172;29,21615;0,18657
7,426;2,04824;29,32572;0,18713
7,446;2,05472;29,43365;0,18768
7,466;2,0612;29,54212;0,18823
7,486;2,06768;29,6509;0,18879
7,506;2,07416;29,76038;0,18937
7,526;2,0806;29,87104;0,18994
7,544;2,0864;29,9711;0,19046
7,564;2,0928;30,07991;0,19105
7,584;2,0992;30,18693;0,19164
7,604;2,1056;30,29343;0,19227
7,624;2,112;30,40013;0,19285
7,644;2,11836;30,50786;0,19347
7,664;2,12468;30,61549;0,19406
7,684;2,13108;30,72217;0,19464
7,704;2,1374;30,82886;0,19521
7,724;2,14376;30,93412;0,19579
7,744;2,15008;31,03913;0,19634
7,764;2,1564;31,14412;0,19692
7,784;2,16268;31,24958;0,19752
7,804;2,16892;31,35505;0,1981
7,824;2,1752;31,46124;0,19866
7,844;2,1814;31,56556;0,19922
7,864;2,1876;31,66874;0,1998
7,884;2,1938;31,77214;0,20039
7,904;2,19996;31,87576;0,20097
7,924;2,20616;31,98082;0,20158
7,944;2,21232;32,08691;0,20222
7,964;2,21844;32,19241;0,20287
7,984;2,22456;32,29729;0,20347
8,004;2,23064;32,39951;0,20409
8,024;2,23668;32,50197;0,20472
8,044;2,24276;32,6037;0,20533
8,064;2,24876;32,7048;0,20596
8,084;2,25476;32,8062;0,20661
8,104;2,26072;32,90871;0,20722
8,124;2,26672;33,00915;0,20783
8,144;2,27268;33,10919;0,20845
8,166;2,2792;33,21708;0,20911
8,188;2,28572;33,32515;0,20976
8,21;2,2922;33,43321;0,21042
8,232;2,29868;33,54198;0,21113
8,254;2,30512;33,6493;0,21182
8,276;2,31152;33,75715;0,21248
8,298;2,31792;33,86362;0,21318
8,32;2,32428;33,96781;0,21392
8,342;2,3306;34,07151;0,21462
8,364;2,33696;34,17651;0,2153
8,386;2,34328;34,28306;0,21595
8,408;2,34952;34,38974;0,21665
8,43;2,3558;34,49536;0,21734
8,452;2,362;34,60041;0,21803
8,474;2,36824;34,7037;0,21875
8,496;2,37448;34,8073;0,21947
8,518;2,38068;34,91198;0,22019
8,54;2,38684;35,01678;0,22096
8,562;2,393;35,12118;0,22169
8,584;2,39912;35,22611;0,22242
8,606;2,40516;35,32874;0,22323
8,628;2,41112;35,42976;0,22399
8,652;2,41756;35,53532;0,22478
8,676;2,42392;35,63798;0,22557
8,7;2,43024;35,7416;0,22632
8,724;2,43656;35,84682;0,22708
8,748;2,44284;35,95051;0,22782
8,772;2,44908;36,05365;0,22861
8,796;2,45528;36,15432;0,2294
8,82;2,46152;36,25543;0,23015
8,844;2,46776;36,35729;0,23096
8,868;2,47396;36,45945;0,23173
8,892;2,48008;36,56163;0,23256
8,916;2,48616;36,66233;0,2334
8,942;2,49272;36,769;0,23431
8,968;2,4992;36,87558;0,23522
8,994;2,50568;36,98046;0,23608
9,02;2,51208;37,08461;0,237
9,046;2,51844;37,1879;0,23792
9,072;2,5248;37,29163;0,23882
9,098;2,53108;37,39696;0,23968
9,124;2,53736;37,50104;0,24056
9,15;2,54356;37,60229;0,24146
9,176;2,54972;37,70294;0,24236
9,204;2,55628;37,8092;0,24338
9,232;2,56276;37,91558;0,24439
9,26;2,5692;38,02006;0,24538
9,288;2,5756;38,12316;0,24637
9,316;2,58188;38,22427;0,24735
9,346;2,5886;38,33089;0,24843
9,376;2,59532;38,43572;0,24948
9,406;2,60192;38,54029;0,25055
9,436;2,60844;38,64395;0,2516
9,466;2,61488;38,74616;0,25263
9,498;2,62164;38,85251;0,25378
9,53;2,62824;38,95469;0,255
9,562;2,63484;39,055;0,2561
9,594;2,64128;39,15535;0,25721
9,628;2,64808;39,26066;0,25837
9,662;2,65484;39,36369;0,25959
9,696;2,66152;39,46909;0,26082
9,73;2,66812;39,57226;0,26201
9,764;2,67468;39,67322;0,2632
9,8;2,68148;39,77772;0,26457
9,836;2,6882;39,87943;0,26587
9,872;2,69484;39,97962;0,26712
9,908;2,70132;40,08056;0,26839
9,946;2,70808;40,18384;0,26976
9,986;2,71504;40,28809;0,27118
10,026;2,72184;40,3902;0,2726
10,068;2,72892;40,49249;0,27412
10,11;2,73584;40,59491;0,27566
10,152;2,7426;40,69499;0,27711
10,196;2,74952;40,79513;0,27867
10,242;2,75664;40,89783;0,28024
10,29;2,76392;41,00181;0,28186
10,338;2,77104;41,10347;0,28348
10,388;2,77824;41,20441;0,28528
10,44;2,78564;41,30566;0,28708
10,492;2,79284;41,4075;0,28883
10,546;2,80016;41,5087;0,29071
10,602;2,80752;41,60968;0,29252
10,66;2,815;41,71076;0,2944
10,722;2,82276;41,81309;0,29653
10,784;2,83028;41,91545;0,29854
10,848;2,83788;42,01611;0,30063
10,916;2,84564;42,11682;0,30286
10,988;2,85364;42,21943;0,30521
11,06;2,86148;42,32126;0,30752
11,134;2,86928;42,42156;0,30982
11,212;2,87716;42,5223;0,31221
11,298;2,88548;42,6245;0,31484
11,388;2,89384;42,72556;0,31769
11,48;2,90212;42,8272;0,32039
11,576;2,91056;42,92823;0,32314
11,676;2,91912;43,02987;0,32606
11,776;2,92736;43,12935;0,32904
11,876;2,93536;43,22186;0,33191
11,976;2,94312;43,31096;0,33472
12,076;2,95064;43,39516;0,33759
12,176;2,95792;43,47445;0,34036
12,276;2,96504;43,5515;0,34313
12,376;2,97196;43,62523;0,34586
12,476;2,97868;43,69794;0,34863
12,576;2,98528;43,76975;0,35131
12,676;2,99184;43,84135;0,35396
12,776;2,99832;43,90849;0,35667
12,876;3,00448;43,97294;0,35945
12,976;3,01048;44,03107;0,36199
13,076;3,0164;44,08955;0,36464
13,176;3,02216;44,14779;0,36729
13,276;3,0278;44,20358;0,37
13,376;3,03332;44,25581;0,37256
13,476;3,03876;44,3063;0,37513
13,576;3,04416;44,35752;0,37771
13,676;3,04956;44,41078;0,38036
13,776;3,05488;44,46032;0,3831
13,876;3,06004;44,50906;0,38575
13,976;3,06504;44,55381;0,38839
14,076;3,06988;44,59354;0,39103
14,176;3,07468;44,63208;0,39361
14,276;3,07932;44,66926;0,39621
14,376;3,08392;44,70536;0,39885
14,476;3,08844;44,73885;0,40143
14,576;3,09296;44,77484;0,40391
14,676;3,0974;44,81026;0,40642
14,776;3,10176;44,84489;0,40903
14,876;3,10608;44,87725;0,41159
14,976;3,1104;44,9109;0,41414
15,076;3,11476;44,94948;0,4167
15,176;3,11916;44,9875;0,4193
15,276;3,12344;45,02204;0,42196
15,376;3,12768;45,05197;0,42453
15,476;3,1318;45,07972;0,42716
15,576;3,13576;45,10241;0,42976
15,676;3,13964;45,12459;0,43227
15,776;3,14352;45,14575;0,43477
15,876;3,1474;45,17281;0,43727
15,976;3,15124;45,19769;0,43985
16,076;3,15504;45,22261;0,44236
16,176;3,15876;45,24472;0,44488
16,276;3,1624;45,26472;0,44738
16,376;3,16604;45,28544;0,44984
16,476;3,16964;45,30444;0,45233
16,576;3,17328;45,3258;0,45482
16,676;3,177;45,35115;0,45726
16,776;3,18072;45,37522;0,45981
16,876;3,18436;45,39703;0,46242
16,976;3,18792;45,41587;0,46495
17,076;3,19144;45,43364;0,4675
17,176;3,19492;45,45055;0,47002
17,276;3,19832;45,46481;0,47255
17,376;3,20164;45,47834;0,47512
17,476;3,20496;45,49116;0,47762
17,576;3,20828;45,50449;0,48012
17,676;3,21152;45,51686;0,48268
17,776;3,21476;45,5288;0,48514
17,876;3,21804;45,54133;0,4876
17,976;3,22132;45,55687;0,49015
18,076;3,22456;45,56832;0,49276
18,176;3,22768;45,57903;0,49527
18,276;3,2308;45,58837;0,49767
18,376;3,234;45,6003;0,50011
18,476;3,23712;45,60995;0,50268
18,576;3,24028;45,62241;0,5052
18,676;3,24344;45,63419;0,50775
18,776;3,24664;45,64736;0,51026
18,876;3,2498;45,65819;0,51289
18,976;3,25292;45,66627;0,51537
19,076;3,25604;45,67374;0,51786
19,176;3,26072;45,71024;0,51617
19,276;3,266;45,80339;0,51972
19,376;3,2704;45,83232;0,52347
19,476;3,27416;45,82295;0,52691
19,576;3,27736;45,79279;0,53021
19,676;3,28012;45,75189;0,53329
19,776;3,28268;45,70995;0,53613
19,876;3,28508;45,67154;0,53874
19,976;3,28748;45,63796;0,54117
20,076;3,28988;45,61248;0,54355
20,176;3,29236;45,59273;0,54592
20,276;3,295;45,57994;0,54814
20,376;3,29768;45,57202;0,55038
20,476;3,30048;45,57021;0,55272
20,576;3,3034;45,57114;0,55518
20,676;3,30644;45,57096;0,5575
20,776;3,30956;45,57365;0,55997
20,876;3,31268;45,57361;0,5625
20,976;3,3158;45,57061;0,56506
21,076;3,31888;45,56406;0,56759
21,176;3,32196;45,55758;0,57011
21,276;3,32492;45,54684;0,57266
21,376;3,32776;45,53514;0,57522
21,476;3,33064;45,52463;0,57767
21,576;3,33352;45,51505;0,58003
21,676;3,3364;45,51024;0,5824
21,776;3,33936;45,50862;0,5849
21,876;3,34228;45,50636;0,58736
21,976;3,34528;45,50637;0,5898
22,076;3,34828;45,5057;0,59216
22,176;3,35132;45,50982;0,59464
22,276;3,3544;45,51179;0,59713
22,376;3,35744;45,51198;0,59962
22,476;3,36048;45,51092;0,6021
22,576;3,36348;45,50875;0,60462
22,676;3,36648;45,507;0,60709
22,776;3,36956;45,50724;0,60956
22,876;3,37268;45,51005;0,6121
22,976;3,37584;45,51342;0,61469
23,076;3,37896;45,51699;0,61735
23,176;3,38204;45,5151;0,61996
23,276;3,38508;45,51063;0,62256
23,376;3,388;45,50376;0,62525
23,476;3,3908;45,49243;0,62785
23,576;3,39356;45,48137;0,63041
23,676;3,39624;45,46861;0,63293
23,776;3,39888;45,45611;0,63541
23,876;3,40152;45,44616;0,63793
23,976;3,40428;45,43751;0,64026
24,076;3,40708;45,43454;0,6427
24,176;3,40988;45,43274;0,64522
24,276;3,41276;45,43116;0,64774
24,376;3,4156;45,43023;0,65034
24,476;3,4184;45,42331;0,65282
24,576;3,42116;45,41607;0,65536
24,676;3,42388;45,40835;0,65793
24,776;3,42656;45,40161;0,66036
24,876;3,42924;45,39369;0,66279
24,976;3,43232;45,39307;0,66413
25,076;3,43684;45,45298;0,66524
25,176;3,44092;45,4934;0,66859
25,276;3,44448;45,49518;0,67193
25,376;3,4476;45,47582;0,67508
25,476;3,45024;45,44172;0,67824
25,576;3,45256;45,40106;0,68122
25,676;3,45472;45,35906;0,68387
25,776;3,45676;45,32478;0,68636
25,876;3,45888;45,29919;0,68871
25,976;3,46108;45,28385;0,69104
26,076;3,4634;45,27478;0,69334
26,176;3,4658;45,27142;0,69567
26,276;3,46828;45,27212;0,69803
26,376;3,47076;45,2742;0,70044
26,476;3,47336;45,27817;0,70276
26,576;3,47596;45,28411;0,70512
26,676;3,47856;45,2877;0,70762
26,776;3,4812;45,29175;0,71012
26,876;3,4838;45,29365;0,71261
26,976;3,4864;45,29224;0,71508
27,076;3,48896;45,29071;0,71759
27,176;3,49148;45,28894;0,72016
27,276;3,494;45,28511;0,72256
27,376;3,49656;45,28251;0,72511
27,476;3,49916;45,28177;0,72763
27,576;3,50176;45,28058;0,73017
27,676;3,5044;45,28137;0,73271
27,776;3,50708;45,28287;0,73523
27,876;3,50976;45,28559;0,73784
27,976;3,51236;45,28473;0,74048
28,076;3,51492;45,28074;0,74306
28,176;3,51744;45,27566;0,74561
28,276;3,51988;45,26927;0,74823
28,376;3,52228;45,26101;0,75075
28,476;3,52464;45,25302;0,75325
28,576;3,52704;45,24565;0,75562
28,676;3,52936;45,24074;0,75813
28,776;3,53172;45,23419;0,76062
28,876;3,53412;45,23048;0,76306
28,976;3,53656;45,22756;0,76551
29,076;3,53904;45,22828;0,76796
29,176;3,54156;45,22999;0,77043
29,276;3,54412;45,23208;0,77293
29,376;3,54664;45,23409;0,77546
29,476;3,54936;45,23441;0,77731
29,576;3,5534;45,28668;0,77802
29,676;3,55712;45,32805;0,7812
29,776;3,56028;45,33506;0,78448
29,876;3,563;45,31823;0,78765
29,976;3,56528;45,29055;0,7907
30,076;3,56736;45,25915;0,79361
30,176;3,56936;45,22961;0,79622
30,276;3,57136;45,20656;0,79874
30,376;3,57336;45,19029;0,80118
30,476;3,57544;45,17981;0,80353
30,576;3,57756;45,17485;0,80593
30,676;3,57976;45,17723;0,80831
30,776;3,58204;45,1792;0,81072
30,876;3,58432;45,18408;0,81315
30,976;3,58656;45,1873;0,81564
31,076;3,5888;45,18837;0,81808
31,176;3,59108;45,19188;0,8206
31,276;3,59332;45,19342;0,82316
31,376;3,59556;45,19557;0,82565
31,476;3,59776;45,19635;0,82809
31,576;3,6;45,19944;0,83058
31,676;3,60224;45,20168;0,83309
31,776;3,60444;45,20312;0,83565
31,876;3,6066;45,20387;0,83816
31,976;3,60876;45,20401;0,84072
32,076;3,61088;45,20224;0,84324
32,176;3,61296;45,20131;0,84573
32,276;3,61504;45,20081;0,84829
32,376;3,61708;45,19752;0,85076
32,476;3,61908;45,19372;0,85331
32,576;3,62104;45,19036;0,85585
32,676;3,623;45,18695;0,85833
32,776;3,625;45,18388;0,86078
32,876;3,627;45,18381;0,86328
32,976;3,62904;45,18665;0,86578
33,076;3,63112;45,18913;0,86829
33,176;3,63316;45,19242;0,87086
33,276;3,63524;45,1946;0,87342
33,376;3,63732;45,19731;0,87604
33,476;3,63936;45,19847;0,87861
33,576;3,64136;45,19898;0,88123
33,676;3,64328;45,19561;0,88384
33,776;3,64512;45,18977;0,88636
33,876;3,64696;45,18543;0,88887
33,976;3,64876;45,17951;0,89139
34,076;3,65056;45,17528;0,89389
34,176;3,65236;45,17138;0,89639
34,276;3,65412;45,16787;0,89884
34,376;3,65588;45,16531;0,90127
34,476;3,65768;45,16402;0,90377
34,576;3,65944;45,16107;0,90621
34,676;3,66124;45,16177;0,90872
34,776;3,66308;45,16276;0,91116
34,876;3,66492;45,16568;0,91371
34,976;3,6668;45,16735;0,91619
35,076;3,66868;45,17224;0,91875
35,176;3,6706;45,17651;0,92137
35,276;3,67256;45,1804;0,92396
35,376;3,67448;45,18337;0,9266
35,476;3,67632;45,18436;0,92924
35,576;3,67808;45,1808;0,93188
35,676;3,67972;45,17405;0,93449
35,776;3,68132;45,16445;0,93705
35,876;3,68288;45,15617;0,93955
35,976;3,68448;45,14849;0,94197
36,076;3,68608;45,14382;0,94444
36,176;3,6876;45,13846;0,94693
36,276;3,68916;45,13345;0,94942
36,376;3,69076;45,13106;0,9518
36,476;3,6924;45,13069;0,95429
36,576;3,69408;45,13264;0,95672
36,676;3,69576;45,13378;0,95924
36,776;3,69748;45,1362;0,96179
36,876;3,69916;45,13773;0,96432
36,976;3,70084;45,13928;0,96688
37,076;3,70248;45,14012;0,9694
37,176;3,70412;45,13818;0,97192
37,276;3,70568;45,13501;0,9745
37,376;3,7072;45,12929;0,97702
37,476;3,70868;45,12384;0,97954
37,576;3,71008;45,11638;0,98196
37,676;3,71144;45,10672;0,98441
37,776;3,71276;45,09691;0,98676
37,876;3,71408;45,08992;0,9891
37,976;3,71548;45,08597;0,99142
38,076;3,71692;45,08423;0,99371
38,176;3,71844;45,0849;0,99609
38,276;3,72004;45,09014;0,99842
38,376;3,72168;45,09715;1,00087
38,476;3,72332;45,10311;1,00331
38,576;3,72496;45,10852;1,00587
38,676;3,72656;45,11094;1,00834
38,776;3,72812;45,11078;1,01088
38,876;3,72964;45,11064;1,01336
38,976;3,73116;45,10849;1,01594
39,076;3,73264;45,10556;1,01843
39,176;3,73412;45,10387;1,0209
39,276;3,73564;45,10304;1,02339
39,376;3,73712;45,10126;1,02592
39,476;3,73856;45,09886;1,02844
39,576;3,74004;45,0971;1,03094
39,676;3,74148;45,09515;1,03342
39,776;3,74296;45,09355;1,0359
39,876;3,7444;45,09068;1,03839
39,976;3,7458;45,08675;1,04091
40,076;3,74716;45,08197;1,04342
40,176;3,74856;45,07863;1,04595
40,276;3,74996;45,07435;1,04832
40,376;3,75144;45,07453;1,05078
40,476;3,75292;45,07623;1,05332
40,576;3,7544;45,0766;1,05582
40,676;3,75584;45,07703;1,05839
40,776;3,75736;45,07738;1,06089
40,876;3,75888;45,07971;1,0634
40,976;3,7604;45,08114;1,06597
41,076;3,76192;45,08102;1,0686
41,176;3,76344;45,08258;1,07117
41,276;3,76492;45,07951;1,07381
41,376;3,7664;45,07718;1,07641
41,476;3,76776;45,07116;1,07905
41,576;3,76912;45,06424;1,08164
41,676;3,77044;45,05726;1,08416
41,776;3,77176;45,05134;1,08669
41,876;3,77312;45,04466;1,08921
41,976;3,77444;45,03987;1,09166
42,076;3,77576;45,03451;1,09416
42,176;3,77712;45,03206;1,09662
42,276;3,77848;45,02924;1,09907
42,376;3,77988;45,02826;1,10147
42,476;3,78128;45,03058;1,10399
42,576;3,78268;45,02928;1,10644
42,676;3,78412;45,02876;1,10895
42,776;3,78548;45,02823;1,11145
42,876;3,78684;45,02517;1,11393
42,976;3,7882;45,02262;1,11643
43,076;3,78956;45,02058;1,11886
43,176;3,79096;45,02088;1,12135
43,276;3,79236;45,01787;1,12387
43,376;3,79372;45,01675;1,12636
43,476;3,79512;45,01663;1,12888
43,576;3,79648;45,01511;1,13137
43,676;3,79792;45,01417;1,13378
43,776;3,79932;45,01746;1,13641
43,876;3,80072;45,01576;1,13895
43,976;3,80208;45,01263;1,14143
44,076;3,80352;45,01465;1,14389
44,176;3,80492;45,01519;1,14641
44,276;3,80632;45,01518;1,14901
44,376;3,80768;45,01179;1,15152
44,476;3,809;45,00812;1,154
44,576;3,81036;45,00606;1,15643
44,676;3,81172;45,00418;1,15893
44,776;3,81312;45,00412;1,16135
44,876;3,81452;45,00532;1,16387
44,976;3,81592;45,0067;1,16639
45,076;3,81728;45,00652;1,16884
45,176;3,81864;45,00391;1,17131
45,276;3,82004;45,00533;1,17383
45,376;3,82148;45,00584;1,17629
45,476;3,82288;45,00657;1,17884
45,576;3,82428;45,0075;1,18135
45,676;3,82568;45,00776;1,18383
45,776;3,82716;45,01112;1,1863
45,876;3,82864;45,01568;1,1888
45,976;3,83008;45,01862;1,19137
46,076;3,8316;45,02232;1,1939
46,176;3,83304;45,02464;1,19643
46,276;3,83452;45,02709;1,19897
46,376;3,83592;45,02813;1,20151
46,476;3,83728;45,02694;1,20409
46,576;3,83864;45,02418;1,20661
46,676;3,84;45,02298;1,20913
46,776;3,84136;45,0212;1,21157
46,876;3,84272;45,02054;1,21404
46,976;3,84408;45,02173;1,21652
47,076;3,84544;45,02134;1,21891
47,176;3,8468;45,02276;1,2215
47,276;3,8482;45,02307;1,22384
47,376;3,84964;45,02646;1,22629
47,476;3,85116;45,03359;1,22875
47,576;3,85264;45,03955;1,23128
47,676;3,85408;45,04242;1,2338
47,776;3,85556;45,04626;1,23627
47,876;3,85696;45,04892;1,23885
47,976;3,8584;45,04978;1,24127
48,076;3,85984;45,05337;1,24385
48,176;3,86124;45,05435;1,24634
48,276;3,86264;45,05224;1,24883
48,376;3,86404;45,05301;1,25135
48,476;3,8654;45,05295;1,25384
48,576;3,86684;45,05343;1,25629
48,676;3,86824;45,05663;1,25887
48,776;3,86964;45,05433;1,26135
48,876;3,871;45,05373;1,26391
48,976;3,87236;45,05225;1,2663
49,076;3,87372;45,05266;1,26887
49,176;3,87512;45,0529;1,27139
49,276;3,8764;45,04904;1,27384
49,376;3,87772;45,0466;1,2763
49,476;3,87908;45,04585;1,27871
49,576;3,88044;45,04739;1,2812
49,676;3,88184;45,04883;1,28373
49,776;3,8832;45,04965;1,28626
49,876;3,8846;45,04845;1,28869
49,976;3,886;45,04965;1,29124
50,076;3,8874;45,05108;1,29374
50,176;3,8888;45,05189;1,29622
50,276;3,89024;45,05427;1,29874
50,376;3,89164;45,05563;1,30144
50,476;3,89304;45,05379;1,30396
50,576;3,89444;45,05231;1,3065
50,676;3,89588;45,05301;1,30904
50,776;3,89724;45,05269;1,31165
50,876;3,8986;45,05206;1,31427
50,976;3,89992;45,04767;1,31681
51,076;3,90124;45,04185;1,31932
51,176;3,9026;45,03962;1,32182
51,276;3,90388;45,03797;1,32436
51,376;3,9052;45,03548;1,3268
51,476;3,90652;45,03345;1,3293
51,576;3,90784;45,03312;1,33175
51,676;3,90924;45,03377;1,33418
51,776;3,91064;45,03689;1,3366
51,876;3,91204;45,03917;1,33912
51,976;3,91344;45,04192;1,34164
52,076;3,91484;45,04465;1,34412
52,176;3,91624;45,04719;1,34649
52,276;3,91768;45,05062;1,34894
52,376;3,91916;45,05669;1,35134
52,476;3,9206;45,06246;1,35393
52,576;3,92204;45,06653;1,35645
52,676;3,92348;45,07079;1,35887
52,776;3,92496;45,07644;1,36129
52,876;3,9264;45,083;1,36378
52,976;3,92784;45,08799;1,36628
53,076;3,92932;45,09447;1,36879
53,176;3,93084;45,10098;1,37119
53,276;3,93236;45,10934;1,37371
53,376;3,93388;45,11682;1,3762
53,476;3,93544;45,12649;1,37869
53,576;3,937;45,13454;1,38117
53,676;3,93848;45,14171;1,38375
53,776;3,93996;45,14647;1,3862
53,876;3,94144;45,15183;1,38864
53,976;3,94296;45,158;1,3911
54,076;3,94452;45,16729;1,39355
54,176;3,94604;45,17446;1,39604
54,276;3,94756;45,18259;1,3985
54,376;3,94912;45,18959;1,40087
54,476;3,95076;45,20295;1,40336
54,576;3,9524;45,21578;1,40585
54,676;3,95404;45,22725;1,40836
54,776;3,95564;45,23586;1,41085
54,876;3,95736;45,24829;1,4133
54,976;3,95904;45,26149;1,41591
55,076;3,96076;45,27411;1,41844
55,176;3,96252;45,28574;1,421
55,276;3,9642;45,29615;1,42358
55,376;3,96584;45,306;1,42619
55,476;3,9674;45,31233;1,42873
55,576;3,96904;45,31922;1,43122
55,676;3,97068;45,32884;1,43372
55,776;3,97224;45,33468;1,43627
55,876;3,9738;45,34016;1,43875
55,976;3,97544;45,34805;1,44114
56,076;3,97708;45,35775;1,44353
56,176;3,97876;45,37086;1,44599
56,276;3,98048;45,3826;1,44851
56,376;3,9822;45,39498;1,45097
56,476;3,98404;45,40879;1,45323
56,576;3,98844;45,50502;1,45186
56,676;3,9922;45,59554;1,45579
56,776;3,995;45,62484;1,4599
56,876;3,99692;45,61256;1,46375
56,976;3,9982;45,57645;1,46711
57,076;3,99912;45,53348;1,46997
57,176;4,00004;45,49662;1,47241
57,276;4,001;45,46907;1,47472
57,376;4,00216;45,45422;1,4769
57,476;4,00352;45,45198;1,47898
57,576;4,00512;45,46366;1,48113
57,676;4,00692;45,48385;1,48325
57,776;4,00888;45,50889;1,48553
57,876;4,01092;45,53584;1,48799
57,976;4,01292;45,55933;1,49051
58,076;4,01488;45,57908;1,49302
58,176;4,01684;45,59479;1,49552
58,276;4,01868;45,60702;1,49813
58,376;4,02052;45,61515;1,50063
58,476;4,02232;45,62338;1,50321
58,576;4,02412;45,63095;1,50576
58,676;4,02596;45,6403;1,50823
58,776;4,02784;45,64973;1,51073
58,876;4,02972;45,66058;1,51326
58,976;4,03164;45,67188;1,51575
59,076;4,03356;45,68166;1,51831
59,176;4,03544;45,69099;1,52087
59,276;4,03732;45,69966;1,5233
59,376;4,03924;45,70849;1,5258
59,476;4,04116;45,71707;1,52834
59,576;4,04296;45,72272;1,5309
59,676;4,04484;45,72884;1,53331
59,776;4,04672;45,73764;1,53572
59,876;4,04864;45,74696;1,53817
59,976;4,05052;45,755;1,54069
60,076;4,05244;45,7624;1,54309
60,176;4,0544;45,77295;1,54553
60,276;4,05644;45,7867;1,54795
60,376;4,05844;45,79844;1,55047
60,476;4,06048;45,81071;1,55297
60,576;4,06256;45,82159;1,55544
60,676;4,0646;45,83372;1,55804
60,776;4,0666;45,84133;1,56064
60,876;4,0686;45,84827;1,56307
60,976;4,07056;45,85379;1,56554
61,076;4,07252;45,85973;1,56795
61,176;4,07448;45,86721;1,57054
61,276;4,07644;45,87313;1,57295
61,376;4,0784;45,87978;1,57532
61,476;4,08048;45,88971;1,57769
61,576;4,0826;45,90134;1,58018
61,676;4,08472;45,91331;1,58262
61,776;4,08688;45,92323;1,58512
61,876;4,08904;45,93569;1,58762
61,976;4,09132;45,95008;1,59015
62,076;4,09356;45,96249;1,5927
62,176;4,0958;45,97433;1,5952
62,276;4,09804;45,98212;1,59779
62,362;4,09992;45,99076;1,60001
62,364;4,09996;45,99082;1,60006
62,442;4,11036;46,09508;1,60253
62,454;4,11432;46,20159;1,60345
62,464;4,11788;46,30834;1,60444
62,474;4,12172;46,42415;1,60567
62,484;4,12576;46,54346;1,6072
62,494;4,12996;46,66092;1,60904
62,504;4,13436;46,77321;1,61127
62,514;4,13884;46,87738;1,61388
62,526;4,14444;46,98884;1,61755
62,54;4,15108;47,09885;1,62264
62,558;4,15988;47,20856;1,63045
62,584;4,17296;47,31359;1,64373
62,636;4,19984;47,41639;1,67407
62,706;4,23688;47,51846;1,71652
62,768;4,27004;47,62029;1,75329
62,83;4,30328;47,72343;1,78715
62,888;4,33436;47,8241;1,81856
62,942;4,36332;47,92531;1,8478
62,996;4,39236;48,02763;1,87659
63,05;4,42132;48,12782;1,90483
63,062;4,4278;48,14911;1,91099
63,088;4,44176;48,19632;1,92426
63,09;4,44284;48,20001;1,92527
88,20001;4,48276;45,61874;
88,25201;4,493;45,72144;
88,26401;4,49688;45,84141;
88,274;4,50036;45,96829;
88,28201;4,5034;46,083;
88,29;4,50656;46,20671;
88,29801;4,5098;46,33745;
88,304;4,51236;46,43897;
88,31001;4,51492;46,54298;
88,316;4,51756;46,64905;
88,32201;4,52024;46,75637;
88,328;4,52296;46,86447;
88,33401;4,52576;46,97306;
88,34001;4,52852;47,08152;
88,346;4,5314;47,18936;
88,35201;4,53428;47,29603;
88,358;4,53716;47,40113;
88,36401;4,54008;47,50409;
88,37;4,54304;47,60458;
88,37801;4,547;47,73376;
88,386;4,551;47,85653;
88,39401;4,55508;47,9718;
88,402;4,55916;48,07863;
88,412;4,56432;48,20057;
88,42201;4,56944;48,30961;
88,43401;4,57564;48,42286;
88,44801;4,58292;48,53214;
88,466;4,59232;48,64128;
88,49001;4,60496;48,74677;
88,524;4,623;48,84858;
88,57201;4,6486;48,95153;
88,62801;4,67852;49,05232;
88,68601;4,7096;49,1531;
88,744;4,74068;49,25354;
88,802;4,7718;49,3556;
88,86401;4,80496;49,45765;
88,924;4,8372;49,5609;
88,982;4,86824;49,66099;
89,04;4,8994;49,76306;
89,10001;4,93156;49,86378;
89,16;4,9638;49,96517;
89,22;4,996;50,06692;
89,28001;5,02824;50,1699;
89,342;5,06124;50,2701;
89,4;5,09236;50,37245;
89,46201;5,12556;50,47291;
89,522;5,15776;50,57294;
89,582;5,18992;50,67366;
89,64201;5,22212;50,77506;
89,704;5,25532;50,87519;
89,76601;5,28864;50,97613;
89,828;5,32192;51,07747;
89,89201;5,3562;51,17939;
89,956;5,39044;51,28182;
90,022;5,42584;51,38435;
90,08601;5,46012;51,48603;
90,15;5,4944;51,5872;
90,218;5,5308;51,68923;
90,28201;5,5652;51,79111;
90,34801;5,60056;51,89124;
90,41601;5,63696;51,99179;
90,48601;5,67448;52,09347;
90,554;5,711;52,19475;
90,624;5,74856;52,29729;
90,69801;5,78808;52,3997;
90,77001;5,8266;52,50011;
90,842;5,86512;52,60134;
90,912;5,90256;52,70304;
90,98801;5,94328;52,80558;
91,068;5,9862;52,90754;
91,146;6,02804;53,00851;
91,22601;6,07096;53,11093;
91,30801;6,11488;53,21125;
91,38801;6,15772;53,31374;
91,468;6,2006;53,41576;
91,54601;6,24244;53,51587;
91,632;6,2886;53,61769;
91,716;6,33376;53,71827;
91,804;6,38072;53,81957;
91,886;6,42476;53,92126;
91,97201;6,47092;54,02192;
92,064;6,52024;54,12285;
92,146;6,56412;54,22384;
92,234;6,61132;54,32526;
92,328;6,66164;54,42672;
92,42001;6,71092;54,5287;
92,508;6,75812;54,62965;
92,608;6,81164;54,73093;
92,70001;6,861;54,83124;
92,79201;6,91032;54,93196;
92,89001;6,96268;55,03303;
92,98601;7,01432;55,13357;
93,08401;7,06684;55,23368;
93,18401;7,12036;55,33;
93,28401;7,17396;55,42819;
93,384;7,2274;55,52745;
93,484;7,2812;55,62648;
93,58401;7,3348;55,71375;
93,68401;7,38852;55,81105;
93,78401;7,44204;55,89982;
93,884;7,49552;55,98867;
93,984;7,54916;56,08366;
94,08401;7,60264;56,16953;
94,18401;7,6562;56,25498;
94,28401;7,70972;56,33957;
94,384;7,76332;56,42769;
94,484;7,817;56,50806;
94,58401;7,87052;56,58713;
94,68401;7,92432;56,67571;
94,78401;7,9778;56,75042;
94,884;8,0314;56,83054;
94,984;8,08508;56,91219;
95,08401;8,13864;56,98417;
95,18401;8,19236;57,06134;
95,28401;8,2458;57,13673;
95,384;8,29944;57,21238;
95,484;8,35312;57,2867;
95,58401;8,40668;57,35897;
95,68401;8,46028;57,43138;
95,78401;8,5138;57,4998;
95,884;8,5674;57,57282;
95,984;8,62096;57,6422;
96,08401;8,67456;57,71144;
96,18401;8,72816;57,78075;
96,28401;8,78168;57,84733;
96,384;8,83532;57,91448;
96,484;8,88888;57,97829;
96,58401;8,9426;58,04505;
96,68401;8,996;58,10576;
96,78401;9,0496;58,17005;
96,884;9,10336;58,23266;
96,984;9,15692;58,28925;
97,08401;9,21052;58,35202;
97,18401;9,26416;58,41721;
97,28401;9,31768;58,47205;
97,384;9,37136;58,5308;
97,484;9,42488;58,58655;
97,58401;9,47848;58,64328;
97,68401;9,53212;58,69848;
97,78401;9,58552;58,75693;
97,884;9,6392;58,81249;
97,984;9,69284;58,86279;
98,08401;9,7464;58,92004;
98,18401;9,8;58,97065;
98,28401;9,8536;59,02039;
98,384;9,9072;59,07441;
98,484;9,96076;59,12505;
98,58401;10,01448;59,17203;
98,68401;10,06796;59,21831;
98,78401;10,12156;59,26788;
98,884;10,1752;59,31633;
98,984;10,22884;59,3658;
99,08401;10,28236;59,41015;
99,18401;10,33592;59,45749;
99,28401;10,3896;59,50344;
99,384;10,4432;59,54922;
99,484;10,49672;59,59105;
99,58401;10,55048;59,63728;
99,68401;10,60396;59,67695;
99,78401;10,65748;59,71984;
99,884;10,71104;59,76141;
99,984;10,76456;59,80664;
100,08401;10,81828;59,84752;
100,18401;10,87184;59,88331;
100,28401;10,92552;59,92681;
100,384;10,97916;59,96474;
100,484;11,03276;60,00122;
100,58401;11,08632;60,04329;
100,68401;11,1398;60,07931;
100,78401;11,19356;60,11751;
100,884;11,24712;60,15564;
100,984;11,3008;60,19338;
101,08401;11,35436;60,22491;
101,18401;11,40792;60,26402;
101,28401;11,46156;60,29866;
101,384;11,51508;60,33024;
101,484;11,56876;60,37073;
101,58401;11,62212;60,4009;
101,68401;11,67568;60,43292;
101,78401;11,7294;60,46574;
101,884;11,78292;60,4966;
101,984;11,83652;60,52562;
102,08401;11,89016;60,55852;
102,18401;11,94368;60,58983;
102,28401;11,99732;60,61979;
102,384;12,05084;60,64884;
102,484;12,10456;60,68134;
102,58401;12,15816;60,70604;
102,68401;12,21172;60,73613;
102,78401;12,26544;60,77226;
102,884;12,31904;60,79593;
102,984;12,37268;60,82156;
103,08401;12,42616;60,84804;
103,18401;12,47976;60,87134;
103,28401;12,53344;60,89979;
103,384;12,58704;60,92789;
103,484;12,64072;60,95079;
103,58401;12,69424;60,97314;
103,68401;12,74784;61,0022;
103,78401;12,80148;61,02409;
103,884;12,85516;61,04614;
103,984;12,90864;61,06908;
104,08401;12,9622;61,09322;
104,18401;13,01588;61,11596;
104,28401;13,06932;61,13831;
104,384;13,12276;61,1617;
104,484;13,17648;61,18658;
104,58401;13,22996;61,2057;
104,68401;13,28368;61,22932;
104,78401;13,33728;61,24619;
104,884;13,39092;61,26814;
104,98401;13,44456;61,28908;
105,08401;13,49808;61,30281;
105,18401;13,5518;61,32679;
105,28401;13,6054;61,34624;
105,384;13,659;61,36277;
105,48401;13,71256;61,38185;
105,58401;13,76604;61,40277;
105,68401;13,81976;61,41998;
105,78401;13,87336;61,43588;
105,884;13,92696;61,45458;
105,98401;13,98056;61,46726;
106,08401;14,03412;61,48331;
106,18401;14,0878;61,50309;
106,28401;14,1414;61,51562;
106,384;14,19504;61,53065;
106,48401;14,24856;61,54515;
106,58401;14,30216;61,55812;
106,68401;14,3558;61,57508;
106,78401;14,40932;61,59051;
106,884;14,463;61,60595;
106,98401;14,51656;61,61455;
107,08401;14,57016;61,63009;
107,18401;14,6238;61,6449;
107,28401;14,67736;61,65423;
107,384;14,73104;61,66869;
107,48401;14,78456;61,68236;
107,58401;14,83812;61,69381;
107,68401;14,8918;61,70567;
107,78401;14,94532;61,7186;
107,884;14,99892;61,72886;
107,98401;15,05248;61,73674;
108,08401;15,10608;61,75001;
108,18401;15,15976;61,75896;
108,28401;15,21348;61,77065;
108,384;15,26708;61,78188;
108,48401;15,32064;61,78917;
108,58401;15,37432;61,79718;
108,68401;15,42792;61,80871;
108,78401;15,48148;61,81656;
108,884;15,53488;61,82243;
108,98401;15,5884;61,83556;
109,08401;15,64204;61,84535;
109,18401;15,69568;61,84959;
109,28401;15,7492;61,8586;
109,384;15,80292;61,86734;
109,48401;15,8564;61,87188;
109,58401;15,91004;61,88393;
109,68401;15,9636;61,88951;
109,78401;16,01724;61,89272;
109,884;16,07096;61,90063;
109,98401;16,12448;61,90402;
110,08401;16,17824;61,91058;
110,18401;16,23188;61,91568;
110,28401;16,28544;61,92192;
110,384;16,33904;61,92529;
110,48401;16,39256;61,9316;
110,58401;16,4462;61,94182;
110,68401;16,4998;61,94326;
110,78401;16,55352;61,94699;
110,884;16,607;61,95024;
110,98401;16,66052;61,95266;
111,08401;16,71416;61,95785;
111,18401;16,76772;61,9634;
111,28401;16,82124;61,96603;
111,384;16,8748;61,96576;
111,48401;16,92836;61,97127;
111,58401;16,98208;61,97519;
111,68401;17,03564;61,97329;
111,78401;17,08944;61,98182;
111,884;17,14296;61,98075;
111,98401;17,19656;61,98152;
112,08401;17,25016;61,98488;
112,18401;17,30368;61,98559;
112,28401;17,3574;61,98742;
112,384;17,41092;61,98806;
112,48401;17,46456;61,99083;
112,58401;17,51828;61,99061;
112,68401;17,57172;61,98941;
112,78401;17,6254;61,99374;
112,884;17,67884;61,98872;
112,98401;17,73248;61,98965;
113,08401;17,78612;61,98996;
113,18401;17,83972;61,98811;
113,28401;17,89328;61,98766;
113,384;17,94672;61,98677;
113,48401;18,0004;61,98463;
113,58401;18,05408;61,98042;
113,68401;18,10776;61,98049;
113,78401;18,16128;61,9761;
113,884;18,21488;61,97613;
113,98401;18,26852;61,97576;
114,08401;18,32204;61,96967;
114,18401;18,37568;61,96656;
114,28401;18,42936;61,96527;
114,384;18,48288;61,95935;
114,48401;18,5366;61,95626;
114,58401;18,59016;61,94948;
114,68401;18,64376;61,94603;
114,78401;18,69748;61,9411;
114,884;18,75092;61,93632;
114,98401;18,80468;61,93389;
115,08401;18,85824;61,92741;
115,18401;18,91184;61,92114;
115,28401;18,96544;61,91473;
115,384;19,01896;61,90557;
115,48401;19,07264;61,90245;
115,58401;19,1262;61,89787;
115,68401;19,1798;61,89206;
115,78401;19,23332;61,88562;
115,884;19,28688;61,87865;
115,98401;19,34052;61,86929;
116,08401;19,3942;61,86389;
116,18401;19,4476;61,85406;
116,28401;19,50124;61,84661;
116,384;19,55488;61,83861;
116,48401;19,60852;61,83029;
116,58401;19,662;61,81563;
116,68401;19,71576;61,81023;
116,78401;19,76924;61,80004;
116,884;19,82288;61,78958;
116,98401;19,87644;61,77912;
117,08401;19,93004;61,77093;
117,18401;19,98372;61,75894;
117,28401;20,03728;61,74464;
117,384;20,09104;61,73762;
117,48401;20,14476;61,72304;
117,58401;20,19832;61,70692;
117,68401;20,25196;61,6976;
117,78401;20,3054;61,68219;
117,884;20,35896;61,66792;
117,98401;20,41256;61,6556;
118,08401;20,4662;61,64072;
118,18401;20,5198;61,62383;
118,28401;20,57328;61,61;
118,384;20,627;61,59774;
118,48401;20,68056;61,57495;
118,58401;20,73412;61,56077;
118,68401;20,78764;61,54379;
118,78401;20,84128;61,52704;
118,884;20,895;61,51116;
118,98401;20,94852;61,49117;
119,08401;21,00228;61,47183;
119,18401;21,05588;61,45056;
119,28401;21,1094;61,43137;
119,384;21,16304;61,41006;
119,48401;21,21656;61,38715;
119,58401;21,27024;61,36961;
119,68401;21,32384;61,3411;
119,78401;21,37748;61,31696;
119,884;21,4312;61,2929;
119,98401;21,48476;61,26566;
120,08401;21,53832;61,24256;
120,18401;21,59184;61,21461;
120,28401;21,6454;61,18522;
120,384;21,69904;61,15476;
120,48401;21,75256;61,12593;
120,58401;21,8062;61,09398;
120,68401;21,85972;61,05915;
120,78401;21,91336;61,02849;
120,884;21,96704;60,99155;
120,98401;22,02076;60,95415;
121,08401;22,0742;60,91502;
121,18401;22,12772;60,87543;
121,28401;22,1814;60,83536;
121,384;22,23504;60,79113;
121,48401;22,28856;60,74396;
121,58401;22,34232;60,69757;
121,68401;22,39584;60,64906;
121,78401;22,44952;60,60337;
121,884;22,50312;60,54476;
121,98401;22,55672;60,49097;
122,08401;22,61048;60,43702;
122,18401;22,66392;60,37329;
122,28401;22,71768;60,31652;
122,384;22,77112;60,25245;
122,48401;22,82464;60,18546;
122,58401;22,87832;60,11697;
122,68401;22,93184;60,04542;
122,78401;22,98552;59,9719;
122,884;23,03912;59,89215;
122,98401;23,09276;59,81782;
123,08401;23,14636;59,73275;
123,18401;23,19988;59,64952;
123,28401;23,25364;59,56918;
123,384;23,30732;59,47555;
123,48401;23,3608;59,38175;
123,58401;23,41444;59,29343;
123,68401;23,46796;59,19361;
123,78201;23,52056;59,09334;
123,882;23,57404;58,99218;
123,97801;23,6256;58,89203;
124,06601;23,6728;58,79197;
124,15801;23,72204;58,69072;
124,25001;23,77144;58,59046;
124,33601;23,81744;58,48897;
124,42001;23,8624;58,38878;
124,50601;23,9086;58,28799;
124,58601;23,95136;58,1869;
124,66601;23,99428;58,08468;
124,746;24,03732;57,9823;
124,82401;24,07912;57,8809;
124,898;24,11872;57,77928;
124,97201;24,15848;57,67735;
125,04401;24,19708;57,57639;
125,118;24,23668;57,47392;
125,19;24,27536;57,37345;
125,26;24,31296;57,2719;
125,32601;24,34836;57,17021;
125,396;24,38588;57,06816;
125,46201;24,42132;56,96766;
125,52801;24,45668;56,86464;
125,59001;24,48984;56,76379;
125,65201;24,52308;56,66342;
125,71401;24,5564;56,56323;
125,77801;24,59068;56,46003;
125,83801;24,62288;56,35703;
125,896;24,65388;56,25528;
125,954;24,68488;56,15363;
126,01401;24,71704;56,05327;
126,07201;24,74812;55,95047;
126,13001;24,77924;55,84984;
126,18401;24,80828;55,74792;
126,23801;24,83728;55,64549;
126,29201;24,8662;55,54509;
126,34601;24,8952;55,44264;
126,40001;24,92424;55,3402;
126,454;24,95324;55,23743;
126,50401;24,98004;55,13381;
126,55401;25,0068;55,03225;
126,606;25,03468;54,93003;
126,65601;25,06152;54,82982;
126,70601;25,08836;54,72803;
126,75401;25,11412;54,62428;
126,80201;25,1398;54,52097;
126,84801;25,1644;54,41954;
126,896;25,19012;54,31578;
126,94401;25,21592;54,21458;
126,98801;25,23952;54,11403;
127,03401;25,26408;54,01045;
127,078;25,28764;53,90793;
127,12201;25,31128;53,80643;
127,16601;25,33496;53,70316;
127,21001;25,3586;53,59918;
127,25201;25,38112;53,49669;
127,29401;25,40364;53,39523;
127,33401;25,42504;53,29425;
127,37401;25,44648;53,19332;
127,41401;25,46796;53,09232;
127,454;25,4894;52,98895;
127,49201;25,50976;52,88878;
127,53201;25,53116;52,7843;
127,57201;25,5526;52,68048;
127,61001;25,573;52,57865;
127,648;25,5934;52,47664;
127,68401;25,61268;52,37561;
127,72201;25,63308;52,27025;
127,758;25,65236;52,16756;
127,79401;25,67168;52,06566;
127,83001;25,691;51,96259;
127,86601;25,71032;51,86119;
127,90201;25,72964;51,75794;
127,93601;25,74784;51,65668;
127,97001;25,76608;51,55504;
128,00402;25,78428;51,44894;
128,03801;25,80252;51,34503;
128,07201;25,82072;51,24177;
128,104;25,83792;51,14128;
128,138;25,8562;51,03582;
128,17002;25,87336;50,93518;
128,20201;25,89056;50,83108;
128,23401;25,90768;50,72844;
128,26401;25,9238;50,62838;
128,29601;25,941;50,52234;
128,32601;25,957;50,42006;
128,354;25,97192;50,31966;
128,384;25,98796;50,21715;
128,414;26,00408;50,11523;
128,444;26,0202;50,00909;
128,474;26,03628;49,90435;
128,502;26,05128;49,80276;
128,53;26,06632;49,70054;
128,558;26,08132;49,59922;
128,586;26,0964;49,49384;
128,61402;26,11144;49,38713;
128,64202;26,12652;49,28;
128,668;26,14044;49,17779;
128,694;26,15444;49,07363;
128,72;26,16836;48,97055;
128,746;26,18228;48,86625;
128,772;26,1962;48,76153;
128,79801;26,21016;48,6568;
128,82401;26,22416;48,55142;
128,84801;26,23708;48,45082;
128,87201;26,25;48,3485;
128,89601;26,26288;48,24619;
128,92002;26,27572;48,14107;
128,944;26,2886;48,03406;
128,968;26,30144;47,9293;
128,99201;26,31428;47,82183;
129,01401;26,32608;47,72179;
129,03601;26,33788;47,62167;
129,06002;26,35072;47,51262;
129,082;26,36256;47,4114;
129,104;26,3744;47,30842;
129,12601;26,3862;47,20421;
129,14801;26,398;47,09957;
129,17002;26,4098;46,99093;
129,19;26,42052;46,89004;
129,21001;26,4312;46,78829;
129,23001;26,44192;46,68564;
129,25;26,45264;46,58175;
129,27001;26,46336;46,47582;
129,29001;26,47408;46,36783;
129,31002;26,48484;46,25947;
129,33;26,4956;46,14883;
129,34801;26,50532;46,04633;
129,36602;26,515;45,9392;
129,382;26,5236;45,83591;
129,39402;26,53;45,72861;
129,40201;26,53436;45,5374;
129,40401;26,53544;45,20498;
129,40601;26,53676;44,3849;
129,40801;26,53788;42,99159;
129,41;26,53936;41,17551;
129,412;26,54052;39,08696;
129,414;26,54196;36,76555;
129,416;26,54304;34,26645;
129,418;26,54432;31,69191;
129,42002;26,54536;29,10061;
129,42202;26,54668;26,50334;