File: data/primary_data/Zx2.csv
Time;Crosshead separation;Load;Extensometer elongation
(sec);(mm);(kN);(%)
0;-0,00004;0,17097;-0,06942
0,834;0,03904;0,63901;-0,06745
1,286;0,09272;1,55842;-0,06367
1,63;0,14828;2,48184;-0,05989
1,928;0,2042;3,41299;-0,05595
2,254;0,27332;4,34536;-0,05198
2,598;0,3578;5,25833;-0,04812
2,994;0,46968;6,17202;-0,04421
3,272;0,55696;7,10546;-0,04045
3,5;0,632;8,03008;-0,03655
3,716;0,7056;8,97208;-0,03267
3,916;0,77524;9,89962;-0,02885
4,114;0,84544;10,85514;-0,0248
4,3;0,91228;11,78475;-0,02096
4,48;0,97752;12,71068;-0,01711
4,66;1,04336;13,66193;-0,01307
4,84;1,10944;14,63764;-0,00899
5,018;1,1752;15,6147;-0,00492
5,188;1,23796;16,56139;-0,00096
5,352;1,2986;17,48249;0,0029
5,514;1,35832;18,40076;0,00687
5,676;1,41808;19,33062;0,01081
5,838;1,47788;20,26522;0,01477
6;1,53724;21,20535;0,01893
6,162;1,59636;22,14819;0,02293
6,324;1,65516;23,09056;0,02705
6,486;1,71396;24,05323;0,0314
6,648;1,77172;24,99283;0,03563
6,81;1,82936;25,93505;0,03992
6,972;1,88648;26,88327;0,04429
7,134;1,94276;27,81096;0,04875
7,296;1,99856;28,73594;0,05325
7,462;2,0546;29,6695;0,05793
7,638;2,113;30,63777;0,06302
7,818;2,17176;31,61327;0,06831
7,998;2,22932;32,57132;0,07384
8,18;2,28616;33,5083;0,07944
8,368;2,34292;34,44615;0,0855
8,566;2,4008;35,39543;0,09206
8,776;2,45928;36,33454;0,09924
8,992;2,51624;37,24894;0,10665
9,234;2,57556;38,17921;0,11536
9,504;2,63636;39,10457;0,12508
9,818;2,69924;40,0387;0,13656
10,2;2,76556;40,9633;0,15044
10,708;2,83672;41,87888;0,16792
11,444;2,91544;42,79052;0,19099
12,344;2,98936;43,53366;0,21618
13,244;3,04976;44,04659;0,23945
14,144;3,10532;44,45392;0,26244
15,044;3,15904;44,75868;0,28482
15,944;3,22276;44,98039;0,30611
16,844;3,27852;45,02902;0,33068
17,744;3,32028;45,06257;0,3553
18,644;3,35468;45,18267;0,37802
19,544;3,38508;45,26117;0,40103
20,444;3,41648;45,39334;0,42413
21,344;3,4416;45,41089;0,44666
22,244;3,46676;45,49134;0,46909
23,144;3,49104;45,54502;0,49196
24,044;3,51596;45,62976;0,51406
24,944;3,53616;45,5514;0,53715
25,844;3,55724;45,57733;0,56
26,744;3,57648;45,54933;0,58221
27,644;3,59524;45,52494;0,60494
28,544;3,61376;45,50786;0,62626
29,444;3,63128;45,4111;0,65059
30,344;3,64772;45,42207;0,67249
31,244;3,663;45,37849;0,69523
32,144;3,67796;45,35683;0,71805
33,044;3,69216;45,33434;0,74068
33,944;3,70616;45,33014;0,76287
34,844;3,72028;45,33045;0,78555
35,744;3,73404;45,3361;0,80778
36,644;3,74792;45,34137;0,83044
37,544;3,7612;45,33195;0,8528
38,444;3,7748;45,34866;0,87519
39,344;3,78772;45,3346;0,89769
40,244;3,80084;45,3298;0,92025
41,144;3,81368;45,31635;0,94309
42,044;3,82608;45,2997;0,96559
42,944;3,8384;45,28982;0,98777
43,844;3,85076;45,27386;1,01053
44,744;3,86248;45,24678;1,0327
45,644;3,87476;45,24106;1,05534
46,544;3,8864;45,20972;1,07799
47,444;3,8984;45,20626;1,10022
48,344;3,91032;45,19695;1,12257
49,244;3,92204;45,17202;1,14506
50,144;3,93372;45,15061;1,16769
51,044;3,94484;45,10126;1,19068
51,944;3,95604;45,07644;1,2127
52,844;3,96884;45,1306;1,23485
53,744;3,9824;45,20646;1,25736
54,644;3,99632;45,30098;1,27953
55,544;4,011;45,4099;1,30238
56,444;4,0256;45,50646;1,32463
57,344;4,04068;45,6054;1,3471
58,244;4,05916;45,73825;1,37035
59,144;4,07424;45,80984;1,39178
60,044;4,09024;45,8849;1,41425
60,944;4,10724;45,98709;1,43668
61,844;4,12444;46,06397;1,45908
62,744;4,14264;46,1536;1,48171
63,644;4,16076;46,22761;1,50383
64,54401;4,18;46,31495;1,52619
65,444;4,19992;46,4045;1,54865
66,344;4,22028;46,4729;1,57156
67,244;4,24128;46,56191;1,5937
68,14401;4,26288;46,64392;1,61589
69,04401;4,28576;46,7347;1,63881
69,944;4,30872;46,81714;1,66113
70,844;4,33264;46,94396;1,68137
71,744;4,35688;46,97703;1,70571
72,64401;4,38088;47,07284;1,72803
73,54401;4,4056;47,17051;1,75058
74,444;4,43;47,24654;1,77268
75,344;4,45536;47,33667;1,79519
76,244;4,48128;47,42211;1,81802
77,14401;4,50708;47,51255;1,84034
78,04401;4,53328;47,60428;1,86258
78,944;4,55936;47,6793;1,88493
79,844;4,58884;47,83697;1,90687
80,744;4,61504;47,84564;1,93022
81,64401;4,64176;47,94294;1,95253
82,54401;4,669;48,03927;1,97507
83,444;4,69516;48,11172;1,99717
84,344;4,7222;48,2113;2,01974
85,244;4,74868;48,28219;2,04241
86,14401;4,77508;48,37167;2,065
87,04401;4,8016;48,46092;2,08768
87,94401;4,82748;48,54171;2,11004
88,844;4,8558;48,68673;2,13211
89,744;4,8804;48,68622;2,15522
90,64401;4,90576;48,78036;2,17762
91,54401;4,9312;48,86661;2,20016
92,44401;4,95616;48,94362;2,22253
93,344;4,98172;49,02959;2,24517
94,244;5,00692;49,09591;2,26795
95,14401;5,03192;49,1771;2,29032
96,04401;5,0568;49,25698;2,31271
96,94401;5,08116;49,32607;2,3347
97,844;5,10852;49,45426;2,35709
98,744;5,13276;49,47482;2,38008
99,64401;5,15748;49,56126;2,40232
100,54401;5,182;49,63735;2,42466
101,44401;5,20612;49,69832;2,44708
102,344;5,23064;49,77922;2,46954
103,244;5,25556;49,86034;2,49235
104,14401;5,27984;49,92267;2,51468
105,04401;5,30444;49,99568;2,5372
105,94401;5,32908;50,06144;2,56001
106,844;5,35532;50,14617;2,58273
107,744;5,37916;50,20924;2,60488
108,64401;5,4032;50,27024;2,62734
109,54401;5,42732;50,3409;2,64972
110,44401;5,4522;50,42166;2,67243
111,344;5,47608;50,47625;2,69463
112,244;5,50056;50,54563;2,71712
113,14401;5,52548;50,61637;2,74012
114,04401;5,5496;50,68091;2,76252
114,94401;5,5762;50,80652;2,78471
115,844;5,59972;50,79805;2,80786
116,744;5,62376;50,86323;2,83014
117,64401;5,64816;50,94695;2,85244
118,54401;5,67264;51,00783;2,87489
119,44401;5,6966;51,05709;2,89745
120,34401;5,72124;51,12588;2,92013
121,244;5,74532;51,19109;2,94241
122,14401;5,76984;51,26081;2,96501
123,04401;5,7948;51,33069;2,98619
123,94401;5,8196;51,35985;3,01023
124,84401;5,844;51,43684;3,03259
125,744;5,86776;51,48926;3,05477
126,64401;5,892;51,5527;3,0773
127,54401;5,91632;51,60953;3,1001
128,444;5,94052;51,66821;3,12221
129,34401;5,965;51,73154;3,14464
130,244;5,98944;51,78044;3,16722
131,14402;6,01372;51,8387;3,18939
132,044;6,0404;51,91525;3,21261
132,944;6,06384;51,94745;3,23456
133,84402;6,08828;52,0067;3,25688
134,744;6,11276;52,0608;3,27964
135,64402;6,13732;52,12484;3,30202
136,544;6,16208;52,18803;3,32462
137,444;6,1862;52,22269;3,34703
138,34402;6,21052;52,28107;3,36945
139,244;6,23484;52,33977;3,39196
140,14402;6,26076;52,41421;3,41432
141,044;6,28448;52,44285;3,4368
141,944;6,3092;52,49529;3,45965
142,84402;6,33332;52,54878;3,48208
143,744;6,35772;52,60808;3,50464
144,64402;6,38136;52,6428;3,52695
145,544;6,40572;52,70134;3,54938
146,444;6,43036;52,76069;3,57203
147,34402;6,45448;52,80309;3,59441
148,244;6,4802;52,87154;3,61697
149,14402;6,5036;52,89207;3,6394
150,044;6,52768;52,95674;3,66188
150,944;6,55184;53,01158;3,68451
151,84402;6,57576;53,04137;3,70703
152,744;6,59996;53,09506;3,72947
153,64402;6,625;53,16156;3,75226
154,544;6,64888;53,1938;3,7746
155,444;6,6732;53,23967;3,79717
156,166;6,67988;52,97405;3,8069
157,06602;6,69772;53,14167;3,82128
157,966;6,71564;53,20811;3,83737
158,86602;6,73356;53,25453;3,85387
159,766;6,75164;53,29669;3,8706
160,666;6,76952;53,32822;3,88717
161,554;6,78728;53,36486;3,90355
178,162;6,79988;52,35286;
179,06202;6,818;52,98467;
179,962;6,83596;53,33518;
180,86202;6,85396;53,49299;
181,76202;6,8718;53,56584;
182,662;6,89;53,6116;
183,56202;6,908;53,63885;
184,462;6,92596;53,66433;
185,36202;6,9438;53,69129;
186,26202;6,96176;53,72121;
187,162;6,97988;53,74861;
188,06202;6,99776;53,77333;
188,962;7,01588;53,80779;
189,86202;7,03372;53,83403;
190,76202;7,05184;53,87075;
191,662;7,06988;53,90034;
192,56202;7,088;53,92892;
193,462;7,10592;53,9573;
194,36202;7,12388;53,98522;
195,26202;7,14192;54,01977;
196,162;7,15988;54,04593;
197,06202;7,17788;54,07716;
197,962;7,19596;54,10993;
198,86202;7,21412;54,13913;
199,76202;7,232;54,16527;
200,662;7,24988;54,18997;
201,56202;7,26796;54,22398;
202,462;7,28588;54,25172;
203,36202;7,30392;54,27882;
204,26202;7,32184;54,30812;
205,162;7,34004;54,34111;
206,06202;7,358;54,36595;
206,962;7,37592;54,39508;
207,86202;7,39396;54,42449;
208,76202;7,41192;54,45153;
209,662;7,42992;54,48004;
210,56202;7,44788;54,50675;
211,462;7,46608;54,54153;
212,36202;7,48388;54,56145;
213,26202;7,50188;54,59579;
214,162;7,51976;54,62171;
215,06202;7,53788;54,65191;
215,962;7,55576;54,67845;
216,86202;7,5738;54,70529;
217,76202;7,59192;54,73773;
218,66202;7,60996;54,76289;
219,56202;7,62796;54,78875;
220,462;7,64588;54,81623;
221,36202;7,664;54,84709;
222,26202;7,68188;54,87131;
223,16202;7,69984;54,90022;
224,06202;7,7178;54,92503;
224,962;7,73588;54,95441;
225,86202;7,75388;54,97952;
226,76202;7,7718;55,00421;
227,66202;7,78984;55,03528;
228,56202;7,80776;55,05697;
229,462;7,82576;55,08656;
230,36202;7,84368;55,11091;
231,26202;7,86188;55,14345;
232,16202;7,87976;55,1658;
233,06202;7,89776;55,1914;
233,962;7,91572;55,21914;
234,86202;7,93384;55,24402;
235,76202;7,9518;55,26972;
236,66202;7,96976;55,29352;
237,56202;7,98792;55,32144;
238,462;8,00576;55,34163;
239,36202;8,0238;55,37012;
240,26202;8,04168;55,3921;
241,16202;8,0598;55,42112;
242,06202;8,07768;55,44257;
242,962;8,09568;55,46923;
243,86202;8,1138;55,49674;
244,76202;8,13184;55,51833;
245,66202;8,1498;55,54312;
246,56202;8,16772;55,56319;
247,462;8,1858;55,59345;
248,36202;8,20388;55,61726;
249,26202;8,22192;55,64156;
250,16202;8,23968;55,65703;
251,06202;8,25772;55,68541;
251,962;8,27568;55,70903;
252,86202;8,29372;55,73146;
253,76202;8,31176;55,75756;
254,66202;8,32972;55,7796;
255,56202;8,34776;55,8038;
256,462;8,36568;55,82766;
257,362;8,38388;55,85386;
258,26203;8,4018;55,87323;
259,16202;8,4198;55,89575;
260,06202;8,43772;55,91655;
260,962;8,45572;55,93998;
261,862;8,47368;55,96327;
262,76203;8,49172;55,98661;
263,66203;8,50992;56,01665;
264,562;8,52788;56,03377;
265,462;8,5458;56,05618;
266,362;8,56364;56,0766;
267,26203;8,58172;56,10248;
268,16203;8,5996;56,12394;
269,062;8,61764;56,14455;
269,962;8,63572;56,16965;
270,862;8,65372;56,18973;
271,76203;8,67176;56,21044;
272,66203;8,6896;56,23094;
273,562;8,70772;56,25584;
274,462;8,7256;56,27049;
275,362;8,74364;56,29837;
276,26203;8,76168;56,31705;
277,16203;8,77976;56,34192;
278,062;8,79772;56,3574;
278,962;8,81564;56,37581;
279,862;8,83368;56,40211;
280,76203;8,85152;56,4193;
281,66203;8,86956;56,4476;
282,562;8,88752;56,46747;
283,462;8,90568;56,49056;
284,362;8,9236;56,50818;
285,26203;8,94164;56,52649;
286,16203;8,95964;56,54869;
287,062;8,97768;56,56561;
287,962;8,9956;56,58528;
288,862;9,01352;56,60624;
289,76203;9,03172;56,63481;
290,66203;9,04964;56,65064;
291,562;9,06772;56,67197;
292,462;9,0856;56,68827;
293,362;9,10368;56,7107;
294,26203;9,12156;56,72537;
295,16203;9,1396;56,74664;
296,062;9,15772;56,77077;
296,962;9,17572;56,78582;
297,862;9,19368;56,80746;
298,76203;9,2116;56,82336;
299,66203;9,22976;56,8495;
300,562;9,24772;56,86321;
301,462;9,26572;56,88244;
302,362;9,28372;56,90166;
303,26203;9,3018;56,9195;
304,16203;9,31964;56,93614;
305,062;9,3376;56,95459;
305,962;9,35572;56,97649;
306,862;9,37364;56,99214;
307,76203;9,39164;57,01214;
308,66203;9,40956;57,02908;
309,562;9,42772;57,05315;
310,462;9,44568;57,06605;
311,36203;9,46364;57,08687;
312,26203;9,48168;57,10499;
313,16203;9,49968;57,12334;
314,062;9,51788;57,14303;
314,962;9,5358;57,15708;
315,86203;9,55364;57,17363;
316,76203;9,5716;57,19396;
317,66203;9,58964;57,2148;
318,562;9,60764;57,22945;
319,462;9,62576;57,24652;
320,36203;9,64364;57,26273;
321,26203;9,66168;57,28087;
322,16203;9,67976;57,30218;
323,062;9,69776;57,31748;
323,962;9,7158;57,3338;
324,86203;9,73364;57,35129;
325,76203;9,75176;57,37146;
326,66203;9,7696;57,38202;
327,562;9,78764;57,40128;
328,462;9,80572;57,41845;
329,36203;9,82388;57,43632;
330,26203;9,84184;57,45098;
331,16203;9,85968;57,46332;
332,062;9,87776;57,4873;
332,962;9,89564;57,49967;
333,86203;9,91356;57,51879;
334,76203;9,93148;57,53453;
335,66203;9,94964;57,55323;
336,562;9,96764;57,5662;
337,462;9,9856;57,58057;
338,36203;10,00364;57,60014;
339,26203;10,0216;57,61447;
340,16203;10,03956;57,63159;
341,062;10,05752;57,64843;
341,962;10,07572;57,66928;
342,86203;10,09368;57,6789;
343,76203;10,11172;57,69646;
344,66203;10,1296;57,70793;
345,562;10,14768;57,72541;
346,462;10,16556;57,73848;
347,36203;10,18356;57,75493;
348,26203;10,20176;57,77596;
349,16203;10,21972;57,78764;
350,062;10,23772;57,80497;
350,962;10,25564;57,81543;
351,86203;10,27372;57,83621;
352,76203;10,2916;57,84562;
353,66203;10,30956;57,86019;
354,562;10,32756;57,87945;
355,462;10,34568;57,89534;
356,36203;10,3636;57,90975;
357,26203;10,38156;57,92359;
358,16203;10,39964;57,94127;
359,062;10,41752;57,95392;
359,962;10,43556;57,96853;
360,86203;10,45348;57,98122;
361,76203;10,47172;57,99958;
362,66203;10,48964;58,00934;
363,562;10,5076;58,02591;
364,462;10,52564;58,0422;
365,36203;10,54368;58,05494;
366,26203;10,56172;58,07096;
367,16203;10,57964;58,08213;
368,062;10,59776;58,10109;
368,962;10,61568;58,10792;
369,86203;10,63364;58,12353;
370,76203;10,65156;58,13638;
371,66203;10,66968;58,15266;
372,562;10,68756;58,16581;
373,462;10,70556;58,18019;
374,36203;10,7236;58,19748;
375,26203;10,7416;58,21092;
376,16203;10,75964;58,2228;
377,062;10,77748;58,23235;
377,962;10,79564;58,25012;
378,86203;10,8136;58,26223;
379,76203;10,83176;58,27935;
380,66203;10,84972;58,28949;
381,562;10,86748;58,30055;
382,462;10,88544;58,31702;
383,36203;10,9034;58,33198;
384,26203;10,92152;58,34874;
385,16203;10,93944;58,35553;
386,062;10,95744;58,36995;
386,962;10,97544;58,38051;
387,86203;10,9936;58,39426;
388,76203;11,01148;58,4044;
389,66203;11,02948;58,41715;
390,562;11,04752;58,43471;
391,462;11,06548;58,44485;
392,36203;11,08344;58,45609;
393,26203;11,1014;58,46779;
394,16203;11,11972;58,48417;
395,062;11,13768;58,49158;
395,962;11,15568;58,50467;
396,86203;11,17348;58,51362;
397,76203;11,19152;58,53028;
398,66203;11,20944;58,54182;
399,562;11,22736;58,55509;
400,462;11,24552;58,57336;
401,36203;11,26352;58,57902;
402,26203;11,28152;58,59187;
403,16203;11,2994;58,59999;
404,062;11,31752;58,61646;
404,962;11,3354;58,62499;
405,86203;11,35344;58,63746;
406,76203;11,37148;58,65381;
407,66203;11,38964;58,66523;
408,562;11,40756;58,6738;
409,462;11,42548;58,6824;
410,36203;11,4436;58,69741;
411,26203;11,4614;58,70521;
412,16203;11,47944;58,71875;
413,062;11,4974;58,73175;
413,962;11,51564;58,74601;
414,86203;11,5336;58,75483;
415,76203;11,55152;58,7675;
416,66203;11,5696;58,78258;
417,562;11,58756;58,78937;
418,462;11,60552;58,79912;
419,36203;11,62348;58,80857;
420,26203;11,64164;58,82478;
421,16203;11,6596;58,83002;
422,062;11,67756;58,84191;
422,962;11,69548;58,85323;
423,86203;11,71352;58,8654;
424,76203;11,7314;58,87735;
425,66203;11,7494;58,88535;
426,562;11,76756;58,89949;
427,462;11,78556;58,9067;
428,36203;11,8036;58,91786;
429,26203;11,82152;58,92651;
430,16203;11,83964;58,94117;
431,062;11,85756;58,94926;
431,962;11,87556;58,96021;
432,86203;11,89364;58,97323;
433,76203;11,91168;58,98215;
434,66203;11,9296;58,99018;
435,562;11,94752;58,99837;
436,462;11,96564;59,01312;
437,36203;11,98356;59,02027;
438,26203;12,00156;59,03086;
439,16203;12,01956;59,04164;
440,062;12,03768;59,05403;
440,96203;12,05564;59,06284;
441,86203;12,07364;59,06989;
442,76203;12,09164;59,08253;
443,66203;12,10964;59,08816;
444,562;12,12784;59,10294;
445,46203;12,1458;59,10931;
446,36203;12,16372;59,1157;
447,26203;12,18156;59,12608;
448,16203;12,19956;59,14138;
449,062;12,21756;59,15184;
449,96203;12,23556;59,16039;
450,86203;12,25352;59,16643;
451,76203;12,27152;59,1773;
452,66203;12,28968;59,19127;
453,562;12,30764;59,19597;
454,46203;12,32552;59,20378;
455,36203;12,34336;59,21263;
456,26203;12,36144;59,22703;
457,16203;12,37928;59,23431;
458,062;12,39732;59,24281;
458,96203;12,4154;59,25757;
459,86203;12,43356;59,2656;
460,76203;12,45156;59,27296;
461,66203;12,4694;59,27625;
462,562;12,48752;59,29003;
463,46203;12,50536;59,2952;
464,36203;12,5234;59,30755;
465,26203;12,5414;59,31881;
466,16203;12,55952;59,32981;
467,062;12,57748;59,33211;
467,96203;12,5954;59,34231;
468,86203;12,61352;59,355;
469,76203;12,63144;59,35974;
470,66203;12,64948;59,37034;
471,562;12,66744;59,37564;
472,46203;12,6856;59,38831;
473,36203;12,70356;59,39333;
474,26203;12,72156;59,40223;
475,16203;12,73948;59,41078;
476,062;12,75748;59,41672;
476,96203;12,77536;59,42116;
477,86203;12,7934;59,43142;
478,76203;12,8116;59,44486;
479,66203;12,8296;59,45176;
480,562;12,84764;59,46003;
481,46203;12,86548;59,46639;
482,36203;12,88364;59,47981;
483,26203;12,90148;59,4852;
484,16203;12,91944;59,49368;
485,062;12,93752;59,50392;
485,96203;12,9556;59,51073;
486,86203;12,97352;59,51564;
487,76203;12,9914;59,52072;
488,66203;13,00952;59,53519;
489,562;13,0274;59,53993;
490,46203;13,04536;59,55094;
491,36203;13,0634;59,56038;
492,26203;13,08156;59,56818;
493,16203;13,09952;59,57146;
494,062;13,11748;59,57613;
494,96203;13,13556;59,58776;
495,86203;13,15348;59,5925;
496,76203;13,17156;59,60222;
497,66203;13,18948;59,60897;
498,562;13,20768;59,61967;
499,46203;13,22556;59,62284;
500,36203;13,24348;59,63023;
501,26203;13,26148;59,63675;
502,16203;13,27948;59,64175;
503,062;13,29752;59,65044;
503,96203;13,31548;59,65664;
504,86203;13,33364;59,66976;
505,76203;13,35168;59,67222;
506,66203;13,36968;59,68173;
507,562;13,38756;59,68541;
508,46203;13,4056;59,69405;
509,36203;13,42356;59,6993;
510,26203;13,44176;59,7049;
511,16203;13,45984;59,71587;
512,062;13,47756;59,71192;
512,96203;13,49552;59,72338;
513,862;13,51344;59,73102;
514,76203;13,53168;59,74292;
515,66206;13,54948;59,74711;
516,562;13,56752;59,75532;
517,46203;13,58556;59,76202;
518,362;13,60368;59,76855;
519,26203;13,62164;59,77194;
520,16206;13,63956;59,77689;
521,062;13,65768;59,78923;
521,96203;13,67556;59,79083;
522,862;13,69356;59,80052;
523,76203;13,71152;59,80467;
524,66206;13,72968;59,81511;
525,562;13,74768;59,81728;
526,46206;13,76564;59,8215;
527,362;13,78352;59,82696;
528,262;13,80156;59,83329;
529,16206;13,81956;59,84026;
530,062;13,83756;59,84548;
530,96206;13,85564;59,85413;
531,862;13,8736;59,85972;
532,762;13,8916;59,86731;
533,66206;13,90944;59,86959;
534,562;13,9276;59,88171;
535,46206;13,94556;59,88253;
536,362;13,96356;59,8892;
537,262;13,98168;59,8988;
538,16206;13,99972;59,90259;
539,062;14,01772;59,9073;
539,96206;14,0356;59,90898;
540,862;14,05368;59,92165;
541,762;14,07152;59,92353;
542,66206;14,08948;59,92872;
543,562;14,10752;59,93811;
544,46206;14,12564;59,94338;
545,362;14,1436;59,94743;
546,262;14,16152;59,94896;
547,16206;14,1796;59,96;
548,062;14,19752;59,96487;
548,96206;14,21548;59,97149;
549,862;14,23336;59,9754;
550,762;14,25148;59,98591;
551,66206;14,2694;59,98779;
552,562;14,2874;59,99311;
553,46206;14,30532;59,99664;
554,362;14,32336;60,00435;
555,262;14,34132;60,00744;
556,16206;14,35932;60,01524;
557,062;14,37748;60,02604;
557,96206;14,39544;60,02592;
558,862;14,41348;60,0323;
559,762;14,4314;60,03507;
560,66206;14,44956;60,04122;
561,562;14,46756;60,04675;
562,46206;14,4856;60,04991;
563,362;14,50372;60,05977;
564,262;14,52172;60,06179;
565,16206;14,53964;60,06628;
566,062;14,55744;60,06954;
566,96206;14,57556;60,0763;
567,862;14,59348;60,08167;
568,762;14,61152;60,08869;
569,66206;14,62956;60,09346;
570,562;14,64764;60,10072;
571,46206;14,66564;60,10236;
572,362;14,68356;60,106;
573,262;14,70164;60,11647;
574,16206;14,71948;60,1171;
575,062;14,7376;60,1289;
575,96206;14,75556;60,12676;
576,862;14,7736;60,13531;
577,762;14,79132;60,13362;
578,66206;14,80928;60,14009;
579,562;14,82736;60,15015;
580,46206;14,84532;60,14996;
581,362;14,86336;60,1566;
582,262;14,88132;60,16292;
583,16206;14,89952;60,17028;
584,062;14,91748;60,17381;
584,96206;14,93548;60,17726;
585,862;14,95336;60,17876;
586,762;14,97148;60,18469;
587,66206;14,98936;60,18644;
588,562;15,00736;60,19178;
589,46206;15,02552;60,20162;
590,362;15,04348;60,20108;
591,262;15,06152;60,20991;
592,16206;15,07936;60,20829;
593,062;15,09736;60,21785;
593,96206;15,11528;60,21954;
594,862;15,13328;60,22455;
595,762;15,15136;60,23209;
596,66206;15,16944;60,23428;
597,562;15,1874;60,23864;
598,46206;15,20536;60,24035;
599,362;15,22344;60,24854;
600,262;15,24132;60,25126;
601,16206;15,25944;60,25826;
602,062;15,27736;60,25946;
602,96206;15,29556;60,26458;
603,862;15,31352;60,2653;
604,762;15,33152;60,26922;
605,66206;15,34956;60,27424;
606,562;15,36748;60,27365;
607,46206;15,38544;60,2801;
608,362;15,40336;60,28324;
609,262;15,42156;60,29567;
610,16206;15,43956;60,29142;
611,062;15,45756;60,29589;
611,96206;15,47548;60,29701;
612,862;15,49352;60,30281;
613,762;15,51148;60,30775;
614,66206;15,52948;60,30917;
615,562;15,54756;60,3204;
616,46206;15,56552;60,32122;
617,362;15,58348;60,32565;
618,262;15,60132;60,32779;
619,16206;15,61948;60,3329;
620,062;15,63732;60,3338;
620,96206;15,6554;60,33911;
621,862;15,67344;60,34415;
622,762;15,69148;60,34858;
623,66206;15,70944;60,35009;
624,562;15,72736;60,35087;
625,46206;15,74548;60,36269;
626,362;15,76344;60,36165;
627,262;15,78148;60,36708;
628,16206;15,79952;60,3684;
629,062;15,81764;60,37274;
629,96206;15,83556;60,3726;
630,862;15,85344;60,37184;
631,762;15,8714;60,38209;
632,66206;15,88936;60,3834;
633,562;15,90736;60,3869;
634,46206;15,92528;60,38879;
635,36206;15,94348;60,39697;
636,262;15,9614;60,39618;
637,16206;15,97952;60,40058;
638,062;15,9974;60,4014;
638,96206;16,01544;60,40667;
639,86206;16,0334;60,40901;
640,762;16,05152;60,41741;
641,66206;16,06976;60,42054;
642,562;16,08744;60,412;
643,46206;16,10532;60,42382;
644,36206;16,12324;60,42322;
645,262;16,14148;60,43226;
646,16206;16,15936;60,42951;
647,062;16,17732;60,43205;
647,96206;16,1954;60,44012;
648,86206;16,21348;60,44267;
649,762;16,23148;60,44739;
650,66206;16,2494;60,44704;
651,562;16,26752;60,45392;
652,46206;16,2854;60,45126;
653,36206;16,30344;60,45595;
654,262;16,3214;60,45836;
655,16206;16,3396;60,46336;
656,062;16,35764;60,46495;
656,96206;16,3756;60,46788;
657,86206;16,39356;60,46955;
658,762;16,41144;60,4695;
659,66206;16,42948;60,47436;
660,562;16,4474;60,47536;
661,46206;16,46556;60,48154;
662,36206;16,48352;60,47968;
663,262;16,50148;60,48467;
664,16206;16,5194;60,48552;
665,062;16,5374;60,48841;
665,96206;16,55532;60,49418;
666,86206;16,57332;60,49476;
667,762;16,59144;60,50529;
668,66206;16,6094;60,50294;
669,562;16,62752;60,50582;
670,46206;16,64532;60,50485;
671,36206;16,66348;60,50967;
672,262;16,68132;60,50879;
673,16206;16,69924;60,51119;
674,062;16,71736;60,51831;
674,96206;16,73536;60,52062;
675,86206;16,75352;60,52564;
676,762;16,77136;60,52303;
677,66206;16,78956;60,52982;
678,562;16,80744;60,52634;
679,46206;16,8254;60,52978;
680,36206;16,8434;60,53267;
681,262;16,86144;60,53666;
682,16206;16,8794;60,53662;
683,062;16,89736;60,53957;
683,96206;16,91536;60,5455;
684,86206;16,93332;60,54379;
685,762;16,95128;60,54701;
686,66206;16,9692;60,54708;
687,562;16,9874;60,55387;
688,46206;17,00532;60,55366;
689,36206;17,02336;60,55453;
690,262;17,04128;60,55484;
691,16206;17,05932;60,55856;
692,062;17,07732;60,5611;
692,96206;17,09532;60,56247;
693,86206;17,1136;60,57004;
694,762;17,13152;60,56575;
695,66206;17,14948;60,56806;
696,562;17,16728;60,5644;
697,46206;17,18528;60,57057;
698,36206;17,20324;60,57093;
699,262;17,22124;60,57477;
700,16206;17,23936;60,58154;
701,062;17,2574;60,57997;
701,96206;17,27544;60,58131;
702,86206;17,2934;60,57848;
703,762;17,31152;60,58457;
704,66206;17,32936;60,58242;
705,562;17,34744;60,58676;
706,46206;17,3656;60,592;
707,36206;17,38376;60,59157;
708,262;17,4014;60,58534;
709,16206;17,41928;60,58809;
710,062;17,43744;60,597;
710,96206;17,4554;60,59674;
711,86206;17,47344;60,6008;
712,762;17,49136;60,6001;
713,66206;17,50952;60,60557;
714,562;17,52748;60,60389;
715,46206;17,54544;60,6048;
716,36206;17,5634;60,60687;
717,262;17,58136;60,60644;
718,16206;17,59932;60,60847;
719,062;17,61728;60,60839;
719,96206;17,63548;60,61554;
720,86206;17,65352;60,61484;
721,762;17,6716;60,61653;
722,66206;17,68948;60,6155;
723,562;17,70748;60,61516;
724,46206;17,72536;60,61741;
725,36206;17,74336;60,62081;
726,262;17,76156;60,62402;
727,16206;17,77952;60,62078;
728,062;17,79756;60,62405;
728,96206;17,81548;60,62121;
729,86206;17,83356;60,62666;
730,762;17,85148;60,62481;
731,66206;17,86948;60,62806;
732,562;17,88748;60,63084;
733,46206;17,9056;60,63212;
734,36206;17,92356;60,62897;
735,262;17,94156;60,62766;
736,16206;17,95964;60,63393;
737,062;17,97752;60,62952;
737,96206;17,99548;60,63094;
738,86206;18,0134;60,63325;
739,762;18,03152;60,63848;
740,66206;18,04952;60,63714;
741,562;18,06756;60,64134;
742,46206;18,08556;60,64028;
743,36206;18,10352;60,64012;
744,262;18,12156;60,64152;
745,16206;18,13948;60,64074;
746,062;18,15764;60,64596;
746,96206;18,17556;60,64174;
747,86206;18,19356;60,64577;
748,762;18,21144;60,64321;
749,66206;18,22944;60,64577;
750,562;18,24736;60,64495;
751,46206;18,26532;60,64394;
752,36206;18,28344;60,64885;
753,262;18,30144;60,64691;
754,16206;18,31944;60,64917;
755,062;18,33732;60,64703;
755,96206;18,35544;60,6519;
756,86206;18,37332;60,65212;
757,762;18,39144;60,65533;
758,66206;18,40944;60,65675;
759,562;18,42756;60,65655;
760,46206;18,44552;60,65305;
761,36206;18,46336;60,65037;
762,262;18,4814;60,6576;
763,16206;18,49928;60,65511;
764,062;18,51736;60,65903;
764,96206;18,53528;60,65707;
765,86206;18,5534;60,6622;
766,762;18,5714;60,65855;
767,66206;18,58936;60,65869;
768,562;18,60736;60,65748;
769,46206;18,62532;60,65444;
770,36206;18,64332;60,65881;
771,262;18,66148;60,66136;
772,16206;18,67972;60,66481;
773,062;18,6976;60,65691;
773,96206;18,71532;60,65547;
774,86206;18,7332;60,65836;
775,762;18,75136;60,66298;
776,66206;18,76928;60,65852;
777,562;18,78732;60,659;
778,46206;18,80552;60,66402;
779,36206;18,82352;60,66115;
780,262;18,84156;60,6609;
781,16206;18,8594;60,65707;
782,062;18,87748;60,66477;
782,96206;18,8954;60,66192;
783,86206;18,91336;60,66276;
784,762;18,9314;60,66408;
785,66206;18,94948;60,66319;
786,562;18,96752;60,6612;
787,46206;18,98548;60,65836;
788,36206;19,00356;60,66306;
789,262;19,02132;60,65814;
790,16206;19,03932;60,66227;
791,062;19,05732;60,6638;
791,96206;19,0754;60,66447;
792,86206;19,09336;60,66091;
793,762;19,1114;60,65935;
794,66206;19,1294;60,66097;
795,562;19,14728;60,65622;
796,46206;19,16532;60,65963;
797,36206;19,18332;60,65936;
798,262;19,20152;60,6647;
799,16206;19,21944;60,66058;
800,062;19,23748;60,66211;
800,96206;19,25536;60,6591;
801,86206;19,2734;60,65778;
802,762;19,2914;60,65686;
803,66206;19,30936;60,65398;
804,562;19,32752;60,66118;
805,46206;19,34556;60,65729;
806,36206;19,36356;60,65864;
807,262;19,38152;60,65462;
808,16206;19,39964;60,65718;
809,062;19,41756;60,65421;
809,96206;19,43556;60,65336;
810,86206;19,45364;60,65493;
811,762;19,47164;60,65321;
812,66206;19,4896;60,65106;
813,562;19,50756;60,64994;
814,46206;19,5256;60,6534;
815,36206;19,54352;60,65106;
816,262;19,56156;60,65407;
817,16206;19,57944;60,65077;
818,062;19,59752;60,65158;
818,96206;19,6154;60,64486;
819,86206;19,6334;60,64761;
820,762;19,6514;60,64951;
821,66206;19,66936;60,64258;
822,562;19,6874;60,64799;
823,46206;19,7054;60,64569;
824,36206;19,72364;60,65048;
825,262;19,74156;60,64478;
826,16206;19,75956;60,64187;
827,062;19,77736;60,63795;
827,96206;19,79544;60,64101;
828,86206;19,8134;60,63967;
829,762;19,8314;60,63816;
830,66206;19,84956;60,64116;
831,562;19,86752;60,63788;
832,46206;19,88556;60,64091;
833,36206;19,90344;60,6357;
834,262;19,92156;60,63803;
835,16206;19,93936;60,6311;
836,062;19,95736;60,63332;
836,96206;19,97564;60,63911;
837,86206;19,99376;60,63222;
838,762;20,01144;60,62231;
839,66206;20,02928;60,62242;
840,562;20,04736;60,6318;
841,46206;20,06536;60,62791;
842,36206;20,0834;60,6259;
843,262;20,10136;60,62716;
844,16206;20,11956;60,62732;
845,062;20,13756;60,62334;
845,96206;20,15556;60,62207;
846,86206;20,17356;60,62198;
847,762;20,19152;60,61819;
848,66206;20,20952;60,61894;
849,562;20,22744;60,61581;
850,46206;20,2456;60,62173;
851,36206;20,2636;60,61527;
852,262;20,28164;60,61566;
853,16206;20,29964;60,61128;
854,062;20,31752;60,60659;
854,96206;20,33548;60,60804;
855,86206;20,35344;60,60585;
856,762;20,37164;60,61159;
857,66206;20,38956;60,6048;
858,562;20,40756;60,60293;
859,46206;20,4254;60,59974;
860,36206;20,44352;60,60122;
861,262;20,4614;60,59719;
862,16206;20,4794;60,59594;
863,062;20,49752;60,59904;
863,96206;20,51556;60,59609;
864,86206;20,53356;60,59381;
865,762;20,55148;60,5914;
866,66206;20,5696;60,59371;
867,562;20,58748;60,58753;
868,46206;20,60548;60,58838;
869,36206;20,62348;60,58397;
870,262;20,6416;60,58525;
871,16206;20,6596;60,58166;
872,062;20,67756;60,57936;
872,96206;20,69564;60,57972;
873,86206;20,71352;60,57419;
874,762;20,73156;60,5775;
875,66206;20,74952;60,57254;
876,562;20,76764;60,57312;
877,46206;20,78552;60,56777;
878,36206;20,80356;60,566;
879,262;20,82148;60,56393;
880,16206;20,83948;60,56143;
881,062;20,8574;60,55988;
881,96206;20,87532;60,55803;
882,86206;20,89348;60,56266;
883,762;20,9114;60,55651;
884,66206;20,92948;60,55816;
885,562;20,94732;60,55083;
886,46206;20,9654;60,55146;
887,36206;20,98332;60,54667;
888,262;21,00132;60,54767;
889,16206;21,01948;60,54883;
890,06206;21,03752;60,54456;
890,96206;21,05548;60,54158;
891,86206;21,0734;60,53687;
892,762;21,0914;60,53804;
893,66206;21,10932;60,53328;
894,56206;21,1274;60,5315;
895,46206;21,1454;60,53066;
896,36206;21,16356;60,52906;
897,262;21,18148;60,52365;
898,16206;21,19952;60,52219;
899,06206;21,2176;60,52139;
899,96206;21,23548;60,51711;
900,86206;21,25348;60,5158;
901,762;21,27144;60,51267;
902,66206;21,28984;60,51553;
903,56206;21,30776;60,50587;
904,46206;21,32548;60,49899;
905,36206;21,34344;60,50016;
906,262;21,3614;60,49921;
907,16206;21,37944;60,49843;
908,06206;21,3974;60,49492;
908,96206;21,41552;60,4989;
909,86206;21,43352;60,49004;
910,762;21,45152;60,48748;
911,66206;21,46944;60,48222;
912,56206;21,48752;60,48018;
913,46206;21,50544;60,47779;
914,36206;21,52344;60,47516;
915,262;21,54148;60,47696;
916,16206;21,55952;60,47274;
917,06206;21,57748;60,46929;
917,96206;21,59548;60,46705;
918,86206;21,61364;60,46299;
919,762;21,63144;60,45647;
920,66206;21,64944;60,45607;
921,56206;21,66744;60,45476;
922,46206;21,68556;60,45274;
923,36206;21,70348;60,44817;
924,262;21,72148;60,44707;
925,16206;21,73956;60,4486;
926,06206;21,75744;60,43817;
926,96206;21,77548;60,43724;
927,86206;21,79348;60,4318;
928,762;21,81164;60,43151;
929,66206;21,8296;60,42427;
930,56206;21,8476;60,42151;
931,46206;21,86556;60,4189;
932,36206;21,88352;60,41452;
933,262;21,90148;60,41273;
934,16206;21,9194;60,40861;
935,06206;21,9376;60,41002;
935,96206;21,95552;60,40061;
936,86206;21,97364;60,40161;
937,762;21,99156;60,3945;
938,66206;22,00956;60,39168;
939,56206;22,02744;60,38587;
940,46206;22,0454;60,38476;
941,36206;22,06352;60,38676;
942,262;22,08148;60,37997;
943,16206;22,09948;60,3752;
944,06206;22,11744;60,36828;
944,96206;22,13552;60,36906;
945,86206;22,1534;60,36267;
946,762;22,1714;60,3582;
947,66206;22,18936;60,35674;
948,56206;22,20752;60,35386;
949,46206;22,2254;60,34885;
950,36206;22,2434;60,34554;
951,262;22,26148;60,34119;
952,16206;22,27936;60,33196;
953,06206;22,29744;60,33184;
953,96206;22,31544;60,32715;
954,86206;22,33364;60,32622;
955,762;22,3516;60,31749;
956,66206;22,36956;60,31339;
957,56206;22,38748;60,30975;
958,46206;22,40536;60,3038;
959,36206;22,42336;60,30154;
960,262;22,44136;60,29503;
961,16206;22,45956;60,29585;
962,06206;22,47752;60,2874;
962,96206;22,49556;60,28612;
963,86206;22,51348;60,2788;
964,762;22,53156;60,27558;
965,66206;22,54944;60,27184;
966,56206;22,56744;60,26664;
967,46206;22,58572;60,26926;
968,36206;22,6038;60,25802;
969,262;22,62176;60,24971;
970,16206;22,63936;60,24034;
971,06206;22,65752;60,24324;
971,96206;22,67544;60,23753;
972,86206;22,69344;60,23406;
973,762;22,71148;60,23028;
974,66206;22,72952;60,22677;
975,56206;22,74748;60,22003;
976,46206;22,76548;60,21237;
977,36206;22,78352;60,20995;
978,262;22,80144;60,20108;
979,16206;22,81948;60,1988;
980,06206;22,8374;60,19149;
980,96206;22,85548;60,18905;
981,86206;22,87344;60,1813;
982,762;22,89152;60,17881;
983,66206;22,90956;60,17389;
984,56206;22,92752;60,16311;
985,46206;22,9454;60,15533;
986,36206;22,96336;60,15118;
987,262;22,98156;60,14975;
988,16206;22,99944;60,13929;
989,06206;23,01748;60,13592;
989,96206;23,0354;60,12752;
990,86206;23,0534;60,12498;
991,762;23,07132;60,11881;
992,66206;23,08928;60,11102;
993,56206;23,10744;60,11026;
994,46206;23,12544;60,09734;
995,36206;23,14348;60,09287;
996,262;23,1614;60,08443;
997,16206;23,17948;60,07915;
998,06206;23,19732;60,0695;
998,96206;23,21532;60,06368;
999,86206;23,23328;60,05984;
1000,762;23,2514;60,05282;
1001,66206;23,2694;60,04398;
1002,56206;23,2874;60,03588;
1003,46206;23,30556;60,03013;
1004,36206;23,3234;60,0202;
1005,262;23,34148;60,01503;
1006,16206;23,35948;60,00634;
1007,06206;23,37756;60,00133;
1007,96206;23,39548;59,99018;
1008,86206;23,4134;59,98427;
1009,762;23,43148;59,97717;
1010,66206;23,4494;59,96244;
1011,56206;23,4674;59,95947;
1012,46206;23,48536;59,94914;
1013,36206;23,50352;59,94792;
1014,262;23,52148;59,9351;
1015,16206;23,53948;59,92906;
1016,06206;23,5574;59,92056;
1016,96206;23,57544;59,91237;
1017,86206;23,5934;59,90462;
1018,762;23,61144;59,89364;
1019,66206;23,62968;59,89036;
1020,56206;23,64772;59,87967;
1021,46206;23,66576;59,86902;
1022,36206;23,6836;59,85691;
1023,262;23,7016;59,85036;
1024,16212;23,7194;59,83977;
1025,062;23,73748;59,83452;
1025,96206;23,75556;59,82736;
1026,86206;23,7736;59,81154;
1027,76206;23,7916;59,80082;
1028,66212;23,80956;59,78973;
1029,562;23,82764;59,78524;
1030,46206;23,84552;59,7706;
1031,36206;23,86348;59,76159;
1032,26206;23,88144;59,7536;
1033,16212;23,8998;59,74762;
1034,062;23,91772;59,73131;
1034,96206;23,93544;59,70917;
1035,86206;23,9534;59,70753;
1036,76206;23,9714;59,6947;
1037,66212;23,98948;59,68639;
1038,562;24,00732;59,67142;
1039,46206;24,02568;59,66855;
1040,36206;24,0436;59,65146;
1041,26206;24,06172;59,64293;
1042,16212;24,0796;59,62517;
1043,062;24,0976;59,61298;
1043,96206;24,1156;59,59949;
1044,86206;24,13356;59,58799;
1045,76206;24,15172;59,58008;
1046,66212;24,16972;59,56355;
1047,562;24,18776;59,55417;
1048,46206;24,20572;59,54009;
1049,362;24,2238;59,52932;
1050,26212;24,24156;59,50965;
1051,16212;24,25956;59,49565;
1052,062;24,27764;59,48413;
1052,962;24,29572;59,46789;
1053,862;24,31368;59,45442;
1054,76212;24,33164;59,44123;
1055,66212;24,34976;59,4291;
1056,562;24,3676;59,41288;
1057,462;24,38564;59,40004;
1058,362;24,40364;59,38644;
1059,26212;24,42176;59,37123;
1060,16212;24,43968;59,34999;
1061,062;24,45756;59,33108;
1061,962;24,47564;59,32082;
1062,862;24,49356;59,30249;
1063,76212;24,51152;59,29031;
1064,66212;24,52944;59,27084;
1065,562;24,5476;59,26227;
1066,462;24,56556;59,24196;
1067,362;24,5836;59,2256;
1068,26212;24,60156;59,2073;
1069,16212;24,61956;59,18458;
1070,062;24,63756;59,16969;
1070,962;24,6556;59,15223;
1071,862;24,6738;59,13832;
1072,76212;24,69168;59,11415;
1073,66212;24,70972;59,0972;
1074,562;24,7276;59,07789;
1075,462;24,74568;59,06224;
1076,362;24,7636;59,03721;
1077,26212;24,78156;59,01912;
1078,16212;24,79968;59,00113;
1079,062;24,81768;58,98135;
1079,962;24,83564;58,96064;
1080,862;24,85356;58,93779;
1081,76212;24,87168;58,92271;
1082,66212;24,88952;58,89711;
1083,562;24,90752;58,87936;
1084,462;24,9256;58,85905;
1085,362;24,94376;58,83479;
1086,26212;24,9618;58,81017;
1087,16212;24,9798;58,78698;
1088,062;24,99776;58,76829;
1088,962;25,01556;58,74336;
1089,862;25,03364;58,72451;
1090,76212;25,05156;58,70044;
1091,66212;25,0698;58,68172;
1092,562;25,08768;58,65179;
1093,462;25,10572;58,62911;
1094,362;25,12372;58,60335;
1095,26212;25,14168;58,57853;
1096,16212;25,15964;58,55629;
1097,062;25,1776;58,52975;
1097,962;25,1958;58,5149;
1098,862;25,21392;58,48492;
1099,76212;25,23192;58,4585;
1100,66212;25,24952;58,42296;
1101,562;25,2676;58,4036;
1102,462;25,28552;58,37784;
1103,362;25,3036;58,35125;
1104,26212;25,32172;58,3301;
1105,16212;25,3398;58,29855;
1106,062;25,3578;58,27011;
1106,962;25,37572;58,24209;
1107,862;25,39384;58,21732;
1108,76212;25,41168;58,18654;
1109,66212;25,42972;58,15953;
1110,562;25,44772;58,12803;
1111,462;25,46588;58,09955;
1112,362;25,48384;58,0672;
1113,26212;25,5018;58,04015;
1114,16212;25,51996;58,01375;
1115,062;25,53788;57,98025;
1115,962;25,55576;57,95059;
1116,862;25,57372;57,9204;
1117,76212;25,59184;57,89326;
1118,66212;25,6098;57,85392;
1119,562;25,6278;57,82239;
1120,462;25,6458;57,79279;
1121,362;25,6638;57,75794;
1122,26212;25,68172;57,7284;
1123,16212;25,69972;57,69499;
1124,062;25,71792;57,66726;
1124,962;25,73584;57,63031;
1125,862;25,75392;57,59576;
1126,76212;25,7718;57,55786;
1127,66212;25,78988;57,52457;
1128,562;25,80776;57,48555;
1129,462;25,82572;57,45152;
1130,362;25,84384;57,42085;
1131,26212;25,8618;57,383;
1132,16212;25,8798;57,34936;
1133,062;25,89772;57,31295;
1133,962;25,91588;57,27918;
1134,862;25,9338;57,23714;
1135,76212;25,95184;57,20088;
1136,66212;25,96988;57,16407;
1137,562;25,98796;57,1259;
1138,462;26,00584;57,08723;
1139,362;26,02384;57,05062;
1140,26212;26,04188;57,01439;
1141,16212;26,05984;56,97151;
1142,062;26,07784;56,93367;
1142,962;26,09576;56,89216;
1143,862;26,11396;56,85436;
1144,76212;26,13184;56,80801;
1145,66212;26,14984;56,76916;
1146,562;26,16788;56,72959;
1147,462;26,1858;56,68563;
1148,362;26,20384;56,64472;
1149,26212;26,22176;56,60198;
1150,16212;26,24;56,56502;
1151,062;26,25796;56,51637;
1151,962;26,27596;56,47283;
1152,862;26,29392;56,42621;
1153,76212;26,31188;56,38193;
1154,66212;26,32976;56,33869;
1155,562;26,34776;56,29452;
1156,462;26,36592;56,25418;
1157,362;26,38396;56,20492;
1158,26212;26,40196;56,15716;
1159,16212;26,41984;56,10721;
1160,062;26,43796;56,06521;
1160,962;26,45592;56,01407;
1161,862;26,47392;55,96558;
1162,76212;26,49196;55,91975;
1163,66212;26,51016;55,87443;
1164,562;26,52816;55,81968;
1165,462;26,54604;55,76584;
1166,362;26,56396;55,72011;
1167,26212;26,58184;55,6668;
1168,16212;26,59992;55,61985;
1169,062;26,61792;55,5638;
1169,962;26,63612;55,51388;
1170,862;26,65412;55,45809;
1171,76212;26,67216;55,404;
1172,66212;26,69016;55,35514;
1173,562;26,70808;55,29785;
1174,462;26,72608;55,24679;
1175,362;26,74404;55,19097;
1176,26212;26,76224;55,13797;
1177,16212;26,78016;55,07621;
1178,062;26,79824;55,02138;
1178,962;26,8162;54,96264;
1179,862;26,83432;54,90618;
1180,76212;26,85216;54,84617;
1181,66212;26,87;54,78737;
1182,562;26,888;54,73508;
1183,462;26,906;54,67357;
1184,362;26,924;54,61396;
1185,26212;26,94192;54,55012;
1186,16212;26,96004;54,49119;
1187,062;26,97796;54,42737;
1187,962;26,99596;54,36584;
1188,862;27,014;54,30567;
1189,76212;27,03212;54,24093;
1190,66212;27,05004;54,17373;
1191,562;27,068;54,10835;
1192,462;27,08608;54,04805;
1193,362;27,10404;53,97682;
1194,26212;27,12208;53,91017;
1195,16212;27,14;53,8412;
1196,062;27,15812;53,77575;
1196,962;27,17608;53,70576;
1197,862;27,19408;53,63773;
1198,76212;27,21212;53,57044;
1199,66212;27,23008;53,49576;
1200,562;27,24808;53,42788;
1201,462;27,26604;53,3511;
1202,362;27,28424;53,2814;
1203,26212;27,3022;53,2021;
1204,16212;27,32016;53,1298;
1205,062;27,33808;53,05569;
1205,962;27,35616;52,98084;
1206,862;27,37408;52,90451;
1207,76212;27,39212;52,82733;
1208,66212;27,4102;52,75347;
1209,562;27,4282;52,6683;
1210,462;27,44628;52,58762;
1211,362;27,46416;52,50479;
1212,26212;27,48236;52,42742;
1213,16212;27,50024;52,34171;
1214,062;27,51828;52,25866;
1214,962;27,53636;52,1789;
1215,862;27,55448;52,09177;
1216,76212;27,57248;52,00354;
1217,66212;27,59044;51,91516;
1218,562;27,60844;51,82958;
1219,462;27,62632;51,73397;
1220,362;27,64436;51,65005;
1221,26212;27,6624;51,55844;
1222,16212;27,68052;51,46675;
1223,062;27,69844;51,37061;
1223,962;27,71644;51,28027;
1224,862;27,73444;51,18594;
1225,76212;27,75244;51,08603;
1226,66212;27,77044;50,98798;
1227,562;27,78836;50,88869;
1228,462;27,80664;50,79324;
1229,362;27,82468;50,69048;
1230,26212;27,84272;50,58781;
1231,16212;27,86036;50,47644;
1232,062;27,87836;50,38151;
1232,962;27,89636;50,27434;
1233,862;27,9144;50,16788;
1234,76212;27,93252;50,06072;
1235,66212;27,95056;49,94456;
1236,562;27,9686;49,83422;
1237,462;27,98656;49,71965;
1238,362;28,00464;49,60855;
1239,26212;28,02252;49,48916;
1240,16212;28,04056;49,37418;
1241,062;28,05856;49,2543;
1241,962;28,07668;49,13129;
1242,862;28,0946;49,00661;
1243,76212;28,11264;48,87964;
1244,66212;28,13084;48,7563;
1245,562;28,14876;48,62362;
1246,462;28,16668;48,49345;
1247,362;28,1846;48,3621;
1248,26212;28,20276;48,23038;
1249,16212;28,22072;48,08964;
1250,062;28,23864;47,95128;
1250,962;28,25672;47,80875;
1251,862;28,27464;47,66041;
1252,76212;28,29264;47,51488;
1253,66212;28,31064;47,36507;
1254,562;28,32884;47,21756;
1255,462;28,34684;47,05793;
1256,362;28,36488;46,90212;
1257,26212;28,3828;46,73701;
1258,16212;28,40092;46,56678;
1259,062;28,41884;46,39595;
1259,962;28,43684;46,21848;
1260,862;28,455;46,03718;
1261,76212;28,47304;45,81886;
1262,15212;28,481;44,45394;
1262,17;28,48292;25,13275;