File: data/primary_data/Zx3.csv
Time;Crosshead separation;Load;Extensometer elongation
(sec);(mm);(kN);(%)
0;-0,00008;0,20536;-0,02301
0,874;0,04304;0,59561;-0,02078
1,314;0,09988;1,51339;-0,01717
1,658;0,15832;2,43952;-0,01349
1,962;0,21844;3,36814;-0,00954
2,23;0,2788;3,64884;-0,00749
2,76;0,423;4,57185;-0,00348
3,128;0,54304;5,50413;0,00035
3,388;0,63412;6,4327;0,00414
3,608;0,71432;7,36439;0,00798
3,81;0,78964;8,3022;0,01181
4,008;0,8648;9,27184;0,01582
4,188;0,93376;10,19753;0,01973
4,368;1,00324;11,1509;0,02363
4,548;1,0732;12,12956;0,02767
4,716;1,13868;13,06162;0,0316
4,88;1,20272;13,98086;0,03539
5,042;1,26624;14,91023;0,03926
5,204;1,32936;15,8469;0,04318
5,366;1,39212;16,78394;0,0471
5,528;1,45464;17,73737;0,05116
5,69;1,51704;18,69539;0,05517
5,852;1,57948;19,6626;0,05935
6,014;1,64144;20,62878;0,06345
6,176;1,70312;21,59792;0,06764
6,338;1,76456;22,5789;0,07196
6,5;1,82572;23,5642;0,07625
6,662;1,8862;24,53973;0,08066
6,824;1,94608;25,51644;0,0851
6,986;2,00532;26,48846;0,08959
7,148;2,0638;27,45254;0,09412
7,31;2,12144;28,4076;0,09883
7,472;2,178;29,33967;0,10348
7,634;2,23352;30,26474;0,10822
7,796;2,2878;31,17782;0,11323
7,974;2,3462;32,1541;0,11863
8,154;2,40372;33,11404;0,12436
8,334;2,45924;34,04297;0,13033
8,532;2,51796;35,01112;0,1369
8,73;2,5744;35,94137;0,14381
8,944;2,63192;36,87601;0,15138
9,178;2,69044;37,80883;0,1597
9,432;2,74896;38,733;0,16897
9,724;2,80976;39,66438;0,17975
10,066;2,87248;40,59232;0,19232
10,5;2,93828;41,51853;0,20781
11,096;3,00892;42,43551;0,2274
11,94;3,08256;43,30831;0,25254
12,84;3,14176;43,93924;0,27751
13,74;3,18932;44,39671;0,30025
14,636;3,23828;44,84424;0,32412
15,536;3,27436;45,08665;0,34686
16,436;3,3076;45,28905;0,37
17,336;3,3378;45,44935;0,3928
18,236;3,36512;45,54089;0,41574
19,136;3,39064;45,62731;0,43835
20,036;3,4144;45,66755;0,46144
20,936;3,43612;45,67497;0,48403
21,836;3,4566;45,66426;0,50668
22,736;3,47664;45,64988;0,5293
23,636;3,49484;45,54851;0,55184
24,536;3,51312;45,42933;0,57456
25,436;3,53068;45,26191;0,59678
26,336;3,54884;45,12453;0,61948
27,236;3,56712;45,02905;0,64166
28,136;3,58864;45,00104;0,66481
29,036;3,60464;44,86437;0,68697
29,936;3,62168;44,79848;0,70977
30,836;3,63832;44,75805;0,7322
31,736;3,65464;44,71723;0,75456
32,636;3,67128;44,69812;0,77725
33,536;3,68744;44,68296;0,79955
34,436;3,70352;44,67096;0,82195
35,336;3,71956;44,66954;0,8444
36,236;3,73616;44,68455;0,8671
37,136;3,75492;44,76405;0,88881
38,036;3,76872;44,64239;0,91196
38,936;3,7848;44,67427;0,93437
39,836;3,80072;44,67798;0,95709
40,736;3,8156;44,66;0,97955
41,636;3,83044;44,65349;1,00196
42,536;3,84524;44,64691;1,02466
43,436;3,86;44,65364;1,04736
44,336;3,87408;44,64064;1,07003
45,236;3,88876;44,67041;1,09235
46,136;3,90316;44,68505;1,11492
47,036;3,91788;44,72528;1,1371
47,936;3,93268;44,7553;1,15958
48,836;3,948;44,80965;1,18184
49,736;3,96352;44,86217;1,20409
50,636;3,97948;44,91527;1,22656
51,536;3,9962;44,98212;1,24943
52,436;4,01236;45,03112;1,27157
53,336;4,02972;45,10374;1,29403
54,236;4,0468;45,15953;1,3163
55,136;4,0684;45,31417;1,33897
56,036;4,08468;45,28869;1,36098
56,936;4,1038;45,37727;1,38348
57,836;4,12364;45,46602;1,40598
58,736;4,14336;45,52113;1,42855
59,636;4,16428;45,61179;1,45105
60,536;4,18524;45,686;1,47329
61,436;4,20672;45,75748;1,49573
62,336;4,22852;45,84263;1,51777
63,236;4,2514;45,9381;1,54028
64,136;4,2742;46,00736;1,56308
65,036;4,29756;46,10199;1,5854
65,93601;4,32128;46,19413;1,60766
66,83601;4,34504;46,2746;1,63011
67,736;4,37228;46,40299;1,65294
68,636;4,39596;46,45653;1,67533
69,536;4,4206;46,56018;1,69788
70,43601;4,44516;46,64021;1,72048
71,33601;4,46888;46,71074;1,7423
72,236;4,49432;46,82667;1,76473
73,136;4,52;46,9254;1,78758
74,036;4,545;47,00131;1,80995
74,93601;4,57032;47,0942;1,83234
75,83601;4,59576;47,1814;1,85495
76,736;4,62128;47,27815;1,87721
77,636;4,64724;47,37649;1,89994
78,536;4,67516;47,52252;1,92151
79,43601;4,70004;47,53557;1,94477
80,33601;4,72616;47,63945;1,96751
81,236;4,75156;47,73078;1,98978
82,136;4,77688;47,81686;2,01213
83,036;4,80244;47,90124;2,03482
83,93601;4,82772;47,98391;2,05711
84,83601;4,85352;48,0772;2,07971
85,73601;4,87856;48,1568;2,10195
86,636;4,9042;48,25324;2,12446
87,536;4,92932;48,3231;2,14714
88,43601;4,95456;48,40878;2,16963
89,33601;4,98296;48,5536;2,19221
90,23601;5,00688;48,57047;2,21453
91,136;5,03248;48,66676;2,23699
92,036;5,0574;48,73439;2,2596
92,93601;5,08228;48,82346;2,28191
93,83601;5,10724;48,90924;2,30451
94,73601;5,13168;48,97646;2,32676
95,636;5,15648;49,05815;2,34921
96,536;5,182;49,14446;2,37225
97,43601;5,2068;49,22104;2,39468
98,33601;5,23104;49,28897;2,4169
99,23601;5,25784;49,43166;2,43821
100,136;5,28188;49,43237;2,46179
101,036;5,30716;49,52984;2,48463
101,93601;5,33124;49,58832;2,50689
102,83601;5,35588;49,66489;2,52931
103,73601;5,38052;49,73654;2,55203
104,636;5,40492;49,8128;2,57431
105,536;5,42968;49,89451;2,59688
106,43601;5,454;49,94911;2,6196
107,33601;5,47852;50,02578;2,64215
108,23601;5,503;50,09618;2,66466
109,136;5,52896;50,21835;2,6854
110,036;5,55308;50,2275;2,70928
110,93601;5,5778;50,30635;2,73201
111,83601;5,60176;50,37256;2,75438
112,73601;5,62608;50,44814;2,77687
113,636;5,64988;50,50147;2,7992
114,536;5,674;50,56813;2,82163
115,43601;5,69888;50,65464;2,8444
116,33601;5,72284;50,70856;2,86698
117,23601;5,74708;50,76446;2,88981
118,13601;5,77024;50,80894;2,9119
119,036;5,79708;50,96889;2,9335
119,93601;5,82056;50,96663;2,95674
120,83601;5,84448;51,02213;2,97948
121,73601;5,86832;51,08331;3,00187
122,63601;5,8928;51,15759;3,02445
123,536;5,9164;51,20612;3,04667
124,43601;5,94072;51,27585;3,0691
125,33601;5,96516;51,33371;3,09195
126,23601;5,9892;51,39484;3,11429
127,13601;6,01356;51,45637;3,13669
128,03601;6,03816;51,5099;3,15927
128,93601;6,0646;51,56871;3,18217
129,83602;6,08884;51,63256;3,20423
130,73601;6,11324;51,68464;3,22671
131,636;6,13752;51,73342;3,2488
132,53602;6,1626;51,79939;3,27143
133,436;6,1872;51,86213;3,29375
134,33602;6,21216;51,92357;3,3164
135,236;6,2368;51,96798;3,33904
136,136;6,26112;52,02035;3,36162
137,03602;6,28576;52,08595;3,38414
137,936;6,3126;52,17869;3,40656
138,83602;6,33588;52,18815;3,42891
139,736;6,36056;52,24351;3,4518
140,636;6,3846;52,29956;3,47412
141,53602;6,40872;52,35822;3,49668
142,436;6,43248;52,40059;3,51912
143,33602;6,45632;52,45281;3,54147
144,236;6,48092;52,52003;3,56425
145,136;6,50468;52,5588;3,58667
146,03602;6,52856;52,60361;3,60895
146,936;6,55516;52,72295;3,6309
147,83602;6,57832;52,70613;3,65385
148,736;6,60244;52,77473;3,67624
149,636;6,62616;52,80771;3,69908
150,53602;6,64988;52,86229;3,72138
151,436;6,67408;52,92203;3,744
152,33602;6,69752;52,95977;3,76639
153,236;6,72124;53,00961;3,78887
153,98002;6,73196;52,8225;3,80476
154,88;6,74868;52,90799;3,81768
155,78002;6,76672;52,99312;3,83372
156,68002;6,78464;53,03572;3,85024
157,58;6,80272;53,07904;3,86682
158,48002;6,82052;53,11348;3,88155
159,38;6,83844;53,14971;3,89834
182,17202;6,85012;51,69991;
183,072;6,86796;52,44923;
183,97202;6,88588;52,95941;
184,87202;6,90392;53,22804;
185,772;6,92184;53,35115;
186,67202;6,93984;53,41082;
187,572;6,95772;53,45051;
188,47202;6,97572;53,48132;
189,37202;6,9938;53,51618;
190,272;7,01184;53,54148;
191,17202;7,02996;53,57326;
192,072;7,04804;53,59941;
192,97202;7,06608;53,63161;
193,87202;7,08364;53,65548;
194,772;7,10164;53,69455;
195,67202;7,11972;53,72809;
196,572;7,1378;53,75815;
197,47202;7,1558;53,78743;
198,37202;7,17376;53,81536;
199,272;7,19188;53,84888;
200,17202;7,20976;53,87576;
201,072;7,22772;53,909;
201,97202;7,24572;53,94182;
202,87202;7,26384;53,97682;
203,772;7,28176;54,00721;
204,67202;7,29976;54,03467;
205,572;7,3178;54,06744;
206,47202;7,3358;54,0925;
207,37202;7,35384;54,12292;
208,272;7,37176;54,15455;
209,17202;7,38984;54,18838;
210,072;7,40772;54,21722;
210,97202;7,4258;54,24715;
211,87202;7,44372;54,27637;
212,772;7,46168;54,30677;
213,67202;7,47964;54,33298;
214,572;7,49752;54,36045;
215,47202;7,51568;54,39457;
216,37202;7,53372;54,42239;
217,272;7,55172;54,4538;
218,17202;7,56964;54,47927;
219,072;7,58772;54,51208;
219,97202;7,60568;54,54149;
220,87202;7,62364;54,56893;
221,772;7,64168;54,60031;
222,67202;7,65976;54,62622;
223,572;7,67768;54,65352;
224,47202;7,69564;54,68009;
225,37202;7,71376;54,71219;
226,272;7,73172;54,73711;
227,17202;7,74972;54,76533;
228,072;7,76768;54,7932;
228,97202;7,78584;54,82401;
229,87202;7,8038;54,8486;
230,77202;7,82176;54,87237;
231,67202;7,8398;54,89984;
232,572;7,85768;54,92247;
233,47202;7,87572;54,94957;
234,37202;7,89368;54,97617;
235,27202;7,91184;55,00979;
236,17202;7,92972;55,03263;
237,072;7,94772;55,06203;
237,97202;7,96568;55,08541;
238,87202;7,98372;55,11076;
239,77202;8,00164;55,13602;
240,67202;8,0196;55,15885;
241,572;8,03776;55,19032;
242,47202;8,0558;55,21542;
243,37202;8,07388;55,24319;
244,27202;8,09176;55,26501;
245,17202;8,1098;55,29326;
246,072;8,12772;55,31249;
246,97202;8,1456;55,33621;
247,87202;8,16364;55,36408;
248,77202;8,18176;55,3881;
249,67202;8,19972;55,41046;
250,572;8,21768;55,43382;
251,47202;8,2358;55,46276;
252,37202;8,25368;55,48374;
253,27202;8,27172;55,51112;
254,17202;8,28968;55,53393;
255,072;8,3078;55,5584;
255,97202;8,32572;55,5802;
256,87202;8,34396;55,60719;
257,772;8,36204;55,63158;
258,672;8,37976;55,64446;
259,57202;8,3976;55,67268;
260,47202;8,41552;55,69693;
261,37202;8,4338;55,72479;
262,272;8,45168;55,74344;
263,17203;8,46976;55,76656;
264,07203;8,48768;55,78826;
264,972;8,50572;55,81213;
265,872;8,52368;55,83436;
266,772;8,54156;55,85614;
267,67203;8,55964;55,88434;
268,57203;8,5776;55,90544;
269,472;8,59556;55,93144;
270,372;8,61348;55,94987;
271,272;8,6316;55,97815;
272,17203;8,64956;55,99679;
273,07203;8,66764;56,01841;
273,972;8,68564;56,04287;
274,872;8,7036;56,06097;
275,772;8,72152;56,08291;
276,67203;8,73952;56,10502;
277,57203;8,75764;56,1305;
278,472;8,77552;56,15133;
279,372;8,79352;56,17113;
280,272;8,81148;56,19191;
281,17203;8,82964;56,21588;
282,07203;8,84764;56,23299;
282,972;8,8656;56,25534;
283,872;8,88368;56,2785;
284,772;8,9016;56,29557;
285,67203;8,9196;56,32048;
286,57203;8,93756;56,33862;
287,472;8,95568;56,36355;
288,372;8,9736;56,38006;
289,272;8,99156;56,40054;
290,17203;9,00952;56,42232;
291,07203;9,0276;56,44369;
291,972;9,04556;56,46485;
292,872;9,06352;56,48551;
293,772;9,08168;56,51029;
294,67203;9,09968;56,52944;
295,57203;9,11772;56,54917;
296,472;9,13556;56,56499;
297,372;9,15364;56,58678;
298,272;9,17152;56,60247;
299,17203;9,18952;56,62313;
300,07203;9,2076;56,64523;
300,972;9,22564;56,66627;
301,872;9,24356;56,68451;
302,772;9,26148;56,70448;
303,67203;9,27956;56,72935;
304,57203;9,29752;56,74373;
305,472;9,31556;56,76393;
306,372;9,33352;56,78263;
307,272;9,35168;56,80164;
308,17203;9,36964;56,81866;
309,07203;9,38764;56,83701;
309,972;9,40568;56,86;
310,872;9,4236;56,8738;
311,772;9,44156;56,89548;
312,67203;9,4594;56,91126;
313,57203;9,4776;56,93376;
314,472;9,49556;56,94823;
315,372;9,5136;56,96853;
316,272;9,5316;56,98513;
317,17203;9,54956;57,00396;
318,07203;9,56756;57,02312;
318,972;9,58556;57,04108;
319,872;9,60368;57,06464;
320,772;9,62164;57,07777;
321,67203;9,63968;57,09864;
322,57203;9,65776;57,11201;
323,472;9,67588;57,13086;
324,372;9,69348;57,13838;
325,272;9,71148;57,1602;
326,17203;9,72952;57,18265;
327,07203;9,74768;57,19811;
327,972;9,7656;57,21644;
328,872;9,78356;57,23323;
329,772;9,80168;57,25002;
330,67203;9,81956;57,26368;
331,57203;9,8376;57,28267;
332,472;9,85556;57,29948;
333,372;9,87368;57,31894;
334,272;9,89164;57,33211;
335,17203;9,90956;57,34904;
336,07203;9,92764;57,36873;
336,972;9,94556;57,38444;
337,872;9,9636;57,40405;
338,772;9,98156;57,41529;
339,67203;9,99956;57,43233;
340,57203;10,01756;57,44707;
341,472;10,0356;57,46449;
342,372;10,05364;57,48254;
343,272;10,0716;57,49705;
344,17203;10,08952;57,51324;
345,07203;10,10748;57,53016;
345,972;10,1256;57,55131;
346,872;10,1436;57,56608;
347,772;10,16164;57,58062;
348,67203;10,17956;57,59309;
349,57203;10,19768;57,61052;
350,472;10,21556;57,62375;
351,372;10,23356;57,64067;
352,272;10,25164;57,65928;
353,17203;10,26964;57,67319;
354,07203;10,2876;57,69005;
354,972;10,30548;57,70192;
355,872;10,3236;57,72296;
356,772;10,34148;57,73308;
357,67203;10,35948;57,74956;
358,57203;10,37748;57,76585;
359,472;10,3956;57,77926;
360,372;10,41356;57,79473;
361,272;10,43152;57,80864;
362,17203;10,44952;57,82604;
363,07203;10,46736;57,83638;
363,972;10,4854;57,85483;
364,872;10,50332;57,86813;
365,772;10,52144;57,8845;
366,67203;10,53936;57,89524;
367,57203;10,55744;57,91117;
368,472;10,57544;57,92618;
369,372;10,59344;57,93957;
370,272;10,6114;57,95375;
371,17203;10,62932;57,96557;
372,07203;10,64752;57,98602;
372,972;10,66556;57,99741;
373,872;10,68364;58,01283;
374,772;10,7016;58,02404;
375,67203;10,71968;58,03852;
376,57203;10,73756;58,04919;
377,472;10,75548;58,06485;
378,372;10,77348;58,08422;
379,272;10,79152;58,09533;
380,17203;10,80956;58,11073;
381,07203;10,82748;58,1221;
381,972;10,8456;58,13869;
382,872;10,86348;58,14898;
383,772;10,88152;58,16331;
384,67203;10,89948;58,17562;
385,57203;10,91756;58,19086;
386,472;10,93552;58,20183;
387,372;10,95352;58,219;
388,27203;10,97168;58,23356;
389,17203;10,98952;58,24023;
390,07203;11,0072;58,25043;
390,972;11,02516;58,26421;
391,872;11,0434;58,2849;
392,77203;11,06136;58,2924;
393,67203;11,0794;58,30818;
394,57203;11,0974;58,32204;
395,472;11,1154;58,33338;
396,372;11,13332;58,34731;
397,27203;11,15132;58,35832;
398,17203;11,16948;58,37498;
399,07203;11,18748;58,38396;
399,972;11,20548;58,39491;
400,872;11,22336;58,40652;
401,77203;11,24148;58,42206;
402,67203;11,2594;58,43282;
403,57203;11,2774;58,44728;
404,472;11,29552;58,46176;
405,372;11,3134;58,47064;
406,27203;11,3314;58,48403;
407,17203;11,34936;58,49419;
408,07203;11,36744;58,5097;
408,972;11,38532;58,51789;
409,872;11,40332;58,53341;
410,77203;11,42132;58,54525;
411,67203;11,43944;58,55989;
412,57203;11,4574;58,57101;
413,472;11,47544;58,58105;
414,372;11,49348;58,59474;
415,27203;11,5114;58,60195;
416,17203;11,52948;58,61478;
417,07203;11,54744;58,62411;
417,972;11,56564;58,6356;
418,872;11,58356;58,64359;
419,77203;11,60152;58,65643;
420,67203;11,61952;58,66934;
421,57203;11,63744;58,67892;
422,472;11,65548;58,69164;
423,372;11,67344;58,70187;
424,27203;11,6916;58,71741;
425,17203;11,70952;58,72378;
426,07203;11,7276;58,7385;
426,972;11,74552;58,7456;
427,872;11,76356;58,76011;
428,77203;11,7814;58,76712;
429,67203;11,79932;58,77923;
430,57203;11,81744;58,79624;
431,472;11,83548;58,80309;
432,372;11,85348;58,81417;
433,27203;11,8714;58,82252;
434,17203;11,88952;58,83648;
435,07203;11,9074;58,84387;
435,972;11,92544;58,85663;
436,872;11,9434;58,86797;
437,77203;11,96148;58,87924;
438,67203;11,97948;58,88836;
439,57203;11,99752;58,89741;
440,472;12,01564;58,91168;
441,372;12,03352;58,91519;
442,27203;12,05148;58,92801;
443,17203;12,06932;58,93509;
444,07203;12,0874;58,95194;
444,972;12,10536;58,96007;
445,872;12,12344;58,97143;
446,77203;12,1414;58,98124;
447,67203;12,15936;58,98752;
448,57203;12,17732;58,99948;
449,472;12,19532;59,0085;
450,372;12,21352;59,02283;
451,27203;12,23144;59,02755;
452,17203;12,24948;59,03906;
453,07203;12,26752;59,05099;
453,972;12,28564;59,06073;
454,872;12,3034;59,0624;
455,77203;12,32116;59,07609;
456,67203;12,33936;59,09101;
457,57203;12,35744;59,09855;
458,472;12,37548;59,10594;
459,372;12,39336;59,11036;
460,27203;12,41144;59,1257;
461,17203;12,42936;59,13282;
462,07203;12,44736;59,14505;
462,972;12,46536;59,15625;
463,872;12,48356;59,16618;
464,77203;12,50144;59,17195;
465,67203;12,51944;59,17871;
466,57203;12,53752;59,19165;
467,472;12,5554;59,19823;
468,372;12,57352;59,20862;
469,27203;12,59148;59,21586;
470,17203;12,60956;59,22684;
471,07203;12,62744;59,23377;
471,972;12,64544;59,24399;
472,872;12,66348;59,2514;
473,77203;12,68136;59,25779;
474,67203;12,6994;59,26706;
475,57203;12,71728;59,27693;
476,472;12,73544;59,29062;
477,372;12,75332;59,294;
478,27203;12,7714;59,30478;
479,17203;12,78932;59,31357;
480,07203;12,80732;59,32095;
480,972;12,82524;59,33204;
481,872;12,84328;59,34055;
482,77203;12,8614;59,3528;
483,67203;12,8794;59,35684;
484,57203;12,8974;59,36657;
485,472;12,91524;59,37133;
486,372;12,93336;59,38326;
487,27203;12,95116;59,38687;
488,17203;12,96928;59,40096;
489,07203;12,98732;59,40871;
489,972;13,00548;59,41988;
490,872;13,02344;59,42237;
491,77203;13,04132;59,42814;
492,67203;13,0594;59,44006;
493,57203;13,07724;59,44261;
494,472;13,09524;59,45621;
495,372;13,11316;59,4608;
496,27203;13,13128;59,47591;
497,17203;13,14924;59,48048;
498,07203;13,16724;59,48761;
498,972;13,18524;59,49588;
499,872;13,20324;59,50052;
500,77203;13,2212;59,50947;
501,67203;13,23912;59,51616;
502,57203;13,25732;59,5278;
503,472;13,27524;59,5327;
504,372;13,2934;59,54319;
505,27203;13,31136;59,54803;
506,17203;13,32944;59,55654;
507,07203;13,34736;59,56041;
507,972;13,36532;59,56733;
508,872;13,38336;59,57791;
509,77203;13,40128;59,58142;
510,67203;13,41932;59,59271;
511,57203;13,43724;59,59668;
512,47203;13,45536;59,60988;
513,372;13,4732;59,61241;
514,27203;13,49124;59,62012;
515,172;13,50936;59,63105;
516,07203;13,52744;59,63616;
516,97203;13,54536;59,64179;
517,872;13,5634;59,64832;
518,77203;13,58164;59,66023;
519,672;13,59948;59,66194;
520,57203;13,61728;59,66332;
521,47203;13,63516;59,67389;
522,372;13,65336;59,68537;
523,27203;13,67136;59,6896;
524,172;13,68936;59,69519;
525,072;13,70744;59,7037;
525,97206;13,72532;59,70732;
526,872;13,74332;59,71537;
527,77206;13,76124;59,72075;
528,672;13,7794;59,73355;
529,572;13,79736;59,73183;
530,47206;13,81532;59,74538;
531,372;13,83324;59,74896;
532,27206;13,85128;59,75553;
533,172;13,86932;59,76516;
534,072;13,88736;59,7702;
534,97206;13,90552;59,78155;
535,872;13,9234;59,78137;
536,77206;13,94144;59,79044;
537,672;13,95932;59,79556;
538,572;13,97748;59,80517;
539,47206;13,99532;59,80607;
540,372;14,01336;59,81492;
541,27206;14,03148;59,82214;
542,172;14,04948;59,82728;
543,072;14,06748;59,8332;
543,97206;14,08544;59,83657;
544,872;14,10356;59,84622;
545,77206;14,1214;59,84815;
546,672;14,1394;59,85542;
547,572;14,1574;59,86168;
548,47206;14,17556;59,86838;
549,372;14,19352;59,87197;
550,27206;14,21144;59,87691;
551,172;14,2294;59,88561;
552,072;14,24732;59,88939;
552,97206;14,2654;59,8988;
553,872;14,28332;59,90472;
554,77206;14,30148;59,91215;
555,672;14,31944;59,91398;
556,572;14,33756;59,92079;
557,47206;14,35548;59,92401;
558,372;14,37344;59,9297;
559,27206;14,39132;59,93344;
560,172;14,40932;59,94018;
561,072;14,42748;59,95164;
561,97206;14,44536;59,95241;
562,872;14,46336;59,95868;
563,77206;14,48124;59,96075;
564,672;14,49928;59,97065;
565,572;14,5172;59,97331;
566,47206;14,5352;59,98142;
567,372;14,55332;59,99032;
568,27206;14,57136;59,99331;
569,172;14,58928;59,99877;
570,072;14,60732;60,0035;
570,97206;14,62544;60,0139;
571,872;14,64332;60,01463;
572,77206;14,66132;60,01928;
573,672;14,6792;60,02234;
574,572;14,69728;60,02936;
575,47206;14,71524;60,03457;
576,372;14,73316;60,04108;
577,27206;14,75132;60,04959;
578,172;14,76916;60,05126;
579,072;14,7872;60,05771;
579,97206;14,80512;60,06135;
580,872;14,82328;60,06968;
581,77206;14,84124;60,06945;
582,67206;14,85924;60,07562;
583,572;14,87736;60,08399;
584,47206;14,89548;60,08562;
585,372;14,9134;60,08992;
586,27206;14,93108;60,08819;
587,17206;14,94916;60,10368;
588,072;14,9672;60,10603;
588,97206;14,98528;60,11174;
589,872;15,00324;60,11333;
590,77206;15,0214;60,11869;
591,67206;15,03924;60,11805;
592,572;15,05724;60,12511;
593,47206;15,07536;60,13397;
594,372;15,09332;60,13657;
595,27206;15,11136;60,14292;
596,17206;15,12924;60,14279;
597,072;15,14732;60,15154;
597,97206;15,1652;60,15287;
598,872;15,18328;60,15986;
599,77206;15,20132;60,16441;
600,67206;15,2194;60,16922;
601,572;15,23724;60,1697;
602,47206;15,2552;60,17464;
603,372;15,27332;60,18587;
604,27206;15,2912;60,18389;
605,17206;15,30916;60,18992;
606,072;15,32712;60,19338;
606,97206;15,34536;60,20092;
607,872;15,3632;60,19997;
608,77206;15,3812;60,20577;
609,67206;15,39932;60,21256;
610,572;15,4172;60,21064;
611,47206;15,43524;60,21859;
612,372;15,45316;60,22199;
613,27206;15,47136;60,23098;
614,17206;15,48932;60,22808;
615,072;15,50732;60,23274;
615,97206;15,52528;60,23466;
616,872;15,54332;60,2412;
617,77206;15,56124;60,24388;
618,67206;15,57928;60,24877;
619,572;15,59744;60,25658;
620,47206;15,61544;60,25796;
621,372;15,63348;60,26128;
622,27206;15,65144;60,26295;
623,17206;15,66956;60,26825;
624,072;15,6874;60,26814;
624,97206;15,70536;60,27303;
625,872;15,7234;60,27814;
626,77206;15,74148;60,28315;
627,67206;15,7594;60,28224;
628,572;15,77736;60,28756;
629,47206;15,79544;60,29508;
630,372;15,81328;60,29443;
631,27206;15,83124;60,29682;
632,17206;15,84916;60,29919;
633,072;15,86732;60,30682;
633,97206;15,88528;60,30776;
634,872;15,90332;60,31208;
635,77206;15,92136;60,31684;
636,67206;15,93936;60,31722;
637,572;15,95732;60,32106;
638,47206;15,97528;60,32166;
639,372;15,99332;60,32982;
640,27206;16,01124;60,32919;
641,17206;16,02936;60,33369;
642,072;16,04728;60,33497;
642,97206;16,06532;60,33739;
643,872;16,0832;60,34032;
644,77206;16,1012;60,34431;
645,67206;16,11936;60,35263;
646,572;16,13732;60,35376;
647,47206;16,15532;60,35532;
648,372;16,17324;60,35697;
649,27206;16,19156;60,36835;
650,17206;16,20944;60,36428;
651,072;16,22728;60,36286;
651,97206;16,24516;60,36779;
652,872;16,26324;60,37309;
653,77206;16,28128;60,37761;
654,67206;16,29928;60,37694;
655,572;16,3174;60,38528;
656,47206;16,33536;60,38384;
657,372;16,3534;60,38705;
658,27206;16,37132;60,38777;
659,17206;16,38948;60,39293;
660,072;16,40744;60,39261;
660,97206;16,4254;60,39537;
661,872;16,4434;60,39867;
662,77206;16,46132;60,39624;
663,67206;16,47936;60,40384;
664,572;16,49736;60,4058;
665,47206;16,51556;60,41129;
666,372;16,5334;60,40658;
667,27206;16,55136;60,41178;
668,17206;16,56928;60,41232;
669,072;16,58736;60,41669;
669,97206;16,60528;60,41853;
670,872;16,62324;60,4186;
671,77206;16,64132;60,42703;
672,67206;16,65928;60,42291;
673,572;16,67724;60,42692;
674,47206;16,69524;60,42786;
675,372;16,7134;60,43353;
676,27206;16,73124;60,43229;
677,17206;16,74928;60,43553;
678,072;16,76736;60,44185;
678,97206;16,7854;60,44322;
679,872;16,80336;60,44015;
680,77206;16,82128;60,44299;
681,67206;16,8394;60,44948;
682,572;16,85724;60,44796;
683,47206;16,87528;60,45401;
684,372;16,89328;60,4556;
685,27206;16,9114;60,46068;
686,17206;16,92936;60,45696;
687,072;16,94736;60,46379;
687,97206;16,96544;60,46935;
688,872;16,98332;60,46567;
689,77206;17,00124;60,46883;
690,67206;17,0192;60,47163;
691,572;17,03732;60,47699;
692,47206;17,05524;60,47699;
693,372;17,07332;60,4806;
694,27206;17,09116;60,48083;
695,17206;17,1092;60,4843;
696,072;17,12708;60,48589;
696,97206;17,14504;60,49033;
697,872;17,16324;60,49601;
698,77206;17,1812;60,49425;
699,67206;17,19924;60,49779;
700,572;17,21716;60,49809;
701,47206;17,23532;60,5038;
702,372;17,2532;60,50153;
703,27206;17,27116;60,50574;
704,17206;17,2892;60,50977;
705,072;17,3072;60,5091;
705,97206;17,32516;60,51207;
706,872;17,34316;60,51286;
707,77206;17,36132;60,52014;
708,67206;17,3792;60,51772;
709,572;17,3972;60,52054;
710,47206;17,4152;60,52418;
711,372;17,4334;60,52845;
712,27206;17,45128;60,52584;
713,17206;17,46932;60,52744;
714,072;17,48736;60,53296;
714,97206;17,50548;60,53412;
715,872;17,52352;60,53416;
716,77206;17,54116;60,52802;
717,67206;17,55932;60,53866;
718,572;17,57728;60,53883;
719,47206;17,59536;60,54273;
720,372;17,61328;60,54171;
721,27206;17,63128;60,54446;
722,17206;17,64928;60,54386;
723,072;17,6672;60,54441;
723,97206;17,6854;60,5527;
724,872;17,70336;60,54956;
725,77206;17,72136;60,55253;
726,67206;17,73924;60,55004;
727,572;17,75736;60,55428;
728,47206;17,7752;60,5556;
729,372;17,7932;60,55809;
730,27206;17,81128;60,56296;
731,17206;17,82944;60,56432;
732,072;17,84732;60,56131;
732,97206;17,86528;60,56379;
733,872;17,88336;60,56808;
734,77206;17,90124;60,56537;
735,67206;17,91924;60,57029;
736,572;17,93724;60,57117;
737,47206;17,95532;60,57507;
738,372;17,97332;60,57458;
739,27206;17,99132;60,57319;
740,17206;18,00944;60,57872;
741,072;18,02736;60,5736;
741,97206;18,04532;60,57684;
742,872;18,06328;60,57721;
743,77206;18,08148;60,58141;
744,67206;18,0994;60,58038;
745,572;18,1174;60,58413;
746,47206;18,13532;60,58446;
747,372;18,15328;60,58447;
748,27206;18,17124;60,58473;
749,17206;18,18928;60,58779;
750,072;18,20748;60,59453;
750,97206;18,2254;60,59029;
751,872;18,24344;60,59265;
752,77206;18,26124;60,58928;
753,67206;18,27936;60,59564;
754,572;18,2972;60,59242;
755,47206;18,31512;60,59112;
756,372;18,33324;60,59728;
757,27206;18,35128;60,59653;
758,17206;18,36924;60,59721;
759,072;18,3872;60,59666;
759,97206;18,40528;60,60175;
760,872;18,42316;60,59901;
761,77206;18,44116;60,60362;
762,67206;18,45916;60,60341;
763,572;18,47728;60,6034;
764,47206;18,49524;60,60313;
765,372;18,51328;60,60252;
766,27206;18,5314;60,60753;
767,17206;18,54932;60,60485;
768,072;18,56736;60,60654;
768,97206;18,58524;60,60451;
769,872;18,60336;60,61044;
770,77206;18,6212;60,60736;
771,67206;18,63924;60,61171;
772,572;18,65724;60,60752;
773,47206;18,67524;60,60727;
774,372;18,6932;60,60845;
775,27206;18,71116;60,60941;
776,17206;18,72936;60,6171;
777,072;18,74736;60,61153;
777,97206;18,76536;60,6147;
778,872;18,78328;60,61282;
779,77206;18,80144;60,6177;
780,67206;18,8194;60,61633;
781,572;18,8374;60,6131;
782,47206;18,8552;60,61299;
783,372;18,87324;60,61763;
784,27206;18,89128;60,61851;
785,17206;18,9092;60,61691;
786,072;18,92736;60,62212;
786,97206;18,9452;60,62064;
787,872;18,9632;60,62346;
788,77206;18,9812;60,62018;
789,67206;18,99928;60,62313;
790,572;19,01728;60,61912;
791,47206;19,03528;60,61975;
792,372;19,05332;60,62288;
793,27206;19,07116;60,61808;
794,17206;19,08912;60,62083;
795,072;19,10716;60,62258;
795,97206;19,12532;60,62558;
796,872;19,14324;60,62301;
797,77206;19,1612;60,61977;
798,67206;19,17916;60,62024;
799,572;19,19716;60,61782;
800,47206;19,21508;60,6189;
801,372;19,233;60,61984;
802,27206;19,2512;60,62664;
803,17206;19,26912;60,62315;
804,072;19,28716;60,62593;
804,97206;19,30504;60,62205;
805,872;19,32312;60,624;
806,77206;19,34108;60,62009;
807,67206;19,359;60,61991;
808,572;19,3772;60,62781;
809,47206;19,39524;60,62251;
810,372;19,4132;60,62206;
811,27206;19,43112;60,61984;
812,17206;19,44916;60,62401;
813,072;19,467;60,62025;
813,97206;19,48508;60,61914;
814,872;19,50312;60,62261;
815,77206;19,52128;60,62049;
816,67206;19,53924;60,61757;
817,572;19,55728;60,61739;
818,47206;19,5754;60,62022;
819,372;19,59324;60,61635;
820,27206;19,6112;60,61663;
821,17206;19,62904;60,61635;
822,072;19,6472;60,61969;
822,97206;19,66516;60,61499;
823,872;19,68316;60,61572;
824,77206;19,70116;60,61518;
825,67206;19,71908;60,61181;
826,572;19,73708;60,61232;
827,47206;19,75504;60,61273;
828,372;19,77324;60,62042;
829,27206;19,7912;60,61618;
830,17206;19,80924;60,61677;
831,072;19,8272;60,6135;
831,97206;19,84536;60,61396;
832,872;19,86328;60,61214;
833,77206;19,88132;60,61177;
834,67206;19,8994;60,61293;
835,572;19,91732;60,61035;
836,47206;19,93528;60,61211;
837,372;19,9532;60,61066;
838,27206;19,97136;60,61396;
839,17206;19,9892;60,60715;
840,072;20,0072;60,60641;
840,97206;20,02524;60,6065;
841,87206;20,04332;60,60812;
842,77206;20,06128;60,60429;
843,67206;20,07924;60,60264;
844,572;20,09732;60,60842;
845,47206;20,1154;60,60833;
846,37206;20,1334;60,606;
847,27206;20,1512;60,59743;
848,17206;20,1692;60,59825;
849,072;20,18716;60,59592;
849,97206;20,20528;60,59964;
850,87206;20,2232;60,59623;
851,77206;20,24124;60,59454;
852,67206;20,25924;60,59378;
853,572;20,27724;60,59501;
854,47206;20,29544;60,59791;
855,37206;20,31332;60,59133;
856,27206;20,3314;60,59098;
857,17206;20,34932;60,58708;
858,072;20,36736;60,58705;
858,97206;20,38532;60,58499;
859,87206;20,40328;60,58569;
860,77206;20,42148;60,59214;
861,67206;20,43948;60,58778;
862,572;20,45744;60,58455;
863,47206;20,47528;60,57993;
864,37206;20,4934;60,58182;
865,27206;20,51132;60,57708;
866,17206;20,52932;60,57525;
867,072;20,54736;60,57724;
867,97206;20,56548;60,57524;
868,87206;20,58336;60,57337;
869,77206;20,60132;60,57349;
870,67206;20,61948;60,57665;
871,572;20,63732;60,57046;
872,47206;20,65532;60,56629;
873,37206;20,6732;60,56505;
874,27206;20,69136;60,56846;
875,17206;20,70924;60,56441;
876,072;20,72728;60,56481;
876,97206;20,74528;60,5661;
877,87206;20,76312;60,56149;
878,77206;20,78116;60,56457;
879,67206;20,79908;60,5606;
880,572;20,81736;60,56604;
881,47206;20,83528;60,55632;
882,37206;20,85332;60,55502;
883,27206;20,87132;60,55466;
884,17206;20,8894;60,55347;
885,072;20,90728;60,54979;
885,97206;20,92524;60,54843;
886,87206;20,94336;60,5544;
887,77206;20,96132;60,54888;
888,67206;20,97936;60,54517;
889,572;20,99724;60,54002;
890,47206;21,01532;60,54141;
891,37206;21,0332;60,53638;
892,27206;21,05116;60,53614;
893,17206;21,06924;60,53814;
894,072;21,08732;60,53513;
894,97206;21,10528;60,53305;
895,87206;21,1232;60,53059;
896,77206;21,1414;60,53376;
897,67206;21,15936;60,52698;
898,572;21,17736;60,52346;
899,47206;21,19532;60,5193;
900,37206;21,21344;60,52013;
901,27206;21,23124;60,51564;
902,17206;21,24924;60,5154;
903,072;21,26732;60,51756;
903,97206;21,28528;60,51347;
904,87206;21,30324;60,51087;
905,77206;21,32112;60,5081;
906,67206;21,3394;60,51071;
907,572;21,35732;60,50522;
908,47206;21,37536;60,50345;
909,37206;21,39324;60,49943;
910,27206;21,41128;60,5012;
911,17206;21,42936;60,50158;
912,072;21,44736;60,49685;
912,97206;21,46524;60,49372;
913,87206;21,4832;60,49153;
914,77206;21,50124;60,49107;
915,67206;21,5192;60,48635;
916,572;21,53732;60,48711;
917,47206;21,55524;60,48242;
918,37206;21,57328;60,48127;
919,27206;21,59132;60,48259;
920,17206;21,60944;60,47879;
921,072;21,62736;60,47468;
921,97206;21,64528;60,47257;
922,87206;21,6634;60,47043;
923,77206;21,68128;60,4664;
924,67206;21,69932;60,46463;
925,572;21,71732;60,46409;
926,47206;21,73548;60,46473;
927,37206;21,75344;60,45818;
928,27206;21,77128;60,45372;
929,17206;21,78936;60,45575;
930,072;21,80728;60,45035;
930,97206;21,82528;60,44889;
931,87206;21,84324;60,443;
932,77206;21,86144;60,44545;
933,67206;21,87936;60,43922;
934,572;21,89736;60,43609;
935,47206;21,91532;60,43447;
936,37206;21,93332;60,42993;
937,27206;21,95124;60,42979;
938,17206;21,96924;60,42548;
939,072;21,98736;60,42554;
939,97206;22,00536;60,41865;
940,87206;22,0234;60,41849;
941,77206;22,04124;60,41172;
942,67206;22,05932;60,4123;
943,572;22,0772;60,4064;
944,47206;22,09512;60,40582;
945,37206;22,11324;60,40768;
946,27206;22,13128;60,40355;
947,17206;22,14932;60,39991;
948,072;22,16728;60,39359;
948,97206;22,18544;60,39473;
949,87206;22,20332;60,38678;
950,77206;22,22124;60,38481;
951,67206;22,2392;60,38344;
952,572;22,25732;60,38231;
953,47206;22,27528;60,37892;
954,37206;22,29328;60,37668;
955,27206;22,31132;60,37357;
956,17206;22,32924;60,36634;
957,072;22,34724;60,36463;
957,97206;22,36516;60,35959;
958,87206;22,38336;60,36164;
959,77206;22,40128;60,35298;
960,67206;22,41932;60,35085;
961,572;22,43728;60,3489;
962,47206;22,45532;60,34603;
963,37206;22,47332;60,34229;
964,27206;22,49124;60,33553;
965,17206;22,50944;60,33728;
966,072;22,52732;60,32616;
966,97206;22,54528;60,32799;
967,87206;22,5632;60,32168;
968,77206;22,58132;60,32122;
969,67206;22,59924;60,31575;
970,572;22,6172;60,31362;
971,47206;22,63524;60,31381;
972,37206;22,65324;60,3071;
973,27206;22,67136;60,30566;
974,17206;22,68924;60,29735;
975,072;22,7074;60,29849;
975,97206;22,72536;60,29384;
976,87206;22,7434;60,29186;
977,77206;22,7614;60,28708;
978,67206;22,77924;60,28202;
979,572;22,79724;60,27766;
980,47206;22,81532;60,27595;
981,37206;22,83344;60,27319;
982,27206;22,85136;60,26336;
983,17206;22,8694;60,26086;
984,072;22,88736;60,25511;
984,97206;22,90552;60,25552;
985,87206;22,92344;60,2484;
986,77206;22,94144;60,2459;
987,67206;22,9594;60,24283;
988,572;22,97736;60,23508;
989,47206;22,99536;60,23359;
990,37206;23,01332;60,22833;
991,27206;23,03156;60,22863;
992,17206;23,04956;60,2218;
993,072;23,06756;60,21779;
993,97206;23,08532;60,20932;
994,87206;23,10328;60,20783;
995,77206;23,1212;60,20548;
996,67206;23,13912;60,20151;
997,572;23,15724;60,20062;
998,47206;23,17528;60,19312;
999,37206;23,19328;60,1872;
1000,27206;23,2112;60,17991;
1001,17206;23,22928;60,17914;
1002,072;23,2472;60,17123;
1002,97206;23,26516;60,16732;
1003,87206;23,28316;60,16536;
1004,77206;23,30128;60,16009;
1005,67206;23,31924;60,15357;
1006,572;23,33724;60,14674;
1007,47206;23,35532;60,14475;
1008,37206;23,3732;60,13485;
1009,27206;23,3912;60,13243;
1010,17206;23,40912;60,12754;
1011,072;23,42728;60,12713;
1011,97206;23,4452;60,11898;
1012,87206;23,46324;60,11696;
1013,77206;23,48128;60,11129;
1014,67206;23,49924;60,10254;
1015,572;23,51724;60,09613;
1016,47206;23,53512;60,08931;
1017,37206;23,55328;60,09029;
1018,27206;23,57124;60,08037;
1019,17206;23,58928;60,07807;
1020,072;23,60724;60,06982;
1020,97206;23,62528;60,06581;
1021,87206;23,64316;60,05838;
1022,77206;23,66116;60,05061;
1023,67206;23,67932;60,05079;
1024,572;23,69736;60,04077;
1025,47206;23,71536;60,03535;
1026,37206;23,73328;60,02892;
1027,27212;23,75148;60,0269;
1028,172;23,7694;60,01859;
1029,072;23,7874;60,01384;
1029,97206;23,8054;60,00747;
1030,87206;23,82348;60,00205;
1031,77212;23,84136;59,98954;
1032,672;23,85936;59,98453;
1033,572;23,87748;59,98167;
1034,47206;23,8954;59,97073;
1035,37206;23,91332;59,96586;
1036,27212;23,93124;59,95809;
1037,172;23,94936;59,95659;
1038,072;23,96736;59,94729;
1038,97206;23,9854;59,93795;
1039,87206;24,00336;59,93128;
1040,77212;24,02136;59,92012;
1041,672;24,03948;59,91855;
1042,572;24,0574;59,90795;
1043,47206;24,0754;59,90119;
1044,37206;24,09324;59,89252;
1045,27212;24,11128;59,89073;
1046,172;24,12924;59,88286;
1047,072;24,14732;59,87519;
1047,97206;24,16524;59,86586;
1048,87213;24,18324;59,85917;
1049,77212;24,2014;59,85584;
1050,672;24,2194;59,84523;
1051,572;24,23736;59,83773;
1052,472;24,25528;59,82753;
1053,37213;24,27336;59,82381;
1054,27212;24,29124;59,81362;
1055,172;24,3092;59,80475;
1056,072;24,32728;59,79787;
1056,972;24,34548;59,79058;
1057,87213;24,36348;59,77992;
1058,77212;24,38136;59,7666;
1059,672;24,3994;59,76242;
1060,572;24,41728;59,74952;
1061,472;24,43532;59,74395;
1062,37213;24,4532;59,73444;
1063,27212;24,47136;59,72457;
1064,172;24,48928;59,71305;
1065,072;24,50728;59,70459;
1065,972;24,52532;59,69704;
1066,87213;24,54328;59,68559;
1067,77212;24,56128;59,6784;
1068,672;24,57924;59,66806;
1069,572;24,59744;59,66384;
1070,472;24,6154;59,64997;
1071,37213;24,63344;59,64217;
1072,27212;24,65136;59,62725;
1073,172;24,66944;59,61727;
1074,072;24,68732;59,60641;
1074,972;24,70536;59,59741;
1075,87213;24,72356;59,59333;
1076,77212;24,7416;59,57734;
1077,672;24,7596;59,56616;
1078,572;24,77752;59,55294;
1079,472;24,79564;59,54353;
1080,37213;24,81348;59,52977;
1081,27212;24,83144;59,5172;
1082,172;24,84948;59,50701;
1083,072;24,86756;59,49479;
1083,972;24,88552;59,48238;
1084,87213;24,9034;59,46885;
1085,77212;24,92148;59,46058;
1086,672;24,93932;59,44462;
1087,572;24,95728;59,43705;
1088,472;24,97528;59,42438;
1089,37213;24,99336;59,41377;
1090,27212;25,01132;59,39814;
1091,172;25,02936;59,38345;
1092,072;25,0474;59,3733;
1092,972;25,06536;59,3572;
1093,87213;25,08332;59,34414;
1094,77212;25,10136;59,3325;
1095,672;25,11952;59,31995;
1096,572;25,13744;59,30146;
1097,472;25,15536;59,28714;
1098,37213;25,17328;59,26973;
1099,27212;25,1914;59,25819;
1100,172;25,20936;59,2414;
1101,072;25,22728;59,22627;
1101,972;25,24548;59,21775;
1102,87213;25,26344;59,19666;
1103,77212;25,28148;59,18375;
1104,672;25,29936;59,16369;
1105,572;25,3174;59,14907;
1106,472;25,33536;59,13125;
1107,37213;25,35348;59,11622;
1108,27212;25,37156;59,10105;
1109,172;25,38936;59,07649;
1110,072;25,40732;59,06278;
1110,972;25,42532;59,04536;
1111,87213;25,44344;59,03225;
1112,77212;25,46132;59,01288;
1113,672;25,47936;58,99469;
1114,572;25,49736;58,97668;
1115,472;25,51548;58,95785;
1116,37213;25,53336;58,93248;
1117,27212;25,55132;58,9143;
1118,172;25,56944;58,89741;
1119,072;25,58728;58,87172;
1119,972;25,60532;58,85586;
1120,87213;25,62328;58,83578;
1121,77212;25,64148;58,82111;
1122,672;25,65952;58,79444;
1123,572;25,67756;58,7744;
1124,472;25,6954;58,75067;
1125,37213;25,7134;58,73234;
1126,27212;25,73136;58,71257;
1127,172;25,74936;58,68928;
1128,072;25,76744;58,67283;
1128,972;25,78544;58,64951;
1129,87213;25,80344;58,62682;
1130,77212;25,82128;58,60176;
1131,672;25,83948;58,58159;
1132,572;25,85736;58,55374;
1133,472;25,87536;58,5337;
1134,37213;25,89344;58,51212;
1135,27212;25,91148;58,48843;
1136,172;25,92948;58,46301;
1137,072;25,94736;58,43754;
1137,972;25,96548;58,41829;
1138,87213;25,98332;58,38812;
1139,77212;26,00128;58,36239;
1140,672;26,01936;58,34073;
1141,572;26,03752;58,31683;
1142,472;26,05552;58,28762;
1143,37213;26,07348;58,25962;
1144,27212;26,09152;58,23698;
1145,172;26,10948;58,20818;
1146,072;26,12748;58,18342;
1146,972;26,1454;58,15456;
1147,87213;26,16352;58,12935;
1148,77212;26,18148;58,09771;
1149,672;26,19952;58,07092;
1150,572;26,2174;58,04132;
1151,472;26,23544;58,01457;
1152,37213;26,25344;57,98643;
1153,27212;26,27136;57,95827;
1154,172;26,28956;57,9364;
1155,072;26,30756;57,8988;
1155,972;26,3256;57,87039;
1156,87213;26,34348;57,83546;
1157,77212;26,3616;57,80727;
1158,672;26,37956;57,77673;
1159,572;26,39756;57,74402;
1160,472;26,41572;57,71986;
1161,37213;26,43376;57,68549;
1162,27212;26,45156;57,65049;
1163,172;26,46944;57,61765;
1164,072;26,4876;57,58729;
1164,972;26,50552;57,55432;
1165,87213;26,52356;57,52095;
1166,77212;26,54156;57,48873;
1167,672;26,55968;57,45524;
1168,572;26,57768;57,41937;
1169,472;26,59564;57,38785;
1170,37213;26,61372;57,35533;
1171,27212;26,63156;57,31688;
1172,172;26,64972;57,28551;
1173,072;26,66776;57,24481;
1173,972;26,68584;57,2116;
1174,87213;26,70356;57,17024;
1175,77212;26,72156;57,14027;
1176,672;26,73956;57,10599;
1177,572;26,75756;57,06553;
1178,472;26,77552;57,03086;
1179,37213;26,79348;56,99148;
1180,27212;26,81164;56,9598;
1181,172;26,8296;56,91588;
1182,072;26,84768;56,87767;
1182,972;26,86556;56,83828;
1183,87213;26,88364;56,80191;
1184,77212;26,90148;56,75939;
1185,672;26,91944;56,72127;
1186,572;26,9376;56,68416;
1187,472;26,95568;56,64136;
1188,37213;26,97368;56,59638;
1189,27212;26,99164;56,55252;
1190,172;27,00968;56,51428;
1191,072;27,0276;56,46939;
1191,972;27,04564;56,428;
1192,87213;27,06364;56,38484;
1193,77212;27,08172;56,34326;
1194,672;27,09968;56,29798;
1195,572;27,1176;56,25167;
1196,472;27,13572;56,21178;
1197,37213;27,15368;56,16273;
1198,27212;27,17172;56,11743;
1199,172;27,18968;56,06998;
1200,072;27,20784;56,02553;
1200,972;27,22576;55,97721;
1201,87213;27,2438;55,93214;
1202,77212;27,2618;55,88593;
1203,672;27,27972;55,83426;
1204,572;27,29764;55,7857;
1205,472;27,31556;55,73646;
1206,37213;27,33376;55,69205;
1207,27212;27,35176;55,63992;
1208,172;27,36976;55,59184;
1209,072;27,38772;55,53842;
1209,972;27,40576;55,49254;
1210,87213;27,42368;55,43901;
1211,77212;27,4416;55,38883;
1212,672;27,45968;55,34199;
1213,572;27,47768;55,28598;
1214,472;27,49564;55,23134;
1215,37213;27,51356;55,17604;
1216,27212;27,53176;55,12602;
1217,172;27,54968;55,06957;
1218,072;27,56768;55,01198;
1218,972;27,58564;54,95948;
1219,87213;27,60376;54,90448;
1220,77212;27,6218;54,84594;
1221,672;27,63972;54,78829;
1222,572;27,65784;54,7284;
1223,472;27,6758;54,67071;
1224,37213;27,69388;54,61434;
1225,27212;27,71188;54,55337;
1226,17212;27,73;54,49622;
1227,072;27,74788;54,43037;
1227,972;27,76576;54,37036;
1228,87213;27,7838;54,31448;
1229,77212;27,8018;54,24917;
1230,67212;27,81984;54,18734;
1231,572;27,83784;54,11887;
1232,472;27,856;54,06272;
1233,37213;27,87396;53,9948;
1234,27212;27,89208;53,93116;
1235,17212;27,91;53,86358;
1236,072;27,92804;53,79772;
1236,972;27,94592;53,73147;
1237,87213;27,964;53,6666;
1238,77212;27,9822;53,5983;
1239,67212;28,00004;53,52012;
1240,572;28,01796;53,45564;
1241,472;28,03592;53,38667;
1242,37213;28,05412;53,31921;
1243,27212;28,072;53,24349;
1244,17212;28,09;53,17338;
1245,072;28,10804;53,10262;
1245,972;28,12616;53,0291;
1246,87213;28,14408;52,95196;
1247,77212;28,16212;52,8739;
1248,67212;28,1802;52,80392;
1249,572;28,19812;52,72294;
1250,472;28,21608;52,64828;
1251,37213;28,23404;52,57229;
1252,27212;28,25228;52,49646;
1253,17212;28,27028;52,41291;
1254,072;28,28828;52,33181;
1254,972;28,3062;52,24864;
1255,87213;28,32412;52,16646;
1256,77212;28,34212;52,08431;
1257,67212;28,36008;52,00073;
1258,572;28,37828;51,92235;
1259,472;28,3962;51,83182;
1260,37213;28,4142;51,74931;
1261,27212;28,43216;51,65761;
1262,17212;28,4502;51,57236;
1263,072;28,46812;51,47998;
1263,972;28,48616;51,3896;
1264,87213;28,50428;51,30632;
1265,77212;28,52232;51,2075;
1266,67212;28,5404;51,1166;
1267,572;28,55828;51,0191;
1268,472;28,5764;50,92547;
1269,37213;28,59428;50,82873;
1270,27212;28,61224;50,72817;
1271,17212;28,63028;50,6332;
1272,072;28,6484;50,53023;
1272,972;28,66644;50,4277;
1273,87213;28,68436;50,32526;
1274,77212;28,70248;50,22409;
1275,67212;28,72044;50,11669;
1276,572;28,7384;50,01215;
1277,472;28,75632;49,90052;
1278,37213;28,77436;49,79332;
1279,27212;28,79236;49,67929;
1280,17212;28,81032;49,56615;
1281,072;28,82832;49,4549;
1281,972;28,84636;49,33511;
1282,87213;28,86432;49,21958;
1283,77212;28,88232;49,10014;
1284,67212;28,90044;48,98203;
1285,572;28,91844;48,85635;
1286,472;28,93652;48,73267;
1287,37213;28,95444;48,60575;
1288,27212;28,97252;48,47727;
1289,17212;28,99048;48,34541;
1290,072;29,00852;48,21369;
1290,972;29,02672;48,08215;
1291,87213;29,04472;47,94601;
1292,77212;29,06268;47,80633;
1293,67212;29,08052;47,66503;
1294,572;29,0986;47,52602;
1295,472;29,11656;47,37685;
1296,37213;29,13456;47,22842;
1297,27212;29,15256;47,07921;
1298,17212;29,17068;46,92066;
1299,072;29,18868;46,76093;
1299,972;29,20668;46,59787;
1300,87213;29,22476;46,43241;
1301,77212;29,24268;46,25568;
1302,67212;29,26072;45,9594;
1302,994;29,26724;45,00947;
1303,01812;29,26904;32,3676;
1303,02212;29,26944;27,27592;