File: data/primary_data/Zy2.csv
Time;Crosshead separation;Load;Extensometer elongation
(sec);(mm);(kN);(%)
0;-0,00004;0,19004;0,08862
0,852;0,03892;0,64665;0,09064
1,334;0,10016;1,56678;0,09437
1,712;0,16648;2,48965;0,09809
2,072;0,24392;2,78726;0,10044
2,47;0,34188;3,27364;0,10545
3,084;0,5366;4,18136;0,10864
3,462;0,67904;5,10492;0,11248
3,734;0,78992;6,03597;0,11611
3,95;0,88152;6,9633;0,11969
4,14;0,96348;7,90014;0,12338
4,318;1,04104;8,86696;0,12711
4,48;1,1118;9,79508;0,13081
4,642;1,18284;10,76175;0,1345
4,804;1,25412;11,75758;0,13831
4,948;1,31744;12,66387;0,14187
5,096;1,38208;13,59468;0,14551
5,24;1,44508;14,51979;0,14899
5,384;1,50796;15,45594;0,15269
5,528;1,57052;16,39523;0,15628
5,672;1,63268;17,34519;0,15988
5,816;1,69472;18,30229;0,16359
5,96;1,75656;19,26696;0,16729
6,104;1,81788;20,24036;0,17107
6,248;1,87884;21,21517;0,17488
6,392;1,9396;22,19926;0,17865
6,536;1,99976;23,18267;0,18251
6,68;2,0598;24,17169;0,18633
6,824;2,11928;25,16197;0,19016
6,968;2,1784;26,14757;0,19416
7,112;2,23704;27,13422;0,19802
7,256;2,29508;28,11539;0,20193
7,4;2,35272;29,08539;0,20594
7,544;2,40972;30,05731;0,20995
7,688;2,46616;31,02821;0,21401
7,832;2,52196;31,9744;0,21794
7,976;2,57728;32,9227;0,22204
8,12;2,63172;33,86181;0,22626
8,266;2,68596;34,78512;0,23032
8,41;2,73904;35,6966;0,23457
8,566;2,79568;36,66685;0,2391
8,728;2,85364;37,64089;0,24379
8,89;2,91052;38,59185;0,24845
9,052;2,9668;39,51711;0,25292
9,232;3,0282;40,49178;0,25816
9,412;3,0886;41,4243;0,26341
9,614;3,1548;42,37428;0,26916
9,848;3,23044;43,31178;0,27577
10,156;3,32764;44,2329;0,28423
10,604;3,471;45,15698;0,29725
11,49;3,66156;45,87106;0,34239
12,39;3,74452;46,08816;0,37651
13,29;3,7992;46,38633;0,40026
14,19;3,84484;46,59859;0,42364
15,09;3,88884;46,89367;0,4448
15,99;3,92856;47,03768;0,46971
16,89;3,96268;47,2097;0,49194
17,79;4,00024;47,49351;0,51353
18,69;4,03052;47,51347;0,53781
19,59;4,06;47,68278;0,56032
20,49;4,08728;47,77223;0,58324
21,39;4,1164;47,91413;0,60632
22,29;4,13892;47,93472;0,62857
23,19;4,1618;48,0094;0,65114
24,09;4,18216;48,02002;0,67381
24,99;4,2026;48,06196;0,69689
25,89;4,22176;48,08539;0,71754
26,79;4,23848;47,98416;0,74269
27,69;4,25508;48,01688;0,76471
28,59;4,27016;47,97545;0,78742
29,49;4,28512;47,96839;0,80985
30,39;4,29944;47,94419;0,83241
31,29;4,31344;47,92893;0,85478
32,19;4,32772;47,92924;0,87775
33,09;4,34124;47,91842;0,90004
33,99;4,35508;47,92474;0,92289
34,89;4,36832;47,91705;0,94528
35,79;4,38128;47,91155;0,96756
36,69;4,39396;47,90612;0,9898
37,59;4,4068;47,90891;1,01224
38,49;4,41932;47,9009;1,03468
39,39;4,43172;47,89426;1,05721
40,29;4,444;47,87945;1,07974
41,19;4,45672;47,88231;1,10258
42,09;4,46836;47,84777;1,12504
42,99;4,48056;47,84596;1,14732
43,89;4,4926;47,83222;1,17002
44,79;4,50476;47,83461;1,19225
45,69;4,51704;47,82634;1,21509
46,59;4,52888;47,81206;1,23739
47,49;4,54456;47,88235;1,26122
48,39;4,5546;47,80195;1,28165
49,29;4,56728;47,81675;1,30508
50,19;4,57972;47,83809;1,3274
51,09;4,59132;47,80888;1,35013
51,99;4,60336;47,81679;1,3724
52,89;4,61588;47,84044;1,39497
53,79;4,62776;47,83732;1,41726
54,69;4,64032;47,85427;1,44
55,59;4,65256;47,8529;1,46263
56,49;4,66488;47,86909;1,48499
57,39;4,67712;47,88021;1,50735
58,29;4,68924;47,87849;1,52984
59,19;4,70192;47,90435;1,55215
60,09;4,7136;47,87133;1,57518
60,99;4,7244;47,80756;1,59774
61,89;4,73436;47,71166;1,62021
62,79;4,74348;47,574;1,64311
63,69;4,7524;47,44814;1,66523
64,59;4,76308;47,41427;1,68739
65,49;4,77564;47,46953;1,70974
66,39;4,78924;47,57746;1,73193
67,29;4,80404;47,73935;1,75411
68,19;4,8194;47,90901;1,77656
69,09001;4,83556;48,0786;1,79894
69,99001;4,8516;48,21614;1,82166
70,89001;4,86804;48,35064;1,84362
71,79;4,88516;48,4756;1,86604
72,69;4,90268;48,59416;1,88841
73,59001;4,92056;48,68434;1,91121
74,49001;4,93864;48,78035;1,93347
75,39001;4,95716;48,85937;1,95586
76,29;4,977;48,96104;1,97845
77,19;4,99772;49,00496;2,00114
78,09001;5,0174;49,10043;2,02304
78,99001;5,03768;49,17988;2,04572
79,89001;5,0578;49,2334;2,06822
80,79;5,0784;49,31253;2,09049
81,69;5,09976;49,39516;2,11296
82,59001;5,12108;49,45126;2,13566
83,49001;5,14304;49,53311;2,15789
84,39001;5,1654;49,60793;2,18026
85,29;5,19084;49,73629;2,20269
86,19;5,21224;49,73814;2,22524
87,09001;5,23548;49,83049;2,24771
87,99001;5,25788;49,88616;2,26989
88,89001;5,28116;49,9694;2,29235
89,79;5,30468;50,0471;2,31512
90,69;5,32772;50,10948;2,33725
91,59001;5,35136;50,18567;2,35965
92,49001;5,37624;50,2757;2,38113
93,39001;5,40104;50,32722;2,40529
94,29;5,42428;50,40225;2,4274
95,19;5,4474;50,45962;2,44982
96,09001;5,47092;50,5457;2,47196
96,99001;5,49472;50,62134;2,49457
97,89001;5,518;50,6769;2,5173
98,79;5,54148;50,74765;2,53977
99,69;5,56536;50,82755;2,56236
100,59001;5,59132;50,93552;2,58494
101,49001;5,61348;50,94571;2,60715
102,39001;5,63732;51,02854;2,63004
103,29001;5,66104;51,09889;2,65273
104,19;5,68396;51,14985;2,67496
105,09001;5,707;51,21009;2,69711
105,99001;5,73052;51,28886;2,71941
106,89001;5,75444;51,36164;2,74215
107,79001;5,78012;51,48206;2,76388
108,69;5,80272;51,46331;2,78733
109,59001;5,82616;51,54809;2,80963
110,49001;5,84896;51,60052;2,83187
111,39001;5,87216;51,66818;2,85438
112,29001;5,89568;51,7334;2,87715
113,19;5,91864;51,79213;2,89936
114,09001;5,94204;51,85452;2,92193
114,99001;5,96592;51,91718;2,9446
115,89001;5,99124;51,98008;2,96729
116,79001;6,01424;52,04805;2,98918
117,69;6,03736;52,0844;3,01208
118,59001;6,06104;52,15594;3,03468
119,49001;6,08444;52,21916;3,05699
120,39001;6,10772;52,26669;3,07927
121,29001;6,13144;52,32846;3,10178
122,19;6,15608;52,40115;3,12476
123,09001;6,18236;52,48756;3,14722
123,99001;6,20504;52,49433;3,16948
124,89001;6,22916;52,55764;3,19214
125,79001;6,2528;52,61542;3,21444
126,69;6,27676;52,67929;3,2371
127,59001;6,3002;52,71557;3,25958
128,49001;6,32416;52,78077;3,28185
129,39;6,3486;52,84507;3,30457
130,29001;6,37516;52,96376;3,32628
131,19;6,39808;52,93249;3,34938
132,09002;6,42212;52,99588;3,37233
132,99;6,44544;53,04694;3,39447
133,89;6,46872;53,09774;3,41663
134,79002;6,49264;53,14729;3,43913
135,69;6,51684;53,20573;3,46154
136,59002;6,54132;53,26585;3,48408
137,49;6,56632;53,33604;3,5047
138,39;6,59124;53,34924;3,52916
139,29002;6,61544;53,41015;3,55165
140,19;6,6394;53,45707;3,57387
141,09002;6,66404;53,51502;3,59649
141,99;6,68872;53,55543;3,61934
142,89;6,71332;53,60727;3,64191
143,79002;6,73804;53,66284;3,6644
144,69;6,76332;53,73005;3,68496
145,59002;6,78868;53,74349;3,70908
146,49;6,8136;53,80129;3,7318
147,39;6,83824;53,84851;3,7543
148,29002;6,86284;53,89311;3,77677
149,19;6,88764;53,92954;3,79919
149,92602;6,89396;53,68072;3,80908
150,826;6,91184;53,82385;3,82326
151,72602;6,92996;53,89383;3,83883
152,626;6,94792;53,9335;3,85488
153,526;6,96616;53,97412;3,87092
154,42602;6,98404;54,00433;3,88648
155,326;7,00192;54,03138;3,90038
155,97602;7,0148;54,05399;3,91186
172,86602;7,03096;53,1874;
173,766;7,04892;53,76065;
174,66602;7,06708;54,07214;
175,56602;7,08504;54,20025;
176,466;7,10308;54,25656;
177,36602;7,12104;54,29344;
178,266;7,13896;54,31803;
179,16602;7,15692;54,34331;
180,06602;7,17488;54,37196;
180,966;7,19308;54,40513;
181,86602;7,21096;54,42721;
182,766;7,229;54,45712;
183,66602;7,24696;54,48007;
184,56602;7,26496;54,51006;
185,466;7,28288;54,53454;
186,36602;7,30076;54,55657;
187,266;7,3188;54,59112;
188,16602;7,3368;54,62021;
189,06602;7,35484;54,65153;
189,966;7,3728;54,67753;
190,86602;7,39084;54,70826;
191,766;7,40872;54,73642;
192,66602;7,42672;54,76085;
193,56602;7,44476;54,79113;
194,466;7,46288;54,82303;
195,36602;7,4808;54,84695;
196,266;7,49876;54,87619;
197,16602;7,51688;54,90549;
198,06602;7,53484;54,93023;
198,966;7,55284;54,95749;
199,86602;7,5708;54,9855;
200,766;7,58896;55,01493;
201,66602;7,60684;55,04111;
202,56602;7,62476;55,06961;
203,466;7,6428;55,10095;
204,36602;7,66084;55,12258;
205,266;7,6788;55,15187;
206,16602;7,6968;55,17691;
207,06602;7,715;55,21241;
207,966;7,73292;55,23523;
208,86602;7,75092;55,26292;
209,766;7,7688;55,2907;
210,66602;7,78684;55,31664;
211,56602;7,80472;55,3422;
212,466;7,82272;55,36816;
213,36602;7,84088;55,39991;
214,266;7,85876;55,42287;
215,16602;7,87672;55,45179;
216,06602;7,89464;55,47835;
216,966;7,9128;55,50932;
217,86602;7,93072;55,53076;
218,766;7,94868;55,55676;
219,66602;7,96672;55,58421;
220,56602;7,98488;55,61232;
221,466;8,00288;55,63689;
222,36602;8,02088;55,66165;
223,266;8,03896;55,68813;
224,16602;8,05688;55,71025;
225,06602;8,07476;55,7364;
225,966;8,09272;55,76429;
226,86602;8,11088;55,79448;
227,766;8,12884;55,81715;
228,66602;8,1468;55,84153;
229,56602;8,16484;55,8675;
230,466;8,18284;55,88861;
231,36602;8,20084;55,91316;
232,266;8,21876;55,93791;
233,16602;8,23688;55,96612;
234,06602;8,25476;55,98812;
234,96602;8,27296;56,01874;
235,86602;8,29092;56,03792;
236,766;8,30876;56,05769;
237,66602;8,32664;56,08378;
238,56602;8,3446;56,10904;
239,46602;8,3628;56,13834;
240,36602;8,38076;56,15725;
241,266;8,3988;56,18274;
242,16602;8,41668;56,20464;
243,06602;8,43476;56,23383;
243,96602;8,45272;56,2546;
244,86602;8,47072;56,27702;
245,766;8,48876;56,30322;
246,66602;8,5068;56,32387;
247,56602;8,52472;56,34481;
248,46602;8,54272;56,36871;
249,36602;8,56088;56,39596;
250,266;8,5788;56,41651;
251,16602;8,59684;56,441;
252,06602;8,61468;56,46034;
252,96602;8,6328;56,48654;
253,86602;8,65072;56,50679;
254,766;8,66876;56,53006;
255,66602;8,6868;56,55402;
256,56602;8,7048;56,56964;
257,466;8,72276;56,59408;
258,366;8,74072;56,61525;
259,26602;8,75888;56,64265;
260,16602;8,77684;56,65968;
261,06602;8,7948;56,68366;
261,966;8,81272;56,70624;
262,866;8,83076;56,72557;
263,76603;8,84872;56,74748;
264,666;8,86668;56,76595;
265,566;8,88476;56,79162;
266,466;8,90272;56,80955;
267,36603;8,92072;56,83065;
268,26603;8,9386;56,85145;
269,166;8,95672;56,87466;
270,066;8,97468;56,89443;
270,966;8,9926;56,91383;
271,86603;9,01072;56,93812;
272,76603;9,0288;56,95873;
273,666;9,0468;56,97812;
274,566;9,06472;56,9958;
275,466;9,0828;57,02174;
276,36603;9,10072;57,04018;
277,26603;9,11868;57,06245;
278,166;9,13664;57,08121;
279,066;9,15476;57,10254;
279,966;9,17264;57,11957;
280,86603;9,1906;57,13669;
281,76603;9,20868;57,16116;
282,666;9,22664;57,1772;
283,566;9,24464;57,19731;
284,466;9,26256;57,21703;
285,36603;9,28072;57,24082;
286,26603;9,29868;57,25709;
287,166;9,31672;57,27717;
288,066;9,33472;57,29497;
288,966;9,35272;57,31505;
289,86603;9,37064;57,33168;
290,76603;9,38852;57,34879;
291,666;9,40668;57,37332;
292,566;9,42468;57,38952;
293,466;9,44272;57,41025;
294,36603;9,46068;57,42345;
295,26603;9,47872;57,44492;
296,166;9,49672;57,46413;
297,066;9,51468;57,48039;
297,966;9,53272;57,50145;
298,86603;9,55076;57,51891;
299,76603;9,56876;57,53815;
300,666;9,5868;57,55613;
301,566;9,60488;57,57598;
302,466;9,62256;57,58776;
303,36603;9,64056;57,61129;
304,26603;9,6586;57,62882;
305,166;9,67672;57,64741;
306,066;9,69468;57,66141;
306,966;9,71264;57,67984;
307,86603;9,73072;57,70065;
308,76603;9,74864;57,71173;
309,666;9,7666;57,73307;
310,566;9,78456;57,74811;
311,466;9,80272;57,77101;
312,36603;9,8206;57,78235;
313,26603;9,83864;57,80296;
314,166;9,8566;57,81917;
315,066;9,87468;57,83631;
315,966;9,89264;57,85403;
316,86603;9,9106;57,86971;
317,76603;9,9286;57,89084;
318,666;9,94652;57,9053;
319,566;9,96464;57,92457;
320,466;9,98252;57,93931;
321,36603;10,0006;57,95611;
322,26603;10,01856;57,97001;
323,166;10,03652;57,98609;
324,066;10,05464;58,00566;
324,966;10,07268;58,02106;
325,86603;10,09064;58,03607;
326,76603;10,10856;58,05014;
327,666;10,1266;58,07163;
328,566;10,14456;58,0862;
329,466;10,16256;58,10282;
330,36603;10,18056;58,1166;
331,26603;10,19872;58,13208;
332,166;10,21656;58,1448;
333,066;10,23448;58,15863;
333,966;10,25252;58,17863;
334,86603;10,27052;58,1945;
335,76603;10,28852;58,21049;
336,666;10,3064;58,22479;
337,566;10,32464;58,24387;
338,466;10,3426;58,25517;
339,36603;10,36068;58,27124;
340,26603;10,37864;58,283;
341,166;10,39656;58,29872;
342,066;10,41452;58,31434;
342,966;10,43248;58,32928;
343,86603;10,45068;58,34968;
344,76603;10,46856;58,3584;
345,666;10,4866;58,37422;
346,566;10,50456;58,38741;
347,466;10,52264;58,40347;
348,36603;10,54056;58,41621;
349,26603;10,55852;58,42909;
350,166;10,57656;58,44684;
351,066;10,59468;58,46109;
351,966;10,61268;58,47756;
352,86603;10,63064;58,48969;
353,76603;10,64872;58,50564;
354,666;10,6666;58,51544;
355,566;10,68448;58,52773;
356,466;10,70248;58,54362;
357,36603;10,7206;58,56094;
358,26603;10,7386;58,57236;
359,166;10,75656;58,58383;
360,066;10,77464;58,60192;
360,966;10,7926;58,6117;
361,86603;10,81056;58,62765;
362,76603;10,82848;58,63732;
363,666;10,84656;58,65434;
364,566;10,8646;58,66826;
365,466;10,88272;58,68459;
366,36603;10,90076;58,69829;
367,26603;10,91864;58,70498;
368,166;10,9364;58,71869;
369,066;10,9544;58,73489;
369,966;10,9726;58,75402;
370,86603;10,99056;58,76381;
371,76603;11,00864;58,77681;
372,666;11,0266;58,78714;
373,566;11,04472;58,80173;
374,466;11,06256;58,81032;
375,36603;11,08052;58,82329;
376,26603;11,09868;58,8409;
377,166;11,11664;58,85137;
378,066;11,13464;58,86573;
378,966;11,1526;58,87501;
379,86603;11,17072;58,89297;
380,76603;11,18868;58,90342;
381,666;11,20672;58,91439;
382,566;11,22464;58,92678;
383,466;11,24272;58,93956;
384,36603;11,26064;58,95169;
385,26603;11,27864;58,96556;
386,166;11,2966;58,97811;
387,066;11,31448;58,98878;
387,966;11,33248;59,00366;
388,86603;11,35044;59,01441;
389,76603;11,36864;59,03001;
390,666;11,3866;59,03733;
391,566;11,4046;59,0503;
392,466;11,42256;59,0619;
393,36603;11,44052;59,07354;
394,26603;11,45852;59,08729;
395,166;11,47648;59,09767;
396,066;11,49468;59,11573;
396,96603;11,51264;59,12254;
397,86603;11,5306;59,13325;
398,76603;11,54848;59,14373;
399,666;11,56656;59,15723;
400,566;11,58456;59,16908;
401,46603;11,60248;59,18062;
402,36603;11,62056;59,19557;
403,26603;11,6386;59,20741;
404,166;11,6566;59,21614;
405,066;11,67448;59,22511;
405,96603;11,69256;59,23854;
406,86603;11,71044;59,24788;
407,76603;11,72844;59,25971;
408,666;11,74644;59,27222;
409,566;11,76456;59,28614;
410,46603;11,78244;59,29326;
411,36603;11,8004;59,30459;
412,26603;11,81848;59,3211;
413,166;11,83648;59,32721;
414,066;11,85448;59,34145;
414,96603;11,8724;59,34974;
415,86603;11,89052;59,36497;
416,76603;11,90852;59,37384;
417,666;11,9266;59,38513;
418,566;11,94456;59,39744;
419,46603;11,96252;59,40447;
420,36603;11,9804;59,41634;
421,26603;11,99828;59,42431;
422,166;12,01644;59,43954;
423,066;12,0344;59,44747;
423,96603;12,05252;59,4606;
424,86603;12,0704;59,46696;
425,76603;12,08848;59,48145;
426,666;12,10636;59,48867;
427,566;12,12432;59,4999;
428,46603;12,1424;59,51612;
429,36603;12,1604;59,52145;
430,26603;12,17844;59,53387;
431,166;12,1966;59,54237;
432,066;12,21468;59,55493;
432,96603;12,2324;59,55525;
433,86603;12,25028;59,56756;
434,76603;12,26832;59,58474;
435,666;12,28648;59,59561;
436,566;12,30444;59,60392;
437,46603;12,32244;59,6103;
438,36603;12,34056;59,62366;
439,26603;12,35844;59,62757;
440,166;12,37648;59,63819;
441,066;12,39436;59,64647;
441,96603;12,41256;59,66128;
442,86603;12,43044;59,66592;
443,76603;12,44844;59,67913;
444,666;12,46648;59,68933;
445,566;12,48444;59,69625;
446,46603;12,50248;59,7058;
447,36603;12,52044;59,71327;
448,26603;12,53848;59,72567;
449,166;12,55644;59,7325;
450,066;12,57448;59,74532;
450,96603;12,59244;59,7531;
451,86603;12,61044;59,76441;
452,76603;12,62832;59,77381;
453,666;12,64624;59,77845;
454,566;12,66436;59,7946;
455,46603;12,6824;59,80096;
456,36603;12,70048;59,80985;
457,26603;12,71832;59,8156;
458,166;12,73644;59,82592;
459,066;12,75432;59,83443;
459,96603;12,77236;59,84488;
460,86603;12,79044;59,8536;
461,76603;12,80852;59,86412;
462,666;12,82648;59,8681;
463,566;12,84436;59,87455;
464,46603;12,86248;59,88904;
465,36603;12,8804;59,89519;
466,26603;12,89848;59,90852;
467,166;12,91644;59,91377;
468,066;12,9346;59,92854;
468,96603;12,9526;59,935;
469,86603;12,9706;59,93933;
470,76603;12,98856;59,94939;
471,666;13,00648;59,95391;
472,566;13,02448;59,96503;
473,46603;13,04244;59,97359;
474,36603;13,0606;59,98576;
475,26603;13,07848;59,9904;
476,166;13,09648;60,0008;
477,066;13,11436;60,00949;
477,96603;13,13244;60,01964;
478,86603;13,1504;60,02281;
479,76603;13,16832;60,03053;
480,666;13,18652;60,04405;
481,566;13,20452;60,04902;
482,46603;13,2226;60,05848;
483,36603;13,24056;60,06362;
484,26603;13,2586;60,07407;
485,166;13,2764;60,07649;
486,066;13,2944;60,08626;
486,96603;13,31236;60,09729;
487,86603;13,33048;60,10635;
488,76603;13,34844;60,10988;
489,666;13,36644;60,1165;
490,566;13,38452;60,12819;
491,46603;13,4024;60,13317;
492,36603;13,4204;60,14253;
493,26603;13,43836;60,15183;
494,166;13,45648;60,16128;
495,066;13,4744;60,16493;
495,96603;13,49248;60,1744;
496,86603;13,51068;60,18517;
497,76603;13,5286;60,18624;
498,666;13,54636;60,18882;
499,566;13,56432;60,1996;
500,46603;13,58252;60,21428;
501,36603;13,60048;60,21767;
502,26603;13,61852;60,22767;
503,166;13,63644;60,23303;
504,066;13,65452;60,23725;
504,96603;13,67244;60,24299;
505,86603;13,6904;60,24749;
506,76603;13,70852;60,26102;
507,666;13,72644;60,26201;
508,566;13,74444;60,27101;
509,46603;13,76232;60,2775;
510,36603;13,78044;60,28759;
511,26603;13,79836;60,29179;
512,166;13,8164;60,29759;
513,06603;13,83452;60,30704;
513,966;13,85244;60,311;
514,86603;13,8704;60,31539;
515,76606;13,88836;60,324;
516,666;13,90648;60,33536;
517,56603;13,92436;60,33776;
518,466;13,94232;60,34973;
519,36603;13,96032;60,35538;
520,26606;13,97844;60,36404;
521,166;13,9964;60,3687;
522,06603;14,01444;60,37339;
522,966;14,03244;60,38248;
523,86603;14,05036;60,3852;
524,76606;14,0684;60,39437;
525,666;14,08632;60,3994;
526,56606;14,10452;60,41073;
527,466;14,1224;60,41279;
528,366;14,14044;60,4212;
529,26606;14,15828;60,42312;
530,166;14,17636;60,4308;
531,06606;14,1944;60,43741;
531,966;14,21236;60,44202;
532,866;14,23052;60,4538;
533,76606;14,24852;60,45669;
534,666;14,2666;60,46526;
535,56606;14,28444;60,46704;
536,466;14,30248;60,47352;
537,366;14,32036;60,4766;
538,26606;14,33836;60,48153;
539,166;14,35648;60,49235;
540,06606;14,37452;60,49533;
540,966;14,39244;60,49871;
541,866;14,41036;60,50423;
542,76606;14,42844;60,51446;
543,666;14,44632;60,51697;
544,56606;14,46436;60,52545;
545,466;14,48232;60,52825;
546,366;14,50052;60,53599;
547,26606;14,51848;60,5392;
548,166;14,53648;60,5453;
549,06606;14,55452;60,5523;
549,966;14,57244;60,55427;
550,866;14,59036;60,56184;
551,76606;14,60824;60,56547;
552,666;14,6264;60,57792;
553,56606;14,6444;60,57924;
554,466;14,66244;60,58514;
555,366;14,68036;60,58852;
556,26606;14,6984;60,59368;
557,166;14,71636;60,60023;
558,06606;14,7344;60,60526;
558,966;14,75256;60,61535;
559,866;14,77048;60,61679;
560,76606;14,78852;60,62326;
561,666;14,80656;60,62901;
562,56606;14,82472;60,63232;
563,466;14,84248;60,63087;
564,366;14,86032;60,63708;
565,26606;14,87844;60,64631;
566,166;14,89652;60,65195;
567,06606;14,91448;60,6538;
567,966;14,93244;60,65807;
568,866;14,95052;60,66908;
569,76606;14,96844;60,66913;
570,666;14,9864;60,67457;
571,56606;15,0044;60,67907;
572,466;15,02252;60,68499;
573,366;15,04044;60,68659;
574,26606;15,05844;60,69089;
575,166;15,07644;60,69895;
576,06606;15,0944;60,70081;
576,966;15,11244;60,70766;
577,866;15,1304;60,71337;
578,76606;15,14848;60,7193;
579,666;15,16632;60,71884;
580,56606;15,1844;60,72818;
581,466;15,20244;60,73074;
582,366;15,22044;60,73394;
583,26606;15,2384;60,73781;
584,166;15,25632;60,74185;
585,06606;15,27448;60,75417;
585,966;15,29244;60,75462;
586,866;15,31048;60,76235;
587,76606;15,3284;60,7619;
588,666;15,34644;60,76669;
589,56606;15,3644;60,76947;
590,466;15,3824;60,77486;
591,366;15,40048;60,78342;
592,26606;15,41852;60,78504;
593,166;15,43648;60,78984;
594,06606;15,45436;60,79186;
594,966;15,4724;60,79978;
595,866;15,49024;60,80053;
596,76606;15,50832;60,80644;
597,666;15,52632;60,80897;
598,56606;15,54448;60,81523;
599,466;15,56244;60,81555;
600,366;15,58044;60,81982;
601,26606;15,59852;60,82535;
602,166;15,61632;60,82206;
603,06606;15,63432;60,83333;
603,966;15,65224;60,83307;
604,866;15,6704;60,84234;
605,76606;15,68832;60,83991;
606,666;15,70628;60,84468;
607,56606;15,72432;60,85064;
608,466;15,74232;60,85343;
609,366;15,76032;60,85932;
610,26606;15,77824;60,85964;
611,166;15,7964;60,86809;
612,06606;15,81436;60,87109;
612,966;15,83248;60,87577;
613,866;15,85048;60,87716;
614,76606;15,86856;60,88191;
615,666;15,88644;60,88014;
616,56606;15,90432;60,88482;
617,466;15,9224;60,8934;
618,366;15,94036;60,89536;
619,26606;15,9584;60,89965;
620,166;15,97632;60,9016;
621,06606;15,99444;60,91023;
621,966;16,01232;60,90795;
622,866;16,03036;60,91176;
623,76606;16,0484;60,91623;
624,666;16,06648;60,91817;
625,56606;16,0844;60,91943;
626,466;16,10244;60,92339;
627,366;16,1206;60,9347;
628,26606;16,13848;60,93146;
629,166;16,1562;60,92649;
630,06606;16,17412;60,93437;
630,966;16,19236;60,94287;
631,866;16,21028;60,94239;
632,76606;16,22836;60,94643;
633,666;16,24636;60,95074;
634,56606;16,26432;60,95166;
635,466;16,28228;60,95774;
636,366;16,3002;60,95889;
637,26606;16,3184;60,96796;
638,166;16,33636;60,9665;
639,06606;16,3544;60,97052;
639,966;16,37236;60,96973;
640,866;16,3904;60,97291;
641,76606;16,40836;60,97565;
642,666;16,42636;60,97832;
643,56606;16,44448;60,98429;
644,466;16,4624;60,98427;
645,366;16,48036;60,98632;
646,26606;16,49832;60,988;
647,166;16,51644;60,99356;
648,06606;16,53428;60,99333;
648,966;16,55228;60,99613;
649,866;16,57028;61,00096;
650,76606;16,58836;61,00395;
651,666;16,60636;61,00648;
652,56606;16,62436;61,00907;
653,466;16,64244;61,01529;
654,366;16,66028;61,01253;
655,26606;16,67828;61,01647;
656,166;16,69632;61,01746;
657,06606;16,71448;61,02428;
657,966;16,7324;61,02163;
658,866;16,7504;61,02393;
659,76606;16,76836;61,02916;
660,666;16,78628;61,02824;
661,56606;16,80428;61,03559;
662,466;16,82232;61,03666;
663,366;16,84048;61,0412;
664,26606;16,8584;61,03901;
665,166;16,87652;61,04169;
666,06606;16,8944;61,04409;
666,966;16,91244;61,04426;
667,866;16,93032;61,04652;
668,76606;16,94828;61,0505;
669,666;16,9664;61,05657;
670,56606;16,98432;61,05751;
671,466;17,00236;61,05728;
672,366;17,02024;61,05602;
673,26606;17,03832;61,06366;
674,166;17,05628;61,06136;
675,06606;17,07428;61,06635;
675,966;17,09228;61,06849;
676,866;17,1104;61,07076;
677,76606;17,12832;61,07387;
678,666;17,1464;61,07504;
679,56606;17,16452;61,07711;
680,466;17,1824;61,07517;
681,366;17,2004;61,07641;
682,26606;17,21824;61,07786;
683,166;17,23636;61,08216;
684,06606;17,25428;61,08205;
684,966;17,27228;61,08643;
685,866;17,29036;61,0895;
686,76606;17,30824;61,08733;
687,666;17,32628;61,09133;
688,56606;17,34424;61,09095;
689,466;17,36244;61,09642;
690,366;17,38036;61,09306;
691,26606;17,3984;61,09689;
692,166;17,41644;61,09874;
693,06606;17,43456;61,10107;
693,966;17,45244;61,09868;
694,866;17,47016;61,09814;
695,76606;17,48832;61,10859;
696,666;17,50636;61,10695;
697,56606;17,5244;61,10777;
698,466;17,54236;61,10647;
699,366;17,56044;61,10812;
700,26606;17,57828;61,10767;
701,166;17,59628;61,10941;
702,06606;17,61432;61,11574;
702,966;17,6324;61,11753;
703,866;17,6504;61,11623;
704,76606;17,66832;61,11404;
705,666;17,68644;61,11797;
706,56606;17,70436;61,1173;
707,466;17,72236;61,12058;
708,366;17,7404;61,12149;
709,26606;17,75852;61,12564;
710,166;17,77636;61,12119;
711,06606;17,79432;61,12648;
711,966;17,8124;61,13238;
712,866;17,83032;61,12615;
713,76606;17,84832;61,12866;
714,666;17,86628;61,12846;
715,56606;17,8844;61,13399;
716,46606;17,90232;61,13065;
717,366;17,9204;61,13431;
718,26606;17,93828;61,13225;
719,166;17,95624;61,13318;
720,06606;17,9742;61,13669;
720,96606;17,99216;61,13945;
721,866;18,0104;61,14503;
722,76606;18,02832;61,14016;
723,666;18,0464;61,14342;
724,56606;18,06424;61,14004;
725,46606;18,0822;61,14355;
726,366;18,10012;61,1422;
727,26606;18,11804;61,14395;
728,166;18,13624;61,15326;
729,06606;18,15432;61,15088;
729,96606;18,17236;61,15254;
730,866;18,19036;61,14765;
731,76606;18,2084;61,15057;
732,666;18,22624;61,14649;
733,56606;18,2442;61,14903;
734,46606;18,26216;61,1508;
735,366;18,28036;61,15424;
736,26606;18,29828;61,15091;
737,166;18,31624;61,15067;
738,06606;18,33428;61,15403;
738,96606;18,3522;61,14965;
739,866;18,37024;61,1523;
740,76606;18,3882;61,15152;
741,666;18,40636;61,15661;
742,56606;18,42432;61,15163;
743,46606;18,4424;61,15556;
744,366;18,46044;61,15661;
745,26606;18,47844;61,1554;
746,166;18,49636;61,15351;
747,06606;18,51432;61,15351;
747,96606;18,5324;61,1585;
748,866;18,55036;61,15668;
749,76606;18,56836;61,15767;
750,666;18,58624;61,1556;
751,56606;18,60432;61,15746;
752,46606;18,6222;61,15748;
753,366;18,6402;61,15763;
754,26606;18,65836;61,16146;
755,166;18,6764;61,15954;
756,06606;18,6944;61,15898;
756,96606;18,71232;61,15816;
757,866;18,73056;61,16488;
758,76606;18,74848;61,15959;
759,666;18,76632;61,15443;
760,56606;18,7842;61,15699;
761,46606;18,80232;61,16184;
762,366;18,82036;61,15918;
763,26606;18,83836;61,15869;
764,166;18,85644;61,16152;
765,06606;18,87436;61,15738;
765,96606;18,89232;61,1595;
766,866;18,91024;61,15879;
767,76606;18,9284;61,16146;
768,666;18,94632;61,15875;
769,56606;18,96436;61,15992;
770,46606;18,98228;61,15946;
771,366;19,00028;61,15836;
772,26606;19,01832;61,15865;
773,166;19,03636;61,16014;
774,06606;19,0546;61,16512;
774,96606;19,07248;61,15591;
775,866;19,09048;61,15857;
776,76606;19,1084;61,15499;
777,666;19,12648;61,15726;
778,56606;19,1444;61,15326;
779,46606;19,16236;61,15263;
780,366;19,18048;61,15857;
781,26606;19,19852;61,15466;
782,166;19,21648;61,15471;
783,06606;19,23452;61,15317;
783,96606;19,25252;61,15381;
784,866;19,27036;61,15152;
785,76606;19,28832;61,15237;
786,666;19,30636;61,15426;
787,56606;19,32448;61,15492;
788,46606;19,34244;61,1504;
789,366;19,36048;61,14872;
790,26606;19,37844;61,14902;
791,166;19,39624;61,14511;
792,06606;19,41432;61,14963;
792,96606;19,43224;61,14751;
793,866;19,45044;61,1524;
794,76606;19,46836;61,14706;
795,666;19,48644;61,14759;
796,56606;19,50448;61,14609;
797,46606;19,52236;61,13971;
798,366;19,54028;61,14203;
799,26606;19,55824;61,14153;
800,166;19,5764;61,14642;
801,06606;19,59436;61,14108;
801,96606;19,61236;61,14149;
802,866;19,6302;61,13928;
803,76606;19,64824;61,14043;
804,666;19,66616;61,13777;
805,56606;19,68416;61,13536;
806,46606;19,70232;61,13963;
807,366;19,72036;61,13721;
808,26606;19,73836;61,13476;
809,166;19,75636;61,13399;
810,06606;19,77452;61,13744;
810,96606;19,7924;61,13103;
811,866;19,81032;61,1291;
812,76606;19,82832;61,12835;
813,666;19,84636;61,12783;
814,56606;19,86432;61,1268;
815,46606;19,88232;61,12647;
816,366;19,90044;61,13057;
817,26606;19,91828;61,1223;
818,166;19,93624;61,12387;
819,06606;19,9542;61,124;
819,96606;19,9724;61,12543;
820,866;19,99028;61,1176;
821,76606;20,00832;61,11676;
822,666;20,02636;61,11843;
823,56606;20,04448;61,11699;
824,46606;20,06248;61,11405;
825,366;20,08016;61,10653;
826,26606;20,09832;61,1149;
827,166;20,11624;61,11189;
828,06606;20,13432;61,1138;
828,96606;20,15228;61,1082;
829,866;20,17036;61,10619;
830,76606;20,18832;61,10368;
831,666;20,20628;61,10111;
832,56606;20,2244;61,10613;
833,46606;20,2424;61,10106;
834,366;20,26036;61,10061;
835,26606;20,27832;61,09757;
836,166;20,29636;61,09698;
837,06606;20,31424;61,09375;
837,96606;20,33232;61,09276;
838,866;20,3504;61,09183;
839,76606;20,36852;61,08882;
840,666;20,38636;61,08024;
841,56606;20,40428;61,08168;
842,46606;20,4224;61,08528;
843,366;20,44028;61,08141;
844,26606;20,45828;61,08285;
845,166;20,47624;61,07784;
846,06606;20,4944;61,07901;
846,96606;20,51236;61,07182;
847,866;20,53036;61,07147;
848,76606;20,54836;61,07092;
849,666;20,56632;61,06573;
850,56606;20,58424;61,06424;
851,46606;20,6022;61,06493;
852,366;20,6204;61,06732;
853,26606;20,63832;61,06113;
854,166;20,6564;61,05993;
855,06606;20,67432;61,05459;
855,96606;20,69232;61,05297;
856,866;20,71024;61,05162;
857,76606;20,72824;61,05112;
858,666;20,74648;61,05435;
859,56606;20,76444;61,04852;
860,46606;20,78256;61,04802;
861,366;20,80048;61,04297;
862,26606;20,8186;61,04087;
863,166;20,83644;61,03436;
864,06606;20,8544;61,03335;
864,96606;20,87252;61,03405;
865,866;20,89056;61,03188;
866,76606;20,90852;61,02675;
867,666;20,92648;61,02284;
868,56606;20,94452;61,02738;
869,46606;20,9624;61,02089;
870,366;20,9804;61,02046;
871,26606;20,99832;61,01582;
872,166;21,01644;61,01479;
873,06606;21,03436;61,01118;
873,96606;21,05244;61,00964;
874,866;21,07052;61,00911;
875,76606;21,08848;61,00279;
876,666;21,10644;61,00139;
877,56606;21,12436;60,99947;
878,46606;21,14248;61,00023;
879,366;21,16036;60,99089;
880,26606;21,17844;60,99325;
881,166;21,1964;60,98631;
882,06606;21,2144;60,98487;
882,96606;21,23232;60,98008;
883,866;21,25028;60,97734;
884,76606;21,26844;60,98211;
885,666;21,28648;60,97238;
886,56606;21,30444;60,97436;
887,46606;21,32232;60,96762;
888,366;21,34056;60,96976;
889,26606;21,35848;60,96348;
890,166;21,37648;60,95892;
891,06606;21,39432;60,95395;
891,96606;21,4124;60,95617;
892,866;21,4304;60,95267;
893,76606;21,44836;60,9494;
894,666;21,46648;60,94915;
895,56606;21,4844;60,94328;
896,46606;21,5024;60,94043;
897,366;21,5204;60,93745;
898,26606;21,53856;60,9374;
899,166;21,55648;60,92957;
900,06606;21,57444;60,92644;
900,96606;21,59248;60,9249;
901,866;21,6104;60,91901;
902,76606;21,6284;60,9181;
903,666;21,6464;60,91154;
904,56606;21,66464;60,9157;
905,46606;21,68256;60,90408;
906,366;21,70052;60,89995;
907,26606;21,71844;60,89645;
908,166;21,73652;60,89242;
909,06606;21,75448;60,88995;
909,96606;21,7724;60,88653;
910,866;21,7906;60,8878;
911,76606;21,80848;60,88062;
912,666;21,82648;60,87642;
913,56606;21,8444;60,87296;
914,46606;21,86248;60,87084;
915,366;21,88036;60,86437;
916,26606;21,89828;60,8634;
917,166;21,91648;60,8652;
918,06606;21,93452;60,8605;
918,96606;21,95244;60,85446;
919,866;21,97044;60,84638;
920,76606;21,98844;60,84652;
921,666;22,00632;60,83887;
922,56606;22,02436;60,8377;
923,46606;22,04236;60,8352;
924,366;22,06052;60,83236;
925,26606;22,07844;60,82495;
926,166;22,09648;60,82078;
927,06606;22,11452;60,81945;
927,96606;22,1324;60,81138;
928,866;22,15036;60,80937;
929,76606;22,16824;60,80472;
930,666;22,18644;60,80415;
931,56606;22,2044;60,79453;
932,46606;22,2224;60,79342;
933,366;22,24032;60,78498;
934,26606;22,25824;60,78021;
935,166;22,2762;60,77706;
936,06606;22,29416;60,77245;
936,96606;22,31232;60,77425;
937,866;22,33028;60,76395;
938,76606;22,34832;60,76202;
939,666;22,36628;60,75543;
940,56606;22,38444;60,75249;
941,46606;22,40232;60,74551;
942,366;22,42028;60,73908;
943,26606;22,43832;60,73841;
944,166;22,45632;60,73137;
945,06606;22,47428;60,72465;
945,96606;22,49232;60,7208;
946,866;22,51044;60,7182;
947,76606;22,52832;60,70857;
948,666;22,54632;60,70591;
949,56606;22,56436;60,70075;
950,46606;22,58252;60,69839;
951,366;22,60048;60,68913;
952,26606;22,61848;60,68335;
953,166;22,63652;60,68131;
954,06606;22,6546;60,67311;
954,96606;22,67264;60,6694;
955,866;22,6904;60,65572;
956,76606;22,70848;60,65713;
957,666;22,72644;60,64917;
958,56606;22,74456;60,64668;
959,46606;22,76248;60,64048;
960,366;22,78044;60,63235;
961,26606;22,7984;60,62789;
962,166;22,81632;60,6217;
963,06606;22,83452;60,61873;
963,96606;22,8524;60,60889;
964,866;22,87052;60,6039;
965,76606;22,88836;60,59516;
966,666;22,90644;60,59042;
967,56606;22,92436;60,58261;
968,46606;22,94232;60,57958;
969,366;22,96048;60,57774;
970,26606;22,97848;60,56704;
971,166;22,99648;60,56007;
972,06606;23,0144;60,55089;
972,96606;23,03252;60,54732;
973,866;23,0504;60,53731;
974,76606;23,06836;60,53174;
975,66606;23,08636;60,5276;
976,56606;23,10452;60,52171;
977,46606;23,12244;60,51382;
978,366;23,14048;60,5041;
979,26606;23,15856;60,49877;
980,16606;23,17644;60,4874;
981,06606;23,19444;60,4818;
981,96606;23,21236;60,47347;
982,866;23,2306;60,47011;
983,76606;23,24852;60,45799;
984,66606;23,26656;60,45283;
985,56606;23,28452;60,4466;
986,46606;23,3024;60,43458;
987,366;23,32036;60,42816;
988,26606;23,33832;60,42129;
989,16606;23,35656;60,4208;
990,06606;23,37452;60,40614;
990,96606;23,39252;60,39948;
991,866;23,41048;60,38985;
992,76606;23,42844;60,3802;
993,66606;23,44632;60,37233;
994,56606;23,46428;60,36456;
995,46606;23,4824;60,3596;
996,366;23,50044;60,34771;
997,26606;23,51844;60,33716;
998,16606;23,5364;60,32608;
999,06606;23,55448;60,32012;
999,96606;23,57232;60,30665;
1000,866;23,59036;60,30017;
1001,76606;23,60836;60,29277;
1002,66606;23,62648;60,28522;
1003,56606;23,64444;60,27093;
1004,46606;23,66244;60,26189;
1005,366;23,6806;60,25637;
1006,26606;23,69856;60,24125;
1007,16606;23,71652;60,23413;
1008,06606;23,73448;60,22059;
1008,96606;23,75256;60,21415;
1009,866;23,77044;60,20013;
1010,76606;23,7884;60,19227;
1011,66606;23,80644;60,18149;
1012,56606;23,8244;60,16761;
1013,46606;23,84236;60,15857;
1014,366;23,86028;60,1458;
1015,26606;23,87848;60,14253;
1016,16606;23,89644;60,12539;
1017,06606;23,91452;60,11713;
1017,96606;23,9324;60,10237;
1018,866;23,95048;60,09499;
1019,76606;23,96852;60,0809;
1020,66606;23,98652;60,06626;
1021,56606;24,00448;60,05162;
1022,46606;24,02244;60,03886;
1023,366;24,04048;60,02973;
1024,266;24,05844;60,01461;
1025,166;24,07652;60,0062;
1026,06606;24,09444;59,99023;
1026,96606;24,1124;59,9797;
1027,86606;24,1304;59,96969;
1028,766;24,14848;59,95352;
1029,666;24,1664;59,93592;
1030,56606;24,1844;59,92382;
1031,46606;24,20248;59,91225;
1032,36606;24,22032;59,89502;
1033,266;24,23828;59,88166;
1034,166;24,25624;59,8676;
1035,06606;24,27448;59,85883;
1035,96606;24,29244;59,83928;
1036,86606;24,31036;59,81997;
1037,766;24,3284;59,80771;
1038,666;24,34636;59,78856;
1039,56606;24,36436;59,77435;
1040,46606;24,38228;59,75562;
1041,36606;24,40048;59,7478;
1042,266;24,4184;59,72615;
1043,166;24,4364;59,71089;
1044,06606;24,45436;59,69477;
1044,96606;24,4724;59,67681;
1045,86606;24,49032;59,65987;
1046,766;24,50828;59,64239;
1047,666;24,52644;59,63082;
1048,56606;24,54452;59,61138;
1049,46612;24,56256;59,59366;
1050,36612;24,58044;59,57493;
1051,266;24,59852;59,55777;
1052,166;24,61632;59,53705;
1053,066;24,63428;59,5212;
1053,96612;24,6524;59,50298;
1054,86612;24,67052;59,48485;
1055,766;24,68852;59,46139;
1056,666;24,70652;59,44241;
1057,566;24,72464;59,42805;
1058,46612;24,74252;59,40352;
1059,36612;24,7604;59,38581;
1060,266;24,77836;59,36729;
1061,166;24,79648;59,35094;
1062,066;24,81444;59,32623;
1062,96612;24,83248;59,30321;
1063,86612;24,85048;59,28594;
1064,766;24,8684;59,2602;
1065,666;24,88636;59,24165;
1066,566;24,90428;59,22124;
1067,46612;24,92256;59,20476;
1068,36612;24,94044;59,17798;
1069,266;24,95852;59,15903;
1070,166;24,97648;59,13473;
1071,066;24,9946;59,11116;
1071,96612;25,0126;59,08543;
1072,86612;25,03056;59,06374;
1073,766;25,04872;59,04483;
1074,666;25,06664;59,016;
1075,566;25,0846;58,9963;
1076,46612;25,10256;58,97237;
1077,36612;25,12064;58,95188;
1078,266;25,13852;58,92248;
1079,166;25,15652;58,89585;
1080,066;25,1746;58,87411;
1080,96612;25,19276;58,84835;
1081,86612;25,21064;58,81915;
1082,766;25,22864;58,79437;
1083,666;25,24668;58,77268;
1084,566;25,26468;58,74684;
1085,46612;25,28276;58,72211;
1086,36612;25,30068;58,69199;
1087,266;25,3186;58,66339;
1088,166;25,33656;58,63342;
1089,066;25,35464;58,61017;
1089,96612;25,37268;58,58525;
1090,86612;25,39056;58,55271;
1091,766;25,4086;58,52992;
1092,666;25,42656;58,50031;
1093,566;25,44476;58,47828;
1094,46612;25,46272;58,44294;
1095,36612;25,48068;58,41389;
1096,266;25,49868;58,38456;
1097,166;25,51668;58,3513;
1098,066;25,5346;58,32429;
1098,96612;25,55264;58,29313;
1099,86612;25,5708;58,26802;
1100,76613;25,5888;58,2363;
1101,666;25,60684;58,2055;
1102,566;25,6246;58,17258;
1103,46612;25,64268;58,14473;
1104,36612;25,6606;58,11006;
1105,26613;25,67856;58,07802;
1106,166;25,69668;58,04883;
1107,066;25,71472;58,01754;
1107,96612;25,73272;57,98306;
1108,86612;25,75064;57,95146;
1109,76613;25,76876;57,92468;
1110,666;25,78664;57,88579;
1111,566;25,8046;57,85446;
1112,46612;25,8226;57,81705;
1113,36612;25,84072;57,78394;
1114,26613;25,85868;57,74703;
1115,166;25,87672;57,71181;
1116,066;25,89476;57,68228;
1116,96612;25,91264;57,64124;
1117,86612;25,9306;57,60884;
1118,76613;25,94856;57,57487;
1119,666;25,9668;57,54176;
1120,566;25,98472;57,50114;
1121,46612;26,0028;57,46125;
1122,36612;26,0208;57,42274;
1123,26613;26,0388;57,38482;
1124,166;26,0568;57,34754;
1125,066;26,07472;57,30942;
1125,96612;26,09288;57,27632;
1126,86612;26,11084;57,23197;
1127,76613;26,12884;57,19626;
1128,666;26,1468;57,15178;
1129,566;26,1648;57,1133;
1130,46612;26,18272;57,07276;
1131,36612;26,20068;57,03244;
1132,26613;26,21876;56,99627;
1133,166;26,23684;56,95269;
1134,066;26,25476;56,9102;
1134,96612;26,27272;56,87028;
1135,86612;26,2908;56,83044;
1136,76613;26,30876;56,78642;
1137,666;26,3268;56,74225;
1138,566;26,34476;56,69803;
1139,46612;26,36296;56,6553;
1140,36612;26,3808;56,6038;
1141,26613;26,39876;56,56264;
1142,166;26,41684;56,52282;
1143,066;26,43476;56,47417;
1143,96612;26,45276;56,43007;
1144,86612;26,47072;56,38117;
1145,76613;26,48888;56,33925;
1146,666;26,50692;56,28733;
1147,566;26,52492;56,24001;
1148,46612;26,54288;56,19428;
1149,36612;26,56084;56,14513;
1150,26613;26,57892;56,10287;
1151,166;26,59692;56,05092;
1152,066;26,61496;56,0026;
1152,96612;26,63288;55,95074;
1153,86612;26,65088;55,90363;
1154,76613;26,66884;55,84981;
1155,666;26,68692;55,79859;
1156,566;26,70484;55,74617;
1157,46612;26,72284;55,69726;
1158,36612;26,741;55,64991;
1159,26613;26,75904;55,59376;
1160,166;26,777;55,53921;
1161,066;26,79492;55,48561;
1161,96612;26,813;55,43557;
1162,86612;26,83092;55,37555;
1163,76613;26,84892;55,32278;
1164,666;26,867;55,27021;
1165,566;26,88516;55,21508;
1166,46612;26,90312;55,15611;
1167,36612;26,92104;55,09694;
1168,26613;26,93904;55,04506;
1169,166;26,95696;54,9834;
1170,066;26,97496;54,92514;
1170,96612;26,99292;54,86692;
1171,86612;27,01116;54,80981;
1172,76613;27,02904;54,7453;
1173,666;27,04708;54,68615;
1174,566;27,06512;54,62799;
1175,46612;27,08308;54,56544;
1176,36612;27,10104;54,50353;
1177,26613;27,11896;54,44151;
1178,166;27,13716;54,38161;
1179,066;27,15512;54,31109;
1179,96612;27,17316;54,25045;
1180,86612;27,19112;54,18187;
1181,76613;27,20912;54,11686;
1182,666;27,22696;54,05156;
1183,566;27,24488;53,98566;
1184,46612;27,263;53,92559;
1185,36612;27,28108;53,85426;
1186,26613;27,29908;53,78519;
1187,166;27,31708;53,71264;
1188,066;27,3352;53,64775;
1188,96612;27,35312;53,57341;
1189,86612;27,37104;53,50221;
1190,76613;27,389;53,43412;
1191,666;27,4072;53,36409;
1192,566;27,42508;53,2869;
1193,46612;27,44312;53,21566;
1194,36612;27,4612;53,14287;
1195,26613;27,47908;53,06171;
1196,166;27,49704;52,98634;
1197,066;27,51504;52,91005;
1197,96612;27,5332;52,83588;
1198,86612;27,55116;52,75399;
1199,76613;27,5692;52,67581;
1200,666;27,5872;52,59712;
1201,566;27,6052;52,51452;
1202,46612;27,62316;52,4333;
1203,36612;27,64116;52,34861;
1204,26613;27,65928;52,26876;
1205,166;27,6772;52,17869;
1206,066;27,6952;52,09463;
1206,96612;27,71312;52,00939;
1207,86612;27,7312;51,92458;
1208,76613;27,74916;51,8367;
1209,666;27,76712;51,7489;
1210,566;27,78528;51,66248;
1211,46612;27,80332;51,56819;
1212,36612;27,82128;51,47352;
1213,26613;27,83936;51,38012;
1214,166;27,8574;51,28706;
1215,066;27,8754;51,19367;
1215,96612;27,89344;51,09739;
1216,86612;27,91148;51,00092;
1217,76613;27,9294;50,89998;
1218,666;27,94736;50,80296;
1219,566;27,9654;50,70062;
1220,46612;27,98348;50,60288;
1221,36612;28,00144;50,49381;
1222,26613;28,01944;50,39096;
1223,166;28,0374;50,28628;
1224,066;28,0556;50,17966;
1224,96612;28,07356;50,06654;
1225,86612;28,09156;49,95775;
1226,76613;28,1096;49,84453;
1227,666;28,12752;49,72569;
1228,566;28,14552;49,61253;
1229,46612;28,16348;49,49395;
1230,36612;28,18172;49,37811;
1231,26613;28,19972;49,2477;
1232,166;28,21776;49,11652;
1233,066;28,2356;48,97287;
1233,96612;28,25356;48,8141;
1234,86612;28,27148;48,38007;
1235,20012;28,27824;47,44202;
1235,24012;28,27976;41,21518;
1235,25;28,28096;28,47769;