File: data/primary_data/Zy3.csv
Time;Crosshead separation;Load;Extensometer elongation
(sec);(mm);(kN);(%)
0;0,00016;0,1937;-0,04644
0,864;0,03868;0,54364;-0,04469
1,31;0,0968;1,46331;-0,04067
1,65;0,1542;2,39635;-0,0367
1,946;0,2116;3,32554;-0,03273
2,236;0,2748;3,99938;-0,02926
2,4;0,309;3,59685;-0,02244
2,906;0,43404;4,5118;-0,01896
3,312;0,55588;5,42816;-0,01519
3,636;0,6648;6,35412;-0,01135
3,898;0,75852;7,27553;-0,00757
4,118;0,8402;8,2126;-0,00373
4,316;0,91544;9,15329;0,00009
4,5;0,98648;10,09407;0,00392
4,68;1,05636;11,06672;0,00792
4,848;1,122;12,00224;0,01166
5,01;1,18532;12,93213;0,01537
5,172;1,2486;13,87113;0,01921
5,334;1,31212;14,84078;0,02302
5,496;1,37548;15,82574;0,02693
5,658;1,43908;16,82396;0,03096
5,816;1,50068;17,80455;0,03489
5,968;1,55996;18,75428;0,03873
6,116;1,61756;19,68742;0,04238
6,26;1,6734;20,60429;0,04605
6,412;1,73172;21,5646;0,04995
6,56;1,788;22,49699;0,05362
6,704;1,84256;23,41377;0,05731
6,848;1,89672;24,32216;0,06103
6,992;1,95076;25,24309;0,06468
7,136;2,00456;26,17102;0,06851
7,28;2,05784;27,08845;0,07231
7,424;2,11088;28,00958;0,07602
7,568;2,16352;28,93598;0,07984
7,712;2,21572;29,85843;0,08368
7,856;2,26772;30,78303;0,08755
8;2,31908;31,7092;0,09152
8,144;2,37008;32,62502;0,0954
8,292;2,42204;33,55369;0,09957
8,444;2,47468;34,50371;0,10369
8,6;2,52824;35,46898;0,10801
8,762;2,58292;36,45464;0,11263
8,924;2,63708;37,44439;0,11665
9,072;2,68796;38,37897;0,11908
9,234;2,74256;39,36184;0,12433
9,396;2,79536;40,31588;0,12955
9,558;2,84656;41,24174;0,13481
9,73;2,89932;42,19087;0,14048
9,91;2,95256;43,14293;0,14639
10,092;3,00456;44,07257;0,15246
10,29;3,05836;45,01116;0,15886
10,494;3,11168;45,9341;0,16554
10,714;3,16664;46,87304;0,17257
10,956;3,22452;47,80659;0,18011
11,254;3,29172;48,73208;0,18997
11,834;3,40196;48,78412;0,21661
12,614;3,46088;48,04788;0,24963
13,514;3,49252;47,78262;0,27412
14,414;3,5262;47,90255;0,29599
15,314;3,55212;47,76083;0,31937
16,214;3,58096;47,83702;0,34081
17,114;3,605;47,71536;0,36475
18,014;3,6284;47,72611;0,38687
18,914;3,65436;47,78152;0,40961
19,814;3,67392;47,68014;0,43216
20,714;3,69456;47,68553;0,45462
21,614;3,71416;47,67358;0,47739
22,514;3,73556;47,68471;0,50092
23,414;3,75112;47,59994;0,52269
24,314;3,76844;47,60193;0,5454
25,214;3,78596;47,62618;0,56751
26,114;3,8024;47,59668;0,59021
27,014;3,81952;47,62568;0,61241
27,914;3,83704;47,64288;0,63254
28,814;3,85448;47,60183;0,65842
29,714;3,87064;47,63496;0,68015
30,614;3,88628;47,62587;0,70267
31,514;3,90188;47,62635;0,72533
32,414;3,91736;47,63541;0,74784
33,314;3,93164;47,60434;0,77031
34,214;3,94624;47,61297;0,79262
35,114;3,96012;47,57955;0,81526
36,014;3,97444;47,58706;0,83758
36,914;3,98888;47,58218;0,86073
37,814;4,00504;47,58722;0,88402
38,714;4,01792;47,56437;0,90516
39,614;4,03172;47,55438;0,92818
40,514;4,04576;47,57276;0,95054
41,414;4,0588;47,53886;0,97315
42,314;4,07208;47,53757;0,99526
43,214;4,08536;47,53262;1,01777
44,114;4,09884;47,53951;1,04024
45,014;4,11276;47,56531;1,06287
45,914;4,12552;47,5391;1,08553
46,814;4,13856;47,5412;1,10781
47,714;4,15196;47,5567;1,13032
48,614;4,16432;47,5304;1,15277
49,514;4,17732;47,53968;1,17537
50,414;4,18956;47,51261;1,19789
51,314;4,20216;47,51199;1,22035
52,214;4,21412;47,48485;1,24279
53,114;4,22628;47,47719;1,26516
54,014;4,23888;47,49069;1,28764
54,914;4,25152;47,49307;1,31062
55,814;4,26348;47,48124;1,3331
56,714;4,27556;47,47509;1,35581
57,614;4,28792;47,48661;1,37832
58,514;4,29972;47,48275;1,40055
59,414;4,31188;47,49939;1,42286
60,314;4,32368;47,49159;1,44531
61,214;4,33504;47,46278;1,46786
62,114;4,34532;47,38577;1,49067
63,014;4,35532;47,30442;1,51306
63,914;4,36456;47,18126;1,53576
64,814;4,3746;47,10414;1,55827
65,71401;4,38584;47,09333;1,5806
66,61401;4,3988;47,17796;1,60279
67,514;4,41324;47,31936;1,62531
68,414;4,4276;47,45451;1,64747
69,314;4,44296;47,62261;1,67013
70,21401;4,45792;47,76152;1,6923
71,11401;4,47352;47,90281;1,71463
72,014;4,48936;48,03151;1,73663
72,914;4,5078;48,12565;1,76041
73,814;4,52436;48,26172;1,78192
74,71401;4,54136;48,3632;1,80434
75,61401;4,55868;48,45274;1,82676
76,514;4,57692;48,55139;1,84961
77,414;4,59488;48,62598;1,8718
78,314;4,61348;48,70021;1,89407
79,21401;4,633;48,80038;1,91628
80,11401;4,65292;48,86606;1,93908
81,01401;4,6734;48,94941;1,96131
81,914;4,69412;49,02154;1,98359
82,814;4,71568;49,09514;2,00619
83,71401;4,73768;49,17707;2,02837
84,61401;4,76012;49,25179;2,05075
85,51401;4,78668;49,37519;2,07392
86,414;4,80848;49,40228;2,09589
87,314;4,83208;49,48622;2,11837
88,21401;4,85564;49,54986;2,14081
89,11401;4,87948;49,62689;2,16307
90,01401;4,90424;49,71968;2,18571
90,914;4,92828;49,7768;2,2081
91,814;4,9526;49,85132;2,23046
92,71401;4,97724;49,92606;2,25328
93,61401;5,00152;50,00343;2,27536
94,51401;5,02668;50,08844;2,29797
95,414;5,05464;50,21523;2,32056
96,314;5,07804;50,21123;2,34316
97,21401;5,10284;50,2998;2,36569
98,11401;5,12696;50,36531;2,38785
99,01401;5,15136;50,43893;2,41033
99,914;5,176;50,50345;2,43299
100,814;5,20064;50,58236;2,4553
101,71401;5,22536;50,65545;2,47801
102,61401;5,24932;50,70816;2,50028
103,51401;5,27336;50,78027;2,52261
104,414;5,29852;50,86727;2,54572
105,314;5,32532;50,9855;2,56815
106,21401;5,34796;50,9742;2,59064
107,11401;5,3718;51,04683;2,6131
108,01401;5,39548;51,11696;2,63522
108,914;5,41984;51,19632;2,65779
109,814;5,4434;51,2417;2,68061
110,71401;5,46736;51,3174;2,70298
111,61401;5,491;51,38102;2,72558
112,51401;5,51432;51,43434;2,74784
113,41401;5,53764;51,49921;2,77012
114,314;5,56172;51,57416;2,79296
115,21401;5,58816;51,68089;2,81596
116,11401;5,61004;51,67924;2,83817
117,01401;5,63272;51,73953;2,86019
117,91401;5,65608;51,81253;2,88274
118,814;5,6792;51,87841;2,90518
119,71401;5,70236;51,92924;2,928
120,61401;5,7256;51,99168;2,95055
121,51401;5,74896;52,05589;2,97308
122,41401;5,77152;52,09743;2,99544
123,314;5,7948;52,16522;3,01782
124,21401;5,81824;52,23215;3,04051
125,11401;5,84272;52,27565;3,06324
126,01401;5,8654;52,33161;3,08539
126,91401;5,8888;52,39156;3,10813
127,814;5,91156;52,44593;3,13036
128,71401;5,93436;52,50187;3,1525
129,61402;5,95776;52,56252;3,17539
130,51401;5,9806;52,6141;3,19791
131,414;6,00344;52,67149;3,22018
132,31402;6,02612;52,71212;3,24261
133,214;6,049;52,77591;3,26503
134,11402;6,07484;52,88592;3,28784
135,014;6,0962;52,86463;3,31031
135,914;6,11876;52,92201;3,33264
136,81402;6,14216;52,99895;3,35523
137,714;6,16436;53,02653;3,37754
138,61402;6,1872;53,08107;3,4
139,514;6,21036;53,14432;3,4227
140,414;6,2328;53,18351;3,44496
141,31402;6,25576;53,23406;3,46757
142,214;6,27896;53,28924;3,49028
143,11402;6,30376;53,39518;3,51207
144,014;6,32544;53,37685;3,53504
144,914;6,3484;53,43555;3,55802
145,81402;6,37076;53,48272;3,58024
146,714;6,39316;53,52665;3,60262
147,61402;6,41576;53,57375;3,62517
148,514;6,43812;53,6248;3,64754
149,414;6,46068;53,67522;3,66997
150,31402;6,48296;53,7127;3,69267
151,214;6,50548;53,7681;3,71512
152,11402;6,53024;53,87033;3,73743
153,014;6,5512;53,83552;3,76009
153,914;6,5734;53,89;3,78236
154,62402;6,59136;53,94354;3,80007
155,524;6,60068;53,76073;3,81306
156,42402;6,61868;53,88834;3,82937
157,324;6,63668;53,94489;3,84697
158,22402;6,65468;53,98588;3,86483
159,12402;6,6726;54,02031;3,88263
160,024;6,69044;54,05656;3,90046
182,998;6,70232;52,66471;
183,89802;6,72024;53,42344;
184,798;6,73832;53,91753;
185,69802;6,75628;54,15991;
186,598;6,77432;54,26575;
187,49802;6,79244;54,31812;
188,39802;6,81032;54,34821;
189,298;6,82824;54,37723;
190,19802;6,8462;54,40519;
191,098;6,86432;54,43494;
191,99802;6,88232;54,46113;
192,89802;6,9004;54,48922;
193,798;6,9184;54,52026;
194,69802;6,93616;54,54471;
195,598;6,95412;54,57872;
196,49802;6,97212;54,60914;
197,39802;6,99024;54,64335;
198,298;7,0082;54,67171;
199,19802;7,02628;54,70378;
200,098;7,04428;54,73307;
200,99802;7,06232;54,76089;
201,89802;7,0802;54,7869;
202,798;7,0982;54,81241;
203,69802;7,11632;54,84876;
204,598;7,13428;54,87849;
205,49802;7,15232;54,90938;
206,39802;7,17028;54,93985;
207,298;7,18844;54,97009;
208,19802;7,20632;54,99508;
209,098;7,22424;55,02146;
209,99802;7,24228;55,05067;
210,89802;7,26028;55,08047;
211,798;7,27828;55,1127;
212,69802;7,29616;55,1377;
213,598;7,31424;55,17015;
214,49802;7,33216;55,1983;
215,39802;7,35012;55,22367;
216,298;7,36812;55,25048;
217,19802;7,38624;55,27909;
218,098;7,40416;55,30354;
218,99802;7,42212;55,33013;
219,89802;7,4402;55,36028;
220,798;7,45824;55,38627;
221,69802;7,4762;55,41359;
222,598;7,49412;55,44055;
223,49802;7,51224;55,46833;
224,39802;7,53012;55,49128;
225,298;7,54816;55,51621;
226,19802;7,5662;55,53266;
227,098;7,5842;55,55561;
227,99802;7,6022;55,58257;
228,89802;7,62008;55,60614;
229,798;7,63824;55,6369;
230,69802;7,65628;55,66061;
231,598;7,67424;55,69031;
232,49802;7,69216;55,71311;
233,39802;7,7102;55,73769;
234,298;7,72812;55,75945;
235,19802;7,74608;55,78308;
236,098;7,76416;55,81238;
236,99802;7,78216;55,83618;
237,89802;7,80012;55,86067;
238,798;7,81804;55,88172;
239,69802;7,8362;55,91193;
240,598;7,85404;55,93255;
241,49802;7,872;55,95571;
242,39802;7,88996;55,9788;
243,298;7,90816;56,00643;
244,19802;7,92612;56,02611;
245,098;7,94412;56,05181;
245,99802;7,96216;56,07866;
246,89802;7,98004;56,09794;
247,798;7,99788;56,12255;
248,69802;8,0158;56,14515;
249,598;8,034;56,17215;
250,49802;8,052;56,19125;
251,39802;8,07008;56,21546;
252,29802;8,08804;56,23983;
253,19802;8,10608;56,25987;
254,098;8,124;56,281;
254,99802;8,14196;56,30069;
255,89802;8,16008;56,32271;
256,798;8,17804;56,34503;
257,698;8,19624;56,37037;
258,59802;8,21416;56,38833;
259,49802;8,23204;56,40432;
260,39802;8,24988;56,42495;
261,298;8,2678;56,45153;
262,198;8,286;56,47661;
263,09803;8,304;56,49691;
263,99803;8,322;56,51993;
264,898;8,33996;56,54114;
265,798;8,358;56,5656;
266,698;8,37592;56,58361;
267,59803;8,39384;56,6025;
268,49803;8,41184;56,62523;
269,398;8,42992;56,6474;
270,298;8,44784;56,66882;
271,198;8,46588;56,69025;
272,09803;8,484;56,71815;
272,99803;8,502;56,73261;
273,898;8,51992;56,75269;
274,798;8,53772;56,77067;
275,698;8,55592;56,7968;
276,59803;8,57392;56,81523;
277,49803;8,592;56,83732;
278,398;8,61;56,85591;
279,298;8,62792;56,87382;
280,19803;8,64584;56,89406;
281,09803;8,6638;56,91608;
281,99803;8,682;56,93903;
282,898;8,69996;56,95655;
283,798;8,718;56,978;
284,69803;8,73596;56,99715;
285,59803;8,75404;57,01751;
286,49803;8,772;57,03675;
287,398;8,78992;57,0549;
288,298;8,808;57,07856;
289,19803;8,826;57,09622;
290,09803;8,844;57,11481;
290,99803;8,86192;57,13406;
291,898;8,88004;57,15548;
292,798;8,89796;57,17169;
293,69803;8,91592;57,1894;
294,59803;8,93396;57,20956;
295,49803;8,95208;57,23066;
296,398;8,97;57,24694;
297,298;8,98788;57,26406;
298,19803;9,00588;57,28656;
299,09803;9,0238;57,29927;
299,99803;9,04176;57,32189;
300,898;9,05972;57,33991;
301,798;9,07784;57,36186;
302,69803;9,09576;57,37628;
303,59803;9,1138;57,39543;
304,49803;9,13184;57,4151;
305,398;9,1498;57,42935;
306,298;9,16772;57,44823;
307,19803;9,18568;57,46511;
308,09803;9,20388;57,48815;
308,99803;9,22192;57,50322;
309,898;9,24008;57,52369;
310,798;9,25804;57,53854;
311,69803;9,27608;57,55636;
312,59803;9,29392;57,57069;
313,49803;9,3118;57,58982;
314,398;9,32992;57,61144;
315,298;9,34796;57,62427;
316,19803;9,366;57,64415;
317,09803;9,38396;57,65947;
317,99803;9,40204;57,68042;
318,898;9,41996;57,69394;
319,798;9,43796;57,71174;
320,69803;9,45596;57,72971;
321,59803;9,47404;57,74773;
322,49803;9,49208;57,76502;
323,398;9,51016;57,78029;
324,298;9,52828;57,79768;
325,19803;9,546;57,80584;
326,09803;9,56392;57,82461;
326,99803;9,58192;57,84516;
327,898;9,60008;57,86306;
328,798;9,61808;57,87818;
329,69803;9,63608;57,89452;
330,59803;9,65416;57,91349;
331,49803;9,672;57,92791;
332,398;9,68996;57,94447;
333,298;9,70784;57,95793;
334,19803;9,72596;57,97898;
335,09803;9,74396;57,99121;
335,99803;9,76196;58,01024;
336,898;9,77996;58,02547;
337,798;9,798;58,04077;
338,69803;9,81588;58,05461;
339,59803;9,83384;58,07073;
340,49803;9,8518;58,08982;
341,398;9,86984;58,10459;
342,298;9,88792;58,12079;
343,19803;9,90584;58,13345;
344,09803;9,92392;58,15115;
344,99803;9,94176;58,16345;
345,898;9,95976;58,18089;
346,798;9,9778;58,19889;
347,69803;9,99592;58,21532;
348,59803;10,01392;58,22799;
349,49803;10,03184;58,23992;
350,398;10,04996;58,25845;
351,298;10,06792;58,26834;
352,19803;10,08588;58,28375;
353,09803;10,10388;58,29775;
353,99803;10,12192;58,31514;
354,898;10,13988;58,32786;
355,798;10,15784;58,34252;
356,69803;10,17584;58,36115;
357,59803;10,19384;58,37137;
358,49803;10,21184;58,3826;
359,398;10,2298;58,3976;
360,298;10,248;58,41494;
361,19803;10,26596;58,42775;
362,09803;10,284;58,44288;
362,99803;10,30188;58,45462;
363,898;10,31988;58,47081;
364,798;10,33776;58,48246;
365,69803;10,35568;58,49715;
366,59803;10,3738;58,5144;
367,49803;10,3918;58,52438;
368,398;10,4098;58,54077;
369,298;10,42768;58,55136;
370,19803;10,4458;58,57115;
371,09803;10,46376;58,5812;
371,99803;10,48168;58,59435;
372,898;10,49976;58,61241;
373,798;10,51788;58,62352;
374,69803;10,53592;58,63683;
375,59803;10,55392;58,64565;
376,49803;10,57208;58,66412;
377,398;10,58996;58,67305;
378,298;10,60784;58,68375;
379,19803;10,62576;58,69805;
380,09803;10,64396;58,71598;
380,99803;10,66192;58,72709;
381,898;10,67992;58,74023;
382,798;10,698;58,75217;
383,69803;10,71592;58,76234;
384,59803;10,73392;58,77661;
385,49803;10,75184;58,78708;
386,398;10,77;58,80525;
387,298;10,78788;58,81253;
388,19803;10,80604;58,83147;
389,09803;10,82404;58,84191;
389,99803;10,84192;58,84828;
390,898;10,85968;58,8578;
391,798;10,87764;58,87322;
392,69803;10,89588;58,89257;
393,59803;10,91388;58,90091;
394,49803;10,93192;58,91471;
395,398;10,94988;58,92457;
396,298;10,96788;58,93586;
397,19803;10,9858;58,94997;
398,09803;11,00376;58,96008;
398,99803;11,02192;58,97524;
399,898;11,03992;58,98685;
400,798;11,05788;58,99707;
401,69803;11,07584;59,00769;
402,59803;11,094;59,02418;
403,49803;11,11196;59,03158;
404,398;11,12992;59,04463;
405,298;11,14792;59,05576;
406,19803;11,16596;59,06885;
407,09803;11,18392;59,07759;
407,99803;11,20196;59,08845;
408,898;11,22;59,10188;
409,79803;11,23792;59,10813;
410,69803;11,25592;59,12208;
411,59803;11,27384;59,13178;
412,49803;11,292;59,14732;
413,398;11,30996;59,15536;
414,29803;11,328;59,16859;
415,19803;11,34592;59,17915;
416,09803;11,36392;59,18789;
416,99803;11,38196;59,20001;
417,898;11,39988;59,20955;
418,79803;11,41796;59,22283;
419,69803;11,43588;59,23157;
420,59803;11,45388;59,24509;
421,49803;11,4718;59,25204;
422,398;11,48988;59,26693;
423,29803;11,50784;59,27225;
424,19803;11,5258;59,28447;
425,09803;11,54388;59,30096;
425,99803;11,562;59,30978;
426,898;11,58;59,3198;
427,79803;11,59792;59,32659;
428,69803;11,61596;59,33948;
429,59803;11,63384;59,34739;
430,49803;11,6518;59,35879;
431,398;11,66976;59,36837;
432,29803;11,68788;59,38157;
433,19803;11,7058;59,38853;
434,09803;11,7238;59,3998;
434,99803;11,74188;59,41117;
435,898;11,7598;59,41842;
436,79803;11,77776;59,42737;
437,69803;11,79568;59,43595;
438,59803;11,8138;59,45146;
439,49803;11,8318;59,45883;
440,398;11,84988;59,46984;
441,29803;11,86792;59,47786;
442,19803;11,88588;59,48409;
443,09803;11,90384;59,49363;
443,99803;11,92172;59,49975;
444,898;11,93988;59,51591;
445,79803;11,95792;59,52307;
446,69803;11,97596;59,53396;
447,59803;11,99384;59,5434;
448,49803;12,01192;59,55317;
449,398;12,02984;59,56045;
450,29803;12,04788;59,57053;
451,19803;12,06592;59,58313;
452,09803;12,08392;59,59178;
452,99803;12,10188;59,598;
453,898;12,11992;59,61044;
454,79803;12,13804;59,62134;
455,69803;12,15576;59,62166;
456,59803;12,17368;59,63325;
457,49803;12,19172;59,64509;
458,398;12,20988;59,65687;
459,29803;12,2278;59,66198;
460,19803;12,2458;59,66926;
461,09803;12,26388;59,68168;
461,99803;12,2818;59,68551;
462,898;12,29976;59,69531;
463,79803;12,31768;59,70304;
464,69803;12,33588;59,71632;
465,59803;12,35376;59,7213;
466,49803;12,3718;59,72883;
467,398;12,3898;59,73818;
468,29803;12,4078;59,7461;
469,19803;12,4258;59,7556;
470,09803;12,44372;59,76394;
470,99803;12,46176;59,77447;
471,898;12,47972;59,78211;
472,79803;12,49776;59,79354;
473,69803;12,51572;59,79807;
474,59803;12,53372;59,80668;
475,49803;12,55168;59,81358;
476,398;12,56964;59,82198;
477,29803;12,58772;59,83576;
478,19803;12,6058;59,8411;
479,09803;12,6238;59,84918;
479,99803;12,64168;59,85491;
480,898;12,6598;59,86667;
481,79803;12,67768;59,87161;
482,69803;12,69572;59,87883;
483,59803;12,71372;59,88891;
484,49803;12,7318;59,89506;
485,398;12,74976;59,89892;
486,29803;12,76764;59,90521;
487,19803;12,78572;59,91747;
488,09803;12,80364;59,92258;
488,99803;12,82172;59,93479;
489,898;12,8396;59,93878;
490,79803;12,85776;59,95064;
491,69803;12,87576;59,95443;
492,59803;12,89384;59,96217;
493,49803;12,91184;59,96863;
494,398;12,92976;59,97227;
495,29803;12,94772;59,98173;
496,19803;12,96564;59,98914;
497,09803;12,9838;60,0026;
497,99803;13,00176;60,00679;
498,898;13,0198;60,01416;
499,79803;13,03772;60,01977;
500,69803;13,05584;60,02759;
501,59803;13,07372;60,03247;
502,49803;13,09168;60,03896;
503,398;13,1098;60,05084;
504,29803;13,12784;60,05655;
505,19803;13,14592;60,06363;
506,09803;13,16388;60,06786;
506,99803;13,18196;60,07903;
507,898;13,19984;60,08127;
508,79803;13,21772;60,08783;
509,69803;13,23568;60,0953;
510,59803;13,25384;60,10448;
511,49803;13,27176;60,11037;
512,398;13,2898;60,1153;
513,29803;13,30788;60,12678;
514,198;13,32576;60,12874;
515,09803;13,34376;60,1385;
515,99806;13,36172;60,14465;
516,898;13,37984;60,15171;
517,79803;13,39768;60,15368;
518,698;13,41588;60,16649;
519,59803;13,43396;60,17143;
520,49806;13,45192;60,17551;
521,398;13,46968;60,17597;
522,29803;13,48752;60,18426;
523,198;13,5058;60,20018;
524,09803;13,52376;60,20055;
524,99806;13,54184;60,21019;
525,898;13,55984;60,2134;
526,79806;13,57788;60,21876;
527,698;13,5958;60,22365;
528,598;13,61376;60,22917;
529,49806;13,63188;60,24204;
530,398;13,64988;60,24515;
531,29806;13,66788;60,25179;
532,198;13,68584;60,2549;
533,098;13,70392;60,26356;
533,99806;13,72188;60,2666;
534,898;13,73992;60,27282;
535,79806;13,75796;60,27913;
536,698;13,77592;60,28218;
537,598;13,79392;60,28793;
538,49806;13,81184;60,29177;
539,398;13,82988;60,2947;
540,29806;13,84764;60,29568;
541,198;13,86568;60,30961;
542,098;13,88364;60,31488;
542,99806;13,9018;60,32464;
543,898;13,9198;60,3278;
544,79806;13,9378;60,33233;
545,698;13,95584;60,33915;
546,598;13,97376;60,34006;
547,49806;13,99172;60,34893;
548,398;14,00968;60,35331;
549,29806;14,02784;60,36232;
550,198;14,0458;60,36464;
551,098;14,06384;60,36907;
551,99806;14,08172;60,37216;
552,898;14,09976;60,37931;
553,79806;14,11768;60,38385;
554,698;14,13564;60,38976;
555,598;14,1538;60,39957;
556,49806;14,17176;60,40358;
557,398;14,1898;60,41285;
558,29806;14,20768;60,41166;
559,198;14,22576;60,41954;
560,098;14,2436;60,41867;
560,99806;14,26156;60,42608;
561,898;14,27964;60,4344;
562,79806;14,29768;60,4395;
563,698;14,31564;60,44515;
564,598;14,3336;60,44761;
565,49806;14,35168;60,45753;
566,398;14,3696;60,4584;
567,29806;14,3876;60,46294;
568,198;14,40556;60,46761;
569,098;14,42368;60,47371;
569,99806;14,44164;60,47782;
570,898;14,45976;60,48311;
571,79806;14,47776;60,49005;
572,698;14,49568;60,49153;
573,598;14,51368;60,49656;
574,49806;14,53148;60,49739;
575,398;14,54964;60,50795;
576,29806;14,5676;60,50735;
577,198;14,58572;60,51513;
578,098;14,60368;60,51764;
578,99806;14,62172;60,52325;
579,898;14,63964;60,52551;
580,79806;14,65756;60,52848;
581,698;14,67564;60,53955;
582,598;14,69364;60,54016;
583,49806;14,71156;60,54188;
584,398;14,72972;60,55065;
585,29806;14,74792;60,55266;
586,198;14,76572;60,55142;
587,098;14,78352;60,55468;
587,99806;14,80156;60,56416;
588,898;14,81972;60,57146;
589,79806;14,83768;60,57378;
590,698;14,85564;60,57569;
591,598;14,8738;60,58338;
592,49806;14,89168;60,58145;
593,398;14,90968;60,58761;
594,29806;14,92764;60,59052;
595,198;14,9458;60,59762;
596,098;14,96372;60,59825;
596,99806;14,98168;60,60297;
597,898;14,99976;60,61223;
598,79806;15,01768;60,6091;
599,698;15,03568;60,61498;
600,598;15,05368;60,61855;
601,49806;15,07176;60,6225;
602,398;15,08964;60,62347;
603,29806;15,10768;60,62936;
604,19806;15,12568;60,63347;
605,098;15,1436;60,63606;
605,99806;15,16152;60,64193;
606,898;15,17948;60,64662;
607,79806;15,19764;60,65373;
608,69806;15,2156;60,65302;
609,598;15,23372;60,658;
610,49806;15,2516;60,65688;
611,398;15,26964;60,6634;
612,29806;15,28752;60,66162;
613,19806;15,30556;60,66823;
614,098;15,32372;60,67665;
614,99806;15,34176;60,67827;
615,898;15,35968;60,67984;
616,79806;15,37764;60,67838;
617,69806;15,39576;60,68624;
618,598;15,41372;60,68695;
619,49806;15,43172;60,69211;
620,398;15,44972;60,69462;
621,29806;15,46792;60,69841;
622,19806;15,48584;60,70331;
623,098;15,50388;60,70379;
623,99806;15,52192;60,70805;
624,898;15,53972;60,70803;
625,79806;15,55776;60,71209;
626,69806;15,57568;60,71469;
627,598;15,59384;60,72156;
628,49806;15,61176;60,72005;
629,398;15,62972;60,7252;
630,29806;15,64768;60,72664;
631,19806;15,66564;60,73162;
632,098;15,6836;60,73387;
632,99806;15,7016;60,7356;
633,898;15,71972;60,74299;
634,79806;15,73772;60,74014;
635,69806;15,7558;60,74749;
636,598;15,77376;60,74654;
637,49806;15,79184;60,7511;
638,398;15,80964;60,75026;
639,29806;15,82752;60,75504;
640,19806;15,8456;60,75982;
641,098;15,86364;60,76359;
641,99806;15,88168;60,7657;
642,898;15,89956;60,76633;
643,79806;15,91768;60,77241;
644,69806;15,93556;60,77204;
645,598;15,95356;60,77768;
646,49806;15,97156;60,78051;
647,398;15,98972;60,78622;
648,29806;16,00764;60,78499;
649,19806;16,02568;60,78768;
650,098;16,04392;60,79503;
650,99806;16,06184;60,78939;
651,898;16,07964;60,78885;
652,79806;16,09756;60,79289;
653,69806;16,11576;60,80163;
654,598;16,13372;60,80033;
655,49806;16,1518;60,80455;
656,398;16,16976;60,80707;
657,29806;16,18772;60,80418;
658,19806;16,20568;60,80787;
659,098;16,22364;60,81004;
659,99806;16,2418;60,8166;
660,898;16,25972;60,81523;
661,79806;16,27768;60,81691;
662,69806;16,2956;60,81859;
663,598;16,31364;60,82481;
664,49806;16,33156;60,8261;
665,398;16,3496;60,82639;
666,29806;16,3678;60,83157;
667,19806;16,38568;60,82817;
668,098;16,40368;60,83295;
668,99806;16,4216;60,83131;
669,898;16,43972;60,8393;
670,79806;16,45756;60,8366;
671,69806;16,47556;60,84116;
672,598;16,49356;60,84815;
673,49806;16,51168;60,84954;
674,398;16,5296;60,84962;
675,29806;16,5476;60,84975;
676,19806;16,56572;60,85497;
677,098;16,58356;60,85234;
677,99806;16,6016;60,85539;
678,898;16,6196;60,85856;
679,79806;16,63776;60,86271;
680,69806;16,65572;60,86033;
681,598;16,67368;60,86379;
682,49806;16,69168;60,86566;
683,398;16,70956;60,86211;
684,29806;16,7276;60,86635;
685,19806;16,74564;60,86603;
686,098;16,7638;60,87325;
686,99806;16,78176;60,87099;
687,898;16,79984;60,87584;
688,79806;16,8178;60,87542;
689,69806;16,83576;60,87659;
690,598;16,85364;60,87643;
691,49806;16,87164;60,87816;
692,398;16,88976;60,88294;
693,29806;16,9078;60,87986;
694,19806;16,92576;60,88241;
695,098;16,94368;60,881;
695,99806;16,96172;60,88673;
696,898;16,9796;60,88526;
697,79806;16,9976;60,88973;
698,69806;17,01564;60,89059;
699,598;17,03376;60,892;
700,49806;17,05176;60,88973;
701,398;17,0698;60,88995;
702,29806;17,08788;60,8948;
703,19806;17,10576;60,89154;
704,098;17,12372;60,89401;
704,99806;17,1416;60,8938;
705,898;17,15972;60,89936;
706,79806;17,17764;60,89748;
707,69806;17,19576;60,8983;
708,598;17,21376;60,90172;
709,49806;17,23168;60,89959;
710,398;17,24972;60,90066;
711,29806;17,26764;60,90335;
712,19806;17,28588;60,90802;
713,098;17,3038;60,90297;
713,99806;17,32184;60,90688;
714,898;17,33984;60,90732;
715,79806;17,35796;60,90807;
716,69806;17,37588;60,90447;
717,598;17,3936;60,90224;
718,49806;17,41176;60,91189;
719,398;17,4298;60,91105;
720,29806;17,44776;60,91203;
721,19806;17,46572;60,9103;
722,098;17,48376;60,91443;
722,99806;17,50172;60,91508;
723,898;17,51968;60,91318;
724,79806;17,53772;60,91843;
725,69806;17,55584;60,91723;
726,598;17,57376;60,91563;
727,49806;17,59172;60,91613;
728,398;17,60976;60,91807;
729,29806;17,62768;60,9161;
730,19806;17,64572;60,91924;
731,098;17,66372;60,91785;
731,99806;17,68184;60,92452;
732,898;17,69968;60,91762;
733,79806;17,71768;60,9193;
734,69806;17,7358;60,92378;
735,598;17,75368;60,91818;
736,49806;17,77168;60,92057;
737,398;17,7896;60,92067;
738,29806;17,80776;60,92562;
739,19806;17,82572;60,92288;
740,098;17,84372;60,92726;
740,99806;17,86172;60,92427;
741,898;17,87972;60,9242;
742,79806;17,8976;60,92251;
743,69806;17,91564;60,92452;
744,598;17,93384;60,92961;
745,49806;17,9518;60,92532;
746,398;17,96976;60,92656;
747,29806;17,98764;60,92422;
748,19806;18,00568;60,92882;
749,098;18,02356;60,92557;
749,99806;18,04164;60,92831;
750,898;18,05972;60,92827;
751,79806;18,07776;60,92647;
752,69806;18,0958;60,92619;
753,598;18,11372;60,92269;
754,49806;18,1318;60,92747;
755,398;18,14964;60,92371;
756,29806;18,16756;60,92477;
757,19806;18,18556;60,92621;
758,098;18,20372;60,92848;
758,99806;18,22164;60,92457;
759,898;18,23956;60,92188;
760,79806;18,25764;60,927;
761,69806;18,2756;60,92323;
762,598;18,29364;60,92639;
763,49806;18,31156;60,92656;
764,398;18,32972;60,92961;
765,29806;18,34764;60,92519;
766,19806;18,36576;60,92714;
767,098;18,3838;60,92566;
767,99806;18,40184;60,92353;
768,898;18,41976;60,92175;
769,79806;18,43768;60,92038;
770,69806;18,45576;60,92505;
771,598;18,47372;60,92142;
772,49806;18,49172;60,9243;
773,398;18,50968;60,92387;
774,29806;18,52772;60,92266;
775,19806;18,54564;60,92073;
776,098;18,56364;60,92247;
776,99806;18,58176;60,92588;
777,898;18,59984;60,92234;
778,79806;18,61776;60,91866;
779,69806;18,63572;60,91748;
780,598;18,65396;60,92517;
781,49806;18,67184;60,91928;
782,398;18,68968;60,9144;
783,29806;18,70748;60,91568;
784,19806;18,72564;60,91741;
785,098;18,74368;60,91723;
785,99806;18,76168;60,91483;
786,898;18,77976;60,91685;
787,79806;18,79768;60,91192;
788,69806;18,81568;60,91297;
789,598;18,8336;60,90999;
790,49806;18,85172;60,91505;
791,398;18,86968;60,909;
792,29806;18,88772;60,91017;
793,19806;18,90572;60,90971;
794,098;18,92372;60,90699;
794,99806;18,94168;60,90564;
795,898;18,95972;60,90565;
796,79806;18,97788;60,91002;
797,69806;18,9958;60,90338;
798,598;19,01376;60,90115;
799,49806;19,03164;60,89986;
800,398;19,04976;60,90199;
801,29806;19,06764;60,8956;
802,19806;19,0856;60,89744;
803,098;19,10372;60,90071;
803,99806;19,12168;60,89574;
804,898;19,13972;60,89492;
805,79806;19,15768;60,8927;
806,69806;19,17572;60,89587;
807,598;19,19364;60,89233;
808,49806;19,2116;60,89199;
809,398;19,22968;60,89351;
810,29806;19,24784;60,89096;
811,19806;19,26576;60,88784;
812,098;19,28376;60,88521;
812,99806;19,30176;60,88413;
813,898;19,31968;60,88301;
814,79806;19,33768;60,88195;
815,69806;19,35568;60,88488;
816,598;19,37384;60,88101;
817,49806;19,39176;60,87672;
818,398;19,40984;60,87745;
819,29806;19,42784;60,87335;
820,19806;19,44576;60,87089;
821,098;19,46372;60,86965;
821,99806;19,48164;60,87033;
822,898;19,4998;60,87305;
823,79806;19,51772;60,86723;
824,69806;19,53572;60,8703;
825,598;19,55364;60,86228;
826,49806;19,57168;60,86254;
827,398;19,58964;60,85972;
828,29806;19,60764;60,85761;
829,19806;19,62576;60,86078;
830,098;19,64376;60,85639;
830,99806;19,66172;60,85476;
831,898;19,67976;60,85309;
832,79806;19,69792;60,85171;
833,69806;19,7158;60,84744;
834,598;19,73376;60,84488;
835,49806;19,75176;60,84332;
836,398;19,76976;60,84186;
837,29806;19,78772;60,83854;
838,19806;19,80568;60,83711;
839,098;19,82384;60,83812;
839,99806;19,84168;60,83274;
840,898;19,85968;60,83183;
841,79806;19,87764;60,83097;
842,69806;19,89584;60,83124;
843,598;19,91376;60,82292;
844,49806;19,9318;60,8216;
845,398;19,94984;60,82257;
846,29806;19,96792;60,81774;
847,19806;19,98584;60,81549;
848,098;20,0036;60,80826;
848,99806;20,02176;60,81367;
849,898;20,03972;60,80972;
850,79806;20,0578;60,80753;
851,69806;20,07576;60,803;
852,598;20,0938;60,80135;
853,49806;20,11168;60,79677;
854,398;20,1296;60,79533;
855,29806;20,14776;60,79857;
856,19806;20,16568;60,79432;
857,098;20,18372;60,79516;
857,99806;20,20164;60,78818;
858,89806;20,21972;60,78811;
859,79806;20,23768;60,7825;
860,69806;20,25568;60,78173;
861,598;20,2738;60,78083;
862,49806;20,29192;60,77775;
863,39806;20,30976;60,77057;
864,29806;20,32776;60,76897;
865,19806;20,34584;60,77164;
866,098;20,36372;60,76474;
866,99806;20,38168;60,75943;
867,89806;20,39964;60,7594;
868,79806;20,4178;60,7571;
869,69806;20,43568;60,75199;
870,598;20,45372;60,75173;
871,49806;20,47176;60,74935;
872,39806;20,48964;60,74309;
873,29806;20,5076;60,73993;
874,19806;20,52548;60,73794;
875,098;20,54372;60,74132;
875,99806;20,56168;60,73383;
876,89806;20,57968;60,73188;
877,79806;20,59764;60,72499;
878,69806;20,61564;60,72319;
879,598;20,63352;60,71952;
880,49806;20,65152;60,71587;
881,39806;20,6696;60,71724;
882,29806;20,68772;60,7128;
883,19806;20,70572;60,70853;
884,098;20,72376;60,7049;
884,99806;20,74184;60,70005;
885,89806;20,7596;60,69216;
886,79806;20,77756;60,69015;
887,69806;20,79564;60,69074;
888,598;20,81372;60,6869;
889,49806;20,83168;60,68171;
890,39806;20,84964;60,67663;
891,29806;20,86776;60,67629;
892,19806;20,8856;60,66571;
893,098;20,9036;60,66548;
893,99806;20,92164;60,66241;
894,89806;20,93976;60,65993;
895,79806;20,95772;60,6539;
896,69806;20,97572;60,64959;
897,598;20,99384;60,65011;
898,49806;21,0118;60,64226;
899,39806;21,0298;60,63825;
900,29806;21,04772;60,6317;
901,19806;21,06588;60,63058;
902,098;21,08372;60,62351;
902,99806;21,10176;60,62338;
903,89806;21,11964;60,61602;
904,79806;21,13768;60,61181;
905,69806;21,15556;60,60675;
906,598;21,17352;60,6052;
907,49806;21,19176;60,60682;
908,39806;21,20976;60,59711;
909,29806;21,22776;60,59204;
910,19806;21,24568;60,58268;
911,098;21,26384;60,58472;
911,99806;21,28184;60,57774;
912,89806;21,2998;60,57058;
913,79806;21,31768;60,56541;
914,69806;21,33576;60,56372;
915,598;21,35372;60,55871;
916,49806;21,37176;60,54819;
917,39806;21,38984;60,54933;
918,29806;21,40776;60,53873;
919,19806;21,42572;60,5356;
920,098;21,44368;60,5309;
920,99806;21,46184;60,52919;
921,89806;21,47976;60,52035;
922,79806;21,49772;60,51707;
923,69806;21,5158;60,51294;
924,598;21,53372;60,5041;
925,49806;21,55172;60,50125;
926,39806;21,56976;60,49452;
927,29806;21,588;60,49454;
928,19806;21,60596;60,48215;
929,098;21,62388;60,47732;
929,99806;21,64188;60,47221;
930,89806;21,65988;60,467;
931,79806;21,6778;60,46015;
932,69806;21,69576;60,45226;
933,598;21,71392;60,45291;
934,49806;21,73192;60,44222;
935,39806;21,74996;60,43553;
936,29806;21,76792;60,42851;
937,19806;21,78596;60,42336;
938,098;21,8038;60,41214;
938,99806;21,82176;60,40743;
939,89806;21,83988;60,4076;
940,79806;21,85792;60,39827;
941,69806;21,87592;60,3909;
942,598;21,89384;60,3812;
943,49806;21,91192;60,37779;
944,39806;21,92972;60,36547;
945,29806;21,94768;60,36171;
946,19806;21,96572;60,35809;
947,098;21,98384;60,34954;
947,99806;22,0018;60,34158;
948,89806;22,0198;60,33468;
949,79806;22,03792;60,32999;
950,69806;22,0558;60,31806;
951,598;22,07372;60,30944;
952,49806;22,09164;60,30413;
953,39806;22,1098;60,30043;
954,29806;22,12772;60,28753;
955,19806;22,14576;60,28284;
956,098;22,16368;60,27368;
956,99806;22,18164;60,26626;
957,89806;22,1996;60,25546;
958,79806;22,21756;60,24786;
959,69806;22,2358;60,24604;
960,598;22,25376;60,23189;
961,49806;22,2718;60,2267;
962,39806;22,28976;60,2145;
963,29806;22,30788;60,20864;
964,19806;22,3258;60,19704;
965,098;22,34372;60,1868;
965,99806;22,36184;60,18096;
966,89806;22,37976;60,16646;
967,79806;22,39776;60,15921;
968,69806;22,41576;60,14889;
969,598;22,43388;60,14171;
970,49806;22,45172;60,12848;
971,39806;22,46968;60,11916;
972,29806;22,48768;60,11043;
973,19806;22,50588;60,10309;
974,098;22,52376;60,08828;
974,99806;22,54172;60,07608;
975,89806;22,55976;60,06953;
976,79806;22,5778;60,05873;
977,69806;22,59588;60,04994;
978,598;22,61372;60,03409;
979,49806;22,63176;60,02779;
980,39806;22,64968;60,01444;
981,29806;22,66772;60,00708;
982,19806;22,68572;59,99447;
983,098;22,70372;59,97805;
983,99806;22,72172;59,96742;
984,89806;22,73972;59,95409;
985,79806;22,75788;59,9466;
986,69806;22,7758;59,92994;
987,598;22,79388;59,92075;
988,49806;22,81176;59,90518;
989,39806;22,82984;59,89594;
990,29806;22,84768;59,87961;
991,19806;22,86572;59,86791;
992,098;22,88392;59,85856;
992,99806;22,90196;59,84157;
993,89806;22,91984;59,82338;
994,79806;22,93772;59,80958;
995,69806;22,95584;59,80085;
996,598;22,97376;59,7835;
997,49806;22,99172;59,7711;
998,39806;23,00972;59,75859;
999,29806;23,02784;59,74175;
1000,19806;23,0458;59,72525;
1001,098;23,0638;59,70951;
1001,99806;23,08188;59,6994;
1002,89806;23,09972;59,68015;
1003,79806;23,11772;59,66693;
1004,69806;23,13568;59,6526;
1005,598;23,15392;59,64196;
1006,49806;23,17176;59,62033;
1007,39806;23,18976;59,60457;
1008,29806;23,20788;59,58983;
1009,19806;23,2258;59,56738;
1010,098;23,24376;59,5496;
1010,99806;23,26176;59,53495;
1011,89806;23,28;59,52296;
1012,79806;23,29792;59,49956;
1013,69806;23,31596;59,4849;
1014,598;23,33396;59,46647;
1015,49806;23,352;59,44944;
1016,39806;23,36988;59,42701;
1017,29806;23,38784;59,40989;
1018,19806;23,406;59,39798;
1019,098;23,424;59,3769;
1019,99806;23,442;59,35691;
1020,89806;23,45992;59,33647;
1021,79806;23,47796;59,31826;
1022,69806;23,49584;59,29745;
1023,598;23,5138;59,28047;
1024,49806;23,53184;59,26224;
1025,39806;23,54992;59,23924;
1026,29812;23,56784;59,21641;
1027,198;23,5858;59,19675;
1028,098;23,60396;59,18095;
1028,99806;23,62188;59,15471;
1029,89806;23,63988;59,1342;
1030,79812;23,65784;59,11111;
1031,698;23,67596;59,09353;
1032,598;23,6938;59,06591;
1033,49806;23,7118;59,04637;
1034,39806;23,72988;59,02594;
1035,29812;23,74784;58,99723;
1036,198;23,7658;58,97475;
1037,098;23,78376;58,95117;
1037,99806;23,80188;58,93285;
1038,89806;23,81988;58,90705;
1039,79812;23,83792;58,88336;
1040,698;23,85584;58,85607;
1041,598;23,87388;58,8346;
1042,49806;23,89196;58,8097;
1043,39806;23,90996;58,78307;
1044,29812;23,92788;58,75719;
1045,198;23,94584;58,73308;
1046,098;23,96392;58,70959;
1046,99806;23,98188;58,68021;
1047,89806;24;58,65846;
1048,79812;24,01788;58,62663;
1049,698;24,03588;58,60169;
1050,598;24,05396;58,57708;
1051,498;24,07204;58,5491;
1052,39812;24,09004;58,51967;
1053,29812;24,10804;58,49118;
1054,198;24,12608;58,4658;
1055,098;24,144;58,43401;
1055,998;24,162;58,40797;
1056,89812;24,18;58,3809;
1057,79812;24,19824;58,35302;
1058,698;24,2162;58,31949;
1059,598;24,23408;58,28416;
1060,498;24,25208;58,2601;
1061,39812;24,27004;58,22925;
1062,29812;24,28804;58,19945;
1063,198;24,30596;58,17;
1064,098;24,32416;58,14278;
1064,998;24,34208;58,10705;
1065,89812;24,36008;58,07572;
1066,79812;24,37804;58,04387;
1067,698;24,39604;58,0147;
1068,598;24,41396;57,97853;
1069,498;24,43192;57,94787;
1070,39812;24,45008;57,92116;
1071,29812;24,46812;57,88267;
1072,198;24,48612;57,85115;
1073,098;24,50404;57,81454;
1073,998;24,52208;57,78178;
1074,89812;24,53992;57,74572;
1075,79812;24,55796;57,71132;
1076,698;24,57604;57,6804;
1077,598;24,59412;57,64255;
1078,498;24,61212;57,60614;
1079,39812;24,63008;57,56981;
1080,29812;24,64824;57,53575;
1081,198;24,66612;57,49461;
1082,098;24,684;57,4585;
1082,998;24,702;57,4212;
1083,89812;24,72012;57,38706;
1084,79812;24,73804;57,34562;
1085,698;24,75604;57,3062;
1086,598;24,77408;57,27134;
1087,498;24,792;57,22739;
1088,39812;24,80992;57,19142;
1089,29812;24,82788;57,15335;
1090,198;24,84604;57,11758;
1091,098;24,86396;57,07219;
1091,998;24,88196;57,03195;
1092,89812;24,89996;56,99255;
1093,79812;24,91808;56,95118;
1094,698;24,93604;56,90845;
1095,598;24,954;56,86535;
1096,498;24,97216;56,82624;
1097,39812;24,99008;56,77922;
1098,29812;25,00808;56,73931;
1099,198;25,02604;56,69037;
1100,098;25,04416;56,65014;
1100,998;25,06208;56,59923;
1101,89812;25,08008;56,55888;
1102,79812;25,09816;56,51729;
1103,698;25,11628;56,47045;
1104,598;25,1342;56,42293;
1105,498;25,1522;56,37416;
1106,39812;25,17028;56,33301;
1107,29812;25,18832;56,28319;
1108,198;25,20636;56,23496;
1109,098;25,22432;56,18689;
1109,998;25,24228;56,13732;
1110,89812;25,2602;56,09108;
1111,79812;25,27824;56,04293;
1112,698;25,29632;55,99571;
1113,598;25,31424;55,94311;
1114,498;25,3322;55,89501;
1115,39812;25,35012;55,84292;
1116,29812;25,36828;55,79231;
1117,198;25,3862;55,73643;
1118,098;25,40424;55,68898;
1118,998;25,42224;55,63481;
1119,89812;25,4402;55,58027;
1120,79812;25,45808;55,52572;
1121,698;25,47608;55,47516;
1122,598;25,49432;55,42756;
1123,498;25,51228;55,36401;
1124,39812;25,53032;55,31302;
1125,29812;25,5482;55,25013;
1126,198;25,56632;55,19812;
1127,098;25,58428;55,13963;
1127,998;25,6022;55,08083;
1128,89812;25,62028;55,02697;
1129,79812;25,63836;54,9654;
1130,698;25,65636;54,90639;
1131,598;25,67428;54,84784;
1132,498;25,69248;54,78854;
1133,39812;25,71032;54,72168;
1134,29812;25,72828;54,66269;
1135,198;25,74632;54,60109;
1136,098;25,7644;54,54053;
1136,998;25,7824;54,4753;
1137,89812;25,8004;54,4107;
1138,79812;25,81848;54,35071;
1139,698;25,8364;54,28364;
1140,598;25,85432;54,21919;
1141,498;25,87232;54,15187;
1142,39812;25,89052;54,08938;
1143,29812;25,90848;54,01881;
1144,198;25,92652;53,95049;
1145,098;25,94452;53,88307;
1145,998;25,96252;53,81187;
1146,89812;25,9804;53,74189;
1147,79812;25,99832;53,6744;
1148,698;26,01648;53,60634;
1149,598;26,03444;53,52857;
1150,498;26,05248;53,45775;
1151,39812;26,07048;53,38269;
1152,29812;26,08848;53,30735;
1153,198;26,1064;53,23192;
1154,098;26,12436;53,15917;
1154,998;26,14248;53,08863;
1155,89812;26,16056;53,00919;
1156,79812;26,17852;52,92999;
1157,698;26,19648;52,848;
1158,598;26,21464;52,77289;
1159,498;26,2326;52,69028;
1160,39812;26,2506;52,6099;
1161,29812;26,26856;52,52926;
1162,198;26,28668;52,44632;
1163,098;26,30448;52,36108;
1163,998;26,32248;52,27883;
1164,89812;26,34056;52,19716;
1165,79812;26,35848;52,10521;
1166,698;26,37648;52,01893;
1167,598;26,39444;51,93158;
1168,498;26,41264;51,84603;
1169,39812;26,4306;51,75281;
1170,29812;26,44864;51,66201;
1171,198;26,46664;51,56977;
1172,098;26,48464;51,47367;
1172,998;26,50272;51,38129;
1173,89812;26,52072;51,28417;
1174,79812;26,53872;51,18457;
1175,698;26,55664;51,08522;
1176,598;26,57468;50,98971;
1177,498;26,59264;50,88768;
1178,39812;26,61072;50,78471;
1179,29812;26,62864;50,68107;
1180,198;26,64664;50,57721;
1181,098;26,66472;50,47462;
1181,998;26,68272;50,36339;
1182,89812;26,70072;50,25011;
1183,79812;26,71868;50,1357;
1184,698;26,73676;50,02393;
1185,598;26,75472;49,90401;
1186,498;26,77264;49,78736;
1187,39812;26,79068;49,66775;
1188,29812;26,80884;49,54022;
1189,198;26,82684;49,39883;
1190,098;26,84476;49,24058;
1190,998;26,8628;49,05246;
1191,89812;26,8808;48,58574;
1192,32012;26,88928;47,66183;
1192,448;26,89192;46,63008;
1192,47012;26,89352;37,3807;
1192,478;26,89424;26,94243;