File: tensile_test_data/primary_data/Zd2.csv
Time;Crosshead separation;Load;Extensometer elongation
(sec);(mm);(kN);(%)
0;-0,00044;0,27944;0,09702
0,87;0,03648;0,76927;0,09881
1,416;0,11092;1,68929;0,10253
2,086;0,2592;2,21466;0,10463
2,426;0,35784;2,9398;0,10765
2,846;0,49764;3,87131;0,11176
3,138;0,60436;4,79471;0,11549
3,396;0,70352;5,73685;0,11935
3,614;0,78988;6,6704;0,12341
3,804;0,8666;7,6134;0,12722
3,984;0,94;8,57007;0,13106
4,164;1,0138;9,55725;0,1352
4,33;1,08212;10,49289;0,13878
4,492;1,14916;11,43957;0,14277
4,654;1,21552;12,38693;0,14671
4,816;1,28228;13,35241;0,15072
4,978;1,34844;14,32349;0,15489
5,14;1,4148;15,29912;0,15877
5,302;1,48072;16,28485;0,16293
5,464;1,54656;17,27393;0,16701
5,626;1,61208;18,27179;0,17106
5,788;1,67748;19,27155;0,17532
5,95;1,7424;20,26814;0,17928
6,112;1,80712;21,27119;0,18347
6,274;1,87128;22,26392;0,1877
6,434;1,93476;23,25701;0,19185
6,596;1,99836;24,2551;0,19602
6,758;2,0618;25,25029;0,20016
6,92;2,12468;26,24702;0,20455
7,082;2,18724;27,23389;0,20872
7,244;2,24904;28,22133;0,21291
7,406;2,31036;29,20438;0,2174
7,568;2,3712;30,17217;0,22166
7,73;2,43176;31,15616;0,22593
7,892;2,49116;32,11412;0,23034
8,054;2,55008;33,06302;0,2348
8,216;2,60848;34,01813;0,23929
8,378;2,66572;34,94312;0,24381
8,54;2,72236;35,86001;0,24852
8,708;2,78;36,79704;0,25337
8,882;2,83876;37,74816;0,25866
9,062;2,898;38,70085;0,26406
9,242;2,95592;39,63154;0,2698
9,434;3,01584;40,57844;0,27558
9,632;3,07616;41,51338;0,28159
9,842;3,13768;42,4442;0,2888
10,074;3,20212;43,37987;0,297
10,338;3,27028;44,30623;0,30664
10,688;3,3512;45,23279;0,31956
11,412;3,48744;45,9384;0,34724
12,312;3,57492;46,0171;0,38308
13,212;3,6246;46,23311;0,40342
14,098;3,67352;46,47734;0,42994
14,998;3,7142;46,71172;0,45254
15,898;3,75328;46,92877;0,47566
16,798;3,78912;47,11738;0,49762
17,698;3,8298;47,43796;0,5185
18,598;3,86312;47,46898;0,54348
19,498;3,8954;47,65712;0,56616
20,398;3,9252;47,77369;0,58884
21,298;3,95408;47,90577;0,61119
22,198;3,98128;47,98985;0,63385
23,098;4,01376;48,20977;0,65577
23,998;4,03468;48,04111;0,67986
24,898;4,05752;48,10717;0,70235
25,798;4,07832;48,10671;0,7253
26,698;4,09744;48,10036;0,74778
27,598;4,11544;48,08618;0,77045
28,498;4,13272;48,08144;0,79302
29,398;4,14852;48,02944;0,81608
30,298;4,16376;48,01657;0,8381
31,198;4,17876;47,99735;0,86092
32,098;4,19284;47,97537;0,88317
32,998;4,20696;47,95441;0,90609
33,898;4,2206;47,94008;0,92844
34,798;4,23408;47,92867;0,95098
35,698;4,2474;47,92188;0,97337
36,598;4,2608;47,92292;0,99585
37,498;4,27416;47,92089;1,01868
38,398;4,2872;47,92211;1,04093
39,298;4,30024;47,91823;1,0634
40,198;4,31296;47,9109;1,08607
41,098;4,32564;47,91155;1,10833
41,998;4,33824;47,90042;1,13105
42,898;4,35076;47,89981;1,15326
43,798;4,36304;47,8889;1,17579
44,698;4,37532;47,88277;1,19815
45,598;4,38756;47,87931;1,22057
46,498;4,40004;47,87662;1,24351
47,398;4,412;47,86821;1,26581
48,298;4,42436;47,8827;1,28826
49,198;4,43684;47,89571;1,3108
50,098;4,44888;47,89012;1,33311
50,998;4,46144;47,91146;1,35566
51,898;4,4734;47,89745;1,37835
52,798;4,48536;47,89035;1,40072
53,698;4,49688;47,85986;1,42344
54,598;4,508;47,81263;1,44595
55,498;4,51868;47,75375;1,4684
56,398;4,53032;47,73728;1,4912
57,298;4,54228;47,74314;1,51348
58,198;4,55508;47,80201;1,53553
59,098;4,5688;47,8915;1,55787
59,998;4,58272;47,98377;1,57997
60,898;4,59752;48,09782;1,60273
61,798;4,61216;48,19433;1,62492
62,698;4,62756;48,29988;1,64703
63,598;4,64328;48,392;1,66942
64,498;4,66028;48,50408;1,69191
65,398;4,68076;48,67498;1,70934
66,29801;4,69928;48,63097;1,73753
67,19801;4,71828;48,77107;1,7592
68,098;4,73716;48,83505;1,78173
68,998;4,7568;48,92138;1,80396
69,898;4,77708;48,99463;1,82644
70,79801;4,79852;49,08579;1,84921
71,69801;4,81912;49,14614;1,87124
72,59801;4,8412;49,23433;1,89371
73,498;4,86396;49,31892;1,9163
74,398;4,88612;49,38191;1,93834
75,29801;4,90932;49,46714;1,96071
76,19801;4,93316;49,55428;1,98347
77,09801;4,95692;49,62954;2,00591
77,998;4,98068;49,70295;2,02842
78,898;5,00496;49,78232;2,05089
79,79801;5,02964;49,87192;2,07346
80,69801;5,05444;49,95152;2,09616
81,59801;5,078;50,00485;2,1181
82,484;5,10892;50,19739;2,1406
83,384;5,13152;50,17421;2,16301
84,28401;5,15576;50,25837;2,18543
85,18401;5,18028;50,34887;2,2078
86,08401;5,20512;50,42655;2,23033
86,984;5,22972;50,49737;2,25308
87,884;5,25428;50,58308;2,27528
88,78401;5,27836;50,64915;2,29766
89,68401;5,30308;50,72808;2,32005
90,58401;5,32788;50,80097;2,34279
91,484;5,35264;50,88319;2,36517
92,384;5,37732;50,95916;2,38772
93,28401;5,40172;51,01993;2,41016
94,18401;5,42632;51,09809;2,43254
95,08401;5,45132;51,18042;2,45514
95,984;5,47572;51,24243;2,4774
96,884;5,5076;51,42471;2,50034
97,78401;5,52972;51,37212;2,52251
98,68401;5,55484;51,46376;2,5452
99,58401;5,57948;51,53884;2,56748
100,484;5,60396;51,6037;2,58989
101,384;5,62872;51,67332;2,6124
102,28401;5,65372;51,74199;2,63487
103,18401;5,67852;51,81762;2,65721
104,08401;5,70392;51,90068;2,67961
104,98401;5,72868;51,95125;2,70239
105,884;5,75356;52,02084;2,72487
106,78401;5,7788;52,09686;2,7475
107,68401;5,80352;52,15521;2,76988
108,58401;5,82852;52,22186;2,79235
109,48401;5,8538;52,28907;2,81527
110,384;5,87848;52,35564;2,83752
111,28401;5,90916;52,57943;2,85808
112,18401;5,93164;52,45026;2,88251
113,08401;5,95628;52,5511;2,90448
113,98401;5,98112;52,61829;2,92736
114,884;6,00556;52,68279;2,94987
115,78401;6,03036;52,7527;2,97232
116,68401;6,05464;52,79759;2,99483
117,58401;6,07932;52,86889;3,01737
118,48401;6,10436;52,94126;3,0401
119,384;6,1282;52,9847;3,06205
120,28401;6,15284;53,05347;3,0847
121,18401;6,17756;53,10927;3,10736
122,08401;6,20184;53,17199;3,12967
122,98401;6,22684;53,24811;3,15213
123,884;6,25116;53,29096;3,17467
124,78401;6,27576;53,34794;3,19723
125,68401;6,30564;53,55299;3,2183
126,58401;6,32816;53,44594;3,2425
127,48401;6,35264;53,53068;3,26495
128,384;6,37644;53,5693;3,28755
129,28402;6,4004;53,64143;3,30941
130,18401;6,42528;53,71054;3,3322
131,084;6,44948;53,75084;3,35475
131,98402;6,47356;53,80192;3,37711
132,884;6,49864;53,87124;3,39967
133,78402;6,52312;53,9212;3,42222
134,684;6,5474;53,96755;3,4446
135,584;6,57188;54,01805;3,46718
136,48402;6,59656;54,08228;3,48957
137,384;6,62152;54,14339;3,51206
138,28402;6,64596;54,18145;3,53449
139,184;6,67072;54,23492;3,5569
140,084;6,70152;54,42675;3,57857
140,98402;6,72396;54,31561;3,60225
141,884;6,74892;54,40308;3,62464
142,78402;6,7732;54,43284;3,64711
143,684;6,79788;54,48973;3,66945
144,584;6,82332;54,55579;3,69211
145,48402;6,84828;54,59696;3,71449
146,384;6,87336;54,64467;3,73692
147,28402;6,89876;54,69017;3,75955
148,184;6,9246;54,75023;3,78186
149,084;6,95028;54,79843;3,80449
149,98402;6,9754;54,83352;3,82664
150,884;7,00096;54,88662;3,84889
151,78402;7,02736;54,93898;3,87174
152,684;7,0534;54,98569;3,89417
153,58402;7,07964;55,0371;3,9168
154,48402;7,11068;55,14565;3,93959
155,384;7,13416;55,10411;3,96191
156,28402;7,15972;55,1594;3,98444
157,01002;7,17512;55,1295;4,002
157,91;7,18868;54,99802;4,01342
158,81002;7,20684;55,10661;4,02829
159,71;7,22476;55,1537;4,04381
160,61;7,2426;55,19239;4,05933
161,51002;7,26052;55,22534;4,07489
162,41;7,27864;55,26213;4,09078
163,31002;7,29656;55,29196;4,10649
164,21;7,31456;55,3244;4,1221
165,11;7,33264;55,36044;4,13778
166,01002;7,3506;55,38739;4,15345
166,91;7,36856;55,42122;4,16912
167,81002;7,38656;55,45296;4,18486
168,71;7,40476;55,4895;4,2008
188,458;7,41704;54,23567;
189,358;7,43488;54,93005;
190,25802;7,4528;55,36058;
191,158;7,47092;55,57225;
192,05802;7,4888;55,65112;
192,958;7,50672;55,6991;
193,858;7,52476;55,73508;
194,75802;7,54288;55,76236;
195,658;7,56092;55,78752;
196,55802;7,57892;55,81217;
197,458;7,59692;55,84226;
198,35802;7,61488;55,86515;
199,25802;7,63284;55,89169;
200,158;7,65092;55,92284;
201,05802;7,66904;55,94955;
201,958;7,68676;55,96994;
202,85802;7,70472;56,00106;
203,75802;7,72276;56,03259;
204,658;7,7408;56,06037;
205,55802;7,7588;56,08834;
206,458;7,77664;56,11446;
207,35802;7,79484;56,148;
208,25802;7,81276;56,1695;
209,158;7,83084;56,19946;
210,05802;7,84876;56,22441;
210,958;7,8668;56,25308;
211,85802;7,88468;56,28101;
212,75802;7,90264;56,30698;
213,658;7,92068;56,34246;
214,55802;7,93876;56,3677;
215,458;7,9568;56,39497;
216,35802;7,9748;56,42012;
217,25802;7,99288;56,44782;
218,158;8,01076;56,47252;
219,05802;8,0288;56,49846;
219,958;8,0468;56,52965;
220,85802;8,06484;56,5571;
221,75802;8,0828;56,5821;
222,658;8,10072;56,60925;
223,55802;8,11884;56,64018;
224,458;8,13676;56,66371;
225,35802;8,15488;56,69134;
226,25802;8,1728;56,71349;
227,158;8,19092;56,74349;
228,05802;8,20888;56,76653;
228,958;8,22684;56,79364;
229,85802;8,24488;56,82155;
230,75802;8,2628;56,84405;
231,658;8,2808;56,87435;
232,55802;8,29868;56,89374;
233,458;8,3168;56,92512;
234,35802;8,33472;56,94879;
235,25802;8,3528;56,97597;
236,158;8,37068;57,00031;
237,05802;8,3888;57,02614;
237,958;8,40672;57,04982;
238,85802;8,42472;57,07442;
239,75802;8,44288;57,10436;
240,658;8,46084;57,12392;
241,55802;8,47884;57,1511;
242,458;8,49668;57,17273;
243,35802;8,51484;57,20037;
244,25802;8,53268;57,22063;
245,158;8,55064;57,24375;
246,05802;8,56864;57,27133;
246,958;8,58672;57,29542;
247,85802;8,60464;57,31785;
248,75802;8,6226;57,34074;
249,658;8,64068;57,36882;
250,55802;8,65856;57,39061;
251,458;8,6766;57,416;
252,35802;8,6946;57,43973;
253,25802;8,7128;57,46466;
254,158;8,73064;57,48154;
255,05802;8,74856;57,50614;
255,958;8,7666;57,53199;
256,858;8,78456;57,55507;
257,75803;8,80256;57,5788;
258,65802;8,82036;57,59932;
259,55802;8,83856;57,62975;
260,458;8,8566;57,64841;
261,358;8,87464;57,67182;
262,25803;8,89264;57,69112;
263,15803;8,91064;57,71315;
264,058;8,9286;57,737;
264,958;8,9466;57,7579;
265,858;8,9648;57,7884;
266,75803;8,9828;57,80446;
267,65803;9,00056;57,82273;
268,558;9,01848;57,84647;
269,458;9,03672;57,87274;
270,358;9,05468;57,89141;
271,25803;9,07264;57,91157;
272,15803;9,0906;57,93617;
273,058;9,10868;57,95691;
273,958;9,12668;57,97915;
274,858;9,14468;57,99984;
275,75803;9,16276;58,02003;
276,65803;9,18068;58,03921;
277,558;9,19868;58,06201;
278,458;9,21668;58,08129;
279,358;9,23476;58,10453;
280,25803;9,25272;58,12324;
281,15803;9,27068;58,14278;
282,058;9,28876;58,16962;
282,958;9,30676;58,18489;
283,858;9,32472;58,20866;
284,75803;9,3426;58,22262;
285,65803;9,36076;58,24986;
286,558;9,37872;58,26811;
287,458;9,39672;58,28662;
288,358;9,41456;58,30505;
289,25803;9,43264;58,32772;
290,15803;9,45056;58,34653;
291,058;9,46848;58,36679;
291,958;9,48664;58,38871;
292,858;9,50452;58,40427;
293,75803;9,5226;58,42761;
294,65803;9,54052;58,4441;
295,558;9,5586;58,46677;
296,458;9,57644;58,4826;
297,358;9,5944;58,5026;
298,25803;9,61244;58,5246;
299,15803;9,63048;58,54305;
300,058;9,64852;58,56275;
300,958;9,66648;58,57617;
301,858;9,6846;58,59958;
302,75803;9,70252;58,61463;
303,65803;9,72056;58,63363;
304,558;9,73852;58,65263;
305,458;9,75668;58,67391;
306,358;9,77456;58,68818;
307,25803;9,79256;58,70594;
308,15803;9,81056;58,72574;
309,058;9,82852;58,74057;
309,958;9,8466;58,76188;
310,858;9,86444;58,77603;
311,75803;9,88264;58,80067;
312,65803;9,90064;58,8142;
313,558;9,91856;58,83358;
314,458;9,93656;58,84998;
315,358;9,95456;58,86745;
316,25803;9,97252;58,88486;
317,15803;9,99056;58,89864;
318,058;10,00876;58,92232;
318,958;10,0268;58,93497;
319,858;10,04472;58,95008;
320,75803;10,0626;58,96692;
321,65803;10,08076;58,98629;
322,558;10,09864;59,00077;
323,458;10,1166;59,01809;
324,358;10,1346;59,0379;
325,25803;10,15264;59,05551;
326,15803;10,17064;59,07135;
327,058;10,18864;59,08625;
327,958;10,20676;59,10573;
328,858;10,22464;59,11861;
329,75803;10,24264;59,13764;
330,65803;10,26068;59,15296;
331,558;10,2788;59,17209;
332,458;10,29672;59,18405;
333,358;10,31444;59,19668;
334,25803;10,33244;59,21859;
335,15803;10,35056;59,23444;
336,058;10,3686;59,25233;
336,958;10,38656;59,26561;
337,858;10,40472;59,28392;
338,75803;10,4226;59,29605;
339,65803;10,4406;59,31092;
340,558;10,45852;59,32893;
341,458;10,47648;59,34471;
342,358;10,49444;59,36108;
343,25803;10,5124;59,37606;
344,15803;10,53056;59,3967;
345,058;10,54852;59,40772;
345,958;10,56656;59,42314;
346,858;10,58444;59,43663;
347,75803;10,6026;59,4552;
348,65803;10,62048;59,46556;
349,558;10,6384;59,48203;
350,458;10,65648;59,49968;
351,358;10,67452;59,51334;
352,25803;10,69248;59,52684;
353,15803;10,71048;59,53905;
354,058;10,72852;59,55734;
354,958;10,74648;59,56934;
355,858;10,76448;59,58392;
356,75803;10,7824;59,60089;
357,65803;10,80056;59,61661;
358,558;10,81844;59,62751;
359,458;10,83648;59,64377;
360,35803;10,85452;59,65815;
361,25803;10,87248;59,67006;
362,15803;10,89056;59,68682;
363,058;10,90836;59,69653;
363,958;10,9266;59,71627;
364,85803;10,94448;59,72455;
365,75803;10,96248;59,74194;
366,65803;10,98048;59,75304;
367,558;10,99848;59,76567;
368,458;11,01648;59,7791;
369,35803;11,03448;59,79066;
370,25803;11,05268;59,81175;
371,15803;11,07068;59,81998;
372,058;11,08864;59,83323;
372,958;11,10648;59,84298;
373,85803;11,12456;59,85964;
374,75803;11,1424;59,87154;
375,65803;11,16036;59,88357;
376,558;11,17844;59,90124;
377,458;11,19648;59,91531;
378,35803;11,21452;59,92858;
379,25803;11,2324;59,93968;
380,15803;11,25056;59,95862;
381,058;11,2684;59,96649;
381,958;11,2864;59,98089;
382,85803;11,30448;59,99516;
383,75803;11,32264;60,00816;
384,65803;11,3406;60,0162;
385,558;11,35848;60,02656;
386,458;11,37656;60,04297;
387,35803;11,39452;60,05346;
388,25803;11,41252;60,06766;
389,15803;11,4304;60,07726;
390,058;11,44852;60,0963;
390,958;11,46644;60,10294;
391,85803;11,48448;60,11901;
392,75803;11,50248;60,12949;
393,65803;11,52048;60,14021;
394,558;11,53848;60,15151;
395,458;11,55644;60,16316;
396,35803;11,57476;60,18355;
397,25803;11,59268;60,18783;
398,15803;11,61048;60,19619;
399,058;11,62828;60,21098;
399,958;11,6464;60,22573;
400,85803;11,6644;60,23677;
401,75803;11,6824;60,2464;
402,65803;11,70048;60,26028;
403,558;11,71848;60,27109;
404,458;11,73648;60,28262;
405,35803;11,75444;60,29224;
406,25803;11,77252;60,30757;
407,15803;11,7904;60,31629;
408,058;11,8084;60,3271;
408,958;11,8264;60,34034;
409,85803;11,84448;60,34961;
410,75803;11,8624;60,35836;
411,65803;11,88036;60,369;
412,558;11,89852;60,38471;
413,458;11,91644;60,38902;
414,35803;11,93448;60,40077;
415,25803;11,95236;60,4109;
416,15803;11,97044;60,42873;
417,058;11,98844;60,43641;
417,958;12,0064;60,44683;
418,85803;12,02444;60,45666;
419,75803;12,04244;60,46582;
420,65803;12,06044;60,48132;
421,558;12,07844;60,48895;
422,458;12,09652;60,50404;
423,35803;12,11444;60,50994;
424,25803;12,13244;60,52241;
425,15803;12,15036;60,53361;
426,058;12,16844;60,54304;
426,958;12,18632;60,55427;
427,85803;12,20428;60,56173;
428,75803;12,22236;60,57591;
429,65803;12,24032;60,58508;
430,558;12,2584;60,59659;
431,458;12,27632;60,60261;
432,35803;12,29448;60,61904;
433,25803;12,31232;60,62514;
434,15803;12,33036;60,63617;
435,058;12,34836;60,64597;
435,958;12,36648;60,65713;
436,85803;12,38452;60,66567;
437,75803;12,40244;60,67215;
438,65803;12,42052;60,6869;
439,558;12,43844;60,69045;
440,458;12,45644;60,70595;
441,35803;12,47428;60,71329;
442,25803;12,49248;60,72499;
443,15803;12,5104;60,73092;
444,058;12,52844;60,73938;
444,958;12,5464;60,74798;
445,85803;12,5644;60,75748;
446,75803;12,58236;60,76536;
447,65803;12,6002;60,77283;
448,558;12,61848;60,79306;
449,458;12,63648;60,79527;
450,35803;12,65444;60,80544;
451,25803;12,67228;60,81156;
452,15803;12,6904;60,82425;
453,058;12,70844;60,83249;
453,958;12,72632;60,83708;
454,85803;12,74432;60,85166;
455,75803;12,76228;60,85669;
456,65803;12,7804;60,87153;
457,558;12,79832;60,87689;
458,458;12,81652;60,8884;
459,35803;12,83432;60,8922;
460,25803;12,85236;60,90103;
461,15803;12,8704;60,91359;
462,058;12,8886;60,92296;
462,958;12,90656;60,92706;
463,85803;12,92424;60,92799;
464,75803;12,94232;60,94359;
465,65803;12,96028;60,95545;
466,558;12,97836;60,96486;
467,458;12,99628;60,96979;
468,35803;13,0144;60,97972;
469,25803;13,03236;60,98412;
470,15803;13,0504;60,99454;
471,058;13,06844;61,00353;
471,958;13,08636;61,00564;
472,85803;13,10436;61,01864;
473,75803;13,12228;61,02583;
474,65803;13,14048;61,03904;
475,558;13,15844;61,04153;
476,458;13,17648;61,05185;
477,35803;13,19436;61,05737;
478,25803;13,21244;61,06607;
479,15803;13,2304;61,07621;
480,058;13,24828;61,0795;
480,958;13,26644;61,09464;
481,85803;13,2844;61,09984;
482,75803;13,30248;61,11048;
483,65803;13,32032;61,11506;
484,558;13,3384;61,12411;
485,458;13,35632;61,12878;
486,35803;13,37432;61,13835;
487,25803;13,39236;61,14655;
488,15803;13,41044;61,15503;
489,058;13,42832;61,15962;
489,95803;13,44628;61,16684;
490,85803;13,4644;61,17939;
491,75803;13,48224;61,18242;
492,65803;13,50024;61,19072;
493,558;13,5182;61,19615;
494,45803;13,53628;61,20501;
495,35803;13,55424;61,20929;
496,25803;13,57224;61,21711;
497,15803;13,59024;61,22537;
498,058;13,6082;61,23163;
498,95803;13,62624;61,24041;
499,85803;13,64416;61,24632;
500,75803;13,6624;61,25816;
501,65803;13,68036;61,25824;
502,558;13,69844;61,26664;
503,45803;13,71632;61,27169;
504,35803;13,73436;61,27955;
505,25803;13,75232;61,28732;
506,15803;13,77024;61,29166;
507,058;13,78836;61,30666;
507,95803;13,80636;61,30645;
508,85803;13,8244;61,31499;
509,75803;13,84236;61,32002;
510,65803;13,86048;61,32851;
511,558;13,87836;61,33239;
512,458;13,89628;61,33741;
513,35803;13,91432;61,34959;
514,258;13,93252;61,35811;
515,15803;13,95052;61,36218;
516,05803;13,96832;61,36517;
516,958;13,98648;61,37418;
517,85803;14,0044;61,37857;
518,758;14,02244;61,38539;
519,65803;14,04032;61,38824;
520,55803;14,05844;61,3979;
521,458;14,0764;61,40338;
522,35803;14,09444;61,41074;
523,258;14,11252;61,4181;
524,15803;14,13052;61,42153;
525,05806;14,14848;61,42817;
525,958;14,1664;61,43029;
526,85806;14,18464;61,44371;
527,758;14,20264;61,44459;
528,658;14,2206;61,44954;
529,55806;14,23832;61,45231;
530,458;14,25636;61,46251;
531,35806;14,2744;61,46969;
532,258;14,29228;61,47494;
533,158;14,31044;61,48462;
534,05806;14,3284;61,48666;
534,958;14,34648;61,49217;
535,85806;14,3644;61,49591;
536,758;14,38252;61,50451;
537,658;14,40036;61,50508;
538,55806;14,41828;61,5095;
539,458;14,4364;61,52147;
540,35806;14,45444;61,5258;
541,258;14,4724;61,52987;
542,158;14,49036;61,53457;
543,05806;14,50848;61,54456;
543,958;14,5264;61,5455;
544,85806;14,5444;61,55196;
545,758;14,56228;61,55576;
546,658;14,58044;61,56284;
547,55806;14,59836;61,56685;
548,458;14,61632;61,5716;
549,35806;14,63436;61,57821;
550,25806;14,65224;61,58029;
551,158;14,67028;61,58788;
552,05806;14,68824;61,59224;
552,958;14,70648;61,60065;
553,85806;14,72436;61,60116;
554,75806;14,74228;61,60681;
555,658;14,7602;61,61104;
556,55806;14,7782;61,61805;
557,458;14,7962;61,62639;
558,35806;14,81412;61,62848;
559,25806;14,83228;61,63931;
560,158;14,85024;61,64026;
561,05806;14,86828;61,64577;
561,958;14,88624;61,6491;
562,85806;14,90428;61,65329;
563,75806;14,92224;61,65823;
564,658;14,94016;61,66233;
565,55806;14,95828;61,67299;
566,458;14,97636;61,67531;
567,35806;14,99432;61,67704;
568,25806;15,0122;61,67928;
569,158;15,03028;61,6873;
570,05806;15,04816;61,68895;
570,958;15,0662;61,69536;
571,85806;15,08416;61,69817;
572,75806;15,10224;61,707;
573,658;15,1202;61,70864;
574,55806;15,1382;61,71365;
575,458;15,15628;61,7201;
576,35806;15,1742;61,71882;
577,25806;15,19216;61,72605;
578,158;15,21016;61,73028;
579,05806;15,22836;61,73808;
579,958;15,24648;61,74057;
580,85806;15,2644;61,74049;
581,75806;15,28224;61,74669;
582,658;15,30028;61,75138;
583,55806;15,31828;61,75657;
584,458;15,3362;61,75878;
585,35806;15,35436;61,76733;
586,25806;15,37228;61,76682;
587,158;15,3904;61,77517;
588,05806;15,40832;61,77451;
588,958;15,42648;61,78368;
589,85806;15,44432;61,78221;
590,75806;15,46224;61,78836;
591,658;15,4804;61,79569;
592,55806;15,49848;61,79743;
593,458;15,51656;61,80071;
594,35806;15,53424;61,79629;
595,25806;15,55228;61,80795;
596,158;15,57024;61,81135;
597,05806;15,58828;61,81625;
597,958;15,60624;61,82062;
598,85806;15,62432;61,82497;
599,75806;15,6422;61,82539;
600,658;15,66024;61,82973;
601,55806;15,67828;61,8345;
602,458;15,6962;61,83397;
603,35806;15,71424;61,84061;
604,25806;15,73216;61,84288;
605,158;15,75036;61,85101;
606,05806;15,76824;61,85064;
606,958;15,78624;61,85483;
607,85806;15,80424;61,85809;
608,75806;15,82228;61,85774;
609,658;15,84032;61,8647;
610,55806;15,85824;61,86516;
611,458;15,87636;61,87324;
612,35806;15,89428;61,87108;
613,25806;15,91236;61,87825;
614,158;15,93028;61,87832;
615,05806;15,94832;61,88239;
615,958;15,96624;61,88461;
616,85806;15,98424;61,88776;
617,75806;16,00244;61,89674;
618,658;16,02044;61,8952;
619,55806;16,03844;61,89792;
620,458;16,05632;61,89977;
621,35806;16,07444;61,90684;
622,25806;16,09232;61,90737;
623,158;16,11024;61,90909;
624,05806;16,12828;61,91356;
624,958;16,14636;61,91854;
625,85806;16,16436;61,91911;
626,75806;16,1824;61,9209;
627,658;16,20048;61,92709;
628,55806;16,21836;61,9259;
629,458;16,23644;61,93305;
630,35806;16,25436;61,93246;
631,25806;16,27256;61,94;
632,158;16,29048;61,94015;
633,05806;16,30848;61,94242;
633,958;16,32648;61,94551;
634,85806;16,3444;61,94442;
635,75806;16,3624;61,94927;
636,658;16,38028;61,95076;
637,55806;16,39844;61,95869;
638,458;16,4164;61,95871;
639,35806;16,43448;61,96259;
640,25806;16,45236;61,96349;
641,158;16,4704;61,96857;
642,05806;16,48836;61,9691;
642,958;16,50624;61,96875;
643,85806;16,52444;61,97776;
644,75806;16,54256;61,97783;
645,658;16,5606;61,98106;
646,55806;16,5784;61,97493;
647,458;16,5964;61,98195;
648,35806;16,61428;61,98384;
649,25806;16,63232;61,98633;
650,158;16,65028;61,99069;
651,05806;16,66832;61,99436;
651,958;16,68624;61,99311;
652,85806;16,7042;61,99605;
653,75806;16,72232;62,00188;
654,658;16,7402;61,99995;
655,55806;16,75816;62,00358;
656,458;16,77608;62,00498;
657,35806;16,79428;62,0109;
658,25806;16,81228;62,01119;
659,158;16,83028;62,01409;
660,05806;16,84812;62,01017;
660,958;16,86604;62,01327;
661,85806;16,88416;62,01894;
662,75806;16,90212;62,01686;
663,658;16,92028;62,02455;
664,55806;16,9382;62,02125;
665,458;16,9562;62,02656;
666,35806;16,97416;62,02849;
667,25806;16,9922;62,02936;
668,158;17,01012;62,03056;
669,05806;17,02816;62,02943;
669,958;17,04628;62,03741;
670,85806;17,06428;62,0355;
671,75806;17,08228;62,03603;
672,658;17,1002;62,03856;
673,55806;17,11832;62,04381;
674,458;17,13628;62,04517;
675,35806;17,15432;62,04512;
676,25806;17,1724;62,04987;
677,158;17,19036;62,04799;
678,05806;17,20836;62,05101;
678,958;17,22632;62,05071;
679,85806;17,24444;62,05636;
680,75806;17,26232;62,05235;
681,658;17,28032;62,05695;
682,55806;17,29828;62,05842;
683,458;17,31644;62,06586;
684,35806;17,33428;62,0613;
685,25806;17,35232;62,06284;
686,158;17,37028;62,06653;
687,05806;17,38828;62,06568;
687,958;17,40624;62,06769;
688,85806;17,42412;62,06769;
689,75806;17,44224;62,07192;
690,658;17,46012;62,07316;
691,55806;17,47816;62,07511;
692,458;17,49616;62,07518;
693,35806;17,5142;62,07764;
694,25806;17,5322;62,07674;
695,158;17,55016;62,07634;
696,05806;17,56836;62,08375;
696,958;17,58632;62,08035;
697,85806;17,60428;62,08004;
698,75806;17,6222;62,08161;
699,658;17,64032;62,08884;
700,55806;17,6582;62,08704;
701,458;17,6762;62,08543;
702,35806;17,69424;62,08961;
703,25806;17,71228;62,08984;
704,158;17,73024;62,09177;
705,05806;17,74824;62,09071;
705,958;17,76632;62,09379;
706,85806;17,78424;62,0927;
707,75806;17,8022;62,09073;
708,658;17,82016;62,09341;
709,55806;17,83836;62,09872;
710,458;17,8564;62,09812;
711,35806;17,87444;62,0997;
712,25806;17,89236;62,09636;
713,158;17,91028;62,09742;
714,05806;17,92832;62,10092;
714,958;17,94624;62,09709;
715,85806;17,96436;62,10294;
716,75806;17,98228;62,10188;
717,658;18,00032;62,10469;
718,55806;18,01836;62,10548;
719,458;18,0364;62,10532;
720,35806;18,05436;62,10575;
721,25806;18,07224;62,10117;
722,158;18,0904;62,10946;
723,05806;18,10844;62,10718;
723,958;18,12652;62,1044;
724,85806;18,14432;62,10732;
725,75806;18,16228;62,10942;
726,658;18,18016;62,10928;
727,55806;18,19828;62,11251;
728,458;18,2164;62,11572;
729,35806;18,23432;62,11278;
730,25806;18,25236;62,1133;
731,158;18,27028;62,11064;
732,05806;18,2884;62,11617;
732,958;18,30628;62,11424;
733,85806;18,32424;62,11655;
734,75806;18,34224;62,11594;
735,658;18,36036;62,11753;
736,55806;18,37836;62,11605;
737,458;18,39632;62,11516;
738,35806;18,41432;62,11813;
739,25806;18,43228;62,11606;
740,158;18,45032;62,11658;
741,05806;18,46816;62,11663;
741,958;18,48632;62,12383;
742,85806;18,50424;62,11685;
743,75806;18,52232;62,11979;
744,658;18,54028;62,11787;
745,55806;18,55828;62,11809;
746,458;18,57624;62,11808;
747,35806;18,59416;62,11645;
748,25806;18,6124;62,12339;
749,158;18,63032;62,11771;
750,05806;18,64832;62,12019;
750,958;18,66624;62,11707;
751,85806;18,68432;62,1202;
752,75806;18,70224;62,11694;
753,658;18,7202;62,11746;
754,55806;18,73828;62,12072;
755,458;18,75624;62,11804;
756,35806;18,77424;62,1191;
757,25806;18,7922;62,11849;
758,158;18,81028;62,12167;
759,05806;18,8282;62,12068;
759,958;18,84628;62,12053;
760,85806;18,86428;62,12104;
761,75806;18,8824;62,12162;
762,658;18,9004;62,11859;
763,55806;18,91836;62,11689;
764,458;18,9364;62,11972;
765,35806;18,95432;62,11454;
766,25806;18,97228;62,11796;
767,158;18,9902;62,1161;
768,05806;19,00828;62,11886;
768,958;19,02624;62,11549;
769,85806;19,04428;62,11715;
770,75806;19,06232;62,11745;
771,658;19,08032;62,11369;
772,55806;19,09828;62,11342;
773,458;19,11616;62,11301;
774,35806;19,13424;62,11895;
775,25806;19,15228;62,11488;
776,158;19,17044;62,11766;
777,05806;19,18832;62,11325;
777,958;19,20632;62,11125;
778,85806;19,2242;62,10958;
779,75806;19,2422;62,11152;
780,658;19,26032;62,11365;
781,55806;19,27824;62,1104;
782,458;19,29632;62,11203;
783,35806;19,3142;62,10917;
784,25806;19,3324;62,1128;
785,158;19,35032;62,10754;
786,05806;19,36828;62,10808;
786,958;19,38628;62,10786;
787,85806;19,40436;62,10748;
788,75806;19,42244;62,10918;
789,658;19,44036;62,10244;
790,55806;19,4582;62,10335;
791,458;19,47608;62,10265;
792,35806;19,49412;62,10507;
793,25806;19,51212;62,10526;
794,158;19,53032;62,10474;
795,05806;19,5482;62,10055;
795,958;19,56624;62,09921;
796,85806;19,58424;62,09892;
797,75806;19,6022;62,09775;
798,658;19,62016;62,09592;
799,55806;19,63804;62,09299;
800,458;19,65624;62,09958;
801,35806;19,6742;62,09359;
802,25806;19,69224;62,09446;
803,158;19,7102;62,09045;
804,05806;19,72828;62,09093;
804,958;19,74624;62,08899;
805,85806;19,76416;62,08594;
806,75806;19,78228;62,09229;
807,658;19,80024;62,08661;
808,55806;19,81824;62,08392;
809,45806;19,83624;62,08357;
810,35806;19,85432;62,08286;
811,25806;19,87216;62,08074;
812,158;19,89016;62,08102;
813,05806;19,9082;62,08208;
813,95806;19,92632;62,08172;
814,85806;19,94428;62,07682;
815,75806;19,9622;62,07544;
816,658;19,98032;62,07842;
817,55806;19,9982;62,0718;
818,45806;20,0162;62,07277;
819,35806;20,03404;62,06754;
820,25806;20,05228;62,07354;
821,158;20,0702;62,06813;
822,05806;20,08828;62,0679;
822,95806;20,10624;62,06685;
823,85806;20,1242;62,06024;
824,75806;20,1422;62,06304;
825,658;20,16016;62,05907;
826,55806;20,17836;62,06151;
827,45806;20,19636;62,05848;
828,35806;20,21444;62,05797;
829,25806;20,23236;62,05298;
830,158;20,2504;62,05074;
831,05806;20,26832;62,04902;
831,95806;20,2862;62,04823;
832,85806;20,30436;62,05192;
833,75806;20,32232;62,04708;
834,658;20,34036;62,04501;
835,55806;20,35832;62,04072;
836,45806;20,37644;62,04365;
837,35806;20,39432;62,03836;
838,25806;20,41232;62,03694;
839,158;20,43032;62,03707;
840,05806;20,4484;62,03595;
840,95806;20,46644;62,03637;
841,85806;20,48444;62,03054;
842,75806;20,50244;62,02661;
843,658;20,52032;62,02289;
844,55806;20,53836;62,02264;
845,45806;20,55628;62,02123;
846,35806;20,57444;62,02139;
847,25806;20,59232;62,01768;
848,158;20,61032;62,01609;
849,05806;20,62836;62,01292;
849,95806;20,64632;62,01073;
850,85806;20,66432;62,01245;
851,75806;20,6822;62,00649;
852,658;20,70044;62,00922;
853,55806;20,7184;62,00277;
854,45806;20,73652;62,00398;
855,35806;20,75444;61,99784;
856,25806;20,7722;61,99015;
857,158;20,79016;61,9946;
858,05806;20,8082;61,99126;
858,95806;20,82636;61,99558;
859,85806;20,84432;61,98784;
860,75806;20,86236;61,98716;
861,658;20,88024;61,98261;
862,55806;20,89836;61,98378;
863,45806;20,9162;61,97892;
864,35806;20,9342;61,97394;
865,25806;20,95228;61,97774;
866,158;20,97028;61,97478;
867,05806;20,98832;61,97085;
867,95806;21,00624;61,96441;
868,85806;21,02436;61,96761;
869,75806;21,04224;61,96142;
870,658;21,06032;61,9606;
871,55806;21,07832;61,95728;
872,45806;21,0964;61,95691;
873,35806;21,11436;61,95085;
874,25806;21,13228;61,94845;
875,158;21,1504;61,94931;
876,05806;21,16832;61,94224;
876,95806;21,18628;61,94079;
877,85806;21,20424;61,93741;
878,75806;21,22236;61,93836;
879,658;21,24028;61,93095;
880,55806;21,25836;61,92966;
881,45806;21,27632;61,92653;
882,35806;21,29432;61,9243;
883,25806;21,31228;61,92117;
884,158;21,3302;61,91408;
885,05806;21,34832;61,91645;
885,95806;21,36628;61,91214;
886,85806;21,38432;61,91002;
887,75806;21,40224;61,90488;
888,658;21,42032;61,90359;
889,55806;21,43824;61,89812;
890,45806;21,45616;61,89399;
891,35806;21,47428;61,89628;
892,25806;21,49236;61,88822;
893,158;21,51036;61,88757;
894,05806;21,52832;61,87997;
894,95806;21,54636;61,87949;
895,85806;21,56424;61,87343;
896,75806;21,58224;61,87211;
897,658;21,60016;61,86947;
898,55806;21,61828;61,86829;
899,45806;21,63616;61,86147;
900,35806;21,6542;61,85675;
901,25806;21,67224;61,85384;
902,158;21,69016;61,84815;
903,05806;21,70828;61,84705;
903,95806;21,72616;61,8406;
904,85806;21,74428;61,84195;
905,75806;21,76228;61,83637;
906,658;21,7804;61,83411;
907,55806;21,79844;61,82845;
908,45806;21,81624;61,81629;
909,35806;21,8342;61,8159;
910,25806;21,8522;61,81045;
911,158;21,87036;61,81283;
912,05806;21,88832;61,80442;
912,95806;21,90636;61,80338;
913,85806;21,92428;61,79545;
914,75806;21,9424;61,79442;
915,658;21,96036;61,78901;
916,55806;21,97836;61,78063;
917,45806;21,99648;61,77981;
918,35806;22,01444;61,77151;
919,25806;22,0326;61,77052;
920,158;22,05052;61,76141;
921,05806;22,06856;61,75895;
921,95806;22,08632;61,74927;
922,85806;22,10428;61,74977;
923,75806;22,12244;61,74825;
924,658;22,14052;61,74015;
925,55806;22,15848;61,73154;
926,45806;22,1764;61,7248;
927,35806;22,19452;61,72563;
928,25806;22,2124;61,71528;
929,158;22,23044;61,71424;
930,05806;22,24836;61,70552;
930,95806;22,26648;61,70309;
931,85806;22,2844;61,69754;
932,75806;22,3024;61,69015;
933,658;22,32036;61,68595;
934,55806;22,33832;61,67886;
935,45806;22,3564;61,67643;
936,35806;22,37432;61,66894;
937,25806;22,39252;61,66742;
938,158;22,41044;61,65897;
939,05806;22,42848;61,65332;
939,95806;22,4464;61,64429;
940,85806;22,46432;61,63818;
941,75806;22,48244;61,63586;
942,658;22,50024;61,62267;
943,55806;22,51848;61,62473;
944,45806;22,53648;61,61202;
945,35806;22,55444;61,60625;
946,25806;22,57244;61,59841;
947,158;22,5904;61,59384;
948,05806;22,60828;61,58505;
948,95806;22,62628;61,57895;
949,85806;22,64424;61,57202;
950,75806;22,66236;61,57012;
951,658;22,68028;61,55927;
952,55806;22,69828;61,55236;
953,45806;22,71632;61,54752;
954,35806;22,73428;61,53799;
955,25806;22,75232;61,53185;
956,158;22,7702;61,5221;
957,05806;22,78836;61,51947;
957,95806;22,80636;61,50944;
958,85806;22,8244;61,50127;
959,75806;22,84244;61,49289;
960,658;22,86032;61,47954;
961,55806;22,87832;61,47415;
962,45806;22,8962;61,46485;
963,35806;22,91428;61,4598;
964,25806;22,93224;61,44761;
965,158;22,95028;61,44179;
966,05806;22,9682;61,42763;
966,95806;22,98628;61,42283;
967,85806;23,00424;61,41107;
968,75806;23,02224;61,4001;
969,658;23,04036;61,39607;
970,55806;23,05832;61,38493;
971,45806;23,07644;61,37582;
972,35806;23,09444;61,36545;
973,25806;23,11252;61,35716;
974,158;23,13032;61,34173;
975,05806;23,14828;61,33273;
975,95806;23,16636;61,3252;
976,85806;23,18444;61,31554;
977,75806;23,2024;61,30013;
978,658;23,22036;61,29001;
979,55806;23,23844;61,28317;
980,45806;23,2564;61,26989;
981,35806;23,27444;61,26145;
982,25806;23,29232;61,2483;
983,158;23,31044;61,23822;
984,05806;23,3284;61,22448;
984,95806;23,34656;61,21232;
985,85806;23,36456;61,19949;
986,75806;23,38228;61,1793;
987,658;23,40028;61,17272;
988,55806;23,41824;61,16223;
989,45806;23,43652;61,15299;
990,35806;23,45444;61,13589;
991,25806;23,4724;61,12444;
992,158;23,49036;61,10749;
993,05806;23,5084;61,09582;
993,95806;23,5264;61,08148;
994,85806;23,54428;61,06591;
995,75806;23,56244;61,05778;
996,658;23,58036;61,03981;
997,55806;23,5984;61,0282;
998,45806;23,61632;61,00985;
999,35806;23,6344;60,99857;
1000,25806;23,65228;60,98204;
1001,158;23,67036;60,96702;
1002,05806;23,68844;60,95415;
1002,95806;23,70652;60,93769;
1003,85806;23,72444;60,91944;
1004,75806;23,7424;60,90389;
1005,658;23,76052;60,89231;
1006,55806;23,7784;60,87279;
1007,45806;23,7964;60,85814;
1008,35806;23,81436;60,8375;
1009,25806;23,83252;60,82284;
1010,158;23,85052;60,80387;
1011,05806;23,86848;60,78478;
1011,95806;23,88652;60,77065;
1012,85806;23,90448;60,7501;
1013,75806;23,92248;60,73535;
1014,658;23,94036;60,71373;
1015,55806;23,9584;60,69781;
1016,45806;23,97632;60,67769;
1017,35806;23,99432;60,66077;
1018,25806;24,01228;60,64132;
1019,158;24,03036;60,62176;
1020,05806;24,04832;60,60443;
1020,95806;24,06632;60,58358;
1021,85806;24,08444;60,5706;
1022,75806;24,10244;60,54761;
1023,658;24,12056;60,53;
1024,55812;24,13848;60,50662;
1025,458;24,1566;60,48556;
1026,35806;24,17444;60,45922;
1027,25806;24,19244;60,43985;
1028,15806;24,21044;60,42235;
1029,05812;24,22848;60,39993;
1029,958;24,2464;60,37729;
1030,85806;24,26436;60,35388;
1031,75806;24,28248;60,3386;
1032,65806;24,3004;60,3131;
1033,55812;24,31836;60,29273;
1034,458;24,33628;60,26915;
1035,35806;24,35444;60,24736;
1036,25806;24,37244;60,22284;
1037,15806;24,3906;60,20018;
1038,05812;24,40872;60,17872;
1038,958;24,42648;60,14677;
1039,85806;24,44452;60,12464;
1040,75806;24,46236;60,10019;
1041,65806;24,48052;60,0822;
1042,55812;24,49844;60,05064;
1043,458;24,51648;60,02829;
1044,35806;24,53448;60,00207;
1045,25806;24,55252;59,97748;
1046,15806;24,57056;59,95399;
1047,05812;24,58848;59,92485;
1047,958;24,60652;59,9017;
1048,858;24,62452;59,87456;
1049,758;24,6426;59,84914;
1050,65812;24,66064;59,81894;
1051,55812;24,67868;59,79178;
1052,458;24,69636;59,75718;
1053,358;24,71432;59,7344;
1054,258;24,73248;59,71412;
1055,15812;24,75056;59,68372;
1056,05812;24,76852;59,65216;
1056,958;24,78644;59,6228;
1057,858;24,80456;59,59735;
1058,758;24,82248;59,56415;
1059,65812;24,84052;59,53503;
1060,55812;24,85844;59,50392;
1061,458;24,87652;59,47738;
1062,358;24,89448;59,44451;
1063,258;24,91256;59,41697;
1064,15812;24,93064;59,39003;
1065,05812;24,9486;59,35412;
1065,958;24,9666;59,32484;
1066,858;24,98452;59,28941;
1067,758;25,00272;59,26277;
1068,65812;25,02064;59,22577;
1069,55812;25,03868;59,19517;
1070,458;25,05664;59,16384;
1071,358;25,07468;59,1276;
1072,258;25,09264;59,09778;
1073,15812;25,11052;59,0621;
1074,05812;25,12872;59,03382;
1074,958;25,14668;58,99566;
1075,858;25,16476;58,95864;
1076,758;25,18268;58,92444;
1077,65812;25,20072;58,89255;
1078,55812;25,2186;58,85685;
1079,458;25,23656;58,82133;
1080,358;25,25464;58,79019;
1081,258;25,27264;58,75192;
1082,15812;25,29064;58,71662;
1083,05812;25,30856;58,67454;
1083,958;25,32664;58,64331;
1084,858;25,34452;58,6004;
1085,758;25,36256;58,56656;
1086,65812;25,38056;58,52973;
1087,55812;25,39872;58,49229;
1088,458;25,41668;58,45312;
1089,358;25,43476;58,41293;
1090,258;25,45284;58,37594;
1091,15812;25,47072;58,33374;
1092,05812;25,48868;58,29375;
1092,958;25,50656;58,25185;
1093,858;25,52472;58,21501;
1094,758;25,54256;58,1693;
1095,65812;25,5606;58,13123;
1096,55812;25,5786;58,09101;
1097,458;25,59656;58,04997;
1098,358;25,6146;58,0085;
1099,258;25,63252;57,96459;
1100,15812;25,65064;57,92521;
1101,05812;25,66864;57,87749;
1101,958;25,68672;57,83452;
1102,858;25,70476;57,79091;
1103,758;25,72284;57,74534;
1104,65812;25,7406;57,69792;
1105,55812;25,75856;57,65405;
1106,458;25,77664;57,61483;
1107,358;25,79468;57,56394;
1108,258;25,81268;57,51522;
1109,15812;25,8306;57,46679;
1110,05812;25,8488;57,42494;
1110,958;25,86672;57,37414;
1111,858;25,88476;57,32729;
1112,758;25,90276;57,28044;
1113,65812;25,92084;57,2343;
1114,55812;25,9388;57,186;
1115,458;25,95688;57,13737;
1116,358;25,97496;57,08776;
1117,258;25,9928;57,03151;
1118,15812;26,01068;56,98202;
1119,05812;26,02864;56,93284;
1119,958;26,04688;56,88826;
1120,858;26,06484;56,83164;
1121,758;26,08284;56,77782;
1122,65812;26,10084;56,72675;
1123,55812;26,11888;56,67095;
1124,458;26,13692;56,62158;
1125,358;26,1548;56,56277;
1126,258;26,17296;56,50868;
1127,15812;26,19088;56,44937;
1128,05812;26,209;56,39884;
1128,958;26,22692;56,3418;
1129,858;26,24492;56,28411;
1130,758;26,26288;56,22673;
1131,65812;26,2808;56,17124;
1132,55812;26,29896;56,11572;
1133,458;26,31696;56,05478;
1134,358;26,335;55,99621;
1135,258;26,353;55,93235;
1136,15812;26,37104;55,87526;
1137,05812;26,38892;55,81197;
1137,958;26,40688;55,75347;
1138,858;26,42484;55,69347;
1139,758;26,44296;55,63022;
1140,65812;26,46096;55,56998;
1141,55812;26,47896;55,50345;
1142,458;26,497;55,43917;
1143,358;26,51492;55,37031;
1144,258;26,533;55,30897;
1145,15812;26,55088;55,24111;
1146,05812;26,56904;55,18054;
1146,958;26,58696;55,11004;
1147,858;26,60496;55,042;
1148,758;26,62296;54,97674;
1149,65812;26,64088;54,90581;
1150,55812;26,65892;54,8367;
1151,458;26,67684;54,76446;
1152,358;26,69504;54,70161;
1153,258;26,713;54,62515;
1154,15812;26,73108;54,55652;
1155,05812;26,74908;54,48323;
1155,958;26,76712;54,40951;
1156,858;26,785;54,33658;
1157,758;26,80296;54,25946;
1158,65812;26,82104;54,18697;
1159,55812;26,83912;54,10841;
1160,458;26,85712;54,02876;
1161,358;26,87508;53,95027;
1162,258;26,89316;53,87547;
1163,15812;26,91104;53,79429;
1164,05812;26,92904;53,71762;
1164,958;26,94704;53,63677;
1165,858;26,96512;53,55744;
1166,758;26,98312;53,47355;
1167,65812;27,00116;53,38821;
1168,55812;27,01932;53,30582;
1169,458;27,0372;53,21488;
1170,358;27,05512;53,13491;
1171,258;27,07304;53,04917;
1172,15812;27,09124;52,96473;
1173,05812;27,10916;52,87309;
1173,958;27,12712;52,78139;
1174,858;27,14508;52,69562;
1175,758;27,16308;52,59885;
1176,65812;27,18116;52,50918;
1177,55812;27,19912;52,41429;
1178,458;27,21728;52,32341;
1179,358;27,2352;52,22647;
1180,258;27,25328;52,13239;
1181,15812;27,27128;52,03542;
1182,05812;27,28932;51,9349;
1182,958;27,307;51,82933;
1183,858;27,32496;51,73317;
1184,758;27,3432;51,63839;
1185,65812;27,36136;51,53071;
1186,55812;27,37936;51,42559;
1187,458;27,39728;51,31903;
1188,358;27,41532;51,21601;
1189,258;27,43324;51,10546;
1190,15812;27,45124;50,99757;
1191,05812;27,4692;50,88535;
1191,958;27,48724;50,77112;
1192,858;27,5052;50,6587;
1193,758;27,52328;50,54316;
1194,65812;27,5414;50,43057;
1195,55812;27,55932;50,30853;
1196,458;27,57736;50,1913;
1197,358;27,59532;50,06977;
1198,258;27,61352;49,94581;
1199,15812;27,63144;49,82004;
1200,05812;27,64948;49,69374;
1200,958;27,66748;49,56715;
1201,858;27,68548;49,43458;
1202,758;27,70352;49,30436;
1203,65812;27,7214;49,16969;
1204,55812;27,73952;49,03912;
1205,458;27,75752;48,89862;
1206,358;27,77556;48,76009;
1207,258;27,79352;48,61737;
1208,15812;27,81156;48,47001;
1209,05812;27,82952;48,32345;
1209,958;27,84748;48,17238;
1210,858;27,86564;48,02666;
1211,758;27,8836;47,86476;
1212,65812;27,90168;47,70905;
1213,55812;27,91956;47,54605;
1214,458;27,93764;47,38183;
1215,358;27,9556;47,20959;
1216,258;27,97364;47,03161;
1217,15812;27,99168;46,83551;
1217,79;28,00448;46,21261;
1217,81;28,00632;29,84003;
1217,812;28,00664;27,2013;