File: tensile_test_data/primary_data/Zd3.csv
Time;Crosshead separation;Load;Extensometer elongation
(sec);(mm);(kN);(%)
0;0;0,26531;0,01717
0,9;0,04272;0,42884;0,01838
1,65;0,1718;1,06901;0,02148
1,934;0,23824;1,98944;0,02535
2,158;0,2932;2,94117;0,02971
2,358;0,34384;3,87396;0,03363
2,556;0,39528;4,84021;0,03756
2,75;0,44668;5,80605;0,04164
2,93;0,49532;6,72164;0,04535
3,11;0,5446;7,63807;0,04911
3,296;0,5964;8,57233;0,05308
3,492;0,65172;9,53992;0,05731
3,69;0,70792;10,48075;0,0618
3,896;0,76732;11,40897;0,06642
4,112;0,82964;12,33282;0,0716
4,328;0,89164;13,24762;0,07712
4,546;0,95384;14,16644;0,08278
4,762;1,01492;15,07931;0,08834
4,986;1,0778;16,01747;0,09389
5,218;1,14324;16,97251;0,09889
5,436;1,2058;17,89077;0,10339
5,652;1,26924;18,82302;0,10747
5,862;1,33256;19,77211;0,11163
6,068;1,39552;20,71241;0,11565
6,266;1,45736;21,64873;0,11969
6,464;1,51992;22,6;0,12407
6,662;1,58336;23,55825;0,12825
6,858;1,6466;24,52365;0,13263
7,054;1,71008;25,49014;0,13714
7,244;1,77168;26,43327;0,14154
7,43;1,83208;27,3657;0,14603
7,628;1,89632;28,34439;0,15078
7,82;1,9586;29,30101;0,15567
8,014;2,02096;30,25997;0,16057
8,212;2,08432;31,22376;0,16585
8,41;2,14668;32,18419;0,17121
8,608;2,20812;33,12088;0,17684
8,806;2,26856;34,04;0,18253
9,016;2,33096;34,99476;0,18916
9,238;2,39356;35,92917;0,19772
9,626;2,46228;36,85644;0,22609
10,032;2,52248;37,77111;0,23459
10,426;2,58452;38,69343;0,24287
10,802;2,6466;39,60852;0,25111
11,184;2,71108;40,52732;0,25994
11,57;2,77736;41,45004;0,26906
11,97;2,84644;42,37637;0,27898
12,404;2,91912;43,29095;0,29049
12,888;2,99764;44,21138;0,30337
13,442;3,083;45,12634;0,31843
14,1;3,17508;46,04049;0,33838
14,99;3,26644;46,81765;0,36683
15,89;3,32852;47,24828;0,39313
16,79;3,3746;47,51631;0,41742
17,69;3,41052;47,64988;0,44099
18,59;3,44176;47,74934;0,46413
19,49;3,46768;47,77132;0,48701
20,39;3,49084;47,76512;0,50977
21,29;3,51184;47,73215;0,53245
22,19;3,53628;47,75135;0,55566
23,09;3,55312;47,58373;0,57741
23,99;3,57268;47,4868;0,60054
24,89;3,58992;47,35035;0,62291
25,79;3,60644;47,25853;0,64547
26,69;3,62832;47,39137;0,66473
27,59;3,64688;47,24866;0,69068
28,49;3,66652;47,34716;0,71239
29,39;3,68428;47,34761;0,73483
30,29;3,70144;47,35012;0,75789
31,19;3,717;47,34257;0,78008
32,09;3,73224;47,32936;0,80313
32,99;3,74664;47,3144;0,82535
33,89;3,761;47,30527;0,84832
34,79;3,77392;47,26443;0,87068
35,69;3,78724;47,25501;0,89322
36,59;3,80008;47,23549;0,91587
37,49;3,81276;47,22054;0,93808
38,39;3,82576;47,22377;0,96087
39,29;3,83828;47,21319;0,98319
40,19;3,85108;47,21729;1,00563
41,09;3,8636;47,21553;1,0282
41,99;3,8762;47,21604;1,05081
42,89;3,88884;47,2135;1,07355
43,79;3,90092;47,19434;1,09633
44,69;3,91292;47,18656;1,11858
45,59;3,92516;47,18685;1,14096
46,49;3,93704;47,17605;1,16314
47,39;3,94924;47,17387;1,18559
48,29;3,96108;47,15464;1,20831
49,19;3,97308;47,15229;1,23069
50,09;3,98488;47,13533;1,2532
50,99;3,99628;47,10754;1,27567
51,89;4,00812;47,10017;1,29803
52,79;4,01992;47,07981;1,32072
53,69;4,03116;47,04691;1,34324
54,59;4,04292;47,04408;1,36576
55,49;4,05528;47,06605;1,38815
56,39;4,06776;47,09411;1,41057
57,29;4,08124;47,16505;1,43298
58,19;4,09448;47,22536;1,45531
59,09;4,10848;47,31388;1,47769
59,99;4,1228;47,40171;1,50015
60,89;4,13848;47,52034;1,5225
61,77;4,15892;47,76;1,54392
62,67;4,16972;47,59543;1,56699
63,57;4,18608;47,74053;1,58919
64,47;4,20204;47,81724;1,61146
65,37;4,2192;47,90609;1,63433
66,27001;4,23584;47,95444;1,65662
67,17001;4,25384;48,03349;1,67914
68,07;4,272;48,10133;1,7011
68,97;4,29136;48,17058;1,72382
69,87;4,31096;48,24309;1,74609
70,77001;4,3316;48,31784;1,76827
71,67001;4,35296;48,39163;1,79115
72,57;4,374;48,46121;1,81314
73,47;4,396;48,53619;1,83552
74,37;4,41868;48,62357;1,85827
75,27001;4,44104;48,68983;1,88065
76,17001;4,46368;48,76577;1,90305
77,07001;4,48708;48,84861;1,92583
77,97;4,51008;48,92569;1,94801
78,87;4,53364;49,0023;1,97019
79,75;4,56224;49,06935;1,99353
80,65;4,58508;49,16212;2,01506
81,55;4,60884;49,24619;2,03747
82,45001;4,6326;49,31756;2,06002
83,35001;4,65684;49,40203;2,0824
84,25001;4,68172;49,49214;2,10499
85,15;4,7058;49,55657;2,12734
86,05;4,73032;49,63803;2,14973
86,95001;4,75504;49,71103;2,1723
87,85001;4,7798;49,79718;2,19459
88,75001;4,80492;49,88263;2,21708
89,65;4,82964;49,94757;2,23955
90,55;4,85484;50,02736;2,26202
91,45001;4,88044;50,11016;2,28466
92,342;4,91164;50,34876;2,30469
93,24201;4,93568;50,24668;2,32994
94,14201;4,96032;50,33235;2,35215
95,04201;4,985;50,4102;2,37448
95,942;5,01036;50,49374;2,39701
96,842;5,03564;50,57116;2,41934
97,74201;5,06124;50,65122;2,44191
98,64201;5,08648;50,71216;2,46466
99,54201;5,1116;50,78949;2,48693
100,442;5,13716;50,86808;2,50964
101,342;5,16196;50,93353;2,53185
102,24201;5,18712;51,00754;2,55422
103,14201;5,2128;51,08486;2,57723
104,04201;5,23704;51,14414;2,59921
104,942;5,26256;51,23791;2,6217
105,842;5,29288;51,32149;2,64496
106,74201;5,31524;51,34761;2,66644
107,64201;5,34008;51,4314;2,68935
108,54201;5,36436;51,50349;2,71176
109,44201;5,3888;51,57623;2,73426
110,342;5,41312;51,63386;2,75664
111,24201;5,43756;51,69983;2,77911
112,14201;5,46236;51,77606;2,80199
113,04201;5,48608;51,82511;2,82407
113,94201;5,51008;51,90169;2,8461
114,842;5,53496;51,97172;2,86915
115,74201;5,55896;52,03429;2,89143
116,64201;5,58332;52,10122;2,91377
117,54201;5,60764;52,15784;2,93644
118,44201;5,638;52,28969;2,95965
119,342;5,65988;52,2765;2,98157
120,24201;5,68324;52,33998;3,00384
121,14201;5,70696;52,40786;3,02611
122,04201;5,73116;52,475;3,04893
122,94201;5,75536;52,54344;3,07136
123,842;5,77928;52,60391;3,0939
124,74201;5,80288;52,65478;3,11653
125,64201;5,82644;52,71358;3,13885
126,54201;5,8508;52,78708;3,16136
127,44201;5,8744;52,8317;3,18385
128,34201;5,8984;52,8928;3,2063
129,24201;5,92264;52,95779;3,22891
130,14202;5,94696;53,01787;3,24982
131,04201;5,97496;53,05744;3,27456
131,942;5,99772;53,11491;3,29642
132,84202;6,0212;53,17586;3,31884
133,742;6,04496;53,24482;3,34146
134,64202;6,06856;53,29408;3,36366
135,542;6,0922;53,33963;3,38613
136,442;6,11664;53,41807;3,40876
137,34202;6,14008;53,45576;3,43116
138,242;6,1642;53,51819;3,45383
139,14202;6,1878;53,56292;3,47642
140,042;6,21164;53,62661;3,49875
140,942;6,2356;53,68242;3,52122
141,84202;6,25964;53,72602;3,54405
142,742;6,28812;53,77827;3,56713
143,64202;6,31068;53,82953;3,58901
144,542;6,33356;53,87579;3,61125
145,442;6,35672;53,92367;3,63361
146,34202;6,38096;53,99162;3,65639
147,242;6,40456;54,03677;3,67887
148,14202;6,42824;54,08993;3,70127
149,042;6,4518;54,13047;3,72394
149,942;6,4756;54,18869;3,74628
150,84202;6,4996;54,24654;3,76897
151,742;6,52336;54,27799;3,79162
152,64202;6,54664;54,32261;3,81365
153,542;6,57132;54,39374;3,83573
154,442;6,59936;54,41557;3,85927
155,34202;6,62188;54,46489;3,88103
156,242;6,64572;54,52048;3,90387
157,14202;6,66896;54,56585;3,9264
158,042;6,69284;54,62142;3,94872
158,942;6,71628;54,65289;3,97128
159,84202;6,74016;54,70709;3,99362
160,59602;6,7482;54,42336;4,00658
161,496;6,76624;54,61366;4,02092
162,39602;6,78408;54,6808;4,03727
163,296;6,80184;54,71928;4,0538
164,19602;6,8198;54,76201;4,07046
165,09602;6,83792;54,79532;4,08729
165,996;6,85592;54,82644;4,10398
166,89602;6,8738;54,85928;4,12062
167,796;6,892;54,89865;4,13724
168,69602;6,90988;54,92787;4,14914
169,59602;6,92796;54,96385;4,16635
170,496;6,94588;54,99479;4,18336
171,39602;6,96396;55,02803;4,20051
191,56802;6,97548;53,68126;
192,468;6,99324;54,41912;
193,36802;7,01124;54,87763;
194,268;7,02936;55,10671;
195,16802;7,04728;55,20324;
196,06802;7,06532;55,2487;
196,968;7,0834;55,28502;
197,86802;7,10136;55,30969;
198,768;7,11936;55,33731;
199,66802;7,13728;55,3583;
200,56802;7,15544;55,3908;
201,468;7,17336;55,41583;
202,36802;7,19136;55,44118;
203,268;7,20932;55,46938;
204,16802;7,22732;55,49643;
205,06802;7,24532;55,52498;
205,968;7,26328;55,55056;
206,86802;7,28136;55,58512;
207,768;7,29928;55,60642;
208,66802;7,31732;55,63703;
209,56802;7,33524;55,66195;
210,46802;7,35332;55,69638;
211,36802;7,37116;55,72132;
212,268;7,38916;55,74956;
213,16802;7,40712;55,78199;
214,06802;7,42524;55,80823;
214,96802;7,4432;55,83716;
215,86802;7,46112;55,86287;
216,768;7,47928;55,8933;
217,66802;7,49716;55,91863;
218,56802;7,51516;55,9478;
219,46802;7,53316;55,97514;
220,36802;7,55132;56,00467;
221,268;7,56932;56,02691;
222,16802;7,58724;56,05185;
223,06802;7,6052;56,08137;
223,96802;7,62316;56,10558;
224,86802;7,64112;56,13433;
225,768;7,65904;56,15744;
226,66802;7,67716;56,19028;
227,56802;7,69512;56,21286;
228,46802;7,71312;56,23802;
229,36802;7,73108;56,26675;
230,268;7,74916;56,29122;
231,16802;7,76708;56,31605;
232,06802;7,78508;56,34309;
232,96802;7,80328;56,37354;
233,86802;7,82132;56,39704;
234,768;7,83924;56,41837;
235,66802;7,85708;56,44329;
236,56802;7,8752;56,47145;
237,46802;7,89312;56,49306;
238,36802;7,91108;56,51885;
239,268;7,92908;56,5474;
240,16802;7,94716;56,57284;
241,06802;7,96516;56,59808;
241,96802;7,98312;56,61815;
242,86802;8,0012;56,64863;
243,768;8,01912;56,66824;
244,66802;8,03716;56,69647;
245,56802;8,05512;56,71989;
246,46802;8,07336;56,74334;
247,36802;8,09124;56,76734;
248,268;8,10896;56,78652;
249,16802;8,12708;56,81635;
250,06802;8,14512;56,84168;
250,96802;8,16324;56,86462;
251,86802;8,18104;56,88788;
252,768;8,1992;56,91563;
253,66802;8,21712;56,9362;
254,56802;8,23516;56,96107;
255,46802;8,25316;56,98417;
256,36802;8,27112;57,00718;
257,268;8,28908;57,02912;
258,168;8,307;57,05097;
259,06803;8,32516;57,07727;
259,96802;8,34308;57,09661;
260,86802;8,36104;57,12256;
261,768;8,379;57,14532;
262,668;8,39712;57,17235;
263,56803;8,41508;57,19296;
264,46803;8,43304;57,2135;
265,368;8,45108;57,24002;
266,268;8,46912;57,26057;
267,168;8,48712;57,28378;
268,06803;8,505;57,2995;
268,96803;8,52304;57,32642;
269,868;8,54096;57,34785;
270,768;8,55904;57,37125;
271,668;8,57708;57,39184;
272,56803;8,59516;57,41398;
273,46803;8,61304;57,43216;
274,368;8,631;57,45142;
275,268;8,64908;57,47811;
276,168;8,667;57,49485;
277,06803;8,68496;57,52195;
277,96803;8,70288;57,5399;
278,868;8,721;57,56411;
279,768;8,73896;57,58348;
280,668;8,757;57,60617;
281,56803;8,77496;57,62715;
282,46803;8,793;57,64734;
283,368;8,81096;57,66682;
284,268;8,82896;57,68785;
285,168;8,84712;57,7132;
286,06803;8,86512;57,73191;
286,96803;8,88312;57,75053;
287,868;8,90104;57,7688;
288,768;8,91908;57,79187;
289,668;8,93692;57,80817;
290,56803;8,95488;57,82853;
291,46803;8,97296;57,85083;
292,368;8,991;57,87228;
293,268;9,009;57,89186;
294,168;9,02688;57,90756;
295,06803;9,04504;57,93351;
295,96803;9,06296;57,94919;
296,868;9,081;57,97086;
297,768;9,09896;57,99121;
298,668;9,1172;58,01434;
299,56803;9,13508;58,02888;
300,46803;9,15292;58,04298;
301,368;9,17096;58,06816;
302,268;9,18892;58,08754;
303,168;9,20696;58,10706;
304,06803;9,22488;58,122;
304,96803;9,243;58,14439;
305,868;9,26096;58,16224;
306,768;9,279;58,1821;
307,66803;9,297;58,2005;
308,56803;9,315;58,21928;
309,46803;9,33296;58,23613;
310,368;9,35092;58,25546;
311,268;9,36912;58,28168;
312,16803;9,38704;58,29046;
313,06803;9,40504;58,30875;
313,96803;9,42284;58,32471;
314,868;9,441;58,34681;
315,768;9,459;58,36479;
316,66803;9,477;58,37982;
317,56803;9,49504;58,40255;
318,46803;9,51304;58,41903;
319,368;9,53104;58,43758;
320,268;9,54896;58,45285;
321,16803;9,56708;58,47437;
322,06803;9,58496;58,4874;
322,96803;9,60292;58,50547;
323,868;9,62092;58,52488;
324,768;9,639;58,54108;
325,66803;9,65696;58,55901;
326,56803;9,67488;58,57607;
327,46803;9,69296;58,59567;
328,368;9,71092;58,60817;
329,268;9,72892;58,62838;
330,16803;9,74688;58,64292;
331,06803;9,765;58,6631;
331,96803;9,78296;58,67593;
332,868;9,80092;58,69147;
333,768;9,81896;58,7114;
334,66803;9,83688;58,72685;
335,56803;9,85488;58,74492;
336,46803;9,87288;58,7622;
337,368;9,89104;58,78072;
338,268;9,909;58,79202;
339,16803;9,927;58,80928;
340,06803;9,94492;58,82355;
340,96803;9,96296;58,84051;
341,868;9,98088;58,85518;
342,768;9,99884;58,87221;
343,66803;10,01692;58,89022;
344,56803;10,0348;58,89839;
345,46803;10,0528;58,9174;
346,368;10,0708;58,9313;
347,268;10,08888;58,95039;
348,16803;10,10684;58,9617;
349,06803;10,1248;58,97757;
349,96803;10,1428;58,99766;
350,868;10,16096;59,01362;
351,768;10,17896;59,02759;
352,66803;10,19688;59,04088;
353,56803;10,21492;59,06041;
354,46803;10,2328;59,07146;
355,368;10,25088;59,09001;
356,268;10,26876;59,10386;
357,16803;10,28688;59,12215;
358,06803;10,30484;59,13382;
358,96803;10,32284;59,15057;
359,868;10,34088;59,16535;
360,768;10,35888;59,17659;
361,66803;10,37688;59,19068;
362,56803;10,39476;59,20359;
363,46803;10,41296;59,22525;
364,368;10,43104;59,23578;
365,268;10,44904;59,25017;
366,16803;10,46688;59,26167;
367,06803;10,48496;59,27783;
367,96803;10,50288;59,28856;
368,868;10,52084;59,30378;
369,768;10,53888;59,32266;
370,66803;10,55692;59,33386;
371,56803;10,575;59,34963;
372,46803;10,59296;59,3614;
373,368;10,61108;59,37838;
374,268;10,62896;59,38796;
375,16803;10,64692;59,4039;
376,06803;10,66492;59,41812;
376,96803;10,68312;59,43382;
377,868;10,70108;59,4441;
378,768;10,7188;59,4488;
379,66803;10,73688;59,47015;
380,56803;10,75484;59,48095;
381,46803;10,77288;59,4968;
382,368;10,79084;59,50792;
383,268;10,80888;59,52376;
384,16803;10,8268;59,53544;
385,06803;10,84484;59,54654;
385,96803;10,86288;59,55989;
386,868;10,88088;59,57121;
387,768;10,89884;59,58592;
388,66803;10,91672;59,59729;
389,56803;10,93488;59,61472;
390,46803;10,95268;59,62183;
391,368;10,97088;59,6429;
392,268;10,98876;59,64745;
393,16803;11,00696;59,66506;
394,06803;11,02488;59,67529;
394,96803;11,04276;59,6854;
395,868;11,061;59,70438;
396,768;11,07896;59,71112;
397,66803;11,097;59,72785;
398,56803;11,11492;59,7354;
399,46803;11,133;59,75004;
400,368;11,15092;59,76037;
401,268;11,16888;59,77103;
402,16803;11,18696;59,78729;
403,06803;11,20504;59,79514;
403,96803;11,223;59,80616;
404,868;11,24096;59,81519;
405,768;11,25904;59,83184;
406,66803;11,27684;59,83949;
407,56803;11,29484;59,8525;
408,46803;11,31276;59,8652;
409,368;11,33088;59,8783;
410,268;11,3488;59,88981;
411,16803;11,3668;59,90092;
412,06803;11,38488;59,9153;
412,96803;11,40284;59,92321;
413,868;11,42088;59,93685;
414,768;11,43876;59,94496;
415,66803;11,45692;59,96233;
416,56803;11,47492;59,96904;
417,46803;11,49296;59,98146;
418,368;11,51088;59,99022;
419,268;11,52884;59,99936;
420,16803;11,54676;60,01242;
421,06803;11,56468;60,02137;
421,96803;11,58284;60,03742;
422,868;11,60084;60,04634;
423,768;11,61888;60,05853;
424,66803;11,63672;60,06509;
425,56803;11,6548;60,07869;
426,46803;11,67268;60,08835;
427,368;11,69064;60,09962;
428,268;11,70872;60,11209;
429,16803;11,72684;60,12633;
430,06803;11,74492;60,13418;
430,96803;11,76268;60,137;
431,868;11,78076;60,15332;
432,768;11,79868;60,15906;
433,66803;11,81668;60,17359;
434,56803;11,8346;60,18114;
435,46803;11,85268;60,19599;
436,368;11,87068;60,20491;
437,26803;11,88868;60,21397;
438,16803;11,90684;60,22882;
439,06803;11,9248;60,23492;
439,96803;11,9428;60,24539;
440,868;11,96072;60,25501;
441,76803;11,97892;60,27054;
442,66803;11,99692;60,27734;
443,56803;12,01488;60,28639;
444,46803;12,03268;60,29038;
445,368;12,05068;60,30349;
446,26803;12,0688;60,31507;
447,16803;12,08672;60,32128;
448,06803;12,10488;60,33413;
448,96803;12,1228;60,34002;
449,868;12,14084;60,35188;
450,76803;12,15876;60,3582;
451,66803;12,17688;60,37068;
452,56803;12,1948;60,37466;
453,46803;12,21276;60,38221;
454,368;12,23088;60,3988;
455,26803;12,24892;60,40502;
456,16803;12,26688;60,41456;
457,06803;12,28476;60,42117;
457,96803;12,30292;60,43606;
458,868;12,3208;60,44369;
459,76803;12,33884;60,45387;
460,66803;12,35676;60,4612;
461,56803;12,37492;60,47167;
462,46803;12,39288;60,47856;
463,368;12,41084;60,48626;
464,26803;12,42896;60,49922;
465,16803;12,44676;60,50217;
466,06803;12,46476;60,51462;
466,96803;12,48268;60,52184;
467,868;12,5008;60,53553;
468,76803;12,51876;60,53991;
469,66803;12,53672;60,54605;
470,56803;12,55472;60,55658;
471,46803;12,57276;60,56247;
472,368;12,59068;60,5718;
473,26803;12,6086;60,57829;
474,16803;12,62672;60,59196;
475,06803;12,64468;60,59705;
475,96803;12,66272;60,60678;
476,868;12,68064;60,61225;
477,76803;12,6988;60,62433;
478,66803;12,71668;60,62622;
479,56803;12,73464;60,63409;
480,46803;12,7528;60,64897;
481,368;12,7708;60,65429;
482,26803;12,78888;60,66206;
483,16803;12,8068;60,66729;
484,06803;12,82488;60,67939;
484,96803;12,84268;60,6813;
485,868;12,86072;60,69075;
486,76803;12,87876;60,70024;
487,66803;12,89692;60,70865;
488,56803;12,91488;60,7137;
489,46803;12,93284;60,71959;
490,368;12,95088;60,73025;
491,26803;12,96884;60,73441;
492,16803;12,98684;60,74499;
493,06803;13,00472;60,74725;
493,96803;13,02296;60,76115;
494,868;13,041;60,76894;
495,76803;13,05912;60,77482;
496,66803;13,07696;60,77911;
497,56803;13,09488;60,78602;
498,46803;13,11296;60,79628;
499,368;13,1308;60,79966;
500,26803;13,14896;60,81343;
501,16803;13,16688;60,81405;
502,06803;13,18492;60,82442;
502,96803;13,20288;60,83201;
503,868;13,221;60,84233;
504,76803;13,23888;60,847;
505,66803;13,25684;60,85284;
506,56803;13,27496;60,86498;
507,46803;13,29304;60,87016;
508,368;13,31108;60,87609;
509,26803;13,32892;60,87838;
510,16803;13,34684;60,8893;
511,06803;13,36464;60,89455;
511,96803;13,38276;60,90448;
512,86803;13,40088;60,91235;
513,768;13,41892;60,91864;
514,66803;13,43692;60,92357;
515,56806;13,4548;60,92672;
516,46803;13,47292;60,93797;
517,36803;13,4908;60,94093;
518,268;13,5088;60,95327;
519,16803;13,52668;60,95671;
520,06806;13,54484;60,96629;
520,96803;13,5628;60,96881;
521,86803;13,58076;60,97375;
522,768;13,59876;60,9828;
523,66803;13,6168;60,98772;
524,56806;13,63476;60,99415;
525,468;13,65268;60,99752;
526,36806;13,6708;61,00836;
527,268;13,68872;61,01122;
528,168;13,7068;61,02061;
529,06806;13,72472;61,0244;
529,968;13,74284;61,03406;
530,86806;13,76072;61,03669;
531,768;13,77868;61,04314;
532,668;13,79688;61,05169;
533,56806;13,81484;61,05438;
534,468;13,83284;61,06362;
535,36806;13,85072;61,06493;
536,268;13,86884;61,07536;
537,168;13,88672;61,07646;
538,06806;13,90476;61,08307;
538,968;13,9228;61,09113;
539,86806;13,94088;61,09535;
540,768;13,95876;61,10002;
541,668;13,97668;61,10603;
542,56806;13,9948;61,11867;
543,468;14,01276;61,121;
544,36806;14,03076;61,12727;
545,268;14,04868;61,13025;
546,168;14,06692;61,14016;
547,06806;14,08488;61,14058;
547,968;14,10292;61,14677;
548,86806;14,12092;61,14951;
549,768;14,1388;61,15457;
550,668;14,15672;61,1623;
551,56806;14,1746;61,16509;
552,468;14,19276;61,17657;
553,36806;14,21072;61,17716;
554,268;14,22876;61,18618;
555,168;14,24668;61,18937;
556,06806;14,26476;61,1952;
556,968;14,28272;61,19995;
557,86806;14,30064;61,20207;
558,768;14,31872;61,21441;
559,668;14,33684;61,21817;
560,56806;14,35488;61,22194;
561,468;14,3728;61,22478;
562,36806;14,39084;61,23016;
563,268;14,40872;61,2322;
564,168;14,42676;61,23945;
565,06806;14,44476;61,24525;
565,968;14,4628;61,24868;
566,86806;14,48076;61,2554;
567,768;14,49872;61,26153;
568,668;14,51684;61,26695;
569,56806;14,53476;61,26848;
570,468;14,55272;61,27571;
571,36806;14,57068;61,27853;
572,268;14,58888;61,28696;
573,168;14,60696;61,29147;
574,06806;14,62492;61,29288;
574,968;14,64272;61,29388;
575,86806;14,66064;61,29825;
576,768;14,67864;61,308;
577,668;14,69664;61,31094;
578,56806;14,71484;61,31859;
579,468;14,73272;61,316;
580,36806;14,7508;61,32385;
581,268;14,76872;61,3269;
582,168;14,7868;61,3323;
583,06806;14,80472;61,33504;
583,968;14,82264;61,33933;
584,86806;14,8408;61,34671;
585,768;14,85872;61,34796;
586,668;14,87676;61,35371;
587,56806;14,89464;61,35533;
588,468;14,91272;61,3646;
589,36806;14,93068;61,36702;
590,268;14,94868;61,36867;
591,168;14,96676;61,3742;
592,06806;14,9848;61,38105;
592,968;15,00272;61,3858;
593,86806;15,02072;61,38813;
594,768;15,0388;61,39402;
595,668;15,05668;61,39255;
596,56806;15,07476;61,39889;
597,468;15,09272;61,40316;
598,36806;15,11096;61,4087;
599,268;15,12884;61,40725;
600,168;15,14676;61,4112;
601,06806;15,1648;61,41598;
601,968;15,18268;61,41976;
602,86806;15,20072;61,42507;
603,768;15,21856;61,42824;
604,668;15,23676;61,43629;
605,56806;15,25464;61,43394;
606,468;15,27264;61,44314;
607,36806;15,29068;61,44586;
608,268;15,30868;61,44783;
609,168;15,32664;61,45356;
610,06806;15,3446;61,45325;
610,968;15,36272;61,46521;
611,86806;15,38072;61,46317;
612,768;15,39884;61,46982;
613,668;15,41676;61,47104;
614,56806;15,43488;61,47443;
615,468;15,45272;61,4747;
616,36806;15,47068;61,4788;
617,268;15,48872;61,4845;
618,168;15,50676;61,48733;
619,06806;15,52476;61,49057;
619,968;15,54268;61,49238;
620,86806;15,56084;61,49802;
621,768;15,57872;61,49741;
622,668;15,59672;61,50278;
623,56806;15,61468;61,50525;
624,468;15,63272;61,51013;
625,36806;15,65076;61,51211;
626,268;15,6688;61,51546;
627,168;15,68672;61,51741;
628,06806;15,7046;61,51891;
628,968;15,72264;61,52377;
629,86806;15,7406;61,52749;
630,768;15,75872;61,53169;
631,668;15,7766;61,53157;
632,56806;15,79456;61,53415;
633,468;15,8126;61,54069;
634,36806;15,83068;61,54218;
635,268;15,84868;61,54624;
636,168;15,86656;61,54339;
637,06806;15,88476;61,5522;
637,968;15,90272;61,55235;
638,86806;15,92084;61,55757;
639,768;15,93876;61,55578;
640,668;15,95656;61,55595;
641,56806;15,97448;61,55992;
642,468;15,99252;61,56477;
643,36806;16,01064;61,572;
644,268;16,02864;61,57262;
645,168;16,04664;61,57598;
646,06806;16,06464;61,57465;
646,968;16,0828;61,58251;
647,86806;16,10072;61,5799;
648,768;16,11868;61,58171;
649,668;16,13668;61,58394;
650,56806;16,1548;61,56977;
651,468;16,17272;61,58509;
652,36806;16,19064;61,59018;
653,268;16,20876;61,59894;
654,168;16,22664;61,59731;
655,06806;16,24468;61,60241;
655,968;16,2626;61,60275;
656,86806;16,28068;61,60805;
657,768;16,29864;61,60804;
658,668;16,31664;61,61228;
659,56806;16,33464;61,61521;
660,468;16,35264;61,61585;
661,36806;16,3706;61,61941;
662,268;16,38852;61,61844;
663,168;16,40672;61,62728;
664,06806;16,42468;61,625;
664,968;16,44272;61,62851;
665,86806;16,4606;61,62884;
666,768;16,47864;61,63079;
667,668;16,4966;61,63436;
668,56806;16,51448;61,6317;
669,468;16,5326;61,63906;
670,36806;16,5506;61,63824;
671,268;16,5686;61,64083;
672,168;16,58652;61,6419;
673,06806;16,60468;61,6459;
673,968;16,62256;61,64423;
674,86806;16,64052;61,64871;
675,768;16,65852;61,65202;
676,668;16,67664;61,65302;
677,56806;16,69464;61,65603;
678,468;16,71268;61,65485;
679,36806;16,7308;61,65729;
680,268;16,74872;61,65485;
681,168;16,76664;61,65942;
682,06806;16,7846;61,66104;
682,968;16,80272;61,66642;
683,86806;16,82068;61,66601;
684,768;16,83872;61,66605;
685,668;16,85672;61,66899;
686,56806;16,87468;61,66727;
687,468;16,89272;61,67136;
688,36806;16,9106;61,66964;
689,268;16,92876;61,67688;
690,168;16,94668;61,67421;
691,06806;16,96484;61,6812;
691,968;16,9828;61,68113;
692,86806;17,00072;61,68057;
693,768;17,01864;61,68099;
694,668;17,0366;61,68163;
695,56806;17,0548;61,68842;
696,468;17,07276;61,68494;
697,36806;17,09076;61,68863;
698,268;17,10872;61,68815;
699,168;17,12684;61,69254;
700,06806;17,1448;61,69065;
700,968;17,16276;61,6912;
701,86806;17,1808;61,69454;
702,768;17,19888;61,69245;
703,668;17,21692;61,69717;
704,56806;17,23488;61,69624;
705,468;17,25296;61,6977;
706,36806;17,27068;61,69549;
707,268;17,28872;61,70009;
708,168;17,30668;61,70073;
709,06806;17,32488;61,70691;
709,968;17,34272;61,70205;
710,86806;17,36072;61,70243;
711,768;17,3788;61,70663;
712,668;17,39676;61,70334;
713,56806;17,41472;61,70602;
714,468;17,43264;61,70439;
715,36806;17,45076;61,71088;
716,268;17,46872;61,70876;
717,168;17,48676;61,71252;
718,06806;17,50464;61,71062;
718,968;17,52272;61,71125;
719,86806;17,54072;61,71367;
720,768;17,55864;61,71091;
721,668;17,5768;61,71699;
722,56806;17,59472;61,71254;
723,468;17,61276;61,71552;
724,36806;17,63064;61,7138;
725,268;17,6488;61,71867;
726,168;17,6666;61,7145;
727,06806;17,68452;61,71875;
727,968;17,7026;61,72027;
728,86806;17,72072;61,72196;
729,768;17,73876;61,72398;
730,668;17,75668;61,71904;
731,56806;17,77476;61,72462;
732,468;17,79264;61,72174;
733,36806;17,8106;61,72199;
734,268;17,82856;61,72583;
735,168;17,84668;61,72917;
736,06806;17,8646;61,72624;
736,968;17,8826;61,7249;
737,86806;17,90064;61,72638;
738,768;17,91864;61,72479;
739,668;17,93664;61,72559;
740,56806;17,95452;61,72395;
741,468;17,97268;61,72942;
742,36806;17,99064;61,72881;
743,268;18,00868;61,73235;
744,168;18,02668;61,72924;
745,06806;18,04464;61,72745;
745,968;18,0626;61,7259;
746,86806;18,08048;61,72463;
747,768;18,09864;61,73354;
748,668;18,1166;61,72854;
749,56806;18,13464;61,73022;
750,468;18,1526;61,72987;
751,36806;18,17068;61,73125;
752,268;18,18856;61,72928;
753,168;18,20652;61,72599;
754,06806;18,22448;61,7309;
754,968;18,24264;61,73319;
755,86806;18,26068;61,7326;
756,76806;18,27876;61,73277;
757,668;18,2968;61,73;
758,56806;18,3146;61,72605;
759,468;18,3326;61,72997;
760,36806;18,35056;61,73031;
761,26806;18,36872;61,73192;
762,168;18,38664;61,72642;
763,06806;18,4046;61,72754;
763,968;18,42272;61,73175;
764,86806;18,44068;61,72608;
765,76806;18,45868;61,72911;
766,668;18,4766;61,7277;
767,56806;18,49472;61,73114;
768,468;18,51268;61,72795;
769,36806;18,53084;61,73108;
770,26806;18,54884;61,72723;
771,168;18,56664;61,7191;
772,06806;18,58456;61,72201;
772,968;18,60256;61,72279;
773,86806;18,6208;61,72901;
774,76806;18,63868;61,72358;
775,668;18,65672;61,72633;
776,56806;18,67452;61,72117;
777,468;18,69268;61,72551;
778,36806;18,71056;61,72118;
779,26806;18,72852;61,71793;
780,168;18,74668;61,72298;
781,06806;18,76464;61,71931;
781,968;18,78272;61,72;
782,86806;18,80064;61,71679;
783,76806;18,81868;61,72086;
784,668;18,8366;61,71455;
785,56806;18,8546;61,71435;
786,468;18,8726;61,7178;
787,36806;18,89076;61,71715;
788,26806;18,90868;61,71381;
789,168;18,92668;61,71353;
790,06806;18,9448;61,71601;
790,968;18,96268;61,71067;
791,86806;18,98068;61,71142;
792,76806;18,99856;61,70799;
793,668;19,01684;61,71333;
794,56806;19,0348;61,70595;
795,468;19,0528;61,70637;
796,36806;19,0708;61,70572;
797,26806;19,08876;61,70114;
798,168;19,10676;61,70458;
799,06806;19,12464;61,69924;
799,968;19,14276;61,70362;
800,86806;19,16072;61,69788;
801,76806;19,17876;61,6991;
802,668;19,19672;61,69757;
803,56806;19,21484;61,69696;
804,468;19,2328;61,69584;
805,36806;19,25072;61,69108;
806,26806;19,26884;61,69701;
807,168;19,28688;61,69284;
808,06806;19,30488;61,69028;
808,968;19,32288;61,6901;
809,86806;19,34096;61,69198;
810,76806;19,3588;61,68506;
811,668;19,37676;61,68365;
812,56806;19,39476;61,68466;
813,468;19,41284;61,68668;
814,36806;19,4308;61,68219;
815,26806;19,44876;61,68049;
816,168;19,46688;61,68171;
817,06806;19,4848;61,67738;
817,968;19,5028;61,68012;
818,86806;19,52068;61,67645;
819,76806;19,5388;61,6776;
820,668;19,55676;61,67443;
821,56806;19,57492;61,67343;
822,468;19,59296;61,67263;
823,36806;19,6108;61,66316;
824,26806;19,62872;61,66347;
825,168;19,64664;61,66254;
826,06806;19,6648;61,66477;
826,968;19,68272;61,65995;
827,86806;19,70076;61,6621;
828,76806;19,71864;61,65597;
829,668;19,73668;61,65447;
830,56806;19,75464;61,65251;
831,468;19,77256;61,64829;
832,36806;19,79064;61,65264;
833,26806;19,80864;61,64761;
834,168;19,82672;61,65166;
835,06806;19,84472;61,64535;
835,968;19,86276;61,64854;
836,86806;19,88048;61,63619;
837,76806;19,89852;61,63695;
838,668;19,91664;61,63899;
839,56806;19,9348;61,6335;
840,468;19,95268;61,62951;
841,36806;19,97064;61,62593;
842,26806;19,98872;61,62868;
843,168;20,00664;61,62469;
844,06806;20,02468;61,62371;
844,968;20,04256;61,61785;
845,86806;20,0608;61,6192;
846,76806;20,07876;61,61348;
847,668;20,09672;61,61204;
848,56806;20,11476;61,6103;
849,468;20,13268;61,60502;
850,36806;20,15072;61,60674;
851,26806;20,16868;61,60304;
852,168;20,18688;61,60749;
853,06806;20,20484;61,59767;
853,968;20,22284;61,59583;
854,86806;20,24076;61,59124;
855,76806;20,2588;61,59061;
856,668;20,27676;61,58723;
857,56806;20,29464;61,58201;
858,468;20,3128;61,58918;
859,36806;20,33084;61,58164;
860,26806;20,34884;61,58205;
861,168;20,36668;61,57495;
862,06806;20,3848;61,57429;
862,968;20,40268;61,56781;
863,86806;20,42068;61,56631;
864,76806;20,43868;61,56503;
865,668;20,45668;61,56048;
866,56806;20,47464;61,55503;
867,468;20,49256;61,55362;
868,36806;20,51068;61,55358;
869,26806;20,5286;61,54871;
870,168;20,54664;61,54861;
871,06806;20,56456;61,54191;
871,968;20,58272;61,53948;
872,86806;20,60068;61,53597;
873,76806;20,61868;61,53192;
874,668;20,63668;61,53153;
875,56806;20,6546;61,5207;
876,468;20,67264;61,52475;
877,36806;20,69048;61,51859;
878,26806;20,70872;61,52016;
879,168;20,72664;61,51108;
880,06806;20,74468;61,50806;
880,968;20,76264;61,50298;
881,86806;20,78068;61,50194;
882,76806;20,7986;61,49546;
883,668;20,81652;61,48784;
884,56806;20,83468;61,49322;
885,468;20,85264;61,48295;
886,36806;20,87072;61,48283;
887,26806;20,88876;61,47914;
888,168;20,90692;61,4776;
889,06806;20,92468;61,46698;
889,968;20,94264;61,46371;
890,86806;20,96068;61,46542;
891,76806;20,97876;61,45655;
892,668;20,99672;61,45186;
893,56806;21,01468;61,44647;
894,468;21,0328;61,44856;
895,36806;21,05076;61,44165;
896,26806;21,0688;61,4372;
897,168;21,08672;61,43075;
898,06806;21,10484;61,42811;
898,968;21,1228;61,42133;
899,86806;21,14088;61,41981;
900,76806;21,15896;61,41379;
901,668;21,1768;61,40599;
902,56806;21,19472;61,40726;
903,468;21,21264;61,39945;
904,36806;21,23088;61,40124;
905,26806;21,24884;61,39204;
906,168;21,2668;61,38616;
907,06806;21,28476;61,38123;
907,968;21,30276;61,37547;
908,86806;21,32076;61,371;
909,76806;21,33864;61,36407;
910,668;21,35676;61,36717;
911,56806;21,37472;61,36014;
912,468;21,39276;61,35551;
913,36806;21,41068;61,34848;
914,26806;21,4288;61,3449;
915,168;21,44668;61,33641;
916,06806;21,46468;61,33171;
916,968;21,48284;61,33003;
917,86806;21,50076;61,32283;
918,76806;21,5188;61,31788;
919,668;21,53672;61,30579;
920,56806;21,55488;61,30685;
921,468;21,57272;61,29496;
922,36806;21,59076;61,29141;
923,26806;21,60872;61,28572;
924,168;21,62684;61,27971;
925,06806;21,64484;61,27383;
925,968;21,6628;61,26504;
926,86806;21,6808;61,26273;
927,76806;21,69872;61,25382;
928,668;21,71676;61,24819;
929,56806;21,73468;61,23927;
930,468;21,7528;61,23589;
931,36806;21,77072;61,22639;
932,26806;21,78876;61,22134;
933,168;21,80668;61,2138;
934,06806;21,82468;61,20674;
934,968;21,84272;61,20254;
935,86806;21,8606;61,19291;
936,76806;21,87884;61,19257;
937,668;21,8968;61,17911;
938,56806;21,91492;61,17514;
939,468;21,93288;61,16427;
940,36806;21,95092;61,15825;
941,26806;21,9688;61,14828;
942,168;21,98672;61,13729;
943,06806;22,00476;61,13744;
943,968;22,02276;61,12716;
944,86806;22,04076;61,12019;
945,76806;22,05872;61,10983;
946,668;22,07684;61,10491;
947,56806;22,09472;61,09274;
948,468;22,11276;61,08608;
949,36806;22,13072;61,07787;
950,26806;22,14876;61,07218;
951,168;22,16668;61,06214;
952,06806;22,18472;61,05639;
952,968;22,20288;61,04892;
953,86806;22,2208;61,03374;
954,76806;22,2388;61,02453;
955,668;22,25668;61,01532;
956,56806;22,27484;61,01118;
957,468;22,29276;60,99661;
958,36806;22,31072;60,98759;
959,26806;22,32872;60,98182;
960,168;22,34668;60,96912;
961,06806;22,36472;60,96309;
961,968;22,38272;60,95073;
962,86806;22,4008;60,94527;
963,76806;22,41876;60,93268;
964,668;22,43684;60,92426;
965,56806;22,45484;60,91284;
966,468;22,47288;60,90199;
967,36806;22,4906;60,88633;
968,26806;22,50848;60,87796;
969,168;22,52664;60,87338;
970,06806;22,54468;60,85892;
970,968;22,5628;60,84852;
971,86806;22,58068;60,83106;
972,76806;22,59884;60,82591;
973,668;22,61668;60,80858;
974,56806;22,63468;60,79888;
975,468;22,65268;60,78829;
976,36806;22,67072;60,77629;
977,26806;22,68872;60,76521;
978,168;22,70672;60,75004;
979,06806;22,72484;60,74207;
979,968;22,74276;60,7235;
980,86806;22,76072;60,71129;
981,76806;22,77872;60,70039;
982,668;22,7968;60,68711;
983,56806;22,81472;60,67325;
984,468;22,83276;60,66074;
985,36806;22,85072;60,64863;
986,26806;22,86876;60,63203;
987,168;22,88676;60,6182;
988,06806;22,9046;60,60195;
988,968;22,92284;60,59585;
989,86806;22,9408;60,57797;
990,76806;22,95888;60,56828;
991,668;22,97684;60,55027;
992,56806;22,9948;60,53589;
993,468;23,01276;60,51919;
994,36806;23,03068;60,50337;
995,26806;23,04876;60,49351;
996,168;23,06672;60,47239;
997,06806;23,08472;60,45911;
997,968;23,10272;60,44205;
998,86806;23,12084;60,42877;
999,76806;23,1388;60,40989;
1000,668;23,15676;60,394;
1001,56806;23,17476;60,37974;
1002,468;23,19288;60,36281;
1003,36806;23,21088;60,34579;
1004,26806;23,22884;60,32668;
1005,168;23,24704;60,31405;
1006,06806;23,26492;60,2928;
1006,968;23,28288;60,27488;
1007,86806;23,30076;60,25703;
1008,76806;23,31888;60,24671;
1009,668;23,33684;60,22405;
1010,56806;23,35484;60,20658;
1011,468;23,37292;60,18895;
1012,36806;23,39088;60,16549;
1013,26806;23,40888;60,14896;
1014,168;23,42684;60,12807;
1015,06806;23,445;60,11369;
1015,96806;23,46292;60,08938;
1016,86806;23,48096;60,0729;
1017,76806;23,49892;60,0531;
1018,668;23,51708;60,03361;
1019,56806;23,53488;60,00556;
1020,46806;23,5528;59,98699;
1021,36806;23,571;59,97429;
1022,26806;23,58892;59,94925;
1023,168;23,60696;59,9297;
1024,068;23,62488;59,90613;
1024,968;23,64296;59,88858;
1025,86806;23,66088;59,86477;
1026,76806;23,67884;59,84129;
1027,66806;23,69692;59,82163;
1028,568;23,71496;59,79827;
1029,468;23,73296;59,77541;
1030,36806;23,751;59,75204;
1031,26806;23,76912;59,73461;
1032,16806;23,787;59,70611;
1033,068;23,8048;59,6816;
1033,968;23,82272;59,66475;
1034,86806;23,84096;59,64302;
1035,76806;23,85888;59,61438;
1036,66806;23,87688;59,58726;
1037,568;23,89492;59,56718;
1038,468;23,91288;59,53997;
1039,36806;23,93088;59,51637;
1040,26806;23,9488;59,49047;
1041,16806;23,96692;59,47067;
1042,068;23,98488;59,44182;
1042,968;24,00288;59,4169;
1043,86806;24,02092;59,39232;
1044,76806;24,03892;59,36506;
1045,66806;24,05688;59,3381;
1046,568;24,07484;59,30887;
1047,468;24,09304;59,28949;
1048,36806;24,111;59,25778;
1049,26812;24,129;59,2318;
1050,16812;24,14688;59,20256;
1051,068;24,165;59,17779;
1051,968;24,18292;59,14938;
1052,868;24,20092;59,12015;
1053,76812;24,21896;59,09691;
1054,66812;24,237;59,0657;
1055,568;24,25504;59,03553;
1056,468;24,273;59,00407;
1057,368;24,29112;58,97803;
1058,26812;24,30896;58,94405;
1059,16812;24,32696;58,918;
1060,068;24,34492;58,88799;
1060,968;24,363;58,85811;
1061,868;24,38096;58,82361;
1062,76812;24,39896;58,79217;
1063,66812;24,41704;58,76516;
1064,568;24,43496;58,72702;
1065,468;24,45304;58,70088;
1066,368;24,47096;58,66686;
1067,26812;24,48904;58,63864;
1068,16812;24,50696;58,60425;
1069,068;24,52508;58,56908;
1069,968;24,54304;58,53667;
1070,868;24,56112;58,5033;
1071,76812;24,57896;58,46743;
1072,66812;24,59684;58,43357;
1073,568;24,615;58,40704;
1074,468;24,63292;58,36621;
1075,368;24,651;58,33528;
1076,26812;24,66888;58,29864;
1077,16812;24,687;58,26608;
1078,068;24,70492;58,22549;
1078,968;24,72284;58,18869;
1079,868;24,74096;58,15814;
1080,76812;24,759;58,11831;
1081,66812;24,77696;58,0826;
1082,568;24,795;58,04707;
1083,468;24,8132;58,01519;
1084,368;24,83112;57,97288;
1085,26812;24,84904;57,9289;
1086,16812;24,86692;57,89313;
1087,068;24,88512;57,85865;
1087,968;24,90308;57,81513;
1088,868;24,92108;57,77699;
1089,76812;24,93916;57,73881;
1090,66812;24,95708;57,69784;
1091,568;24,97512;57,66052;
1092,468;24,99312;57,62017;
1093,368;25,01124;57,58135;
1094,26812;25,0292;57,53278;
1095,16812;25,04724;57,49459;
1096,068;25,06536;57,45549;
1096,968;25,08332;57,40884;
1097,868;25,1012;57,36425;
1098,76812;25,11908;57,32352;
1099,66812;25,13724;57,28756;
1100,568;25,15532;57,24129;
1101,468;25,17336;57,19885;
1102,368;25,19128;57,15079;
1103,26812;25,20932;57,10556;
1104,16812;25,22724;57,05903;
1105,068;25,2452;57,01525;
1105,968;25,26332;56,97554;
1106,868;25,28128;56,92534;
1107,76812;25,29932;56,88131;
1108,66812;25,3172;56,8346;
1109,568;25,33532;56,78986;
1110,468;25,3532;56,73844;
1111,368;25,37116;56,68981;
1112,26812;25,38924;56,64483;
1113,16812;25,40736;56,59714;
1114,068;25,42532;56,54563;
1114,968;25,44328;56,49434;
1115,868;25,46132;56,44889;
1116,76812;25,47928;56,39693;
1117,66812;25,49716;56,34736;
1118,568;25,51516;56,29368;
1119,468;25,53328;56,2445;
1120,368;25,55132;56,19234;
1121,26812;25,5694;56,13903;
1122,16812;25,58736;56,08578;
1123,068;25,60532;56,03065;
1123,968;25,62324;55,97898;
1124,868;25,6412;55,92564;
1125,76812;25,65928;55,87227;
1126,66812;25,6772;55,81506;
1127,568;25,69524;55,76321;
1128,468;25,71312;55,70451;
1129,368;25,73124;55,64825;
1130,26812;25,7492;55,5922;
1131,16812;25,76712;55,5336;
1132,068;25,78528;55,48134;
1132,968;25,80328;55,41959;
1133,868;25,82128;55,36288;
1134,76812;25,83928;55,30223;
1135,66812;25,8574;55,2431;
1136,568;25,87536;55,17881;
1137,468;25,89332;55,11667;
1138,368;25,91124;55,05496;
1139,26812;25,92936;54,99424;
1140,16812;25,94728;54,93057;
1141,068;25,96528;54,86751;
1141,968;25,9834;54,80624;
1142,868;26,00128;54,73908;
1143,76812;26,01932;54,67324;
1144,66812;26,03724;54,60486;
1145,56812;26,05544;54,54229;
1146,468;26,07336;54,47057;
1147,368;26,09136;54,40714;
1148,26812;26,10952;54,34315;
1149,16812;26,12756;54,26905;
1150,06812;26,14548;54,19681;
1150,968;26,16336;54,12773;
1151,868;26,18148;54,06116;
1152,76812;26,19952;53,98598;
1153,66812;26,21752;53,91634;
1154,56812;26,23544;53,84228;
1155,468;26,25356;53,77097;
1156,368;26,27148;53,69778;
1157,26812;26,28952;53,6223;
1158,16812;26,3076;53,55178;
1159,06812;26,32552;53,47094;
1159,968;26,3436;53,39273;
1160,868;26,36156;53,31465;
1161,76812;26,37976;53,23882;
1162,66812;26,39768;53,15545;
1163,56812;26,41544;53,07307;
1164,468;26,43348;52,99703;
1165,368;26,4516;52,9196;
1166,26812;26,46968;52,83652;
1167,16812;26,4876;52,74884;
1168,06812;26,50568;52,67007;
1168,968;26,5236;52,57989;
1169,868;26,5416;52,49633;
1170,76812;26,55952;52,40882;
1171,66812;26,57772;52,32226;
1172,56812;26,59564;52,2329;
1173,468;26,61364;52,14387;
1174,368;26,63168;52,0569;
1175,26812;26,64964;51,96229;
1176,16812;26,6676;51,86933;
1177,06812;26,68552;51,77549;
1177,968;26,70372;51,68569;
1178,868;26,72168;51,58647;
1179,76812;26,73976;51,48947;
1180,66812;26,75772;51,39288;
1181,56812;26,7758;51,29568;
1182,468;26,79372;51,19658;
1183,368;26,81164;51,09426;
1184,26812;26,82976;50,9979;
1185,16812;26,84776;50,88735;
1186,06812;26,86584;50,78607;
1186,968;26,88388;50,67813;
1187,868;26,90196;50,57159;
1188,76812;26,91984;50,46314;
1189,66812;26,9378;50,35352;
1190,56812;26,95584;50,24657;
1191,468;26,97388;50,13378;
1192,368;26,99184;50,01829;
1193,26812;27,00976;49,90115;
1194,16812;27,0278;49,78903;
1195,06812;27,04572;49,66803;
1195,968;27,0638;49,55184;
1196,868;27,08176;49,43052;
1197,76812;27,09988;49,31014;
1198,66812;27,11792;49,18263;
1199,56812;27,13592;49,05751;
1200,468;27,15404;48,93093;
1201,368;27,172;48,79563;
1202,26812;27,19004;48,66451;
1203,16812;27,20796;48,52587;
1204,06812;27,22604;48,39399;
1204,968;27,24404;48,25247;
1205,868;27,26204;48,11497;
1206,76812;27,28;47,97147;
1207,66812;27,29812;47,82347;
1208,56812;27,31604;47,67334;
1209,468;27,334;47,51348;
1210,368;27,35216;47,35074;
1211,26812;27,37016;47,12858;
1212,02;27,38524;46,51235;
1212,078;27,38688;42,53001;
1212,092;27,3884;25,50116;