File: tensile_test_data/primary_data/Zx4.csv
Time;Crosshead separation;Load;Extensometer elongation
(sec);(mm);(kN);(%)
0;0,00012;0,1972;-0,00777
0,864;0,03936;0,54564;-0,00617
1,312;0,09756;1,46272;-0,00204
1,668;0,15796;2,38938;0,00198
1,998;0,22376;3,31774;0,006
2,374;0,31136;4,23789;0,00983
2,666;0,3886;5,17065;0,01374
2,964;0,47408;6,1034;0,01783
3,224;0,5536;7,03412;0,02179
3,54;0,65732;7,96465;0,02573
3,76;0,73288;8,90196;0,02972
3,962;0,80384;9,83894;0,03366
4,158;0,87372;10,80503;0,03777
4,338;0,93864;11,72447;0,04166
4,518;1,00412;12,67218;0,04565
4,698;1,06976;13,6325;0,04976
4,876;1,1348;14,60442;0,05388
5,04;1,19488;15,51984;0,05779
5,206;1,25564;16,45111;0,06183
5,368;1,31524;17,38017;0,06573
5,53;1,374;18,30321;0,06984
5,692;1,4328;19,23879;0,07394
5,854;1,49124;20,18044;0,07808
6,016;1,5494;21,11903;0,08225
6,178;1,6068;22,05737;0,08648
6,34;1,66384;22,9951;0,09084
6,502;1,7206;23,92802;0,0951
6,664;1,77676;24,86546;0,09961
6,826;1,83224;25,79422;0,10408
6,988;1,88724;26,71054;0,10862
7,154;1,94252;27,64626;0,11352
7,328;1,99932;28,60697;0,1185
7,508;2,05708;29,58561;0,12381
7,688;2,11352;30,55246;0,12932
7,868;2,16856;31,48912;0,13483
8,052;2,2232;32,41251;0,14055
8,244;2,27848;33,35969;0,14669
8,444;2,33368;34,29703;0,15327
8,66;2,39076;35,24566;0,16025
8,884;2,44676;36,17869;0,16777
9,126;2,50352;37,11477;0,17592
9,392;2,56152;38,05111;0,18496
9,678;2,61888;38,97608;0,19487
10,016;2,67856;39,90181;0,20619
10,404;2,73924;40,81872;0,2191
10,88;2,80252;41,73387;0,23449
11,494;2,86944;42,64484;0,25319
12,326;2,94068;43,55142;0,27682
13,226;3,0032;44,28726;0,3011
14,126;3,05576;44,8413;0,32459
15,026;3,10164;45,28162;0,3479
15,926;3,14332;45,64847;0,37138
16,826;3,1802;45,90512;0,39406
17,726;3,21536;46,14836;0,41709
18,626;3,2464;46,29889;0,43931
19,526;3,27748;46,44678;0,46224
20,426;3,30748;46,50202;0,48448
21,326;3,3384;46,52472;0,50709
22,226;3,37252;46,59443;0,53002
23,126;3,39836;46,55958;0,55291
24,026;3,42316;46,54836;0,57566
24,926;3,44708;46,51545;0,5981
25,826;3,47;46,47143;0,62073
26,726;3,49192;46,41452;0,64325
27,626;3,51544;46,3894;0,66658
28,526;3,53352;46,28364;0,68908
29,426;3,55144;46,23231;0,71165
30,326;3,56752;46,14432;0,73435
31,226;3,58304;46,08979;0,75695
32,126;3,5974;46,02528;0,77958
33,026;3,61208;46,01551;0,80174
33,926;3,62668;46,0164;0,82424
34,826;3,64076;46,01191;0,84643
35,726;3,65552;46,03452;0,86929
36,626;3,66904;46,01818;0,89168
37,526;3,68292;46,02656;0,9142
38,426;3,70036;46,1553;0,93428
39,326;3,71092;45,94951;0,95949
40,226;3,72564;46,04202;0,98172
41,126;3,7386;46,03519;1,00398
42,026;3,752;46,05072;1,02654
42,926;3,76524;46,06228;1,04894
43,826;3,77904;46,09276;1,07159
44,726;3,79212;46,08682;1,09439
45,626;3,80528;46,09821;1,11668
46,526;3,81852;46,11298;1,13925
47,426;3,83172;46,12873;1,16148
48,326;3,84656;46,20232;1,18418
49,226;3,86072;46,24306;1,20667
50,126;3,8758;46,31378;1,22903
51,026;3,89116;46,37547;1,25171
51,926;3,90688;46,45003;1,27397
52,826;3,92308;46,51608;1,29669
53,726;3,9392;46,58254;1,31861
54,626;3,95624;46,65699;1,34108
55,526;3,97408;46,74394;1,36326
56,426;3,99204;46,80061;1,3859
57,326;4,01108;46,89119;1,40799
58,226;4,03408;47,03005;1,43065
59,126;4,05296;47,03696;1,45328
60,026;4,07364;47,12223;1,47567
60,926;4,09448;47,19295;1,49788
61,826;4,11652;47,28539;1,5205
62,726;4,1388;47,36862;1,5428
63,626;4,16172;47,44766;1,56534
64,526;4,18496;47,52592;1,58764
65,426;4,20916;47,62593;1,60986
66,32601;4,23368;47,71202;1,63231
67,22601;4,25888;47,79873;1,65496
68,126;4,28388;47,88699;1,6772
69,026;4,30988;47,98793;1,69984
69,926;4,33512;48,06381;1,72213
70,82601;4,3656;48,25053;1,74414
71,72601;4,39016;48,24204;1,76705
72,62601;4,41628;48,34735;1,78943
73,526;4,44296;48,4538;1,81222
74,426;4,46856;48,53189;1,83454
75,32601;4,4942;48,61988;1,85672
76,22601;4,52052;48,71564;1,87947
77,12601;4,54564;48,78706;1,90158
78,026;4,57236;48,91123;1,92425
78,926;4,5978;48,98748;1,94657
79,82601;4,62368;49,08367;1,96908
80,72601;4,6494;49,16938;1,99181
81,62601;4,67464;49,2577;2,01407
82,526;4,70068;49,36184;2,03681
83,426;4,72616;49,43845;2,05937
84,32601;4,7554;49,54352;2,08225
85,22601;4,77964;49,60752;2,10421
86,12601;4,80484;49,70397;2,12655
87,026;4,83044;49,80372;2,14924
87,926;4,85536;49,87163;2,17182
88,82601;4,88052;49,95944;2,19418
89,72601;4,90584;50,04444;2,21697
90,62601;4,9304;50,12628;2,23915
91,526;4,95524;50,21908;2,26142
92,426;4,98008;50,29309;2,28415
93,32601;5,00476;50,37301;2,30655
94,22601;5,02984;50,46296;2,32912
95,12601;5,05408;50,53203;2,35129
96,026;5,07884;50,62163;2,37361
96,926;5,10704;50,70686;2,39721
97,82601;5,13072;50,77913;2,41914
98,72601;5,15536;50,86895;2,44174
99,62601;5,17956;50,93453;2,46416
100,526;5,20404;51,0146;2,48667
101,426;5,2288;51,09577;2,50955
102,32601;5,2526;51,16083;2,53163
103,22601;5,2768;51,24008;2,55403
104,12601;5,30132;51,31324;2,57666
105,02601;5,32552;51,38743;2,5989
105,926;5,35032;51,47382;2,62158
106,82601;5,37452;51,53331;2,64418
107,72601;5,39872;51,60109;2,66675
108,62601;5,42684;51,7375;2,68941
109,52601;5,44948;51,74775;2,7116
110,426;5,47356;51,82596;2,73416
111,32601;5,497;51,88276;2,7564
112,22601;5,52136;51,96694;2,77889
113,12601;5,5456;52,04057;2,80153
114,02601;5,5694;52,0958;2,82393
114,926;5,59336;52,16702;2,84628
115,82601;5,6178;52,24185;2,869
116,72601;5,64212;52,30874;2,89144
117,62601;5,66632;52,37309;2,91391
118,52601;5,6904;52,42769;2,93645
119,426;5,71472;52,50334;2,9586
120,32601;5,74284;52,60134;2,98196
121,22601;5,76608;52,62946;3,0041
122,12601;5,7902;52,69015;3,02661
123,02601;5,81492;52,77002;3,04917
123,926;5,83876;52,81859;3,07142
124,82601;5,863;52,88271;3,09339
125,72601;5,88824;52,95066;3,11626
126,62601;5,91296;53,014;3,13893
127,52601;5,93784;53,08532;3,16128
128,42601;5,96192;53,12719;3,18379
129,32601;5,98648;53,19404;3,2061
130,22602;6,0114;53,261;3,22891
131,126;6,03932;53,3713;3,25165
132,026;6,0622;53,36621;3,27368
132,92602;6,0864;53,429;3,29609
133,826;6,1104;53,49041;3,31839
134,72602;6,13504;53,56345;3,34121
135,626;6,15904;53,60494;3,36373
136,526;6,18308;53,65795;3,38625
137,42602;6,20788;53,72528;3,40886
138,326;6,23196;53,77949;3,43107
139,22602;6,25632;53,83817;3,45357
140,126;6,2806;53,88982;3,47629
141,026;6,30456;53,94693;3,49873
141,92602;6,33176;54,04618;3,52151
142,826;6,35404;54,04167;3,54334
143,72602;6,378;54,10469;3,56575
144,626;6,40252;54,17177;3,58873
145,526;6,4262;54,21766;3,61104
146,42602;6,44992;54,26512;3,63341
147,326;6,47424;54,32242;3,65621
148,22602;6,49808;54,37432;3,67852
149,126;6,52256;54,43939;3,70122
150,026;6,54636;54,47026;3,72385
150,92602;6,57024;54,52474;3,74607
151,826;6,5966;54,64666;3,76746
152,72602;6,62008;54,61832;3,79122
153,488;6,6292;54,36646;3,80564
154,388;6,64656;54,52587;3,81881
155,28802;6,66468;54,6115;3,83491
156,188;6,68268;54,66208;3,85142
157,08802;6,70064;54,69907;3,86825
157,988;6,71868;54,74201;3,88497
158,888;6,7366;54,77815;3,9018
184,132;6,74856;53,52512;
185,03202;6,76644;54,21432;
185,932;6,78456;54,66097;
186,83202;6,80232;54,87999;
187,73202;6,82036;54,99093;
188,632;6,83836;55,04651;
189,53202;6,85644;55,08561;
190,432;6,87432;55,1149;
191,33202;6,89228;55,14378;
192,23202;6,91036;55,18083;
193,132;6,9284;55,21052;
194,03202;6,9464;55,24185;
194,932;6,96436;55,26834;
195,83202;6,98248;55,29996;
196,73202;7,00028;55,32746;
197,632;7,0182;55,3591;
198,53202;7,03624;55,39469;
199,432;7,0544;55,42695;
200,33202;7,07244;55,45541;
201,23202;7,09036;55,48754;
202,132;7,1084;55,52153;
203,03202;7,12636;55,5533;
203,932;7,14432;55,58594;
204,83202;7,16208;55,61313;
205,73202;7,1802;55,65135;
206,632;7,1982;55,68174;
207,53202;7,21628;55,71324;
208,432;7,23428;55,74571;
209,33202;7,25228;55,77359;
210,23202;7,2702;55,80554;
211,132;7,28812;55,83701;
212,03202;7,30628;55,87286;
212,932;7,32428;55,90128;
213,83202;7,34236;55,93203;
214,73202;7,36028;55,961;
215,632;7,37832;55,99074;
216,53202;7,3962;56,01823;
217,432;7,41408;56,04789;
218,33202;7,43224;56,08248;
219,23202;7,45024;56,11322;
220,132;7,46828;56,14321;
221,03202;7,48624;56,1702;
221,932;7,50428;56,20189;
222,83202;7,52224;56,22851;
223,73202;7,5402;56,25752;
224,632;7,55824;56,2865;
225,53202;7,57628;56,31484;
226,432;7,59424;56,34201;
227,33202;7,6122;56,36938;
228,23202;7,63028;56,40293;
229,132;7,6482;56,42725;
230,03202;7,66616;56,45543;
230,932;7,68412;56,48454;
231,83202;7,70232;56,51469;
232,73202;7,72028;56,53876;
233,632;7,73832;56,56669;
234,53202;7,75628;56,59301;
235,432;7,77432;56,62186;
236,33202;7,79232;56,64902;
237,23202;7,81028;56,67643;
238,132;7,82844;56,70871;
239,03202;7,84632;56,73096;
239,932;7,8642;56,75698;
240,83202;7,88216;56,78452;
241,73202;7,90024;56,81316;
242,63202;7,9182;56,83911;
243,53202;7,93616;56,86453;
244,432;7,95424;56,8974;
245,33202;7,97228;56,92034;
246,23202;7,99028;56,94778;
247,13202;8,00824;56,97045;
248,03202;8,02628;56,99599;
248,932;8,04412;57,02161;
249,83202;8,06228;57,05082;
250,73202;8,08032;57,07679;
251,63202;8,09832;57,09925;
252,53202;8,1162;57,12246;
253,432;8,13408;57,14885;
254,33202;8,15224;57,17893;
255,23202;8,17012;57,1978;
256,13202;8,18812;57,22684;
257,03202;8,20616;57,25279;
257,932;8,22424;57,2792;
258,832;8,24224;57,30151;
259,73203;8,26024;57,32474;
260,63202;8,27828;57,35248;
261,53202;8,29624;57,37178;
262,432;8,3142;57,39796;
263,332;8,33216;57,42052;
264,23203;8,35032;57,44759;
265,13203;8,36836;57,47076;
266,032;8,38644;57,49493;
266,932;8,40432;57,51445;
267,832;8,42236;57,53949;
268,73203;8,44028;57,56202;
269,63203;8,4582;57,58278;
270,532;8,47616;57,61063;
271,432;8,494;57,63002;
272,332;8,51212;57,66002;
273,23203;8,53004;57,68095;
274,13203;8,54816;57,70536;
275,032;8,56612;57,72552;
275,932;8,58408;57,74848;
276,832;8,60212;57,77255;
277,73203;8,62016;57,79448;
278,63203;8,63816;57,82098;
279,532;8,65612;57,84152;
280,432;8,6742;57,86791;
281,332;8,69212;57,88624;
282,23203;8,71004;57,90853;
283,13203;8,728;57,93023;
284,032;8,74616;57,95512;
284,932;8,76416;57,97521;
285,832;8,78216;57,99671;
286,73203;8,8002;58,01911;
287,63203;8,81812;58,03776;
288,532;8,83608;58,0604;
289,432;8,85396;58,08017;
290,332;8,87212;58,10587;
291,23203;8,89004;58,12227;
292,13203;8,90804;58,14677;
293,032;8,926;58,16538;
293,932;8,94404;58,18811;
294,832;8,96192;58,20751;
295,73203;8,97984;58,22593;
296,63203;8,99796;58,25555;
297,532;9,016;58,27378;
298,432;9,03408;58,29548;
299,332;9,052;58,31383;
300,23203;9,07008;58,3365;
301,13203;9,08804;58,35541;
302,032;9,10608;58,37603;
302,932;9,12416;58,3991;
303,832;9,14216;58,41965;
304,73203;9,16012;58,43624;
305,63203;9,17792;58,45187;
306,532;9,19604;58,47761;
307,432;9,21404;58,49432;
308,332;9,232;58,51575;
309,23203;9,25;58,53396;
310,13203;9,26812;58,5565;
311,032;9,28612;58,57367;
311,932;9,30412;58,59321;
312,832;9,32212;58,61319;
313,73203;9,34004;58,62829;
314,63203;9,35804;58,64839;
315,532;9,37616;58,67005;
316,432;9,39428;58,68945;
317,332;9,41204;58,70248;
318,23203;9,43004;58,72443;
319,13203;9,44796;58,74428;
320,032;9,46608;58,76513;
320,932;9,48396;58,78235;
321,832;9,50192;58,79766;
322,73203;9,52008;58,8207;
323,63203;9,53808;58,83495;
324,532;9,55612;58,85389;
325,432;9,57404;58,86902;
326,332;9,59212;58,89076;
327,23203;9,60996;58,90619;
328,13203;9,62792;58,92633;
329,032;9,646;58,95019;
329,932;9,66412;58,96438;
330,832;9,68212;58,9812;
331,73203;9,70008;58,99575;
332,63203;9,71804;59,01299;
333,532;9,73604;59,03123;
334,432;9,75404;59,04762;
335,332;9,77184;59,06242;
336,23203;9,78988;59,084;
337,13203;9,80784;59,10255;
338,032;9,82588;59,11862;
338,932;9,84396;59,13804;
339,83203;9,86188;59,15306;
340,73203;9,87992;59,16901;
341,63203;9,89784;59,18452;
342,532;9,91596;59,20604;
343,432;9,93396;59,21947;
344,33203;9,95204;59,23806;
345,23203;9,97004;59,25277;
346,13203;9,98804;59,26784;
347,032;10,00596;59,28299;
347,932;10,02388;59,29669;
348,83203;10,04208;59,31915;
349,73203;10,06012;59,33087;
350,63203;10,0782;59,34955;
351,532;10,09612;59,36307;
352,432;10,1142;59,38044;
353,33203;10,13212;59,39583;
354,23203;10,15008;59,41023;
355,13203;10,16804;59,4289;
356,032;10,18604;59,44287;
356,932;10,20412;59,45863;
357,83203;10,22204;59,47201;
358,73203;10,24016;59,49134;
359,63203;10,25804;59,50329;
360,532;10,27596;59,51895;
361,432;10,29392;59,53586;
362,33203;10,312;59,55476;
363,23203;10,33004;59,56731;
364,13203;10,348;59,57862;
365,032;10,36604;59,59705;
365,932;10,384;59,60764;
366,83203;10,40204;59,62415;
367,73203;10,42;59,63753;
368,63203;10,43812;59,65472;
369,532;10,456;59,66541;
370,432;10,47392;59,68242;
371,33203;10,49184;59,69407;
372,23203;10,50992;59,71358;
373,13203;10,52784;59,72579;
374,032;10,5458;59,73845;
374,932;10,56392;59,75838;
375,83203;10,58188;59,76876;
376,73203;10,6;59,78562;
377,63203;10,61792;59,79814;
378,532;10,636;59,81685;
379,432;10,65388;59,82688;
380,33203;10,67192;59,84138;
381,23203;10,69012;59,85905;
382,13203;10,70816;59,86927;
383,032;10,726;59,8781;
383,932;10,74392;59,8913;
384,83203;10,76208;59,91014;
385,73203;10,77996;59,92103;
386,63203;10,79796;59,93636;
387,532;10,81592;59,95038;
388,432;10,83404;59,96451;
389,33203;10,852;59,9748;
390,23203;10,87;59,9873;
391,13203;10,88804;60,00307;
392,032;10,90592;60,01071;
392,932;10,92384;60,02339;
393,83203;10,94176;60,03733;
394,73203;10,95996;60,05526;
395,63203;10,97796;60,06566;
396,532;10,996;60,07801;
397,432;11,01404;60,08993;
398,33203;11,03192;60,09908;
399,23203;11,04992;60,11513;
400,13203;11,06788;60,12668;
401,032;11,08584;60,14137;
401,932;11,1038;60,15494;
402,83203;11,12192;60,17305;
403,73203;11,1398;60,18332;
404,63203;11,15792;60,19626;
405,532;11,1758;60,20498;
406,432;11,1938;60,21812;
407,33203;11,21192;60,23214;
408,23203;11,22992;60,24206;
409,13203;11,248;60,25437;
410,032;11,26596;60,26496;
410,932;11,28404;60,27894;
411,83203;11,30192;60,28851;
412,73203;11,3198;60,30176;
413,63203;11,3378;60,31308;
414,532;11,35596;60,32736;
415,432;11,37396;60,3371;
416,33203;11,392;60,34586;
417,23203;11,41004;60,36011;
418,13203;11,428;60,3691;
419,032;11,446;60,382;
419,932;11,46392;60,39319;
420,83203;11,48204;60,40837;
421,73203;11,49992;60,41504;
422,63203;11,51796;60,42632;
423,532;11,53596;60,43741;
424,432;11,55396;60,44666;
425,33203;11,57188;60,45709;
426,23203;11,5898;60,46821;
427,13203;11,60796;60,48644;
428,032;11,62592;60,49354;
428,932;11,644;60,50751;
429,83203;11,66192;60,51356;
430,73203;11,68;60,52548;
431,63203;11,69796;60,53513;
432,532;11,71596;60,54438;
433,432;11,73408;60,56014;
434,33203;11,75208;60,5679;
435,23203;11,77004;60,57726;
436,13203;11,78788;60,58413;
437,032;11,80596;60,60034;
437,932;11,82388;60,60919;
438,83203;11,84192;60,61851;
439,73203;11,85988;60,62924;
440,63203;11,878;60,64275;
441,532;11,896;60,65013;
442,432;11,91404;60,66075;
443,33203;11,93212;60,67173;
444,23203;11,95;60,67744;
445,13203;11,96792;60,6894;
446,032;11,986;60,70114;
446,932;12,00416;60,71404;
447,83203;12,022;60,71408;
448,73203;12,03992;60,72853;
449,63203;12,05796;60,73856;
450,532;12,07596;60,74889;
451,432;12,09388;60,75809;
452,33203;12,11184;60,76744;
453,23203;12,13;60,78379;
454,13203;12,148;60,78952;
455,032;12,16604;60,80154;
455,932;12,18392;60,80822;
456,83203;12,202;60,81882;
457,73203;12,21988;60,82504;
458,63203;12,23784;60,83539;
459,532;12,25596;60,84936;
460,432;12,27396;60,85827;
461,33203;12,29208;60,86745;
462,23203;12,31;60,87356;
463,13203;12,32804;60,88236;
464,032;12,34592;60,89052;
464,932;12,36388;60,90067;
465,83203;12,382;60,91027;
466,73203;12,39992;60,91586;
467,63203;12,41792;60,9273;
468,532;12,43588;60,9343;
469,43203;12,454;60,94874;
470,33203;12,47188;60,95434;
471,23203;12,48984;60,96315;
472,13203;12,50784;60,97299;
473,032;12,526;60,98373;
473,93203;12,54392;60,98924;
474,83203;12,562;60,9997;
475,73203;12,58004;61,0092;
476,63203;12,598;61,01294;
477,532;12,61588;61,02169;
478,43203;12,6338;61,0311;
479,33203;12,652;61,04562;
480,23203;12,66992;61,04999;
481,13203;12,68804;61,05989;
482,032;12,70596;61,06438;
482,93203;12,724;61,07243;
483,83203;12,74192;61,07906;
484,73203;12,75984;61,08634;
485,63203;12,77792;61,10011;
486,532;12,79584;61,10483;
487,43203;12,81388;61,11798;
488,33203;12,8318;61,12196;
489,23203;12,84988;61,13204;
490,13203;12,86772;61,13802;
491,032;12,88564;61,1433;
491,93203;12,90372;61,15784;
492,83203;12,9218;61,16331;
493,73203;12,93992;61,17289;
494,63203;12,95784;61,17813;
495,532;12,97592;61,18848;
496,43203;12,99376;61,19297;
497,33203;13,0118;61,20296;
498,23203;13,02984;61,21044;
499,13203;13,04804;61,22053;
500,032;13,06596;61,22311;
500,93203;13,08388;61,22946;
501,83203;13,10184;61,23873;
502,73203;13,11976;61,24488;
503,63203;13,13772;61,25532;
504,532;13,15572;61,26305;
505,43203;13,17384;61,27546;
506,33203;13,1918;61,27599;
507,23203;13,20992;61,28564;
508,13203;13,22784;61,29021;
509,032;13,24592;61,29687;
509,93203;13,26372;61,30161;
510,83203;13,28168;61,3117;
511,73203;13,3;61,32695;
512,63203;13,31792;61,32967;
513,53203;13,33572;61,33224;
514,432;13,3536;61,33983;
515,33203;13,37172;61,35207;
516,232;13,38968;61,3536;
517,13203;13,40764;61,36195;
518,03203;13,42576;61,37022;
518,932;13,44384;61,37612;
519,83203;13,46184;61,38174;
520,732;13,4798;61,38448;
521,63203;13,49788;61,39755;
522,53203;13,5158;61,40168;
523,432;13,53376;61,40621;
524,332;13,5518;61,41421;
525,232;13,56996;61,42154;
526,132;13,58796;61,42589;
527,03206;13,606;61,43236;
527,932;13,624;61,43945;
528,832;13,64184;61,44221;
529,73206;13,65984;61,45093;
530,632;13,67776;61,45576;
531,53206;13,69584;61,46374;
532,432;13,71372;61,4666;
533,332;13,7318;61,47679;
534,23206;13,74976;61,48179;
535,132;13,76776;61,48757;
536,03206;13,78572;61,49267;
536,932;13,80372;61,50042;
537,832;13,82188;61,51257;
538,73206;13,8398;61,51332;
539,632;13,85788;61,52225;
540,53206;13,87584;61,52431;
541,432;13,89396;61,53157;
542,332;13,91184;61,53519;
543,23206;13,92976;61,53852;
544,132;13,94784;61,55003;
545,03206;13,96592;61,55717;
545,932;13,98396;61,56318;
546,832;14,00192;61,56694;
547,73206;14,02;61,57395;
548,632;14,03792;61,57633;
549,53206;14,05592;61,58283;
550,432;14,07388;61,58729;
551,332;14,09196;61,59417;
552,23206;14,10988;61,59683;
553,132;14,12788;61,60566;
554,03206;14,14588;61,61179;
554,932;14,16372;61,61425;
555,832;14,18168;61,62266;
556,73206;14,19968;61,62651;
557,632;14,21788;61,63612;
558,53206;14,23584;61,63762;
559,432;14,25388;61,64348;
560,332;14,2718;61,64533;
561,23206;14,28976;61,64871;
562,132;14,30768;61,65707;
563,03206;14,32572;61,66583;
563,932;14,34396;61,67299;
564,832;14,36192;61,67499;
565,73206;14,37992;61,67893;
566,632;14,39776;61,67958;
567,53206;14,4158;61,68801;
568,432;14,43372;61,69181;
569,332;14,45168;61,69888;
570,23206;14,4698;61,70566;
571,132;14,48784;61,71041;
572,03206;14,5058;61,7153;
572,932;14,5238;61,71671;
573,832;14,54188;61,72393;
574,73206;14,5598;61,72506;
575,632;14,57776;61,73046;
576,53206;14,59584;61,73946;
577,432;14,61404;61,74522;
578,332;14,63196;61,74592;
579,23206;14,6498;61,74501;
580,132;14,6678;61,75769;
581,03206;14,68576;61,76092;
581,932;14,70376;61,76322;
582,832;14,72172;61,7681;
583,73206;14,73988;61,77508;
584,632;14,7578;61,77558;
585,53206;14,7758;61,78328;
586,432;14,79376;61,78642;
587,332;14,81172;61,79339;
588,23206;14,82972;61,79849;
589,132;14,84768;61,80227;
590,03206;14,8658;61,81207;
590,932;14,8838;61,81135;
591,832;14,90192;61,82016;
592,73206;14,91988;61,81966;
593,632;14,93796;61,82463;
594,53206;14,9558;61,82641;
595,432;14,9738;61,83318;
596,332;14,99192;61,84345;
597,23206;15,00976;61,84033;
598,132;15,02776;61,84538;
599,03206;15,04572;61,85001;
599,932;15,06384;61,85694;
600,832;15,08168;61,85775;
601,73206;15,09968;61,86372;
602,632;15,11768;61,86855;
603,53206;15,13572;61,87493;
604,432;15,15368;61,87522;
605,332;15,17164;61,88394;
606,23206;15,18976;61,89001;
607,132;15,20772;61,88855;
608,03206;15,22564;61,89239;
608,932;15,2436;61,8962;
609,832;15,26168;61,90127;
610,73206;15,27968;61,90357;
611,632;15,29776;61,9077;
612,53206;15,31564;61,9121;
613,432;15,33372;61,91803;
614,332;15,35164;61,91967;
615,23206;15,36972;61,92368;
616,132;15,38784;61,92904;
617,03206;15,40568;61,92862;
617,932;15,42372;61,93444;
618,832;15,44164;61,93632;
619,73206;15,45972;61,94143;
620,632;15,47764;61,94443;
621,53206;15,49556;61,9473;
622,432;15,51372;61,95637;
623,332;15,53172;61,95513;
624,23206;15,54976;61,95874;
625,132;15,56772;61,95859;
626,03206;15,58576;61,96614;
626,932;15,60368;61,96874;
627,832;15,62168;61,97307;
628,73206;15,63976;61,98058;
629,632;15,65792;61,9835;
630,53206;15,6758;61,9826;
631,432;15,6938;61,98652;
632,332;15,7118;61,98899;
633,23206;15,72968;61,99269;
634,132;15,74768;61,99554;
635,03206;15,7656;61,99847;
635,932;15,78372;62,00428;
636,832;15,80172;62,0049;
637,73206;15,81972;62,01108;
638,632;15,83776;62,0145;
639,53206;15,85572;62,01476;
640,432;15,87364;62,01679;
641,332;15,8916;62,01934;
642,23206;15,90992;62,03225;
643,132;15,92792;62,02896;
644,03206;15,9458;62,02828;
644,932;15,96364;62,02993;
645,832;15,98172;62,03683;
646,73206;15,99964;62,04038;
647,632;16,01764;62,04202;
648,53206;16,03584;62,0502;
649,432;16,05384;62,04916;
650,332;16,07188;62,05254;
651,23206;16,08976;62,05161;
652,132;16,10784;62,05675;
653,03206;16,12572;62,05743;
653,932;16,14368;62,0612;
654,832;16,16172;62,06462;
655,73206;16,1798;62,06869;
656,632;16,19784;62,07175;
657,53206;16,21588;62,07354;
658,432;16,234;62,07907;
659,332;16,25188;62,07539;
660,23206;16,2698;62,08068;
661,132;16,28784;62,08452;
662,03206;16,30596;62,08711;
662,932;16,3238;62,08801;
663,832;16,3418;62,09106;
664,73206;16,35984;62,097;
665,632;16,37788;62,09514;
666,53206;16,39588;62,09771;
667,432;16,4138;62,09945;
668,332;16,432;62,10546;
669,23206;16,44988;62,10145;
670,132;16,46788;62,10629;
671,03206;16,48584;62,10819;
671,932;16,50384;62,11257;
672,832;16,52176;62,11246;
673,73206;16,53968;62,11445;
674,632;16,55784;62,12136;
675,53206;16,57576;62,12091;
676,432;16,59376;62,12628;
677,332;16,61172;62,12669;
678,23206;16,62976;62,13049;
679,132;16,64768;62,13326;
680,03206;16,66568;62,1349;
680,932;16,6838;62,14038;
681,832;16,7018;62,13763;
682,73206;16,71968;62,13918;
683,632;16,73768;62,14126;
684,53206;16,75572;62,14542;
685,432;16,7736;62,14514;
686,332;16,79164;62,14832;
687,23206;16,80956;62,15062;
688,132;16,82768;62,15499;
689,03206;16,84568;62,15397;
689,932;16,86368;62,15639;
690,832;16,8818;62,15988;
691,73206;16,89972;62,1577;
692,632;16,91772;62,16027;
693,53206;16,93572;62,16122;
694,432;16,95392;62,16928;
695,332;16,97188;62,16685;
696,23206;16,98984;62,16891;
697,132;17,00776;62,16801;
698,03206;17,02572;62,16936;
698,932;17,04364;62,17238;
699,832;17,06164;62,17479;
700,73206;17,0798;62,18081;
701,632;17,09776;62,17853;
702,53206;17,1158;62,18035;
703,432;17,13368;62,18156;
704,332;17,1518;62,18682;
705,23206;17,16964;62,18196;
706,132;17,18756;62,18476;
707,03206;17,20568;62,19088;
707,932;17,22384;62,19453;
708,832;17,24184;62,19267;
709,73206;17,25964;62,18808;
710,632;17,27768;62,19545;
711,53206;17,2956;62,19694;
712,432;17,31356;62,2013;
713,332;17,33164;62,20292;
714,23206;17,34976;62,20337;
715,132;17,36776;62,2035;
716,03206;17,3858;62,20318;
716,932;17,40384;62,20667;
717,832;17,42176;62,20488;
718,73206;17,43976;62,20692;
719,632;17,45764;62,20843;
720,53206;17,47584;62,21458;
721,432;17,49376;62,21216;
722,332;17,51188;62,21535;
723,23206;17,52988;62,21408;
724,132;17,54788;62,21211;
725,03206;17,56576;62,20986;
725,932;17,58372;62,21316;
726,832;17,60192;62,21982;
727,73206;17,61964;62,2111;
728,632;17,63768;62,21926;
729,53206;17,65564;62,22005;
730,432;17,67372;62,22209;
731,332;17,69164;62,21882;
732,23206;17,70968;62,22013;
733,132;17,72776;62,22477;
734,03206;17,74572;62,2242;
734,932;17,76376;62,22472;
735,832;17,78172;62,22416;
736,73206;17,79988;62,22897;
737,632;17,81772;62,22664;
738,53206;17,83564;62,22799;
739,432;17,85364;62,22993;
740,332;17,87172;62,23103;
741,23206;17,88972;62,22908;
742,132;17,90776;62,23195;
743,03206;17,92588;62,23384;
743,932;17,94376;62,23058;
744,832;17,96176;62,23306;
745,73206;17,97976;62,23469;
746,632;17,99792;62,23853;
747,53206;18,0158;62,23296;
748,432;18,03384;62,23518;
749,332;18,05184;62,23648;
750,23206;18,0698;62,23472;
751,132;18,08772;62,23618;
752,03206;18,10564;62,23501;
752,932;18,1238;62,24239;
753,832;18,14176;62,24066;
754,73206;18,1598;62,2428;
755,632;18,17768;62,23903;
756,53206;18,19572;62,24067;
757,432;18,2136;62,23994;
758,332;18,2316;62,24182;
759,23206;18,2498;62,24725;
760,132;18,2678;62,24563;
761,03206;18,28584;62,24431;
761,932;18,30372;62,24292;
762,832;18,32172;62,24548;
763,73206;18,33956;62,24281;
764,632;18,35756;62,24546;
765,53206;18,37564;62,24726;
766,432;18,3938;62,24709;
767,332;18,41172;62,24422;
768,23206;18,42976;62,24257;
769,132;18,4478;62,2475;
770,03206;18,46572;62,24353;
770,932;18,48364;62,24678;
771,832;18,50156;62,24577;
772,73206;18,5198;62,25093;
773,632;18,53784;62,24629;
774,53206;18,55584;62,24576;
775,432;18,57368;62,2436;
776,332;18,59164;62,24245;
777,23206;18,6096;62,24518;
778,132;18,62756;62,24476;
779,03206;18,6458;62,2528;
779,932;18,66376;62,24732;
780,832;18,6818;62,24981;
781,73206;18,6998;62,24582;
782,632;18,71788;62,24585;
783,53206;18,7358;62,2441;
784,432;18,7538;62,24337;
785,332;18,77192;62,24856;
786,23206;18,78992;62,24485;
787,132;18,80796;62,24694;
788,03206;18,82596;62,24526;
788,93206;18,84404;62,24639;
789,832;18,86196;62,24184;
790,73206;18,87984;62,23997;
791,632;18,89792;62,24403;
792,53206;18,916;62,24343;
793,43206;18,93384;62,23829;
794,332;18,95176;62,23958;
795,23206;18,96992;62,24421;
796,132;18,98784;62,2394;
797,03206;19,00576;62,24189;
797,93206;19,02376;62,23893;
798,832;19,04188;62,24367;
799,73206;19,0598;62,23707;
800,632;19,07784;62,23999;
801,53206;19,09592;62,24328;
802,43206;19,11388;62,23853;
803,332;19,13172;62,23724;
804,23206;19,14964;62,23758;
805,132;19,1678;62,2393;
806,03206;19,18568;62,23882;
806,93206;19,20384;62,23972;
807,832;19,2218;62,23724;
808,73206;19,23984;62,2349;
809,632;19,25776;62,23332;
810,53206;19,27572;62,23567;
811,43206;19,29392;62,23749;
812,332;19,31184;62,23408;
813,23206;19,32984;62,23346;
814,132;19,34772;62,22877;
815,03206;19,3658;62,23218;
815,93206;19,38372;62,22758;
816,832;19,40168;62,22679;
817,73206;19,41972;62,22816;
818,632;19,43776;62,22672;
819,53206;19,45572;62,22665;
820,43206;19,47368;62,22585;
821,332;19,49176;62,22796;
822,23206;19,50964;62,22425;
823,132;19,5276;62,22263;
824,03206;19,54564;62,22433;
824,93206;19,56384;62,22479;
825,832;19,5818;62,21939;
826,73206;19,59984;62,21709;
827,632;19,6178;62,21607;
828,53206;19,63564;62,21129;
829,43206;19,65364;62,21358;
830,332;19,67164;62,21277;
831,23206;19,68988;62,21721;
832,132;19,70784;62,20844;
833,03206;19,72588;62,21129;
833,93206;19,74384;62,20757;
834,832;19,76192;62,20673;
835,73206;19,77984;62,20403;
836,632;19,79776;62,20198;
837,53206;19,81592;62,20827;
838,43206;19,83404;62,20524;
839,332;19,85208;62,2026;
840,23206;19,86984;62,19416;
841,132;19,88788;62,19758;
842,03206;19,90576;62,19597;
842,93206;19,92376;62,19716;
843,832;19,94184;62,19847;
844,73206;19,95988;62,19587;
845,632;19,97788;62,19369;
846,53206;19,9958;62,19006;
847,43206;20,01388;62,19206;
848,332;20,03176;62,18619;
849,23206;20,04976;62,18824;
850,132;20,06772;62,18463;
851,03206;20,08584;62,18657;
851,93206;20,1038;62,18223;
852,832;20,12184;62,18196;
853,73206;20,13996;62,1846;
854,632;20,15784;62,17734;
855,53206;20,17572;62,17642;
856,43206;20,19372;62,17406;
857,332;20,21196;62,17859;
858,23206;20,22988;62,17026;
859,132;20,2478;62,16854;
860,03206;20,26572;62,16682;
860,93206;20,2838;62,16663;
861,832;20,30176;62,16362;
862,73206;20,31968;62,16368;
863,632;20,33792;62,16768;
864,53206;20,35584;62,15702;
865,43206;20,37388;62,15689;
866,332;20,3918;62,15158;
867,23206;20,40988;62,15205;
868,132;20,4278;62,14765;
869,03206;20,44576;62,1456;
869,93206;20,46384;62,14946;
870,832;20,48184;62,14558;
871,73206;20,49976;62,14456;
872,632;20,51776;62,13995;
873,53206;20,53588;62,14156;
874,43206;20,55384;62,13766;
875,332;20,5718;62,13508;
876,23206;20,5898;62,13496;
877,132;20,60792;62,13285;
878,03206;20,62572;62,12592;
878,93206;20,64372;62,12825;
879,832;20,6618;62,12949;
880,73206;20,67968;62,12159;
881,632;20,69768;62,12043;
882,53206;20,71564;62,11796;
883,43206;20,73376;62,11921;
884,332;20,75168;62,11339;
885,23206;20,76976;62,11157;
886,132;20,78776;62,1106;
887,03206;20,80572;62,10642;
887,93206;20,82368;62,10273;
888,832;20,84164;62,09911;
889,73206;20,85988;62,10447;
890,632;20,87788;62,09701;
891,53206;20,89592;62,09516;
892,43206;20,91376;62,09142;
893,332;20,9318;62,0886;
894,23206;20,94956;62,08378;
895,132;20,96756;62,08661;
896,03206;20,98568;62,08957;
896,93206;21,00376;62,08543;
897,832;21,02176;62,0793;
898,73206;21,03976;62,07474;
899,632;21,05788;62,07518;
900,53206;21,07576;62,0699;
901,43206;21,09376;62,06712;
902,332;21,11172;62,06588;
903,23206;21,12984;62,06558;
904,132;21,14792;62,06316;
905,03206;21,16588;62,05694;
905,93206;21,18376;62,05497;
906,832;21,20164;62,04953;
907,73206;21,21964;62,04997;
908,632;21,23764;62,04787;
909,53206;21,25584;62,04657;
910,43206;21,27372;62,04161;
911,332;21,2918;62,0397;
912,23206;21,30976;62,03609;
913,132;21,32772;62,03163;
914,03206;21,34564;62,02816;
914,93206;21,3636;62,0244;
915,832;21,38184;62,0261;
916,73206;21,39976;62,01703;
917,632;21,41784;62,01647;
918,53206;21,43572;62,01094;
919,43206;21,4538;62,01048;
920,332;21,47172;62,00712;
921,23206;21,48956;61,99947;
922,132;21,50784;62,00553;
923,03206;21,52584;61,9976;
923,93206;21,54372;61,98917;
924,832;21,5616;61,98324;
925,73206;21,57968;61,98393;
926,632;21,5976;61,9788;
927,53206;21,61564;61,97627;
928,43206;21,63368;61,97572;
929,332;21,6518;61,97276;
930,23206;21,66972;61,96304;
931,132;21,68768;61,95942;
932,03206;21,7058;61,96036;
932,93206;21,72368;61,95364;
933,832;21,74168;61,95256;
934,73206;21,75964;61,94654;
935,632;21,77776;61,94652;
936,53206;21,79564;61,93957;
937,43206;21,81364;61,93896;
938,332;21,83172;61,93632;
939,23206;21,84968;61,92692;
940,132;21,86764;61,9244;
941,03206;21,88564;61,91955;
941,93206;21,90388;61,92082;
942,832;21,9218;61,91211;
943,73206;21,93976;61,90811;
944,632;21,95764;61,90328;
945,53206;21,97572;61,9005;
946,43206;21,99356;61,89629;
947,332;22,01156;61,88989;
948,23206;22,02968;61,88932;
949,132;22,04768;61,88222;
950,03206;22,06572;61,87744;
950,93206;22,08364;61,87389;
951,832;22,1018;61,872;
952,73206;22,11968;61,86391;
953,632;22,1376;61,86238;
954,53206;22,15572;61,86184;
955,43206;22,17384;61,85672;
956,332;22,19188;61,84955;
957,23206;22,20992;61,84201;
958,132;22,228;61,84061;
959,03206;22,24584;61,83006;
959,93206;22,26372;61,82655;
960,832;22,28176;61,82355;
961,73206;22,29992;61,82097;
962,632;22,31784;61,81329;
963,53206;22,33588;61,81043;
964,43206;22,35388;61,80472;
965,332;22,37188;61,79653;
966,23206;22,38984;61,79169;
967,132;22,40772;61,78619;
968,03206;22,42592;61,7869;
968,93206;22,44392;61,77993;
969,832;22,46204;61,77687;
970,73206;22,47992;61,76683;
971,632;22,49776;61,75795;
972,53206;22,51568;61,75384;
973,43206;22,53368;61,75049;
974,332;22,55188;61,74892;
975,23206;22,56988;61,73966;
976,132;22,58784;61,73431;
977,03206;22,60588;61,7302;
977,93206;22,62392;61,72388;
978,832;22,64184;61,71804;
979,73206;22,65976;61,7088;
980,632;22,6778;61,70488;
981,53206;22,69588;61,6987;
982,43206;22,7138;61,69137;
983,332;22,7318;61,68581;
984,23206;22,75;61,68339;
985,132;22,76788;61,67397;
986,03206;22,78584;61,66904;
986,93206;22,80372;61,66314;
987,832;22,82188;61,65966;
988,73206;22,83988;61,64802;
989,632;22,85772;61,63909;
990,53206;22,8758;61,63496;
991,43206;22,89376;61,62533;
992,332;22,91176;61,62058;
993,23206;22,92976;61,6109;
994,132;22,94792;61,60964;
995,03206;22,96588;61,59963;
995,93206;22,98388;61,59332;
996,832;23,00184;61,58265;
997,73206;23,01988;61,57413;
998,632;23,03776;61,56673;
999,53206;23,05576;61,56003;
1000,43206;23,07392;61,5573;
1001,332;23,0918;61,54551;
1002,23206;23,10984;61,53936;
1003,132;23,12776;61,53097;
1004,03206;23,14592;61,52676;
1004,93206;23,16384;61,51453;
1005,832;23,18176;61,50608;
1006,73206;23,19992;61,49851;
1007,632;23,218;61,49032;
1008,53206;23,23596;61,48027;
1009,43206;23,25388;61,46998;
1010,332;23,27192;61,46444;
1011,23206;23,28984;61,45284;
1012,132;23,30776;61,4473;
1013,03206;23,32576;61,44035;
1013,93206;23,34384;61,43063;
1014,832;23,36172;61,41605;
1015,73206;23,37976;61,40882;
1016,632;23,3978;61,40183;
1017,53206;23,41572;61,38999;
1018,43206;23,43368;61,37987;
1019,332;23,4516;61,37136;
1020,23206;23,46984;61,36761;
1021,132;23,4878;61,3526;
1022,03206;23,50592;61,34309;
1022,93206;23,52388;61,32641;
1023,832;23,54184;61,3142;
1024,73206;23,55972;61,30224;
1025,63206;23,57768;61,2934;
1026,53212;23,59588;61,29163;
1027,432;23,61388;61,27539;
1028,332;23,63188;61,26449;
1029,23206;23,64988;61,2507;
1030,13206;23,66796;61,24035;
1031,03212;23,68588;61,22485;
1031,932;23,70388;61,21063;
1032,832;23,72196;61,20209;
1033,73206;23,74;61,18844;
1034,63206;23,75808;61,17773;
1035,53212;23,77604;61,16475;
1036,432;23,79396;61,14941;
1037,332;23,8118;61,13915;
1038,23206;23,82976;61,12732;
1039,13206;23,8478;61,11497;
1040,03212;23,86588;61,10236;
1040,932;23,88384;61,08564;
1041,832;23,90188;61,07402;
1042,73206;23,92;61,06279;
1043,63206;23,93792;61,04422;
1044,53212;23,95588;61,03113;
1045,432;23,97388;61,01615;
1046,332;23,99196;61,00446;
1047,23206;24,00992;60,98256;
1048,13206;24,02796;60,97076;
1049,03212;24,04596;60,95618;
1049,932;24,064;60,93758;
1050,832;24,082;60,9225;
1051,732;24,09984;60,90376;
1052,63213;24,11808;60,89569;
1053,53212;24,13596;60,877;
1054,432;24,154;60,86226;
1055,332;24,17184;60,84286;
1056,232;24,18992;60,82625;
1057,13213;24,20788;60,80841;
1058,03212;24,22584;60,79191;
1058,932;24,244;60,77952;
1059,832;24,26204;60,75771;
1060,732;24,28004;60,73838;
1061,63213;24,29796;60,71857;
1062,53212;24,316;60,70378;
1063,432;24,33396;60,68139;
1064,332;24,35192;60,66141;
1065,232;24,36992;60,64418;
1066,13213;24,388;60,62512;
1067,03212;24,40588;60,6042;
1067,932;24,42388;60,58574;
1068,832;24,44196;60,56769;
1069,732;24,45988;60,54427;
1070,63213;24,4778;60,52586;
1071,53212;24,49576;60,50659;
1072,432;24,514;60,48674;
1073,332;24,53196;60,46134;
1074,232;24,54992;60,43883;
1075,13213;24,56792;60,42013;
1076,03212;24,58584;60,39463;
1076,932;24,60384;60,37371;
1077,832;24,62176;60,35135;
1078,732;24,63996;60,33479;
1079,63213;24,65788;60,30641;
1080,53212;24,67588;60,2827;
1081,432;24,69388;60,25736;
1082,332;24,71192;60,23387;
1083,232;24,72984;60,20846;
1084,13213;24,74784;60,1845;
1085,03212;24,76596;60,16673;
1085,932;24,784;60,13867;
1086,832;24,80204;60,11201;
1087,732;24,82;60,08477;
1088,63213;24,83804;60,05996;
1089,53212;24,85588;60,02839;
1090,432;24,8738;60,00267;
1091,332;24,89188;59,97872;
1092,232;24,91004;59,95141;
1093,13213;24,928;59,92248;
1094,03212;24,946;59,89366;
1094,932;24,96404;59,87062;
1095,832;24,982;59,8394;
1096,732;24,99992;59,80995;
1097,63213;25,01788;59,78047;
1098,53212;25,03608;59,75548;
1099,432;25,05404;59,72342;
1100,332;25,0722;59,69617;
1101,232;25,0902;59,66531;
1102,13213;25,10792;59,62957;
1103,03212;25,1258;59,60469;
1103,932;25,14384;59,57829;
1104,832;25,16208;59,55081;
1105,732;25,18004;59,51464;
1106,63213;25,19812;59,48187;
1107,53212;25,21608;59,44689;
1108,432;25,23412;59,41567;
1109,332;25,25204;59,38241;
1110,232;25,26996;59,35075;
1111,13213;25,28812;59,32475;
1112,03212;25,30612;59,28799;
1112,932;25,32412;59,2546;
1113,832;25,34204;59,2174;
1114,732;25,36016;59,18391;
1115,63213;25,37812;59,14647;
1116,53212;25,39608;59,10862;
1117,432;25,41404;59,07499;
1118,332;25,43212;59,04082;
1119,232;25,45008;59,00511;
1120,13213;25,46788;58,96598;
1121,03212;25,48592;58,93434;
1121,932;25,50384;58,89475;
1122,832;25,52184;58,85714;
1123,732;25,53984;58,81789;
1124,63213;25,55808;58,78423;
1125,53212;25,576;58,74071;
1126,432;25,594;58,70277;
1127,332;25,61196;58,6651;
1128,232;25,62992;58,6228;
1129,13213;25,64796;58,58495;
1130,03212;25,66588;58,54197;
1130,932;25,68408;58,50768;
1131,832;25,70204;58,46064;
1132,732;25,72004;58,4192;
1133,63213;25,738;58,3766;
1134,53212;25,75608;58,33457;
1135,432;25,774;58,29158;
1136,332;25,79196;58,24976;
1137,232;25,81016;58,21274;
1138,13213;25,82816;58,16566;
1139,03212;25,8462;58,12007;
1139,932;25,86404;58,07146;
1140,832;25,88216;58,02888;
1141,732;25,90004;57,98268;
1142,63213;25,91808;57,93959;
1143,53212;25,93616;57,8959;
1144,432;25,9542;57,84776;
1145,332;25,9722;57,79788;
1146,232;25,99012;57,74999;
1147,13213;26,00824;57,70569;
1148,03212;26,02616;57,65254;
1148,932;26,04412;57,60589;
1149,832;26,06212;57,55622;
1150,732;26,08028;57,51094;
1151,63213;26,09832;57,4572;
1152,53212;26,11636;57,40739;
1153,432;26,1344;57,35923;
1154,332;26,15232;57,30285;
1155,232;26,17016;57,24949;
1156,13213;26,18812;57,19911;
1157,03212;26,20636;57,15048;
1157,932;26,22432;57,09388;
1158,832;26,2424;57,03987;
1159,732;26,26032;56,98372;
1160,63213;26,27828;56,92878;
1161,53212;26,29628;56,87566;
1162,432;26,3142;56,82023;
1163,332;26,33236;56,76692;
1164,232;26,35032;56,70333;
1165,13213;26,36848;56,65052;
1166,03212;26,38648;56,58638;
1166,932;26,40444;56,52779;
1167,832;26,42216;56,46833;
1168,732;26,44012;56,41168;
1169,63213;26,45824;56,35642;
1170,53212;26,47632;56,29395;
1171,432;26,49428;56,23084;
1172,332;26,51228;56,16913;
1173,232;26,53036;56,10793;
1174,13213;26,54832;56,0419;
1175,03212;26,56628;55,97811;
1175,932;26,58428;55,91713;
1176,832;26,60244;55,85358;
1177,732;26,62036;55,78308;
1178,63213;26,63832;55,71964;
1179,53212;26,65644;55,65645;
1180,432;26,6744;55,58351;
1181,332;26,69244;55,5173;
1182,232;26,7104;55,4471;
1183,13213;26,72848;55,3829;
1184,03212;26,74648;55,30923;
1184,932;26,76452;55,2409;
1185,832;26,78236;55,16827;
1186,732;26,8004;55,09614;
1187,63213;26,81836;55,02765;
1188,53212;26,83632;54,94852;
1189,432;26,85452;54,88063;
1190,332;26,87252;54,80111;
1191,232;26,89056;54,72488;
1192,13213;26,90844;54,64963;
1193,03212;26,92656;54,57392;
1193,932;26,94452;54,4954;
1194,832;26,96252;54,41769;
1195,732;26,98064;54,33829;
1196,63213;26,99864;54,25758;
1197,53212;27,0166;54,17272;
1198,432;27,03456;54,09052;
1199,332;27,05264;54,01431;
1200,232;27,0706;53,9279;
1201,13213;27,0886;53,84601;
1202,03212;27,10664;53,75994;
1202,932;27,1248;53,67597;
1203,832;27,14276;53,5853;
1204,732;27,16068;53,4942;
1205,63213;27,17872;53,41107;
1206,53212;27,19668;53,31433;
1207,432;27,21464;53,22381;
1208,332;27,2326;53,13289;
1209,232;27,25072;53,04087;
1210,13213;27,2686;52,94233;
1211,03212;27,28664;52,84788;
1211,932;27,3046;52,75463;
1212,832;27,32256;52,65477;
1213,732;27,34056;52,55323;
1214,63213;27,35848;52,45122;
1215,53212;27,37668;52,35446;
1216,432;27,39472;52,24703;
1217,332;27,41276;52,14553;
1218,232;27,43068;52,03596;
1219,13213;27,44872;51,93272;
1220,03212;27,46664;51,82173;
1220,932;27,48456;51,71294;
1221,832;27,50264;51,60522;
1222,732;27,52072;51,48878;
1223,63213;27,53872;51,37206;
1224,53212;27,55672;51,25712;
1225,432;27,57484;51,14059;
1226,332;27,59276;51,02088;
1227,232;27,6108;50,90176;
1228,13213;27,62876;50,77937;
1229,03212;27,64688;50,65566;
1229,932;27,66488;50,5268;
1230,832;27,683;50,40067;
1231,732;27,70112;50,27194;
1232,63213;27,71888;50,13367;
1233,53212;27,73684;50,00569;
1234,432;27,75484;49,87185;
1235,332;27,77304;49,73843;
1236,232;27,791;49,59505;
1237,13213;27,809;49,45579;
1238,03212;27,82704;49,31368;
1238,932;27,84508;49,16442;
1239,832;27,863;49,01763;
1240,732;27,88092;48,86596;
1241,63213;27,89908;48,71913;
1242,53212;27,91704;48,55857;
1243,432;27,93508;48,4011;
1244,332;27,953;48,23928;
1245,232;27,97108;48,07394;
1246,13213;27,98912;47,90639;
1247,03212;28,00712;47,73078;
1247,932;28,02516;47,55445;
1248,832;28,04324;47,37695;
1249,732;28,06128;47,19242;
1250,63213;28,07916;47,00314;
1251,53212;28,0972;46,81707;
1252,432;28,11512;46,61698;
1253,332;28,13312;46,4112;
1254,062;28,1478;45,81405;
1254,092;28,1496;34,09339;
1254,098;28,15024;26,32115;