File: tensile_test_data/primary_data/Zy1.csv
Time;Crosshead separation;Load;Extensometer elongation
(sec);(mm);(kN);(%)
0;-0,00004;0,26954;-0,06349
0,762;0,0322;0,68219;-0,06163
1,256;0,08972;1,4976;-0,05823
1,6;0,1464;2,31301;-0,05487
1,984;0,22428;3,13488;-0,0516
2,276;0,29316;3,9555;-0,04825
2,522;0,35708;4,77746;-0,04491
2,742;0,41796;5,60396;-0,04154
2,946;0,4766;6,43659;-0,03829
3,138;0,53396;7,27105;-0,03487
3,326;0,59164;8,11688;-0,03151
3,516;0,65156;8,97354;-0,02814
3,692;0,70864;9,79836;-0,02481
3,868;0,76672;10,6277;-0,02149
4,054;0,82956;11,46723;-0,01826
4,238;0,89332;12,30304;-0,01494
4,408;0,95312;13,15225;-0,01155
4,568;1,01016;13,98294;-0,00829
4,728;1,06788;14,83696;-0,005
4,886;1,12536;15,70005;-0,00162
5,04;1,18192;16,55427;0,00173
5,184;1,23484;17,36841;0,00489
5,328;1,28792;18,19485;0,00821
5,472;1,3412;19,0244;0,0114
5,616;1,39468;19,87363;0,01468
5,76;1,44832;20,73499;0,01818
5,904;1,5018;21,58903;0,02155
6,048;1,55544;22,46249;0,0248
6,192;1,60904;23,34821;0,02829
6,336;1,6626;24,2297;0,03179
6,468;1,71188;25,05673;0,03507
6,608;1,76344;25,92369;0,03852
6,746;1,81436;26,77961;0,0419
6,878;1,86308;27,6098;0,0453
7,006;1,91004;28,42066;0,04861
7,142;1,95956;29,26999;0,05201
7,278;2,00908;30,11961;0,05547
7,41;2,05668;30,94941;0,05898
7,544;2,10476;31,78915;0,0625
7,688;2,15604;32,67748;0,06628
7,832;2,20688;33,57248;0,07018
7,974;2,25664;34,44801;0,07403
8,118;2,3066;35,32305;0,078
8,262;2,35608;36,19314;0,08205
8,406;2,40496;37,05787;0,08615
8,55;2,45324;37,90256;0,09026
8,694;2,50084;38,73578;0,09432
8,838;2,54764;39,56177;0,09859
8,988;2,5954;40,39585;0,103
9,148;2,64564;41,25611;0,1076
9,308;2,69476;42,09139;0,11238
9,476;2,74528;42,9264;0,11777
9,66;2,7986;43,77147;0,1236
9,858;2,85412;44,6093;0,12974
10,086;2,9162;45,44158;0,13642
10,396;2,99676;46,26624;0,14713
11,068;3,14464;46,70859;0,17521
11,868;3,24368;46,82862;0,20632
12,668;3,30432;47,01637;0,23129
13,468;3,35008;47,2204;0,25084
14,268;3,39204;47,41492;0,27358
15,068;3,42624;47,55401;0,29398
15,868;3,45912;47,73985;0,31262
16,668;3,4892;47,80844;0,33503
17,468;3,51568;47,9266;0,35471
18,268;3,54116;48,02087;0,37499
19,068;3,56836;48,15119;0,39541
19,868;3,58932;48,12379;0,41576
20,668;3,6096;48,13269;0,43578
21,468;3,62992;48,15564;0,45439
22,268;3,65012;48,13471;0,47657
23,068;3,66732;48,12584;0,49614
23,868;3,68428;48,11555;0,51628
24,668;3,701;48,11917;0,53569
25,468;3,71832;48,09952;0,55728
26,268;3,73224;48,06556;0,57665
27,068;3,74672;48,0541;0,59686
27,868;3,76016;48,03074;0,61693
28,668;3,7736;48,03279;0,63669
29,468;3,78668;48,01586;0,65694
30,268;3,79932;48,00673;0,67662
31,068;3,81204;48,01719;0,69662
31,868;3,82464;48,02291;0,71667
32,668;3,83688;48,02423;0,73668
33,468;3,84916;48,02872;0,75701
34,268;3,86028;47,99818;0,77709
35,068;3,87212;48,01601;0,79664
35,868;3,88424;48,03956;0,81673
36,668;3,89544;48,02336;0,83678
37,468;3,9066;48,01356;0,85667
38,268;3,91804;48,0096;0,87711
39,068;3,92848;47,97556;0,89669
39,868;3,93964;47,9786;0,9167
40,668;3,95024;47,95371;0,93677
41,468;3,96108;47,94687;0,95656
42,268;3,97216;47,94918;0,97663
43,068;3,98308;47,93997;0,99702
43,868;3,99344;47,91337;1,01703
44,668;4,00448;47,92515;1,03683
45,468;4,02068;48,10272;1,05619
46,268;4,0262;47,80509;1,07713
47,068;4,0398;47,96548;1,09693
47,868;4,0492;47,88444;1,11728
48,668;4,06032;47,9151;1,13685
49,468;4,0706;47,89757;1,15683
50,268;4,08152;47,91548;1,17665
51,068;4,092;47,90733;1,19635
51,868;4,10332;47,93132;1,21662
52,668;4,11376;47,9163;1,23683
53,468;4,1246;47,92688;1,25669
54,268;4,13528;47,92954;1,27666
55,068;4,14636;47,94101;1,29687
55,868;4,15668;47,92608;1,31675
56,668;4,1678;47,94729;1,33665
57,468;4,1786;47,94992;1,35691
58,268;4,1894;47,95822;1,37672
59,068;4,20008;47,96009;1,3967
59,868;4,2106;47,95167;1,41676
60,668;4,22064;47,91977;1,4369
61,468;4,2298;47,84304;1,45708
62,268;4,2382;47,72976;1,4776
63,068;4,24608;47,60697;1,49755
63,868;4,25484;47,54061;1,51719
64,668;4,26448;47,51905;1,53686
65,468;4,276;47,58593;1,55683
66,26801;4,2882;47,68517;1,57673
67,068;4,30128;47,81885;1,59671
67,868;4,31468;47,95842;1,61679
68,66801;4,32804;48,09063;1,63622
69,468;4,34212;48,23755;1,65587
70,26801;4,35628;48,36281;1,6756
71,068;4,37152;48,49725;1,69612
71,868;4,38596;48,58469;1,71607
72,66801;4,40112;48,69053;1,73583
73,468;4,4164;48,77474;1,75574
74,26801;4,43232;48,8732;1,7757
75,068;4,44792;48,93813;1,79558
75,868;4,46428;49,02354;1,81535
76,66801;4,48068;49,09195;1,83519
77,468;4,498;49,18166;1,85512
78,26801;4,516;49,2456;1,87316
79,068;4,53536;49,30518;1,89566
79,868;4,55268;49,37404;1,91481
80,66801;4,57132;49,45267;1,9351
81,468;4,58968;49,5112;1,95484
82,26801;4,60876;49,58172;1,97488
83,068;4,628;49,65267;1,99472
83,868;4,64772;49,71974;2,01479
84,66801;4,66748;49,78452;2,03477
85,468;4,68764;49,85238;2,05469
86,26801;4,708;49,91819;2,07469
87,068;4,73128;50,04178;2,09454
87,868;4,7504;50,03664;2,11436
88,66801;4,77168;50,12659;2,13466
89,468;4,79232;50,18872;2,15457
90,26801;4,813;50,24304;2,17464
91,068;4,83432;50,32076;2,19475
91,868;4,85504;50,37851;2,21445
92,66801;4,8762;50,44329;2,23453
93,468;4,89792;50,52222;2,25466
94,26801;4,91976;50,59019;2,27271
95,068;4,94208;50,63147;2,29481
95,868;4,9634;50,7093;2,31464
96,66801;4,98444;50,76521;2,33446
97,468;5,00576;50,82739;2,3544
98,26801;5,02764;50,90392;2,37462
99,06801;5,04868;50,95114;2,39466
99,868;5,06988;51,00949;2,41454
100,66801;5,0912;51,08107;2,43416
101,468;5,11252;51,13436;2,45384
102,26801;5,13632;51,26335;2,47259
103,06801;5,15832;51,26125;2,49431
103,868;5,17936;51,3164;2,5139
104,66801;5,2008;51,37466;2,53398
105,468;5,2224;51,44361;2,55394
106,26801;5,24344;51,49159;2,57371
107,06801;5,26472;51,55109;2,59372
107,868;5,2868;51,6291;2,61393
108,66801;5,30804;51,66739;2,63396
109,468;5,3302;51,73549;2,65417
110,26801;5,35476;51,85503;2,67416
111,06801;5,37468;51,82684;2,69429
111,868;5,3958;51,8888;2,7139
112,66801;5,41764;51,96665;2,73404
113,468;5,43868;52,00241;2,75402
114,26801;5,46016;52,06581;2,77413
115,06801;5,48168;52,12635;2,79409
115,868;5,5028;52,17134;2,81401
116,66801;5,5242;52,23005;2,834
117,468;5,5462;52,29849;2,85413
118,26801;5,56932;52,3421;2,87462
119,06801;5,59;52,38945;2,89436
119,868;5,6116;52,45333;2,91474
120,66801;5,63196;52,48209;2,93456
121,468;5,65248;52,54015;2,95396
122,26801;5,674;52,61146;2,97409
123,06801;5,69504;52,64638;2,99448
123,868;5,71616;52,70461;3,01438
124,66801;5,73756;52,76176;3,0343
125,468;5,7612;52,85819;3,05419
126,26801;5,78116;52,84202;3,07431
127,06801;5,8024;52,90554;3,0941
127,868;5,82372;52,95055;3,11447
128,668;5,84484;53,00383;3,13433
129,468;5,86576;53,05088;3,15418
130,26801;5,88672;53,09396;3,17419
131,06801;5,9078;53,15089;3,19409
131,86802;5,92872;53,19668;3,21393
132,668;5,95;53,24273;3,23366
133,468;5,97316;53,30027;3,2543
134,268;5,99332;53,3326;3,27386
135,06802;6,0144;53,37808;3,29402
135,86802;6,03512;53,43009;3,31373
136,668;6,0558;53,47122;3,33366
137,468;6,07692;53,52406;3,35396
138,268;6,09764;53,56708;3,37392
139,06802;6,11844;53,60764;3,39388
139,86802;6,13976;53,66415;3,41399
140,668;6,16292;53,72891;3,43411
141,468;6,18272;53,73609;3,45379
142,268;6,204;53,79825;3,4741
143,06802;6,22416;53,82931;3,494
143,86802;6,24456;53,86956;3,51389
144,668;6,26512;53,9274;3,53388
145,468;6,28544;53,95772;3,55378
146,268;6,30608;54,00393;3,57373
147,06802;6,32752;54,06465;3,59384
147,86802;6,35048;54,12221;3,61427
148,66802;6,37024;54,12315;3,63421
149,468;6,3906;54,17271;3,65401
150,268;6,4108;54,20519;3,67383
151,06802;6,43144;54,25721;3,69374
151,86802;6,45204;54,30057;3,7136
152,66802;6,47308;54,34017;3,73399
153,468;6,49368;54,37953;3,75374
154,268;6,51444;54,41844;3,77358
155,06802;6,53768;54,49184;3,79393
155,714;6,5432;54,18834;3,80565
156,514;6,55848;54,33236;3,81749
157,31402;6,57444;54,41773;3,83188
158,11402;6,59064;54,46918;3,84709
158,914;6,60656;54,49938;3,86243
159,714;6,62264;54,53507;3,87781
160,514;6,6386;54,55756;3,89296
161,25802;6,65364;54,59096;3,90719
185,44802;6,6642;53,33068;
186,24802;6,68004;53,96262;
187,048;6,69592;54,39414;
187,848;6,71192;54,63825;
188,64802;6,72804;54,74934;
189,44802;6,744;54,80394;
190,24802;6,76;54,83861;
191,048;6,776;54,86388;
191,848;6,792;54,88153;
192,64802;6,80796;54,90131;
193,44802;6,82396;54,92641;
194,24802;6,83996;54,94962;
195,048;6,85608;54,97763;
195,848;6,87196;54,99822;
196,64802;6,888;55,02579;
197,44802;6,90412;55,05037;
198,24802;6,9202;55,07429;
199,048;6,93604;55,09203;
199,848;6,9518;55,11279;
200,64802;6,96776;55,13785;
201,44802;6,98396;55,16489;
202,24802;6,99996;55,16629;
203,048;7,01604;55,19707;
203,848;7,03192;55,22341;
204,64802;7,04796;55,24924;
205,44802;7,06388;55,27116;
206,24802;7,07992;55,29727;
207,048;7,09588;55,31694;
207,848;7,11204;55,33998;
208,64802;7,12796;55,36031;
209,44802;7,144;55,38716;
210,24802;7,15992;55,40758;
211,048;7,176;55,4331;
211,848;7,192;55,45428;
212,64802;7,20804;55,48009;
213,44802;7,224;55,50084;
214,24802;7,24016;55,52735;
215,048;7,25596;55,54339;
215,848;7,27204;55,56952;
216,64802;7,28796;55,59139;
217,44802;7,30404;55,62111;
218,24802;7,32;55,64074;
219,048;7,336;55,66576;
219,848;7,35192;55,68789;
220,64802;7,36804;55,71391;
221,44802;7,38404;55,73564;
222,24802;7,4;55,75857;
223,048;7,416;55,7779;
223,848;7,43204;55,80368;
224,64802;7,448;55,82343;
225,44802;7,46396;55,8481;
226,24802;7,47992;55,87143;
227,048;7,496;55,8973;
227,848;7,51196;55,91726;
228,64802;7,52792;55,9413;
229,44802;7,54388;55,96308;
230,24802;7,55988;55,98761;
231,048;7,57584;56,01186;
231,848;7,59184;56,03178;
232,64802;7,60784;56,05646;
233,44802;7,62388;56,08263;
234,24802;7,64;56,10375;
235,048;7,65596;56,12578;
235,848;7,67204;56,14816;
236,64802;7,688;56,16778;
237,44802;7,70392;56,19116;
238,24802;7,71984;56,21173;
239,048;7,73588;56,23439;
239,848;7,7518;56,25949;
240,64802;7,76792;56,28176;
241,44802;7,78392;56,30285;
242,24802;7,79992;56,32436;
243,048;7,81584;56,34293;
243,848;7,83184;56,36523;
244,64802;7,84776;56,38581;
245,44802;7,86376;56,40914;
246,24802;7,87972;56,43095;
247,048;7,89588;56,45599;
247,848;7,9118;56,47407;
248,64802;7,92788;56,49896;
249,44802;7,94384;56,51689;
250,24802;7,95996;56,54071;
251,04802;7,97584;56,55669;
251,848;7,99184;56,57805;
252,64802;8,00772;56,59764;
253,44802;8,02384;56,62266;
254,24802;8,0398;56,64053;
255,04802;8,05584;56,66373;
255,848;8,0718;56,68404;
256,64802;8,08788;56,70816;
257,448;8,1038;56,72157;
258,24802;8,1198;56,74449;
259,048;8,1358;56,76401;
259,84802;8,15192;56,78727;
260,64802;8,16792;56,80494;
261,448;8,18388;56,82264;
262,24803;8,19984;56,84336;
263,048;8,21604;56,87065;
263,84803;8,232;56,88525;
264,648;8,24784;56,90193;
265,448;8,26364;56,92024;
266,24803;8,2798;56,94704;
267,048;8,29588;56,96392;
267,84803;8,31184;56,98181;
268,648;8,3278;56,99841;
269,448;8,34384;57,0217;
270,24803;8,35976;57,038;
271,048;8,37572;57,05662;
271,84803;8,39172;57,07746;
272,648;8,4078;57,09827;
273,448;8,42388;57,11914;
274,24803;8,43984;57,1357;
275,048;8,45576;57,15027;
275,84803;8,4718;57,1723;
276,648;8,48776;57,18825;
277,448;8,50376;57,20663;
278,24803;8,5198;57,22678;
279,048;8,5358;57,24768;
279,84803;8,55188;57,26547;
280,648;8,56768;57,28195;
281,44803;8,58372;57,30384;
282,24803;8,59976;57,32033;
283,048;8,61576;57,3399;
283,84803;8,63164;57,35515;
284,648;8,64768;57,37311;
285,44803;8,66368;57,39223;
286,24803;8,67976;57,41012;
287,048;8,69572;57,42523;
287,84803;8,71176;57,44633;
288,648;8,72772;57,46136;
289,44803;8,74376;57,48207;
290,24803;8,75968;57,49825;
291,048;8,77568;57,51688;
291,84803;8,79164;57,53514;
292,648;8,8078;57,55528;
293,44803;8,82372;57,56549;
294,24803;8,83976;57,58521;
295,048;8,8556;57,59967;
295,84803;8,87168;57,61893;
296,648;8,88756;57,63253;
297,44803;8,90364;57,65539;
298,24803;8,91956;57,67046;
299,048;8,93568;57,69209;
299,84803;8,95168;57,70465;
300,648;8,96776;57,72347;
301,44803;8,98372;57,73766;
302,24803;8,9998;57,75607;
303,048;9,01568;57,76728;
303,84803;9,03164;57,78704;
304,648;9,0476;57,80241;
305,44803;9,06372;57,82236;
306,24803;9,07972;57,83815;
307,048;9,09576;57,85342;
307,84803;9,11168;57,86538;
308,648;9,12776;57,88535;
309,44803;9,14368;57,89674;
310,24803;9,15964;57,91421;
311,048;9,17564;57,92959;
311,84803;9,19172;57,94883;
312,648;9,20772;57,96251;
313,44803;9,22376;57,97827;
314,24803;9,2398;57,99335;
315,048;9,25584;58,01125;
315,84803;9,2718;58,02435;
316,648;9,28772;58,03791;
317,44803;9,30364;58,05259;
318,24803;9,31968;58,0696;
319,048;9,33572;58,08349;
319,84803;9,35168;58,10186;
320,648;9,36768;58,11564;
321,44803;9,38368;58,1331;
322,24803;9,39968;58,14834;
323,048;9,41564;58,1625;
323,84803;9,4316;58,1786;
324,648;9,44768;58,19539;
325,44803;9,46376;58,20791;
326,24803;9,4796;58,21913;
327,048;9,49576;58,23826;
327,84803;9,51172;58,24957;
328,648;9,52796;58,26838;
329,44803;9,54388;58,2765;
330,24803;9,5596;58,28588;
331,048;9,57548;58,30696;
331,84803;9,59168;58,32729;
332,648;9,60768;58,33938;
333,44803;9,62372;58,35648;
334,24803;9,63968;58,36876;
335,048;9,65576;58,38568;
335,84803;9,67172;58,39739;
336,648;9,68772;58,41179;
337,44803;9,70364;58,42537;
338,24803;9,71976;58,44301;
339,048;9,73576;58,45293;
339,84803;9,75176;58,47056;
340,648;9,76768;58,48187;
341,44803;9,7838;58,49714;
342,24803;9,79968;58,50872;
343,048;9,81576;58,52519;
343,84803;9,83176;58,53661;
344,648;9,84792;58,55425;
345,44803;9,86376;58,56043;
346,24803;9,87976;58,57563;
347,048;9,89572;58,58788;
347,84803;9,9118;58,60637;
348,648;9,9276;58,61275;
349,44803;9,94356;58,6279;
350,24803;9,95952;58,64199;
351,048;9,97568;58,65909;
351,84803;9,99168;58,67037;
352,648;10,00768;58,68268;
353,44803;10,02368;58,69631;
354,24803;10,0398;58,71404;
355,048;10,05568;58,72113;
355,84803;10,0716;58,73691;
356,648;10,0876;58,74838;
357,44803;10,10368;58,7675;
358,24803;10,11972;58,77832;
359,048;10,13572;58,78862;
359,84803;10,15168;58,79849;
360,648;10,16768;58,81296;
361,44803;10,18364;58,82261;
362,24803;10,1996;58,83441;
363,048;10,2156;58,84843;
363,84803;10,23168;58,86251;
364,648;10,24768;58,87592;
365,44803;10,26364;58,88698;
366,24803;10,27968;58,90153;
367,048;10,29568;58,9125;
367,84803;10,31164;58,92282;
368,648;10,32752;58,93218;
369,44803;10,34348;58,94738;
370,24803;10,35952;58,96192;
371,048;10,37564;58,97539;
371,84803;10,39156;58,98768;
372,648;10,4076;59,00185;
373,44803;10,42356;59,01073;
374,24803;10,43956;59,02604;
375,048;10,45552;59,03474;
375,84803;10,47156;59,047;
376,648;10,48756;59,05869;
377,44803;10,50368;59,07296;
378,24803;10,5196;59,07991;
379,048;10,53572;59,09667;
379,84803;10,55168;59,10604;
380,648;10,5678;59,12144;
381,44803;10,58372;59,13023;
382,24803;10,59964;59,14217;
383,048;10,61556;59,15293;
383,84803;10,6316;59,16713;
384,648;10,64752;59,17397;
385,44803;10,66364;59,18927;
386,24803;10,67956;59,19648;
387,048;10,69564;59,21159;
387,84803;10,71152;59,22061;
388,648;10,72756;59,23293;
389,44803;10,74344;59,24239;
390,24803;10,7596;59,26027;
391,048;10,77556;59,26798;
391,84803;10,79156;59,27854;
392,648;10,80752;59,2872;
393,44803;10,82376;59,30445;
394,24803;10,83972;59,30893;
395,048;10,85572;59,32152;
395,84803;10,8714;59,32411;
396,648;10,88748;59,34524;
397,44803;10,90352;59,35736;
398,24803;10,91956;59,3693;
399,048;10,93552;59,37534;
399,84803;10,95164;59,38854;
400,648;10,96756;59,39227;
401,44803;10,98356;59,40384;
402,24803;10,99956;59,41121;
403,048;11,01564;59,4266;
403,84803;11,0316;59,43385;
404,648;11,0476;59,444;
405,44803;11,0636;59,45476;
406,24803;11,07964;59,46886;
407,048;11,09556;59,47362;
407,84803;11,11152;59,48294;
408,648;11,12756;59,49521;
409,44803;11,14364;59,50571;
410,24803;11,15976;59,51611;
411,04803;11,1756;59,52126;
411,84803;11,1916;59,5358;
412,648;11,20752;59,54727;
413,44803;11,2236;59,55757;
414,24803;11,23948;59,5665;
415,04803;11,2554;59,57788;
415,84803;11,27144;59,58747;
416,648;11,28752;59,59685;
417,44803;11,3034;59,6036;
418,24803;11,31952;59,61699;
419,04803;11,33548;59,62452;
419,84803;11,35148;59,63514;
420,648;11,3674;59,64165;
421,44803;11,3834;59,65375;
422,24803;11,3994;59,66626;
423,04803;11,4156;59,67517;
423,84803;11,43152;59,68171;
424,648;11,44756;59,691;
425,44803;11,46348;59,69779;
426,24803;11,47952;59,7105;
427,04803;11,49548;59,71656;
427,84803;11,51148;59,72964;
428,648;11,52748;59,73946;
429,44803;11,54368;59,75065;
430,24803;11,5596;59,75615;
431,04803;11,57568;59,76939;
431,84803;11,59164;59,77487;
432,648;11,60772;59,78604;
433,44803;11,62352;59,79034;
434,24803;11,6396;59,80098;
435,04803;11,65552;59,80851;
435,84803;11,67164;59,82233;
436,648;11,6876;59,827;
437,44803;11,7036;59,83804;
438,24803;11,71952;59,84586;
439,04803;11,7356;59,85727;
439,84803;11,75148;59,86352;
440,648;11,76748;59,87108;
441,44803;11,78344;59,8789;
442,24803;11,7996;59,8917;
443,04803;11,8156;59,89733;
443,84803;11,8316;59,90489;
444,648;11,84764;59,91507;
445,44803;11,86372;59,92653;
446,24803;11,87968;59,92938;
447,04803;11,89556;59,93925;
447,84803;11,91152;59,94714;
448,648;11,92764;59,95998;
449,44803;11,94356;59,96321;
450,24803;11,95956;59,97184;
451,04803;11,97556;59,978;
451,84803;11,99156;59,98827;
452,648;12,00748;59,99491;
453,44803;12,02344;60,0044;
454,24803;12,03944;60,0143;
455,04803;12,05552;60,02548;
455,84803;12,07164;60,03677;
456,648;12,0876;60,04007;
457,44803;12,1036;60,04568;
458,24803;12,11956;60,05409;
459,04803;12,13576;60,06624;
459,84803;12,15172;60,07123;
460,648;12,16768;60,07764;
461,44803;12,18344;60,08182;
462,24803;12,19956;60,09602;
463,04803;12,21552;60,102;
463,84803;12,23164;60,11367;
464,648;12,24756;60,11891;
465,44803;12,2636;60,12587;
466,24803;12,27948;60,13252;
467,04803;12,29552;60,14055;
467,84803;12,31148;60,14735;
468,648;12,32764;60,15763;
469,44803;12,34352;60,16141;
470,24803;12,35952;60,1705;
471,04803;12,37544;60,17619;
471,84803;12,39148;60,18987;
472,648;12,4074;60,19271;
473,44803;12,4234;60,20198;
474,24803;12,43936;60,21138;
475,04803;12,4556;60,22143;
475,84803;12,4716;60,22292;
476,648;12,48752;60,2293;
477,44803;12,50344;60,23399;
478,24803;12,51956;60,24603;
479,04803;12,53544;60,2488;
479,84803;12,55144;60,25756;
480,648;12,56736;60,26585;
481,44803;12,58356;60,27727;
482,24803;12,59952;60,27868;
483,04803;12,61548;60,28447;
483,84803;12,63148;60,28944;
484,648;12,64764;60,30059;
485,44803;12,66348;60,30499;
486,24803;12,67948;60,31181;
487,04803;12,69544;60,31794;
487,84803;12,71156;60,33031;
488,648;12,72756;60,33471;
489,44803;12,74356;60,34054;
490,24803;12,75948;60,34692;
491,04803;12,77552;60,35597;
491,84803;12,79136;60,35697;
492,648;12,80736;60,3649;
493,44803;12,8234;60,37281;
494,24803;12,83956;60,38365;
495,04803;12,8556;60,38956;
495,84803;12,8716;60,39379;
496,648;12,8876;60,40177;
497,44803;12,90364;60,41098;
498,24803;12,9196;60,41413;
499,04803;12,93548;60,42055;
499,84803;12,95144;60,42543;
500,648;12,96752;60,43411;
501,44803;12,9836;60,44065;
502,24803;12,99956;60,44275;
503,04803;13,0156;60,44983;
503,84803;13,03152;60,45424;
504,648;13,04752;60,46273;
505,44803;13,06344;60,46718;
506,24803;13,07944;60,4762;
507,04803;13,09544;60,48252;
507,84803;13,1116;60,48977;
508,648;13,12756;60,49132;
509,44803;13,14364;60,4986;
510,24803;13,1596;60,50413;
511,04803;13,17568;60,51195;
511,84803;13,1916;60,51536;
512,648;13,20756;60,52249;
513,448;13,22348;60,52866;
514,24806;13,2396;60,53885;
515,04803;13,25548;60,54139;
515,84803;13,27156;60,549;
516,648;13,28752;60,55005;
517,448;13,30364;60,56068;
518,24806;13,31952;60,5621;
519,04803;13,33556;60,56854;
519,84803;13,35148;60,57358;
520,648;13,36772;60,58369;
521,448;13,38368;60,58526;
522,24806;13,39964;60,59238;
523,04803;13,41556;60,5938;
523,84803;13,43168;60,60642;
524,648;13,44772;60,60878;
525,448;13,46376;60,61403;
526,24806;13,47952;60,6122;
527,04806;13,4956;60,62376;
527,848;13,51156;60,62839;
528,648;13,5276;60,63756;
529,448;13,5436;60,63997;
530,24806;13,55968;60,64848;
531,04806;13,57556;60,65084;
531,848;13,59156;60,65782;
532,648;13,60752;60,66069;
533,448;13,62368;60,66993;
534,24806;13,63968;60,67013;
535,04806;13,65564;60,67495;
535,848;13,6716;60,68029;
536,648;13,68764;60,68599;
537,448;13,70352;60,68792;
538,24806;13,71952;60,69458;
539,04806;13,73552;60,70024;
539,848;13,75164;60,70911;
540,648;13,76772;60,71635;
541,448;13,78364;60,71538;
542,24806;13,79952;60,72003;
543,04806;13,81556;60,72763;
543,848;13,8316;60,72999;
544,648;13,84752;60,73648;
545,448;13,86352;60,74076;
546,24806;13,87952;60,74677;
547,04806;13,8956;60,7541;
547,848;13,91152;60,7558;
548,648;13,92752;60,76325;
549,448;13,94352;60,7686;
550,24806;13,9596;60,7746;
551,04806;13,97544;60,77456;
551,848;13,99152;60,78199;
552,648;14,00752;60,7867;
553,448;14,02368;60,79382;
554,24806;14,0396;60,79422;
555,04806;14,0556;60,79975;
555,848;14,07148;60,80328;
556,648;14,08756;60,81066;
557,448;14,1034;60,81429;
558,24806;14,1194;60,82041;
559,04806;14,1354;60,82479;
559,848;14,15156;60,83118;
560,648;14,16744;60,83193;
561,448;14,18352;60,83923;
562,24806;14,19944;60,84043;
563,04806;14,21556;60,84854;
563,848;14,23144;60,84931;
564,648;14,24736;60,85166;
565,448;14,26328;60,85736;
566,24806;14,27948;60,86721;
567,04806;14,29544;60,86771;
567,848;14,31148;60,87236;
568,648;14,32736;60,87061;
569,448;14,34348;60,88182;
570,24806;14,35936;60,88015;
571,04806;14,37544;60,88684;
571,848;14,39136;60,88997;
572,648;14,40752;60,89897;
573,448;14,42348;60,89782;
574,24806;14,43948;60,90329;
575,04806;14,45548;60,90615;
575,848;14,47164;60,91493;
576,648;14,4876;60,914;
577,448;14,5036;60,91812;
578,24806;14,51952;60,91973;
579,04806;14,53564;60,92951;
579,848;14,55156;60,93006;
580,648;14,56752;60,93481;
581,448;14,58352;60,93875;
582,24806;14,59956;60,94413;
583,04806;14,61548;60,94738;
583,848;14,6314;60,95079;
584,648;14,6474;60,95327;
585,448;14,66352;60,96141;
586,24806;14,67964;60,96414;
587,04806;14,69552;60,96391;
587,848;14,71152;60,96904;
588,648;14,72752;60,97149;
589,448;14,74356;60,97904;
590,24806;14,75956;60,98294;
591,04806;14,77552;60,98507;
591,848;14,79128;60,98382;
592,648;14,80736;60,99226;
593,448;14,82332;60,99393;
594,24806;14,83944;61,00075;
595,04806;14,8554;61,00183;
595,848;14,87148;61,00587;
596,648;14,88736;61,00693;
597,448;14,90344;61,01466;
598,24806;14,9194;61,01586;
599,04806;14,93548;61,02386;
599,848;14,95144;61,02486;
600,648;14,96752;61,02929;
601,44806;14,9834;61,0288;
602,24806;14,99956;61,03351;
603,04806;15,0154;61,03352;
603,848;15,03144;61,04022;
604,648;15,04744;61,04195;
605,44806;15,06364;61,05029;
606,24806;15,07956;61,04993;
607,04806;15,09552;61,05223;
607,848;15,11136;61,05267;
608,648;15,12752;61,06042;
609,44806;15,1434;61,06031;
610,24806;15,1594;61,06452;
611,04806;15,17532;61,06539;
611,848;15,19152;61,07374;
612,648;15,20744;61,07275;
613,44806;15,22348;61,07817;
614,24806;15,2394;61,07724;
615,04806;15,25552;61,08845;
615,848;15,27144;61,08544;
616,648;15,28744;61,08812;
617,44806;15,30332;61,09103;
618,24806;15,3196;61,10007;
619,04806;15,33556;61,09722;
619,848;15,35156;61,10146;
620,648;15,36752;61,10091;
621,44806;15,3836;61,1064;
622,24806;15,39944;61,10502;
623,04806;15,41544;61,11073;
623,848;15,43136;61,11304;
624,648;15,44756;61,12263;
625,44806;15,4636;61,11907;
626,24806;15,47952;61,12282;
627,04806;15,49556;61,12291;
627,848;15,5116;61,12885;
628,648;15,52752;61,12879;
629,44806;15,54348;61,13208;
630,24806;15,55944;61,13195;
631,04806;15,57548;61,14261;
631,848;15,59152;61,14489;
632,648;15,60744;61,14421;
633,44806;15,62344;61,14863;
634,24806;15,63948;61,14873;
635,04806;15,65544;61,1506;
635,848;15,6714;61,15291;
636,648;15,6874;61,15533;
637,44806;15,70344;61,16079;
638,24806;15,71956;61,16357;
639,04806;15,73548;61,16226;
639,848;15,75148;61,16834;
640,648;15,76744;61,16893;
641,44806;15,7836;61,17221;
642,24806;15,79948;61,1727;
643,04806;15,81552;61,17553;
643,848;15,83148;61,17662;
644,648;15,84756;61,1815;
645,44806;15,86344;61,18011;
646,24806;15,87944;61,1842;
647,04806;15,89536;61,18714;
647,848;15,91148;61,18965;
648,648;15,92736;61,19089;
649,44806;15,94336;61,19441;
650,24806;15,95932;61,19449;
651,04806;15,97548;61,20237;
651,848;15,99148;61,19949;
652,648;16,00756;61,20181;
653,44806;16,02344;61,20021;
654,24806;16,03952;61,20699;
655,04806;16,05552;61,2071;
655,848;16,0716;61,21107;
656,648;16,08752;61,21056;
657,44806;16,10344;61,21029;
658,24806;16,11936;61,21429;
659,04806;16,13544;61,21994;
659,848;16,1514;61,21773;
660,648;16,16752;61,22414;
661,44806;16,1834;61,21961;
662,24806;16,19936;61,22251;
663,04806;16,21528;61,22497;
663,848;16,23148;61,23257;
664,648;16,24748;61,23312;
665,44806;16,26344;61,23508;
666,24806;16,27948;61,23348;
667,04806;16,29552;61,2388;
667,848;16,31144;61,23499;
668,648;16,3274;61,23698;
669,44806;16,3434;61,23976;
670,24806;16,35956;61,24536;
671,04806;16,37564;61,24554;
671,848;16,3916;61,24554;
672,648;16,40748;61,24159;
673,44806;16,42348;61,2515;
674,24806;16,4394;61,25037;
675,04806;16,4554;61,25184;
675,848;16,47132;61,25315;
676,648;16,4874;61,2588;
677,44806;16,50348;61,25958;
678,24806;16,5194;61,26009;
679,04806;16,5354;61,26204;
679,848;16,5514;61,26454;
680,648;16,5674;61,26556;
681,44806;16,58332;61,26714;
682,24806;16,59932;61,26451;
683,04806;16,61532;61,27108;
683,848;16,63148;61,27329;
684,648;16,64744;61,27167;
685,44806;16,66344;61,27408;
686,24806;16,6794;61,27311;
687,04806;16,69544;61,27605;
687,848;16,71124;61,27442;
688,648;16,72732;61,27898;
689,44806;16,74324;61,27999;
690,24806;16,75932;61,28629;
691,04806;16,7754;61,28491;
691,848;16,7914;61,28822;
692,648;16,8074;61,2873;
693,44806;16,82352;61,28986;
694,24806;16,83932;61,28552;
695,04806;16,85532;61,28869;
695,848;16,87124;61,28848;
696,648;16,8874;61,29565;
697,44806;16,90332;61,29093;
698,24806;16,9194;61,29377;
699,04806;16,93528;61,29444;
699,848;16,95136;61,29928;
700,648;16,96724;61,2968;
701,44806;16,98324;61,29914;
702,24806;16,99924;61,29762;
703,04806;17,0154;61,30388;
703,848;17,03136;61,3015;
704,648;17,04744;61,30204;
705,44806;17,06332;61,29984;
706,24806;17,07952;61,30611;
707,04806;17,09548;61,30294;
707,848;17,11148;61,30385;
708,648;17,12744;61,30267;
709,44806;17,1436;61,30797;
710,24806;17,15956;61,30505;
711,04806;17,17544;61,30537;
711,848;17,1914;61,30472;
712,648;17,2074;61,30936;
713,44806;17,22332;61,3077;
714,24806;17,23928;61,30948;
715,04806;17,25524;61,31259;
715,848;17,2714;61,31853;
716,648;17,28748;61,31605;
717,44806;17,30344;61,31586;
718,24806;17,31944;61,31474;
719,04806;17,33548;61,31717;
719,848;17,3514;61,31693;
720,648;17,36756;61,31917;
721,44806;17,38356;61,31796;
722,24806;17,39952;61,31977;
723,04806;17,41544;61,31711;
723,848;17,43136;61,31637;
724,648;17,4474;61,32011;
725,44806;17,46344;61,32004;
726,24806;17,47944;61,32109;
727,04806;17,4954;61,31989;
727,848;17,5114;61,32112;
728,648;17,5274;61,32289;
729,44806;17,54352;61,32625;
730,24806;17,55944;61,32123;
731,04806;17,57544;61,32509;
731,848;17,5914;61,3248;
732,648;17,6074;61,32377;
733,44806;17,62328;61,32362;
734,24806;17,63932;61,32566;
735,04806;17,65536;61,32618;
735,848;17,67156;61,33142;
736,648;17,68756;61,32665;
737,44806;17,70364;61,32825;
738,24806;17,71944;61,32367;
739,04806;17,73556;61,32693;
739,848;17,75144;61,32597;
740,648;17,76748;61,32428;
741,44806;17,78344;61,32486;
742,24806;17,7996;61,32897;
743,04806;17,81556;61,3247;
743,848;17,8316;61,32571;
744,648;17,84752;61,32454;
745,44806;17,86368;61,32885;
746,24806;17,87956;61,32377;
747,04806;17,89552;61,32531;
747,848;17,91144;61,32433;
748,648;17,92756;61,32906;
749,44806;17,94356;61,32809;
750,24806;17,9596;61,32795;
751,04806;17,97556;61,32373;
751,848;17,9916;61,32867;
752,648;18,00748;61,32494;
753,44806;18,0234;61,32671;
754,24806;18,03936;61,32634;
755,04806;18,05552;61,3323;
755,848;18,07152;61,32953;
756,648;18,08756;61,3298;
757,44806;18,10348;61,32631;
758,24806;18,1196;61,32927;
759,04806;18,13556;61,32484;
759,848;18,15148;61,32404;
760,648;18,1674;61,32411;
761,44806;18,18348;61,32969;
762,24806;18,19952;61,32752;
763,04806;18,21544;61,32641;
763,848;18,2314;61,32501;
764,648;18,2474;61,32686;
765,44806;18,26332;61,32343;
766,24806;18,27928;61,32227;
767,04806;18,29524;61,32375;
767,848;18,31132;61,32604;
768,648;18,32748;61,32656;
769,44806;18,3434;61,32212;
770,24806;18,35944;61,32362;
771,04806;18,3754;61,32134;
771,848;18,39148;61,32272;
772,648;18,4074;61,32157;
773,44806;18,42344;61,32321;
774,24806;18,43944;61,32422;
775,04806;18,45556;61,32231;
775,848;18,47144;61,31843;
776,648;18,48744;61,32025;
777,44806;18,5034;61,31843;
778,24806;18,51944;61,3212;
779,04806;18,53532;61,31808;
779,848;18,55136;61,31852;
780,648;18,56728;61,31912;
781,44806;18,58344;61,32249;
782,24806;18,59944;61,31737;
783,04806;18,61544;61,31755;
783,848;18,63132;61,31022;
784,648;18,64744;61,31404;
785,44806;18,66336;61,31203;
786,24806;18,67956;61,31572;
787,04806;18,69556;61,3111;
787,848;18,71152;61,30882;
788,648;18,72736;61,30559;
789,44806;18,7434;61,30916;
790,24806;18,75936;61,30794;
791,04806;18,77548;61,30836;
791,848;18,79136;61,30469;
792,648;18,8074;61,30491;
793,44806;18,8234;61,30304;
794,24806;18,83952;61,30697;
795,04806;18,85552;61,30334;
795,848;18,87152;61,30288;
796,648;18,8874;61,29973;
797,44806;18,90348;61,30431;
798,24806;18,91936;61,29926;
799,04806;18,93532;61,2977;
799,848;18,95128;61,29581;
800,648;18,96748;61,30005;
801,44806;18,98356;61,29599;
802,24806;18,99956;61,29262;
803,04806;19,01548;61,28831;
803,848;19,03144;61,29135;
804,648;19,04732;61,28637;
805,44806;19,06332;61,28818;
806,24806;19,07928;61,28812;
807,04806;19,0954;61,28995;
807,848;19,11144;61,28707;
808,648;19,1274;61,28255;
809,44806;19,1434;61,28115;
810,24806;19,15944;61,28173;
811,04806;19,17536;61,27675;
811,848;19,19136;61,2775;
812,648;19,20732;61,275;
813,44806;19,22344;61,27815;
814,24806;19,23956;61,27654;
815,04806;19,25548;61,2731;
815,848;19,27148;61,27081;
816,648;19,28744;61,26742;
817,44806;19,30348;61,26649;
818,24806;19,31936;61,26218;
819,04806;19,3354;61,26319;
819,848;19,35144;61,26559;
820,648;19,3676;61,26492;
821,44806;19,38356;61,25926;
822,24806;19,39956;61,26123;
823,04806;19,41556;61,25666;
823,848;19,43164;61,25633;
824,648;19,44756;61,25241;
825,44806;19,4636;61,25078;
826,24806;19,47956;61,24831;
827,04806;19,49568;61,24795;
827,848;19,5116;61,24318;
828,648;19,52764;61,24398;
829,44806;19,54356;61,239;
830,24806;19,5596;61,24076;
831,04806;19,57548;61,23768;
831,848;19,59148;61,23845;
832,648;19,6074;61,23481;
833,44806;19,62352;61,23584;
834,24806;19,63948;61,23024;
835,04806;19,65552;61,22904;
835,848;19,67144;61,22489;
836,648;19,68756;61,22538;
837,44806;19,70348;61,22101;
838,24806;19,71956;61,22127;
839,04806;19,73552;61,21652;
839,848;19,7516;61,21959;
840,648;19,76756;61,21187;
841,44806;19,78348;61,20754;
842,24806;19,7994;61,20557;
843,04806;19,81556;61,20759;
843,848;19,83144;61,20072;
844,648;19,84744;61,20049;
845,44806;19,86336;61,19649;
846,24806;19,87952;61,20012;
847,04806;19,89548;61,19592;
847,848;19,91152;61,19476;
848,648;19,92748;61,18765;
849,44806;19,94352;61,19018;
850,24806;19,9594;61,18425;
851,04806;19,97544;61,18384;
851,848;19,99156;61,18333;
852,648;20,00768;61,18045;
853,44806;20,02352;61,17188;
854,24806;20,0394;61,16924;
855,04806;20,0554;61,16801;
855,848;20,07148;61,16992;
856,648;20,08744;61,16344;
857,44806;20,1034;61,16349;
858,24806;20,1194;61,16027;
859,04806;20,13552;61,16117;
859,848;20,1516;61,15655;
860,64806;20,16756;61,15203;
861,44806;20,18356;61,14901;
862,24806;20,19956;61,14556;
863,04806;20,21552;61,14232;
863,848;20,23144;61,13814;
864,64806;20,24744;61,13591;
865,44806;20,26348;61,13744;
866,24806;20,27964;61,13397;
867,04806;20,29564;61,1289;
867,848;20,31168;61,12528;
868,64806;20,32756;61,11678;
869,44806;20,34356;61,1165;
870,24806;20,35948;61,11245;
871,04806;20,37556;61,11176;
871,848;20,39152;61,10775;
872,64806;20,40768;61,10689;
873,44806;20,4236;61,10038;
874,24806;20,4396;61,09783;
875,04806;20,45548;61,09291;
875,848;20,4716;61,09197;
876,64806;20,48748;61,08673;
877,44806;20,50352;61,08438;
878,24806;20,51948;61,07948;
879,04806;20,5356;61,07957;
879,848;20,5516;61,07398;
880,64806;20,5676;61,0722;
881,44806;20,58352;61,06814;
882,24806;20,5996;61,06679;
883,04806;20,61548;61,05922;
883,848;20,63148;61,05767;
884,64806;20,64744;61,05245;
885,44806;20,6636;61,05431;
886,24806;20,67964;61,04668;
887,04806;20,69564;61,04133;
887,848;20,71152;61,03764;
888,64806;20,72764;61,03657;
889,44806;20,74356;61,02957;
890,24806;20,75952;61,02732;
891,04806;20,77548;61,01978;
891,848;20,79152;61,02102;
892,64806;20,80756;61,01515;
893,44806;20,82352;61,00882;
894,24806;20,83944;61,00346;
895,04806;20,85548;61,00329;
895,848;20,8714;60,99331;
896,64806;20,88736;60,99076;
897,44806;20,90328;60,98687;
898,24806;20,9194;60,98749;
899,04806;20,93544;60,98005;
899,848;20,95144;60,97551;
900,64806;20,9674;60,96975;
901,44806;20,9834;60,96443;
902,24806;20,9994;60,9574;
903,04806;21,0154;60,95433;
903,848;21,03144;60,94984;
904,64806;21,04748;60,94632;
905,44806;21,06352;60,94057;
906,24806;21,0794;60,93352;
907,04806;21,0954;60,92767;
907,848;21,11132;60,92405;
908,64806;21,12744;60,92187;
909,44806;21,1434;60,9132;
910,24806;21,1594;60,90956;
911,04806;21,17544;60,90529;
911,848;21,1916;60,90083;
912,64806;21,20756;60,89311;
913,44806;21,22364;60,8903;
914,24806;21,23956;60,8782;
915,04806;21,2556;60,87616;
915,848;21,27152;60,86785;
916,64806;21,28768;60,86644;
917,44806;21,30372;60,85924;
918,24806;21,31984;60,85365;
919,04806;21,33556;60,83736;
919,848;21,3516;60,83974;
920,64806;21,36752;60,83109;
921,44806;21,38368;60,82917;
922,24806;21,39956;60,81854;
923,04806;21,41556;60,81445;
923,848;21,43148;60,80652;
924,64806;21,44764;60,80607;
925,44806;21,46356;60,79129;
926,24806;21,4796;60,78748;
927,04806;21,49552;60,77682;
927,848;21,5116;60,7754;
928,64806;21,52748;60,76486;
929,44806;21,54348;60,75956;
930,24806;21,55936;60,75099;
931,04806;21,57556;60,75163;
931,848;21,59156;60,74101;
932,64806;21,60756;60,73294;
933,44806;21,6236;60,725;
934,24806;21,63956;60,71553;
935,04806;21,65552;60,70816;
935,848;21,67148;60,69963;
936,64806;21,68744;60,69141;
937,44806;21,70356;60,68826;
938,24806;21,71956;60,67846;
939,04806;21,7356;60,67023;
939,848;21,75152;60,66186;
940,64806;21,7676;60,65682;
941,44806;21,78352;60,64155;
942,24806;21,79948;60,63401;
943,04806;21,81552;60,62545;
943,848;21,8316;60,62104;
944,64806;21,84764;60,61221;
945,44806;21,86364;60,6021;
946,24806;21,8796;60,591;
947,04806;21,89564;60,58346;
947,848;21,91156;60,57371;
948,64806;21,92748;60,56362;
949,44806;21,94348;60,55508;
950,24806;21,95948;60,54646;
951,04806;21,97564;60,53855;
951,848;21,9916;60,52713;
952,64806;22,00764;60,51638;
953,44806;22,0236;60,50574;
954,24806;22,03964;60,49761;
955,04806;22,05552;60,48305;
955,848;22,07148;60,4758;
956,64806;22,08744;60,46624;
957,44806;22,10352;60,45573;
958,24806;22,11948;60,44334;
959,04806;22,13552;60,43449;
959,848;22,15144;60,42203;
960,64806;22,16756;60,41373;
961,44806;22,18348;60,40039;
962,24806;22,19944;60,38983;
963,04806;22,2154;60,37812;
963,848;22,23156;60,37095;
964,64806;22,24752;60,35562;
965,44806;22,2636;60,34602;
966,24806;22,27948;60,32893;
967,04806;22,2956;60,31975;
967,848;22,31156;60,30554;
968,64806;22,3276;60,29624;
969,44806;22,34356;60,28203;
970,24806;22,3598;60,27322;
971,04806;22,37568;60,25307;
971,848;22,39164;60,2427;
972,64806;22,40748;60,22826;
973,44806;22,4236;60,21835;
974,24806;22,43948;60,2042;
975,04806;22,45548;60,18893;
975,848;22,4714;60,17582;
976,64806;22,4876;60,16767;
977,44806;22,5036;60,14987;
978,24806;22,5196;60,1352;
979,04806;22,5356;60,11981;
979,848;22,55168;60,10841;
980,64806;22,56752;60,09037;
981,44806;22,58352;60,0774;
982,24806;22,5996;60,06595;
983,04806;22,61576;60,05129;
983,848;22,63176;60,03026;
984,64806;22,64752;60,01258;
985,44806;22,66348;60,00047;
986,24806;22,6796;59,98834;
987,04806;22,69556;59,96609;
987,848;22,71152;59,95193;
988,64806;22,72752;59,93345;
989,44806;22,7436;59,92289;
990,24806;22,75964;59,90589;
991,04806;22,7756;59,88415;
991,848;22,79156;59,86896;
992,64806;22,80756;59,85391;
993,44806;22,82356;59,83449;
994,24806;22,83948;59,81649;
995,04806;22,85548;59,79902;
995,848;22,87144;59,78344;
996,64806;22,88756;59,76638;
997,44806;22,9036;59,7482;
998,24806;22,9196;59,73088;
999,04806;22,93556;59,70783;
999,848;22,95152;59,68819;
1000,64806;22,96744;59,66847;
1001,44806;22,98352;59,65404;
1002,24806;22,99948;59,63284;
1003,04806;23,0156;59,61474;
1003,848;23,03152;59,59408;
1004,64806;23,0476;59,57667;
1005,44806;23,06348;59,55199;
1006,24806;23,07956;59,53614;
1007,04806;23,09544;59,51182;
1007,848;23,11148;59,49073;
1008,64806;23,12744;59,46985;
1009,44806;23,1436;59,45312;
1010,24806;23,15952;59,42777;
1011,04806;23,17564;59,40947;
1011,848;23,19156;59,38497;
1012,64806;23,20764;59,36673;
1013,44806;23,22356;59,33997;
1014,24806;23,23956;59,32075;
1015,04806;23,25544;59,29752;
1015,848;23,27164;59,28108;
1016,64806;23,28764;59,25201;
1017,44806;23,30368;59,23149;
1018,24806;23,31964;59,20478;
1019,04806;23,33572;59,18528;
1019,848;23,35164;59,16035;
1020,64806;23,36764;59,13745;
1021,44806;23,38356;59,11213;
1022,24806;23,39968;59,09326;
1023,04806;23,41564;59,06615;
1023,848;23,4316;59,04478;
1024,64806;23,44756;59,01673;
1025,448;23,46368;58,99448;
1026,24806;23,47956;58,96668;
1027,04812;23,49552;58,93901;
1027,848;23,51148;58,91312;
1028,64806;23,5276;58,89321;
1029,448;23,54368;58,86432;
1030,24806;23,55968;58,83704;
1031,04812;23,5756;58,80988;
1031,848;23,59168;58,78855;
1032,64806;23,6076;58,75772;
1033,448;23,6236;58,73207;
1034,24806;23,63972;58,70401;
1035,04812;23,65584;58,68012;
1035,848;23,67192;58,65075;
1036,64806;23,68788;58,62027;
1037,448;23,70376;58,59262;
1038,24806;23,71972;58,56708;
1039,04812;23,73572;58,5383;
1039,848;23,7516;58,51098;
1040,64806;23,76768;58,48238;
1041,448;23,78372;58,45272;
1042,24806;23,7998;58,42327;
1043,04812;23,8158;58,38848;
1043,848;23,83184;58,36283;
1044,64806;23,84776;58,33184;
1045,448;23,86384;58,30026;
1046,24806;23,87972;58,26699;
1047,04812;23,89576;58,24051;
1047,848;23,91192;58,21322;
1048,64812;23,92804;58,18148;
1049,448;23,9438;58,13822;
1050,248;23,95976;58,113;
1051,04812;23,97568;58,07909;
1051,848;23,99188;58,05211;
1052,64812;24,00776;58,01561;
1053,448;24,02368;57,98608;
1054,248;24,03972;57,95501;
1055,04812;24,05592;57,9255;
1055,848;24,07188;57,88935;
1056,64812;24,08796;57,85654;
1057,448;24,1038;57,81673;
1058,248;24,11988;57,78773;
1059,04812;24,13588;57,74835;
1059,848;24,15184;57,71558;
1060,64812;24,1678;57,67987;
1061,448;24,184;57,64859;
1062,248;24,19996;57,61088;
1063,04812;24,21604;57,5786;
1063,848;24,232;57,54004;
1064,64812;24,248;57,50649;
1065,448;24,26384;57,46436;
1066,248;24,27984;57,42577;
1067,04812;24,2958;57,38885;
1067,848;24,31196;57,35688;
1068,64812;24,32796;57,3171;
1069,448;24,34392;57,27962;
1070,248;24,35988;57,23991;
1071,04812;24,37592;57,2049;
1071,848;24,39184;57,16587;
1072,64812;24,40784;57,12876;
1073,448;24,4238;57,08897;
1074,248;24,43992;57,05268;
1075,04812;24,45592;57,00751;
1075,848;24,47184;56,96606;
1076,64812;24,48784;56,92576;
1077,448;24,50388;56,88818;
1078,248;24,51984;56,84569;
1079,04812;24,53576;56,80391;
1079,848;24,55172;56,76179;
1080,64812;24,56784;56,72545;
1081,448;24,58392;56,68169;
1082,248;24,59992;56,63406;
1083,04812;24,61596;56,58982;
1083,848;24,63196;56,54508;
1084,64812;24,648;56,50104;
1085,448;24,66396;56,45768;
1086,248;24,68;56,4141;
1087,04812;24,696;56,36812;
1087,848;24,71204;56,3264;
1088,64812;24,728;56,27864;
1089,448;24,744;56,23485;
1090,248;24,75992;56,18843;
1091,04812;24,776;56,13961;
1091,848;24,79188;56,09171;
1092,64812;24,80788;56,04506;
1093,448;24,82388;55,99685;
1094,248;24,84;55,95186;
1095,04812;24,856;55,90259;
1095,848;24,87204;55,85563;
1096,64812;24,88788;55,80252;
1097,448;24,904;55,75729;
1098,248;24,91992;55,70626;
1099,04812;24,93592;55,65795;
1099,848;24,95196;55,60554;
1100,64812;24,96816;55,55429;
1101,448;24,98412;55,49875;
1102,248;25,00012;55,44946;
1103,04812;25,01596;55,39405;
1103,848;25,032;55,34692;
1104,64812;25,04796;55,2927;
1105,448;25,06396;55,24077;
1106,248;25,07992;55,18664;
1107,04812;25,09612;55,13499;
1107,848;25,11208;55,07573;
1108,64812;25,12812;55,02046;
1109,448;25,14412;54,96064;
1110,248;25,1602;54,90978;
1111,04812;25,17612;54,85001;
1111,848;25,19204;54,79249;
1112,64812;25,20808;54,73862;
1113,448;25,22432;54,68628;
1114,248;25,24036;54,62289;
1115,04812;25,25612;54,55774;
1115,848;25,27204;54,50093;
1116,64812;25,28812;54,44424;
1117,448;25,30408;54,379;
1118,248;25,32008;54,3174;
1119,04812;25,33608;54,25888;
1119,848;25,35224;54,20119;
1120,64812;25,36832;54,13411;
1121,448;25,38428;54,07097;
1122,248;25,40024;54,00814;
1123,04812;25,41628;53,94465;
1123,848;25,4322;53,87757;
1124,64812;25,44816;53,81372;
1125,448;25,46416;53,74659;
1126,248;25,48024;53,68337;
1127,04812;25,49636;53,61634;
1127,848;25,51232;53,54831;
1128,64812;25,52836;53,48099;
1129,448;25,5444;53,4126;
1130,248;25,56032;53,33765;
1131,04812;25,57624;53,26898;
1131,848;25,59224;53,20095;
1132,64812;25,60828;53,13069;
1133,448;25,6244;53,05851;
1134,248;25,64036;52,98164;
1135,04812;25,6564;52,91085;
1135,848;25,67236;52,8378;
1136,64812;25,6884;52,76431;
1137,448;25,70432;52,68827;
1138,248;25,72036;52,61568;
1139,04812;25,73632;52,53726;
1139,848;25,75244;52,46236;
1140,64812;25,76836;52,37938;
1141,448;25,78444;52,30229;
1142,248;25,80036;52,21978;
1143,04812;25,81652;52,14103;
1143,848;25,8324;52,0577;
1144,64812;25,84836;51,97872;
1145,448;25,86432;51,89651;
1146,248;25,88044;51,81679;
1147,04812;25,8964;51,72845;
1147,848;25,91248;51,64673;
1148,64812;25,92836;51,55718;
1149,448;25,94448;51,47315;
1150,248;25,9604;51,38144;
1151,04812;25,97644;51,29508;
1151,848;25,99244;51,20414;
1152,64812;26,00852;51,1175;
1153,448;26,02448;51,02334;
1154,248;26,04052;50,93163;
1155,04812;26,05644;50,83307;
1155,848;26,07256;50,74271;
1156,64812;26,08848;50,64138;
1157,448;26,10444;50,54137;
1158,248;26,1204;50,44071;
1159,04812;26,13656;50,34295;
1159,848;26,1526;50,23647;
1160,64812;26,16856;50,13127;
1161,448;26,18456;50,02255;
1162,248;26,2006;49,91311;
1163,04812;26,21656;49,79054;
1163,848;26,23256;49,47879;
1164,62;26,24804;48,92908;
1164,96012;26,25492;48,09724;
1165,02812;26,25636;47,14777;
1165,04413;26,25796;34,73364;
1165,05;26,25856;26,70422;