File: tensile_test_data/primary_data/Zy4.csv
Time;Crosshead separation;Load;Extensometer elongation
(sec);(mm);(kN);(%)
0;0,0002;0,21495;-0,04504
0,8;0,03268;0,33729;-0,04449
1,236;0,08932;1,13554;-0,04142
1,534;0,13968;1,96408;-0,03822
1,782;0,18788;2,78533;-0,03516
2,008;0,2358;3,61426;-0,03203
2,22;0,28404;4,44695;-0,02888
2,428;0,3342;5,27641;-0,02564
2,664;0,39496;6,10177;-0,02243
2,89;0,457;6,92556;-0,01923
3,098;0,51684;7,75253;-0,016
3,292;0,57484;8,58773;-0,01272
3,48;0,63264;9,43263;-0,00943
3,662;0,69032;10,26446;-0,00609
3,85;0,75136;11,09457;-0,00282
4,054;0,8198;11,93956;0,00045
4,23;0,8804;12,77654;0,00374
4,394;0,9376;13,61408;0,00707
4,554;0,99412;14,44995;0,01035
4,714;1,05136;15,30576;0,01366
4,874;1,10892;16,18281;0,01715
5,028;1,16464;17,0384;0,02058
5,174;1,21796;17,86392;0,02378
5,318;1,27068;18,69224;0,02701
5,462;1,3236;19,52521;0,03035
5,606;1,37648;20,36531;0,03363
5,75;1,42944;21,22155;0,03704
5,894;1,48256;22,08554;0,04044
6,038;1,53552;22,95145;0,04382
6,182;1,58828;23,82761;0,04736
6,326;1,64096;24,70459;0,05087
6,47;1,69368;25,58523;0,05435
6,606;1,74348;26,43199;0,05778
6,75;1,79588;27,32206;0,06145
6,892;1,84728;28,18956;0,06493
7,032;1,8978;29,06036;0,06854
7,17;1,9472;29,91783;0,07212
7,312;1,99792;30,79286;0,07579
7,45;2,0468;31,65101;0,07939
7,592;2,09656;32,52967;0,08324
7,734;2,14612;33,39932;0,08702
7,878;2,19604;34,27877;0,091
8,022;2,24536;35,15854;0,09493
8,166;2,29404;36,02137;0,09901
8,31;2,34212;36,87452;0,10306
8,454;2,3896;37,72533;0,10718
8,598;2,43616;38,55509;0,11135
8,742;2,48184;39,36599;0,11556
8,886;2,52692;40,17264;0,11977
9,044;2,57536;41,04255;0,12452
9,204;2,62352;41,9001;0,12943
9,364;2,67016;42,71788;0,13414
9,524;2,71616;43,53282;0,13904
9,7;2,76536;44,39383;0,14449
9,88;2,81416;45,22622;0,14989
10,068;2,86368;46,06365;0,15562
10,268;2,91496;46,89722;0,16146
10,492;2,97072;47,73264;0,16814
10,758;3,03456;48,55749;0,17591
11,314;3,15888;48,94735;0,19624
12,004;3,23356;48,17741;0,23687
12,804;3,25852;48,0009;0,25713
13,604;3,2906;48,27063;0,27543
14,404;3,3174;48,25149;0,29773
15,204;3,34208;48,3211;0,31762
16,004;3,36828;48,4437;0,33607
16,804;3,39104;48,37703;0,35781
17,604;3,41368;48,44231;0,37733
18,404;3,43856;48,55489;0,39594
19,204;3,4606;48,49896;0,41782
20,004;3,48196;48,54048;0,43776
20,804;3,5024;48,55026;0,4578
21,604;3,52464;48,58289;0,47836
22,404;3,54208;48,53309;0,49799
23,204;3,5606;48,56531;0,51796
24,004;3,57784;48,55409;0,53812
24,804;3,59484;48,56316;0,55857
25,604;3,6146;48,65834;0,57816
26,404;3,62876;48,53603;0,59879
27,204;3,64464;48,57129;0,61838
28,004;3,66028;48,57358;0,63879
28,804;3,67496;48,5617;0,65864
29,604;3,6896;48,56305;0,6786
30,404;3,7038;48,56029;0,69832
31,204;3,71868;48,5772;0,71847
32,004;3,73264;48,56156;0,73875
32,804;3,74632;48,55851;0,75855
33,604;3,76064;48,57694;0,77881
34,404;3,7738;48,55559;0,79845
35,204;3,79128;48,61504;0,81988
36,004;3,80212;48,52058;0,83821
36,804;3,81636;48,56405;0,85875
37,604;3,82876;48,54092;0,87838
38,404;3,84212;48,56008;0,89843
39,204;3,85512;48,55776;0,91885
40,004;3,8676;48,55131;0,93897
40,804;3,87988;48,54456;0,95871
41,604;3,89268;48,5531;0,97925
42,404;3,90416;48,52871;0,99885
43,204;3,91692;48,55775;1,01909
44,004;3,92816;48,52307;1,03878
44,804;3,94028;48,53991;1,05853
45,604;3,9516;48,5209;1,07862
46,404;3,96332;48,52616;1,09843
47,204;3,97512;48,53234;1,11859
48,004;3,98672;48,52026;1,13917
48,804;3,99792;48,51182;1,15917
49,604;4,00936;48,52542;1,17887
50,404;4,02056;48,51398;1,19923
51,204;4,03148;48,50628;1,21897
52,004;4,04284;48,51976;1,23897
52,804;4,05392;48,5162;1,25927
53,604;4,06456;48,50588;1,27901
54,404;4,07564;48,51136;1,29908
55,204;4,0864;48,51094;1,31889
56,004;4,09744;48,52447;1,33863
56,804;4,10848;48,52772;1,35879
57,604;4,11944;48,52429;1,37917
58,404;4,13016;48,52461;1,39898
59,204;4,14136;48,54757;1,41882
60,004;4,15232;48,55295;1,43906
60,804;4,16328;48,56263;1,45872
61,604;4,17452;48,57959;1,47884
62,404;4,1848;48,54978;1,49911
63,204;4,1948;48,52309;1,51874
64,004;4,20472;48,48368;1,53897
64,804;4,21348;48,39011;1,55899
65,604;4,22184;48,28834;1,579
66,40401;4,22992;48,17888;1,59891
67,204;4,23892;48,11607;1,61866
68,00401;4,25004;48,15558;1,6388
68,804;4,26172;48,23288;1,65846
69,604;4,27448;48,36198;1,67822
70,40401;4,28784;48,50484;1,69829
71,204;4,3016;48,65664;1,71787
72,00401;4,31592;48,80959;1,73825
72,804;4,32996;48,93594;1,75792
73,604;4,34448;49,06054;1,77791
74,40401;4,35908;49,16728;1,79767
75,204;4,37708;49,35845;1,81398
76,00401;4,39252;49,34344;1,83849
76,804;4,40808;49,47498;1,85719
77,604;4,42388;49,54878;1,87716
78,40401;4,4408;49,65411;1,89715
79,204;4,4572;49,71047;1,91712
80,00401;4,47456;49,79533;1,93693
80,804;4,49224;49,86575;1,95679
81,604;4,51092;49,95014;1,97703
82,40401;4,52932;50,00741;1,99692
83,204;4,54844;50,08319;2,01684
84,00401;4,56772;50,1546;2,03661
84,804;4,58764;50,22017;2,05659
85,604;4,60816;50,3012;2,0766
86,40401;4,62868;50,36387;2,09656
87,204;4,64924;50,42325;2,11642
88,00401;4,67068;50,50504;2,13626
88,804;4,69176;50,56339;2,15622
89,604;4,71808;50,69493;2,17667
90,40401;4,73812;50,69309;2,19617
91,204;4,76016;50,77523;2,21616
92,00401;4,78216;50,83914;2,23647
92,804;4,804;50,90611;2,25623
93,604;4,82592;50,97197;2,27614
94,40401;4,84796;51,03171;2,29624
95,204;4,86972;51,10014;2,31599
96,00401;4,89204;51,17638;2,33602
96,804;4,91444;51,2364;2,35656
97,604;4,93644;51,30213;2,37646
98,40401;4,95792;51,35375;2,39607
99,204;4,98028;51,42301;2,41617
100,00401;5,00232;51,4847;2,43603
100,80401;5,02864;51,58945;2,45666
101,604;5,04932;51,60655;2,47617
102,40401;5,07124;51,68241;2,49624
103,204;5,09284;51,74773;2,51613
104,00401;5,1142;51,79788;2,53624
104,80401;5,13564;51,86036;2,55612
105,604;5,1574;51,93375;2,57609
106,40401;5,17892;51,98292;2,59641
107,204;5,20048;52,0493;2,61647
108,00401;5,2216;52,10361;2,63632
108,80401;5,2424;52,14979;2,65619
109,604;5,26352;52,21906;2,6759
110,40401;5,28496;52,28657;2,69587
111,204;5,30756;52,3544;2,71338
112,00401;5,33112;52,40006;2,73679
112,80401;5,35164;52,45766;2,75621
113,604;5,37256;52,50713;2,77639
114,40401;5,39336;52,56853;2,79606
115,204;5,41408;52,62476;2,81579
116,00401;5,4352;52,68195;2,83607
116,80401;5,45612;52,74038;2,85588
117,604;5,477;52,79117;2,87579
118,40401;5,4982;52,84626;2,89594
119,204;5,51892;52,90037;2,91572
120,00401;5,53968;52,95398;2,93565
120,80401;5,56104;53,01694;2,95603
121,604;5,58168;53,06312;2,97601
122,40401;5,6066;53,22543;2,99496
123,204;5,6266;53,15794;3,01644
124,00401;5,6472;53,22341;3,03608
124,80401;5,66804;53,27674;3,05616
125,604;5,68908;53,33334;3,07643
126,40401;5,70936;53,37342;3,09607
127,204;5,73012;53,42727;3,11601
128,00402;5,7514;53,49285;3,13602
128,804;5,77188;53,52761;3,15596
129,604;5,7926;53,58088;3,17576
130,40401;5,81412;53,64857;3,19609
131,20402;5,83484;53,67838;3,21611
132,00402;5,85592;53,72943;3,23618
132,804;5,87708;53,7892;3,25574
133,604;5,90172;53,84401;3,27657
134,404;5,92192;53,87547;3,29606
135,20402;5,94308;53,93362;3,31629
136,00402;5,96312;53,96297;3,33586
136,804;5,98432;54,02839;3,356
137,604;6,00496;54,07376;3,37602
138,404;6,02548;54,11175;3,396
139,20402;6,04612;54,16282;3,41592
140,00402;6,06716;54,21773;3,43588
140,804;6,08808;54,25413;3,45624
141,604;6,10848;54,30084;3,47595
142,404;6,12892;54,34364;3,49589
143,20402;6,14964;54,3875;3,51589
144,00402;6,1746;54,4988;3,53608
144,804;6,19356;54,47088;3,55564
145,604;6,21472;54,53181;3,57635
146,404;6,23464;54,56413;3,59597
147,20402;6,25468;54,60133;3,61584
148,00402;6,27524;54,6612;3,63582
148,804;6,29524;54,69375;3,65575
149,604;6,31536;54,72988;3,67551
150,404;6,33636;54,79679;3,69569
151,20402;6,35636;54,81852;3,71589
152,00402;6,37664;54,86739;3,73578
152,804;6,39692;54,91208;3,75574
153,604;6,417;54,9457;3,77575
154,404;6,44148;55,04104;3,79618
155,06002;6,446;54,70268;3,80689
155,86;6,46188;54,88822;3,81955
156,66;6,47792;54,96867;3,83443
157,46;6,49396;55,01398;3,84989
158,26002;6,50992;55,05053;3,86537
159,06002;6,526;55,08681;3,88101
159,86;6,54184;55,11426;3,89658
181,37402;6,55188;53,6342;
182,17402;6,567;54,266;
182,97402;6,58292;54,79324;
183,774;6,59912;55,11729;
184,574;6,61508;55,26834;
185,37402;6,63108;55,33608;
186,17402;6,64704;55,37684;
186,97402;6,6632;55,40934;
187,774;6,67908;55,42956;
188,574;6,69504;55,45727;
189,37402;6,71096;55,48212;
190,17402;6,72708;55,51198;
190,97402;6,74304;55,5349;
191,774;6,75908;55,56132;
192,574;6,77496;55,58389;
193,37402;6,79108;55,61321;
194,17402;6,807;55,63788;
194,97402;6,82292;55,66726;
195,774;6,83884;55,69275;
196,574;6,85504;55,72512;
197,37402;6,87104;55,75069;
198,17402;6,88712;55,77862;
198,97402;6,90304;55,80155;
199,774;6,91916;55,82935;
200,574;6,93512;55,85338;
201,37402;6,95108;55,8815;
202,17402;6,96708;55,9051;
202,97402;6,98324;55,93444;
203,774;6,99924;55,95579;
204,574;7,0152;55,9808;
205,37402;7,03112;56,00572;
206,17402;7,04716;56,03623;
206,97402;7,06316;56,05988;
207,77402;7,07912;56,08569;
208,574;7,09504;56,11252;
209,37402;7,11116;56,14037;
210,17402;7,12716;56,16213;
210,97402;7,14316;56,18612;
211,77402;7,15916;56,21117;
212,574;7,17516;56,23665;
213,37402;7,19116;56,26255;
214,17402;7,20708;56,28511;
214,97402;7,22312;56,3076;
215,77402;7,2392;56,33282;
216,574;7,25516;56,35045;
217,37402;7,271;56,37403;
218,17402;7,28704;56,39778;
218,97402;7,303;56,42256;
219,77402;7,31904;56,44709;
220,574;7,335;56,46918;
221,37402;7,35096;56,49365;
222,17402;7,367;56,51832;
222,97402;7,38308;56,54289;
223,77402;7,39892;56,56357;
224,574;7,41504;56,59098;
225,37402;7,43096;56,60893;
226,17402;7,44712;56,63328;
226,97402;7,46296;56,65303;
227,77402;7,47892;56,67698;
228,574;7,49492;56,7;
229,37402;7,51112;56,72485;
230,17402;7,52708;56,7455;
230,97402;7,54316;56,77063;
231,77402;7,55904;56,78823;
232,574;7,57504;56,81242;
233,37402;7,591;56,83239;
234,17402;7,60696;56,85776;
234,97402;7,62284;56,87772;
235,77402;7,639;56,9065;
236,574;7,65496;56,92439;
237,37402;7,67108;56,94854;
238,17402;7,68696;56,96746;
238,97402;7,70308;56,99205;
239,77402;7,719;57,00981;
240,574;7,73492;57,03192;
241,37402;7,75088;57,05377;
242,17402;7,76704;57,08073;
242,97402;7,783;57,1004;
243,77402;7,79908;57,12271;
244,574;7,81504;57,14189;
245,37402;7,83108;57,16537;
246,17402;7,84696;57,18005;
246,97402;7,8628;57,20092;
247,77402;7,87876;57,22337;
248,574;7,89492;57,25044;
249,37402;7,91096;57,27207;
250,17402;7,92696;57,29234;
250,97402;7,94292;57,31162;
251,77402;7,95896;57,33445;
252,574;7,975;57,35272;
253,37402;7,99096;57,37057;
254,17402;8,00688;57,39075;
254,97402;8,02296;57,41509;
255,77402;8,03896;57,43301;
256,574;8,05496;57,45469;
257,37403;8,07096;57,4752;
258,17402;8,08692;57,49838;
258,974;8,10288;57,51917;
259,77402;8,11884;57,53745;
260,574;8,13476;57,55559;
261,37403;8,15084;57,5796;
262,174;8,16692;57,59791;
262,974;8,18288;57,61666;
263,77403;8,19892;57,63609;
264,574;8,21488;57,65585;
265,37403;8,23092;57,67765;
266,174;8,24692;57,6955;
266,974;8,26292;57,71617;
267,77403;8,27892;57,73514;
268,574;8,29504;57,75672;
269,37403;8,31092;57,77064;
270,174;8,32692;57,79175;
270,974;8,34284;57,80954;
271,77403;8,35892;57,83148;
272,574;8,37488;57,84937;
273,37403;8,39084;57,8705;
274,174;8,4068;57,88972;
274,974;8,42296;57,91245;
275,77403;8,43888;57,92788;
276,574;8,45496;57,94902;
277,37403;8,47092;57,9653;
278,174;8,487;57,98501;
278,974;8,50288;58,00077;
279,77403;8,51892;58,02029;
280,574;8,53496;58,03693;
281,37403;8,55108;58,05961;
282,174;8,56684;58,06888;
282,974;8,58288;58,09184;
283,77403;8,59876;58,11083;
284,574;8,61492;58,13187;
285,37403;8,63084;58,1472;
286,174;8,6468;58,16536;
286,974;8,66276;58,18221;
287,77403;8,67888;58,20447;
288,574;8,69484;58,2193;
289,37403;8,71084;58,23506;
290,174;8,7268;58,25209;
290,974;8,74292;58,27489;
291,77403;8,7588;58,28665;
292,574;8,77476;58,30618;
293,37403;8,79064;58,32158;
294,174;8,80684;58,3462;
294,974;8,82284;58,36223;
295,77403;8,83892;58,37783;
296,574;8,85488;58,39303;
297,37403;8,8708;58,4113;
298,174;8,8868;58,42721;
298,974;8,90272;58,44597;
299,77403;8,91872;58,46308;
300,574;8,93476;58,48017;
301,37403;8,95076;58,49918;
302,174;8,96676;58,51367;
302,97403;8,9828;58,52976;
303,77403;8,9988;58,54573;
304,574;9,0148;58,56244;
305,37403;9,03076;58,57661;
306,174;9,04672;58,59298;
306,97403;9,06276;58,61175;
307,77403;9,07884;58,62895;
308,574;9,0948;58,64464;
309,37403;9,11088;58,66162;
310,174;9,12688;58,67555;
310,97403;9,14292;58,69189;
311,77403;9,1588;58,70297;
312,574;9,17472;58,71835;
313,37403;9,19068;58,73732;
314,174;9,20684;58,7545;
314,97403;9,22276;58,76755;
315,77403;9,23884;58,78721;
316,574;9,25476;58,79875;
317,37403;9,27084;58,8155;
318,174;9,28676;58,82972;
318,97403;9,30276;58,84391;
319,77403;9,31872;58,8585;
320,574;9,33488;58,87756;
321,37403;9,3508;58,88835;
322,174;9,3668;58,90818;
322,97403;9,38276;58,922;
323,77403;9,3988;58,93882;
324,574;9,41472;58,9532;
325,37403;9,43072;58,96918;
326,174;9,4466;58,98026;
326,97403;9,46284;59,00315;
327,77403;9,4788;59,01378;
328,574;9,49488;59,02955;
329,37403;9,51084;59,0409;
330,174;9,52692;59,05645;
330,97403;9,54284;59,06939;
331,77403;9,55888;59,08408;
332,574;9,5748;59,09721;
333,37403;9,591;59,11713;
334,174;9,60696;59,12818;
334,97403;9,62288;59,14055;
335,77403;9,63872;59,15151;
336,574;9,6548;59,17066;
337,37403;9,67076;59,18304;
338,174;9,68672;59,19792;
338,97403;9,70268;59,21046;
339,77403;9,7188;59,23051;
340,574;9,7348;59,24173;
341,37403;9,7508;59,25597;
342,174;9,7668;59,2667;
342,97403;9,78284;59,28587;
343,77403;9,7988;59,29215;
344,574;9,81464;59,30407;
345,37403;9,83076;59,3245;
346,174;9,84692;59,33879;
346,97403;9,86296;59,35108;
347,77403;9,87876;59,35835;
348,574;9,89476;59,37278;
349,37403;9,91068;59,38877;
350,174;9,9268;59,40455;
350,97403;9,94268;59,41304;
351,77403;9,95868;59,42999;
352,574;9,9748;59,44336;
353,37403;9,99088;59,45504;
354,174;10,00684;59,46561;
354,97403;10,02292;59,48039;
355,77403;10,0388;59,49069;
356,574;10,05492;59,50766;
357,37403;10,0708;59,51659;
358,174;10,08676;59,53107;
358,97403;10,10276;59,54719;
359,77403;10,11892;59,56085;
360,574;10,13488;59,5717;
361,37403;10,151;59,58645;
362,174;10,16692;59,59418;
362,97403;10,18288;59,60665;
363,77403;10,19884;59,61695;
364,574;10,21484;59,62977;
365,37403;10,23076;59,64019;
366,174;10,24684;59,65742;
366,97403;10,26268;59,6618;
367,77403;10,27876;59,68253;
368,574;10,29468;59,69082;
369,37403;10,31072;59,70404;
370,174;10,32664;59,71423;
370,97403;10,34264;59,72801;
371,77403;10,3586;59,73847;
372,574;10,37476;59,75581;
373,37403;10,39068;59,76181;
374,174;10,40676;59,77832;
374,97403;10,42268;59,78821;
375,77403;10,4388;59,80462;
376,574;10,45468;59,81172;
377,37403;10,47064;59,82222;
378,174;10,48656;59,83191;
378,97403;10,50272;59,85112;
379,77403;10,5188;59,8608;
380,574;10,5348;59,86969;
381,37403;10,55076;59,87982;
382,174;10,56684;59,89572;
382,97403;10,58272;59,90074;
383,77403;10,59868;59,91524;
384,574;10,6146;59,92689;
385,37403;10,63068;59,94242;
386,174;10,64668;59,94891;
386,97403;10,66264;59,95842;
387,77403;10,6786;59,96836;
388,574;10,69464;59,98347;
389,37403;10,7106;59,99121;
390,174;10,72648;60,0034;
390,97403;10,74244;60,01582;
391,77403;10,75852;60,03051;
392,574;10,7746;60,04314;
393,37403;10,7906;60,05073;
394,174;10,80668;60,0606;
394,97403;10,82264;60,07104;
395,77403;10,83872;60,08068;
396,574;10,85468;60,09101;
397,37403;10,87068;60,10283;
398,174;10,88676;60,11498;
398,97403;10,90288;60,1279;
399,77403;10,91876;60,13484;
400,574;10,9348;60,14514;
401,37403;10,9506;60,15016;
402,174;10,96668;60,16534;
402,97403;10,9826;60,171;
403,77403;10,99864;60,18212;
404,574;11,01464;60,19369;
405,37403;11,0308;60,20668;
406,174;11,04672;60,21512;
406,97403;11,06284;60,22916;
407,77403;11,07872;60,23487;
408,574;11,09476;60,24824;
409,37403;11,11064;60,25492;
410,174;11,12664;60,26517;
410,97403;11,14268;60,27742;
411,77403;11,15896;60,28969;
412,574;11,17484;60,29139;
413,37403;11,19076;60,30256;
414,174;11,20664;60,31002;
414,97403;11,22272;60,32459;
415,77403;11,23864;60,33247;
416,574;11,25464;60,34275;
417,37403;11,27056;60,35101;
418,174;11,2868;60,36714;
418,97403;11,30272;60,37011;
419,77403;11,31876;60,37964;
420,574;11,33472;60,386;
421,37403;11,35076;60,39923;
422,174;11,36668;60,40531;
422,97403;11,38264;60,41587;
423,77403;11,39852;60,42475;
424,574;11,41472;60,44287;
425,37403;11,43076;60,44893;
426,174;11,44676;60,45761;
426,97403;11,46276;60,46288;
427,77403;11,47884;60,4731;
428,574;11,49464;60,47624;
429,37403;11,5106;60,48861;
430,174;11,5266;60,49628;
430,97403;11,54268;60,50843;
431,77403;11,55868;60,51604;
432,57403;11,5746;60,52362;
433,37403;11,5906;60,53363;
434,174;11,60664;60,54591;
434,97403;11,6226;60,5496;
435,77403;11,63852;60,55866;
436,57403;11,65452;60,56615;
437,37403;11,67064;60,57807;
438,174;11,68668;60,58688;
438,97403;11,70264;60,59298;
439,77403;11,71872;60,60245;
440,57403;11,73472;60,61166;
441,37403;11,75076;60,61882;
442,174;11,76668;60,62436;
442,97403;11,7826;60,63503;
443,77403;11,79864;60,64351;
444,57403;11,81476;60,65277;
445,37403;11,83076;60,65856;
446,174;11,84684;60,66853;
446,97403;11,8628;60,6753;
447,77403;11,87888;60,68228;
448,57403;11,8948;60,6882;
449,37403;11,91076;60,70047;
450,174;11,92676;60,70943;
450,97403;11,94288;60,71745;
451,77403;11,95872;60,72189;
452,57403;11,9748;60,73312;
453,37403;11,99072;60,73709;
454,174;12,0068;60,74975;
454,97403;12,02272;60,7552;
455,77403;12,03864;60,76242;
456,57403;12,05452;60,76946;
457,37403;12,07068;60,78351;
458,174;12,0866;60,78807;
458,97403;12,10264;60,79761;
459,77403;12,11856;60,79991;
460,57403;12,13464;60,81282;
461,37403;12,15052;60,81728;
462,174;12,16656;60,82624;
462,97403;12,18252;60,83427;
463,77403;12,19876;60,84686;
464,57403;12,21472;60,84902;
465,37403;12,23064;60,85673;
466,174;12,24644;60,86155;
466,97403;12,26256;60,87411;
467,77403;12,2784;60,87719;
468,57403;12,29448;60,8869;
469,37403;12,31044;60,89099;
470,174;12,32656;60,90238;
470,97403;12,34252;60,90832;
471,77403;12,35856;60,91567;
472,57403;12,3746;60,92194;
473,37403;12,39068;60,93084;
474,174;12,4066;60,93473;
474,97403;12,42256;60,94216;
475,77403;12,43852;60,9493;
476,57403;12,4548;60,96331;
477,37403;12,47088;60,96646;
478,174;12,48672;60,96689;
478,97403;12,50264;60,97441;
479,77403;12,51868;60,98475;
480,57403;12,53472;60,99105;
481,37403;12,5506;60,99747;
482,174;12,5666;61,00607;
482,97403;12,58268;61,01547;
483,77403;12,59876;61,02313;
484,57403;12,61468;61,02407;
485,37403;12,63076;61,0317;
486,174;12,64672;61,03703;
486,97403;12,66272;61,0425;
487,77403;12,6786;61,04677;
488,57403;12,69448;61,05329;
489,37403;12,71048;61,06304;
490,174;12,72656;61,07344;
490,97403;12,74256;61,07775;
491,77403;12,75868;61,08679;
492,57403;12,7746;61,09175;
493,37403;12,79064;61,0973;
494,174;12,80648;61,10041;
494,97403;12,82248;61,10938;
495,77403;12,83852;61,11581;
496,57403;12,85456;61,12313;
497,37403;12,87044;61,12584;
498,174;12,88652;61,13641;
498,97403;12,90252;61,14274;
499,77403;12,9186;61,15269;
500,57403;12,93452;61,15282;
501,37403;12,95048;61,1625;
502,174;12,96648;61,16593;
502,97403;12,98268;61,17432;
503,77403;12,9986;61,17576;
504,57403;13,01468;61,18655;
505,37403;13,03064;61,18802;
506,174;13,04676;61,19766;
506,97403;13,06264;61,19972;
507,77403;13,0786;61,20499;
508,57403;13,09444;61,21025;
509,37403;13,1106;61,22047;
510,174;13,1266;61,22321;
510,97403;13,14268;61,23194;
511,77403;13,15868;61,23205;
512,57403;13,17476;61,24082;
513,37403;13,19068;61,24525;
514,174;13,20668;61,25143;
514,974;13,2226;61,25457;
515,77406;13,23872;61,2656;
516,57403;13,25468;61,2694;
517,37403;13,27064;61,27365;
518,174;13,2866;61,2777;
518,974;13,30268;61,28651;
519,77406;13,31864;61,28798;
520,57403;13,3346;61,29106;
521,37403;13,35052;61,29583;
522,174;13,3666;61,308;
522,974;13,38264;61,31219;
523,77406;13,3986;61,31494;
524,57406;13,41464;61,32289;
525,374;13,43068;61,32903;
526,174;13,44668;61,32964;
526,974;13,4626;61,33497;
527,77406;13,47864;61,3421;
528,57406;13,49476;61,34745;
529,374;13,51084;61,3544;
530,174;13,52672;61,35559;
530,974;13,54268;61,36135;
531,77406;13,55856;61,36333;
532,57406;13,5746;61,37153;
533,374;13,59052;61,37598;
534,174;13,60656;61,3835;
534,974;13,6226;61,38851;
535,77406;13,63864;61,3947;
536,57406;13,6546;61,39725;
537,374;13,67072;61,40311;
538,174;13,68664;61,40769;
538,974;13,70276;61,41387;
539,77406;13,71864;61,41366;
540,57406;13,73456;61,41983;
541,374;13,7506;61,42825;
542,174;13,76684;61,43692;
542,974;13,78276;61,43747;
543,77406;13,79868;61,43613;
544,57406;13,81456;61,44381;
545,374;13,83068;61,45166;
546,174;13,84664;61,45283;
546,974;13,86256;61,45808;
547,77406;13,87856;61,46254;
548,57406;13,89472;61,47053;
549,374;13,91064;61,47218;
550,174;13,92672;61,47904;
550,974;13,9426;61,48088;
551,77406;13,95872;61,48952;
552,57406;13,97468;61,49008;
553,374;13,9906;61,49215;
554,174;14,00652;61,49559;
554,974;14,02272;61,50613;
555,77406;14,03868;61,50599;
556,57406;14,05472;61,51252;
557,374;14,07072;61,51296;
558,174;14,0868;61,52266;
558,974;14,10256;61,51931;
559,77406;14,11856;61,52796;
560,57406;14,13448;61,53154;
561,374;14,15072;61,54101;
562,174;14,16664;61,5382;
562,974;14,1826;61,5427;
563,77406;14,19864;61,54701;
564,57406;14,21472;61,55379;
565,374;14,2306;61,55496;
566,174;14,24656;61,56005;
566,974;14,26248;61,56518;
567,77406;14,27864;61,57611;
568,57406;14,29472;61,57683;
569,374;14,31064;61,57722;
570,174;14,32672;61,58245;
570,974;14,3428;61,58669;
571,77406;14,35876;61,5886;
572,57406;14,37468;61,59034;
573,374;14,3906;61,59185;
574,174;14,4066;61,60091;
574,974;14,42268;61,60661;
575,77406;14,43864;61,60783;
576,57406;14,45468;61,61282;
577,374;14,47068;61,61466;
578,174;14,48668;61,61835;
578,974;14,5026;61,61914;
579,77406;14,51864;61,62623;
580,57406;14,5346;61,62909;
581,374;14,55064;61,63502;
582,174;14,56656;61,63533;
582,974;14,58256;61,64241;
583,77406;14,59844;61,6447;
584,57406;14,61456;61,65095;
585,374;14,63044;61,64947;
586,174;14,6464;61,65524;
586,974;14,66232;61,65629;
587,77406;14,67848;61,66378;
588,57406;14,69448;61,66571;
589,374;14,7106;61,67148;
590,174;14,72652;61,67144;
590,974;14,7426;61,67668;
591,77406;14,75848;61,6757;
592,57406;14,77444;61,68367;
593,374;14,79044;61,68585;
594,174;14,80668;61,69416;
594,974;14,82264;61,69312;
595,77406;14,83872;61,69772;
596,57406;14,85456;61,6959;
597,374;14,87052;61,70243;
598,174;14,88644;61,70366;
598,974;14,90244;61,70934;
599,77406;14,91836;61,70985;
600,57406;14,93452;61,71993;
601,374;14,95048;61,72023;
602,174;14,96652;61,72256;
602,974;14,98248;61,72459;
603,77406;14,99864;61,73129;
604,57406;15,01452;61,72906;
605,374;15,03044;61,73086;
606,174;15,04636;61,73458;
606,974;15,06268;61,74821;
607,77406;15,07872;61,74731;
608,57406;15,09464;61,74468;
609,374;15,11044;61,74481;
610,174;15,12644;61,75247;
610,974;15,1424;61,75399;
611,77406;15,1584;61,7568;
612,57406;15,1744;61,75763;
613,374;15,19052;61,76558;
614,174;15,2066;61,76695;
614,974;15,22256;61,76704;
615,77406;15,23856;61,77079;
616,57406;15,2546;61,77654;
617,374;15,27052;61,77336;
618,174;15,28652;61,77835;
618,974;15,30244;61,78016;
619,77406;15,31852;61,78671;
620,57406;15,33464;61,7881;
621,374;15,3506;61,78643;
622,174;15,36668;61,79116;
622,97406;15,38268;61,79374;
623,77406;15,39868;61,79481;
624,57406;15,41444;61,79239;
625,374;15,43044;61,80196;
626,174;15,44644;61,8047;
626,97406;15,46256;61,80918;
627,77406;15,4784;61,80515;
628,57406;15,49444;61,81011;
629,374;15,51044;61,81194;
630,174;15,52652;61,81729;
630,97406;15,5424;61,81599;
631,77406;15,5584;61,82095;
632,57406;15,5744;61,82089;
633,374;15,59056;61,83039;
634,174;15,60648;61,8282;
634,97406;15,62252;61,83251;
635,77406;15,63852;61,83488;
636,57406;15,65468;61,83867;
637,374;15,6706;61,83622;
638,174;15,68656;61,83972;
638,97406;15,70248;61,83979;
639,77406;15,7186;61,84565;
640,57406;15,73456;61,84486;
641,374;15,75068;61,85142;
642,174;15,76664;61,85228;
642,97406;15,78272;61,85547;
643,77406;15,7986;61,85246;
644,57406;15,8146;61,85592;
645,374;15,83056;61,85626;
646,174;15,84672;61,86225;
646,97406;15,8626;61,86055;
647,77406;15,87864;61,86361;
648,57406;15,8946;61,86436;
649,374;15,91064;61,87104;
650,174;15,92652;61,86731;
650,97406;15,94248;61,87086;
651,77406;15,95836;61,87279;
652,57406;15,97456;61,87972;
653,374;15,99056;61,87799;
654,174;16,00656;61,88023;
654,97406;16,02256;61,87969;
655,77406;16,03864;61,88457;
656,57406;16,05452;61,88226;
657,374;16,07044;61,88386;
658,174;16,08644;61,88846;
658,97406;16,1026;61,89386;
659,77406;16,11872;61,89507;
660,57406;16,13464;61,89155;
661,374;16,15064;61,89324;
662,174;16,16664;61,8941;
662,97406;16,18252;61,89426;
663,77406;16,19844;61,89682;
664,57406;16,21448;61,89957;
665,374;16,23052;61,90375;
666,174;16,2466;61,90505;
666,97406;16,26252;61,90468;
667,77406;16,27856;61,90722;
668,57406;16,29456;61,90991;
669,374;16,3106;61,90927;
670,174;16,32652;61,90986;
670,97406;16,34248;61,91047;
671,77406;16,35848;61,91284;
672,57406;16,37472;61,92034;
673,374;16,39072;61,91577;
674,174;16,40668;61,91512;
674,97406;16,42248;61,91578;
675,77406;16,43856;61,92322;
676,57406;16,45444;61,92232;
677,374;16,47044;61,92331;
678,174;16,48644;61,92483;
678,97406;16,50256;61,92836;
679,77406;16,51856;61,92628;
680,57406;16,53456;61,92749;
681,374;16,55044;61,92777;
682,174;16,56656;61,93234;
682,97406;16,58244;61,93128;
683,77406;16,59844;61,93573;
684,57406;16,6144;61,93573;
685,374;16,63056;61,94093;
686,174;16,64648;61,93836;
686,97406;16,66264;61,94076;
687,77406;16,6786;61,9408;
688,57406;16,69472;61,9445;
689,374;16,71064;61,93969;
690,174;16,72648;61,9406;
690,97406;16,74244;61,94394;
691,77406;16,75864;61,94931;
692,57406;16,77452;61,945;
693,374;16,79052;61,94792;
694,174;16,8064;61,94667;
694,97406;16,82256;61,95455;
695,77406;16,83848;61,94915;
696,57406;16,8544;61,94989;
697,374;16,87032;61,9523;
698,174;16,88652;61,9585;
698,97406;16,90244;61,95669;
699,77406;16,9184;61,95877;
700,57406;16,93436;61,95815;
701,374;16,95052;61,9648;
702,174;16,96644;61,96027;
702,97406;16,9824;61,95926;
703,77406;16,99832;61,95886;
704,57406;17,01444;61,96498;
705,374;17,03044;61,96321;
706,174;17,0464;61,9637;
706,97406;17,06248;61,96426;
707,77406;17,07848;61,9646;
708,57406;17,09436;61,96442;
709,374;17,11044;61,96669;
710,174;17,1264;61,96465;
710,97406;17,14256;61,97115;
711,77406;17,15864;61,96868;
712,57406;17,17448;61,96472;
713,374;17,19048;61,96763;
714,174;17,20648;61,96794;
714,97406;17,22248;61,96917;
715,77406;17,2384;61,96819;
716,57406;17,2544;61,97029;
717,374;17,27036;61,97054;
718,174;17,28648;61,9715;
718,97406;17,3024;61,97042;
719,77406;17,31848;61,97309;
720,57406;17,33448;61,97173;
721,374;17,35056;61,97206;
722,174;17,36644;61,97112;
722,97406;17,38244;61,97493;
723,77406;17,39848;61,97346;
724,57406;17,41464;61,97807;
725,374;17,43064;61,97501;
726,174;17,44664;61,97408;
726,97406;17,46256;61,97319;
727,77406;17,4786;61,97592;
728,57406;17,49444;61,97333;
729,374;17,51044;61,97474;
730,174;17,5264;61,97658;
730,97406;17,54252;61,98024;
731,77406;17,55844;61,97639;
732,57406;17,57448;61,97883;
733,374;17,59044;61,97789;
734,174;17,6066;61,98292;
734,97406;17,62248;61,97687;
735,77406;17,63848;61,97761;
736,57406;17,6544;61,97491;
737,374;17,6706;61,98179;
738,174;17,68668;61,98177;
738,97406;17,70276;61,97976;
739,77406;17,71856;61,97194;
740,57406;17,73456;61,97774;
741,374;17,75048;61,97621;
742,174;17,76652;61,97806;
742,97406;17,78244;61,97622;
743,77406;17,79864;61,98163;
744,57406;17,81464;61,97903;
745,374;17,83068;61,97775;
746,174;17,84664;61,97552;
746,97406;17,86268;61,97844;
747,77406;17,8786;61,97429;
748,57406;17,89456;61,97444;
749,374;17,91048;61,9748;
750,174;17,92664;61,981;
750,97406;17,9426;61,97779;
751,77406;17,9586;61,97783;
752,57406;17,97468;61,97724;
753,374;17,99076;61,97787;
754,174;18,00676;61,9762;
754,97406;18,02264;61,97329;
755,77406;18,03856;61,97233;
756,57406;18,05468;61,97876;
757,374;18,0708;61,97724;
758,174;18,08664;61,97085;
758,97406;18,10264;61,97395;
759,77406;18,11864;61,97181;
760,57406;18,13468;61,97234;
761,374;18,1506;61,97122;
762,174;18,1666;61,97143;
762,97406;18,18264;61,97305;
763,77406;18,19876;61,97432;
764,57406;18,21468;61,96882;
765,374;18,23064;61,96805;
766,174;18,2466;61,96819;
766,97406;18,26264;61,97008;
767,77406;18,2786;61,96769;
768,57406;18,29456;61,96829;
769,374;18,31048;61,96826;
770,174;18,32664;61,97121;
770,97406;18,34252;61,96736;
771,77406;18,35852;61,96977;
772,57406;18,37448;61,96837;
773,374;18,3906;61,9688;
774,174;18,40648;61,96432;
774,97406;18,42248;61,9686;
775,77406;18,43848;61,96782;
776,57406;18,45464;61,96785;
777,374;18,47056;61,96228;
778,174;18,48656;61,96231;
778,97406;18,50248;61,95965;
779,77406;18,5186;61,96371;
780,57406;18,53452;61,96033;
781,374;18,55044;61,95818;
782,174;18,5664;61,95772;
782,97406;18,58252;61,96182;
783,77406;18,59844;61,95794;
784,57406;18,61448;61,95748;
785,374;18,63044;61,95301;
786,174;18,6466;61,95819;
786,97406;18,66252;61,95061;
787,77406;18,67844;61,94878;
788,57406;18,69444;61,9507;
789,374;18,71068;61,95408;
790,174;18,72668;61,95068;
790,97406;18,74268;61,95053;
791,77406;18,75864;61,94604;
792,57406;18,77464;61,94677;
793,374;18,79048;61,9379;
794,174;18,80644;61,94062;
794,97406;18,8224;61,94119;
795,77406;18,83856;61,94496;
796,57406;18,85456;61,94108;
797,374;18,87052;61,93893;
798,174;18,88648;61,93636;
798,97406;18,90252;61,93916;
799,77406;18,91848;61,93821;
800,57406;18,9344;61,93597;
801,374;18,95032;61,9328;
802,174;18,96636;61,93511;
802,97406;18,98256;61,93553;
803,77406;18,99856;61,93203;
804,57406;19,01464;61,93216;
805,374;19,03044;61,92384;
806,174;19,04644;61,92633;
806,97406;19,0624;61,92558;
807,77406;19,0784;61,92608;
808,57406;19,09436;61,92576;
809,374;19,11056;61,92651;
810,174;19,12652;61,91911;
810,97406;19,1426;61,92141;
811,77406;19,15856;61,91564;
812,57406;19,17464;61,91642;
813,374;19,19048;61,91136;
814,174;19,20656;61,91301;
814,97406;19,22248;61,91018;
815,77406;19,23864;61,9128;
816,57406;19,25456;61,9084;
817,374;19,2706;61,90775;
818,174;19,2866;61,90563;
818,97406;19,30276;61,90395;
819,77406;19,31864;61,8993;
820,57406;19,33456;61,89477;
821,374;19,35052;61,89455;
822,174;19,36664;61,89793;
822,97406;19,38264;61,89334;
823,77406;19,39856;61,89082;
824,57406;19,41448;61,88976;
825,374;19,43056;61,89251;
826,174;19,44648;61,88606;
826,97406;19,46248;61,88415;
827,77406;19,47844;61,88205;
828,57406;19,4946;61,88449;
829,374;19,51052;61,87758;
830,174;19,52652;61,87611;
830,97406;19,54252;61,87323;
831,77406;19,55864;61,8775;
832,57406;19,5746;61,87275;
833,374;19,59052;61,87047;
834,174;19,60644;61,86807;
834,97406;19,62256;61,86993;
835,77406;19,63852;61,8641;
836,57406;19,65456;61,86249;
837,374;19,6706;61,8583;
838,174;19,68672;61,86182;
838,97406;19,70264;61,85281;
839,77406;19,7186;61,85037;
840,57406;19,73456;61,84853;
841,374;19,75076;61,85221;
842,174;19,7668;61,84649;
842,97406;19,78272;61,84171;
843,77406;19,79868;61,838;
844,57406;19,81476;61,83994;
845,374;19,83068;61,83217;
846,174;19,8466;61,83043;
846,97406;19,86256;61,82904;
847,77406;19,8786;61,82947;
848,57406;19,89468;61,82806;
849,374;19,91056;61,82399;
850,174;19,9266;61,8238;
850,97406;19,94256;61,82257;
851,77406;19,9586;61,81791;
852,57406;19,97448;61,81229;
853,374;19,99044;61,81025;
854,174;20,00652;61,81208;
854,97406;20,02272;61,81129;
855,77406;20,03864;61,80489;
856,57406;20,05472;61,80389;
857,374;20,07064;61,79831;
858,174;20,08664;61,79852;
858,97406;20,10244;61,79041;
859,77406;20,11844;61,79178;
860,57406;20,13444;61,78945;
861,374;20,15068;61,79035;
862,174;20,1666;61,77962;
862,97406;20,18268;61,7802;
863,77406;20,19856;61,77372;
864,57406;20,21468;61,775;
865,374;20,23056;61,76905;
866,174;20,24652;61,76744;
866,97406;20,26244;61,76471;
867,77406;20,2786;61,76608;
868,57406;20,29464;61,76075;
869,374;20,31076;61,75838;
870,174;20,32664;61,75057;
870,97406;20,34256;61,74731;
871,77406;20,35848;61,74238;
872,57406;20,37448;61,74232;
873,374;20,39044;61,73791;
874,174;20,4066;61,73981;
874,97406;20,42264;61,73478;
875,77406;20,43868;61,73171;
876,57406;20,4546;61,72411;
877,374;20,47076;61,72373;
878,174;20,48672;61,71591;
878,97406;20,50264;61,7126;
879,77406;20,5186;61,70899;
880,57406;20,53476;61,70963;
881,374;20,55072;61,70294;
882,17406;20,56672;61,69901;
882,97406;20,58272;61,69632;
883,77406;20,59884;61,6958;
884,57406;20,6148;61,6878;
885,374;20,63076;61,6829;
886,17406;20,64656;61,67654;
886,97406;20,66276;61,67892;
887,77406;20,67876;61,67374;
888,57406;20,69472;61,66695;
889,374;20,71068;61,6608;
890,17406;20,72668;61,66079;
890,97406;20,74264;61,6556;
891,77406;20,7586;61,65056;
892,57406;20,77452;61,6432;
893,374;20,7906;61,64557;
894,17406;20,80664;61,64006;
894,97406;20,82256;61,63393;
895,77406;20,8386;61,62782;
896,57406;20,8546;61,62485;
897,374;20,87064;61,62103;
898,17406;20,8866;61,61466;
898,97406;20,90256;61,61078;
899,77406;20,91852;61,60726;
900,57406;20,9346;61,60393;
901,374;20,95048;61,59368;
902,17406;20,96656;61,59446;
902,97406;20,98256;61,58841;
903,77406;20,99868;61,5849;
904,57406;21,01456;61,57601;
905,374;21,03056;61,57075;
906,17406;21,04656;61,56788;
906,97406;21,06272;61,56397;
907,77406;21,07864;61,55341;
908,57406;21,0946;61,55176;
909,374;21,11052;61,5425;
910,17406;21,12664;61,54093;
910,97406;21,14248;61,53109;
911,77406;21,15848;61,52681;
912,57406;21,1744;61,52069;
913,374;21,19056;61,51884;
914,17406;21,20648;61,509;
914,97406;21,22252;61,50604;
915,77406;21,23844;61,49891;
916,57406;21,2546;61,4964;
917,374;21,27044;61,48541;
918,17406;21,28644;61,48;
918,97406;21,30236;61,47354;
919,77406;21,31856;61,47246;
920,57406;21,33464;61,46137;
921,374;21,35064;61,45426;
922,17406;21,36656;61,44444;
922,97406;21,38268;61,4415;
923,77406;21,39848;61,42722;
924,57406;21,4144;61,42329;
925,374;21,4304;61,41686;
926,17406;21,44656;61,41478;
926,97406;21,46264;61,40537;
927,77406;21,47864;61,39526;
928,57406;21,4946;61,38695;
929,374;21,51068;61,38226;
930,17406;21,52664;61,37157;
930,97406;21,5426;61,36259;
931,77406;21,55856;61,35495;
932,57406;21,57468;61,35076;
933,374;21,59072;61,34375;
934,17406;21,6068;61,33499;
934,97406;21,6228;61,32357;
935,77406;21,6388;61,31659;
936,57406;21,6546;61,30375;
937,374;21,67056;61,29634;
938,17406;21,68656;61,29182;
938,97406;21,70264;61,285;
939,77406;21,71876;61,27548;
940,57406;21,73464;61,2623;
941,374;21,75068;61,2542;
942,17406;21,76668;61,24583;
942,97406;21,78268;61,23703;
943,77406;21,79856;61,2228;
944,57406;21,81452;61,21619;
945,374;21,8306;61,2084;
946,17406;21,84672;61,19694;
946,97406;21,8626;61,18457;
947,77406;21,87868;61,17696;
948,57406;21,89464;61,16499;
949,374;21,91076;61,15884;
950,17406;21,92664;61,14419;
950,97406;21,94252;61,13244;
951,77406;21,95852;61,12511;
952,57406;21,97472;61,11578;
953,374;21,99072;61,10005;
954,17406;22,00668;61,08804;
954,97406;22,0226;61,0745;
955,77406;22,03864;61,06648;
956,57406;22,0546;61,05247;
957,374;22,0706;61,04148;
958,17406;22,08652;61,02999;
958,97406;22,10272;61,02297;
959,77406;22,11872;61,00252;
960,57406;22,13472;60,98968;
961,374;22,1506;60,97378;
962,17406;22,16676;60,96522;
962,97406;22,18268;60,94962;
963,77406;22,19872;60,93658;
964,57406;22,21464;60,92002;
965,374;22,23076;60,91091;
966,17406;22,24668;60,89356;
966,97406;22,26268;60,8824;
967,77406;22,2786;60,8672;
968,57406;22,2948;60,85741;
969,374;22,31072;60,83539;
970,17406;22,32668;60,82163;
970,97406;22,34268;60,80692;
971,77406;22,3588;60,79621;
972,57406;22,37484;60,77815;
973,374;22,39072;60,75892;
974,17406;22,40664;60,74267;
974,97406;22,42272;60,73326;
975,77406;22,43864;60,71103;
976,57406;22,45456;60,69451;
977,374;22,47056;60,67626;
978,17406;22,48672;60,6646;
978,97406;22,50272;60,64462;
979,77406;22,51868;60,62614;
980,57406;22,53464;60,6074;
981,374;22,55068;60,59346;
982,17406;22,56668;60,57344;
982,97406;22,58256;60,55489;
983,77406;22,59856;60,5382;
984,57406;22,61464;60,52389;
985,374;22,6308;60,50467;
986,17406;22,64676;60,4823;
986,97406;22,6628;60,46272;
987,77406;22,67876;60,44356;
988,57406;22,69476;60,42508;
989,374;22,71056;60,40026;
990,17406;22,72648;60,38531;
990,97406;22,74252;60,36904;
991,77406;22,75868;60,35067;
992,57406;22,7746;60,32581;
993,374;22,79068;60,30634;
994,17406;22,80664;60,28196;
994,97406;22,82272;60,26521;
995,77406;22,83864;60,24042;
996,57406;22,8546;60,22087;
997,374;22,8706;60,20067;
998,17406;22,88676;60,1812;
998,97406;22,90268;60,15756;
999,77406;22,9188;60,1385;
1000,57406;22,93476;60,11022;
1001,374;22,95068;60,08533;
1002,17406;22,96652;60,06281;
1002,97406;22,98252;60,0404;
1003,77406;22,99848;60,01821;
1004,57406;23,01472;59,99854;
1005,374;23,03068;59,96849;
1006,17406;23,04672;59,94733;
1006,97406;23,06272;59,92256;
1007,77406;23,07876;59,89904;
1008,57406;23,09468;59,87104;
1009,374;23,1106;59,84662;
1010,17406;23,12656;59,8191;
1010,97406;23,14272;59,79668;
1011,77406;23,15876;59,76658;
1012,57406;23,17476;59,74095;
1013,374;23,19072;59,71279;
1014,17406;23,20684;59,69114;
1014,97406;23,22272;59,66086;
1015,77406;23,23868;59,63531;
1016,57406;23,2546;59,60709;
1017,374;23,27072;59,587;
1018,17406;23,2868;59,55527;
1018,97406;23,3028;59,52413;
1019,77406;23,31868;59,49239;
1020,57406;23,33472;59,46673;
1021,374;23,35064;59,43576;
1022,17406;23,3666;59,40919;
1022,97406;23,38256;59,38178;
1023,77406;23,39872;59,35722;
1024,57413;23,41476;59,32747;
1025,374;23,43072;59,29489;
1026,17406;23,44668;59,26293;
1026,974;23,46268;59,23529;
1027,77406;23,47868;59,20063;
1028,57413;23,49464;59,17084;
1029,374;23,51064;59,14046;
1030,17406;23,52672;59,11278;
1030,974;23,54276;59,08014;
1031,77406;23,55864;59,04483;
1032,57413;23,57468;59,01546;
1033,374;23,59068;58,98506;
1034,17406;23,60672;58,95252;
1034,974;23,62268;58,91365;
1035,77406;23,63864;58,88268;
1036,57413;23,65472;58,85136;
1037,374;23,67084;58,81784;
1038,17406;23,68672;58,7828;
1038,974;23,70276;58,75019;
1039,77406;23,71868;58,71575;
1040,57413;23,7348;58,68378;
1041,374;23,75068;58,64435;
1042,17406;23,76664;58,61209;
1042,974;23,78264;58,57789;
1043,77406;23,7988;58,54055;
1044,57413;23,81468;58,50131;
1045,374;23,83072;58,46756;
1046,17406;23,84668;58,42906;
1046,974;23,8628;58,39708;
1047,77406;23,87876;58,35803;
1048,57413;23,89476;58,3216;
1049,374;23,91068;58,28435;
1050,17412;23,92692;58,25016;
1050,974;23,94292;58,20789;
1051,774;23,95904;58,17105;
1052,57413;23,97504;58,12589;
1053,374;23,99112;58,09001;
1054,17412;24,00704;58,04569;
1054,974;24,02292;58,00784;
1055,774;24,03884;57,96886;
1056,57413;24,05504;57,93642;
1057,374;24,07104;57,89041;
1058,17412;24,08704;57,84985;
1058,974;24,10296;57,80746;
1059,774;24,11908;57,76873;
1060,57413;24,135;57,7221;
1061,374;24,151;57,68126;
1062,17412;24,16696;57,63786;
1062,974;24,18304;57,5995;
1063,774;24,19904;57,55376;
1064,57413;24,21512;57,51317;
1065,374;24,23112;57,46711;
1066,17412;24,24724;57,42548;
1066,974;24,26292;57,37251;
1067,774;24,27884;57,33106;
1068,57413;24,29484;57,28759;
1069,374;24,311;57,24437;
1070,17412;24,32704;57,19688;
1070,974;24,34304;57,14954;
1071,774;24,35896;57,10177;
1072,57413;24,375;57,05912;
1073,374;24,39104;57,00871;
1074,17412;24,40692;56,96217;
1074,974;24,42296;56,9179;
1075,774;24,439;56,87024;
1076,57413;24,45504;56,8204;
1077,374;24,471;56,76677;
1078,17412;24,48704;56,71735;
1078,974;24,50304;56,66941;
1079,774;24,51912;56,61708;
1080,57413;24,53508;56,56502;
1081,374;24,55104;56,51732;
1082,17412;24,567;56,46473;
1082,974;24,58312;56,41518;
1083,774;24,59904;56,36014;
1084,57413;24,61512;56,30817;
1085,374;24,63104;56,25094;
1086,17412;24,64708;56,19938;
1086,974;24,66304;56,1429;
1087,774;24,67904;56,09123;
1088,57413;24,69504;56,03694;
1089,374;24,71124;55,98261;
1090,17412;24,72716;55,92371;
1090,974;24,74316;55,87035;
1091,774;24,75912;55,80984;
1092,57413;24,7752;55,75418;
1093,374;24,79116;55,69424;
1094,17412;24,8072;55,63629;
1094,974;24,82312;55,5752;
1095,774;24,83924;55,51973;
1096,57413;24,85516;55,45729;
1097,374;24,8712;55,40131;
1098,17412;24,88716;55,33904;
1098,974;24,90328;55,28225;
1099,774;24,9192;55,21761;
1100,57413;24,9352;55,15375;
1101,374;24,95112;55,08991;
1102,17412;24,96736;55,03052;
1102,974;24,98336;54,95897;
1103,774;24,99936;54,89604;
1104,57413;25,01524;54,82947;
1105,374;25,03136;54,76767;
1106,17412;25,04724;54,69955;
1106,974;25,0632;54,63427;
1107,774;25,07916;54,56586;
1108,57413;25,09528;54,50475;
1109,374;25,11124;54,43071;
1110,17412;25,1272;54,35832;
1110,974;25,14316;54,28705;
1111,774;25,15928;54,22123;
1112,57413;25,1752;54,14454;
1113,374;25,19116;54,07498;
1114,17412;25,20716;54,00326;
1114,974;25,2232;53,93401;
1115,774;25,23932;53,86046;
1116,57413;25,25536;53,78447;
1117,374;25,27136;53,70799;
1118,17412;25,28744;53,63207;
1118,974;25,3034;53,55055;
1119,774;25,31928;53,47049;
1120,57413;25,33524;53,39497;
1121,374;25,35132;53,31724;
1122,17412;25,36744;53,23809;
1122,974;25,38344;53,15531;
1123,774;25,39948;53,07361;
1124,57413;25,41544;52,99295;
1125,374;25,43152;52,90949;
1126,17412;25,44748;52,82339;
1126,974;25,46344;52,73946;
1127,774;25,47952;52,65428;
1128,57413;25,49556;52,56584;
1129,374;25,51152;52,47624;
1130,17412;25,52768;52,39211;
1130,974;25,54364;52,29988;
1131,774;25,55968;52,21005;
1132,57413;25,57544;52,11453;
1133,374;25,59144;52,02637;
1134,17412;25,60744;51,93201;
1134,974;25,6236;51,8357;
1135,774;25,63956;51,73268;
1136,57413;25,65564;51,63404;
1137,374;25,6716;51,5281;
1138,17412;25,68768;51,42084;
1138,974;25,70368;51,30485;
1139,774;25,71964;51,17334;
1140,57413;25,7356;51,00414;
1141,374;25,75184;50,64375;
1142,062;25,76556;49,9099;
1142,302;25,7704;49,05801;
1142,348;25,77164;46,87026;
1142,364;25,77352;27,80709;